Workbook
Name \A: #REF!
Name \M: #REF!
Name ___ATS98: #REF!
Name ___BGT02: [1]Budget!$A$1:$IV$65536
Name ___CHF98: #REF!
Name ___CHX2002: [2]Zellennamen!#REF!
Name ___CHX2003: [2]Zellennamen!#REF!
Name ___CHX2004: [2]Zellennamen!#REF!
Name ___CHX2005: [2]Zellennamen!#REF!
Name ___DTB2003: #REF!
Name ___DTB2004: #REF!
Name ___LY01: '[3]Last Year'!$A$1:$IV$65536
Name ___Mkt1: '[4]Rolling F''Cast P&L'!$GQ$26:$GQ$42
Name ___VAR1: #REF!
Name ___VAR2: #REF!
Name ___var22: '[5](Setup)'!$C$17
Name ___VAR3: #REF!
Name ___VAR4: #REF!
Name ___VAR5: #REF!
Name ___VAR6: #REF!
Name ___VAR7: #REF!
Name __ATS98: #REF!
Name __BGT02: [1]Budget!$A$1:$IV$65536
Name __CHF98: #REF!
Name __CHX2002: [2]Zellennamen!#REF!
Name __CHX2003: [2]Zellennamen!#REF!
Name __CHX2004: [2]Zellennamen!#REF!
Name __CHX2005: [2]Zellennamen!#REF!
Name __DAT1: #REF!
Name __DAT10: #REF!
Name __DAT11: #REF!
Name __DAT12: #REF!
Name __DAT13: #REF!
Name __DAT14: #REF!
Name __DAT15: #REF!
Name __DAT16: #REF!
Name __DAT17: #REF!
Name __DAT18: #REF!
Name __DAT19: #REF!
Name __DAT2: #REF!
Name __DAT20: #REF!
Name __DAT21: #REF!
Name __DAT22: #REF!
Name __DAT23: #REF!
Name __DAT24: #REF!
Name __DAT25: #REF!
Name __DAT26: #REF!
Name __DAT27: #REF!
Name __DAT28: #REF!
Name __DAT29: #REF!
Name __DAT3: #REF!
Name __DAT30: #REF!
Name __DAT31: #REF!
Name __DAT32: #REF!
Name __DAT33: #REF!
Name __DAT34: #REF!
Name __DAT35: #REF!
Name __DAT36: #REF!
Name __DAT37: #REF!
Name __DAT38: #REF!

Sheet Summary Capex
C2: TỔNG GIÁ TRỊ ĐẦU TƯ CAPEX 2019 đến 2026 (VND)
C3: Ghi chú: 2019 không phát sinh | K3: ĐVT: VNĐ
D4: ='Capex TT 2020'!G2 -> 24000 | E4: ='Capex TT 2021'!G2 -> 24300 | F4: ='Capex TT 2022'!G2 -> 24500 | G4: ='Capex TT 2023'!G2 -> 24700 | H4: ='Capex TT 2024'!G2 -> 25000 | I4: ='Capex TT 2025'!G2 -> 25500 | J4: ='Capex TT 2026'!G2 -> 26500 | S4: ĐVT: USD
B5: STT | C5: Nội dung | D5: Giá trị đầu tư VND | L5: Giá trị đầu tư USD
D6: 2020 | E6: 2021 | F6: 2022 | G6: 2023 | H6: 2024 | I6: 2025 | J6: 2026 | K6: Cộng 2020 -> 2026 | L6: 2020 | M6: 2021 | N6: 2022 | O6: 2023 | P6: 2024 | Q6: 2025 | R6: 2026 | S6: Cộng 2020 -> 2026
B7: 1 | C7: Nhà cửa, vật kiến trúc | D7: =D22 -> 2816980160 | E7: =E22 -> 98740200260 | F7: =F22 -> 45313950003 | G7: =G22 -> 58568025289 | H7: =H22 -> 2816980160 | I7: =I22 -> 1842503798 | J7: =J22 -> 1087426293 | K7: =SUM(D7:J7) -> 211186065963 | L7: =D7/D$4 -> 117374.17 | M7: =E7/E$4 -> 4063382.7 | N7: =F7/F$4 -> 1849549 | O7: =G7/G$4 -> 2371175.1 | P7: =H7/H$4 -> 112679.21 | Q7: =I7/I$4 -> 72255.051 | R7: =J7/J$4 -> 41034.954 | S7: =SUM(L7:R7) -> 8627450.2
B8: 2 | C8: Máy móc thiết bị | D8: =D30 -> 4317651482 | E8: =E30 -> 217005167222 | F8: =F30 -> 176781774442 | G8: =G30-G28 -> 2.9387833e+11 | H8: =H30 -> 69251846447 | I8: =I30 -> 52052051838 | J8: =J30 -> 26020850224 | K8: =SUM(D8:J8) -> 8.3930768e+11 | L8: =D8/D$4 -> 179902.15 | M8: =E8/E$4 -> 8930253.8 | N8: =F8/F$4 -> 7215582.6 | O8: =G8/G$4 -> 11897908 | P8: =H8/H$4 -> 2770073.9 | Q8: =I8/I$4 -> 2041256.9 | R8: =J8/J$4 -> 981918.88 | S8: =SUM(L8:R8) -> 34016896
B9: 3 | C9: Khuôn đầu tư sản phẩm mới | D9: =VLOOKUP($C9,'Capex TT 2020'!$E$5:$G$86,2,0) -> 0 | E9: =VLOOKUP($C9,'Capex TT 2021'!$E$5:$G$86,2,0) -> 0 | F9: =VLOOKUP($C9,'Capex TT 2022'!$E$5:$G$86,2,0) -> 60000000 | G9: =VLOOKUP($C9,'Capex TT 2023'!$E$5:$G$114,2,0) -> 79900000 | H9: =VLOOKUP(C9,'Capex TT 2024'!$E$5:$F$79,2,0) -> 1164204641 | I9: =VLOOKUP(C9,'Capex TT 2025'!$E$5:$F$203,2,0) -> 0 | J9: =VLOOKUP(C9,'Capex TT 2026'!$E$5:$F$210,2,0) -> 0 | K9: =SUM(D9:J9) -> 1304104641 | L9: =D9/D$4 -> 0 | M9: =E9/E$4 -> 0 | N9: =F9/F$4 -> 2448.9796 | O9: =G9/G$4 -> 3234.8178 | P9: =H9/H$4 -> 46568.186 | Q9: =I9/I$4 -> 0 | R9: =J9/J$4 -> 0 | S9: =SUM(L9:R9) -> 52251.983
B10: 4 | C10: Khuôn đầu tư thay thế | D10: =VLOOKUP($C10,'Capex TT 2020'!$E$5:$G$86,2,0) -> 0 | E10: =VLOOKUP($C10,'Capex TT 2021'!$E$5:$G$86,2,0) -> 0 | F10: =VLOOKUP($C10,'Capex TT 2022'!$E$5:$G$86,2,0) -> 0 | G10: =VLOOKUP($C10,'Capex TT 2023'!$E$5:$G$114,2,0) -> 0 | H10: =VLOOKUP(C10,'Capex TT 2024'!$E$5:$F$79,2,0) -> 0 | I10: =VLOOKUP(C10,'Capex TT 2025'!$E$5:$F$203,2,0) -> 0 | J10: =VLOOKUP(C10,'Capex TT 2026'!$E$5:$F$210,2,0) -> 0 | K10: =SUM(D10:J10) -> 0 | L10: =D10/D$4 -> 0 | M10: =E10/E$4 -> 0 | N10: =F10/F$4 -> 0 | O10: =G10/G$4 -> 0 | P10: =H10/H$4 -> 0 | Q10: =I10/I$4 -> 0 | R10: =J10/J$4 -> 0 | S10: =SUM(L10:R10) -> 0
B11: 5 | C11: Phương tiện vận tải | D11: =VLOOKUP($C11,'Capex TT 2020'!$E$5:$G$86,2,0) -> 380000000 | E11: =VLOOKUP($C11,'Capex TT 2021'!$E$5:$G$86,2,0) -> 2573766789 | F11: =VLOOKUP($C11,'Capex TT 2022'!$E$5:$G$86,2,0) -> 7797835728 | G11: =VLOOKUP($C11,'Capex TT 2023'!$E$5:$G$114,2,0) -> 5418910000 | H11: =VLOOKUP(C11,'Capex TT 2024'!$E$5:$F$79,2,0) -> 306314815 | I11: =VLOOKUP(C11,'Capex TT 2025'!$E$5:$F$203,2,0) -> 589564815 | J11: =VLOOKUP(C11,'Capex TT 2026'!$E$5:$F$210,2,0) -> 4514261846 | K11: =SUM(D11:J11) -> 21580653993 | L11: =D11/D$4 -> 15833.333 | M11: =E11/E$4 -> 105916.33 | N11: =F11/F$4 -> 318279.01 | O11: =G11/G$4 -> 219389.07 | P11: =H11/H$4 -> 12252.593 | Q11: =I11/I$4 -> 23120.189 | R11: =J11/J$4 -> 170349.5 | S11: =SUM(L11:R11) -> 865140.03
B12: 6 | C12: Thiết bị quản lý | D12: =VLOOKUP($C12,'Capex TT 2020'!$E$5:$G$86,2,0) -> 0 | E12: =VLOOKUP($C12,'Capex TT 2021'!$E$5:$G$86,2,0) -> 105866000 | F12: =VLOOKUP($C12,'Capex TT 2022'!$E$5:$G$86,2,0) -> 1208647832 | G12: =VLOOKUP($C12,'Capex TT 2023'!$E$5:$G$114,2,0) -> 369065000 | H12: =VLOOKUP(C12,'Capex TT 2024'!$E$5:$F$79,2,0) -> 0 | I12: =VLOOKUP(C12,'Capex TT 2025'!$E$5:$F$203,2,0) -> 68076000 | J12: =VLOOKUP(C12,'Capex TT 2026'!$E$5:$F$210,2,0) -> 232367703 | K12: =SUM(D12:J12) -> 1984022535 | L12: =D12/D$4 -> 0 | M12: =E12/E$4 -> 4356.6255 | N12: =F12/F$4 -> 49332.565 | O12: =G12/G$4 -> 14941.903 | P12: =H12/H$4 -> 0 | Q12: =I12/I$4 -> 2669.6471 | R12: =J12/J$4 -> 8768.5926 | S12: =SUM(L12:R12) -> 80069.333
B13: 7 | C13: Phần mềm vi tính | D13: =VLOOKUP($C13,'Capex TT 2020'!$E$5:$G$86,2,0) -> 0 | E13: =VLOOKUP($C13,'Capex TT 2021'!$E$5:$G$86,2,0) -> 0 | F13: =VLOOKUP($C13,'Capex TT 2022'!$E$5:$G$86,2,0) -> 784148252 | G13: =G28 -> 3483552000 | H13: =VLOOKUP(C13,'Capex TT 2024'!$E$5:$F$79,2,0) -> 960422938 | I13: =VLOOKUP(C13,'Capex TT 2025'!$E$5:$F$203,2,0) -> 2485202733 | J13: =VLOOKUP(C13,'Capex TT 2026'!$E$5:$F$210,2,0) -> 0 | K13: =SUM(D13:J13) -> 7713325923 | L13: =D13/D$4 -> 0 | M13: =E13/E$4 -> 0 | N13: =F13/F$4 -> 32006.051 | O13: =G13/G$4 -> 141034.49 | P13: =H13/H$4 -> 38416.918 | Q13: =I13/I$4 -> 97458.931 | R13: =J13/J$4 -> 0 | S13: =SUM(L13:R13) -> 308916.39
B14: 8 | C14: Khác | D14: =VLOOKUP($C14,'Capex TT 2020'!$E$5:$G$86,2,0) -> 0 | E14: =VLOOKUP($C14,'Capex TT 2021'!$E$5:$G$86,2,0) -> 1813062045 | F14: =VLOOKUP($C14,'Capex TT 2022'!$E$5:$G$86,2,0) -> 0 | G14: =VLOOKUP($C14,'Capex TT 2023'!$E$5:$G$114,2,0) -> 0 | H14: =VLOOKUP(C14,'Capex TT 2024'!$E$5:$F$79,2,0) -> 0 | I14: =VLOOKUP(C14,'Capex TT 2025'!$E$5:$F$203,2,0) -> 0 | J14: =VLOOKUP(C14,'Capex TT 2026'!$E$5:$F$210,2,0) -> 1230644844 | K14: =SUM(D14:J14) -> 3043706889 | L14: =D14/D$4 -> 0 | M14: =E14/E$4 -> 74611.607 | N14: =F14/F$4 -> 0 | O14: =G14/G$4 -> 0 | P14: =H14/H$4 -> 0 | Q14: =I14/I$4 -> 0 | R14: =J14/J$4 -> 46439.428 | S14: =SUM(L14:R14) -> 121051.03
C15: TỔNG CỘNG | D15: =SUM(D7:D14) -> 7514631642 | E15: =SUM(E7:E14) -> 320238062316 | F15: =SUM(F7:F14) -> 231946356257 | G15: =SUM(G7:G14) -> 3.6179779e+11 | H15: =SUM(H7:H14) -> 74499769001 | I15: =SUM(I7:I14) -> 57037399184 | J15: =SUM(J7:J14) -> 33085550910 | K15: =SUM(K7:K14) -> 1.0861196e+12 | ... S15: =SUM(S7:S14) -> 44071775
C16: LŨY KẾ | D16: =D15 -> 7514631642 | E16: =E15+D16 -> 327752693958 | F16: =F15+E16 -> 559699050215 | G16: =G15+F16 -> 9.2149684e+11 | H16: =H15+G16 -> 9.9599661e+11 | I16: =I15+H16 -> 1.053034e+12 | J16: =J15+I16 -> 1.0861196e+12 | K16: =K15+J16 -> 2.1722391e+12 | L16: =L15 -> 313109.65 | M16: =M15+L16 -> 13491631 | N16: =N15+M16 -> 22958829 | O16: =O15+N16 -> 37606513 | P16: =P15+O16 -> 40586503 | Q16: =Q15+P16 -> 42823264 | R16: =R15+Q16 -> 44071775 | S16: =S15+R16 -> 88143551
C20: Nhà cửa vật kiến trúc (VNĐ)
D21: 2020 | E21: 2021 | F21: 2022 | G21: 2023 | H21: 2024 | I21: 2025 | J21: 2026 | K21: Cộng
D22: ='Nhà cửa vật kiến trúc (VNĐ)'!F5 -> 2816980160 | E22: ='Nhà cửa vật kiến trúc (VNĐ)'!F2 -> 98740200260 | F22: ='Nhà cửa vật kiến trúc (VNĐ)'!F3 -> 45313950003 | G22: ='Nhà cửa vật kiến trúc (VNĐ)'!F4 -> 58568025289 | H22: ='Nhà cửa vật kiến trúc (VNĐ)'!F5 -> 2816980160 | I22: ='Nhà cửa vật kiến trúc (VNĐ)'!F6 -> 1842503798 | J22: ='Nhà cửa vật kiến trúc (VNĐ)'!F7 -> 1087426293 | K22: =SUM(D22:I22) -> 210098639670
C24: Máy móc thiết bị | D24: (VNĐ)
D25: 2020 | E25: 2021 | F25: 2022 | G25: 2023 | H25: 2024 | I25: 2025 | J25: 2026 | K25: Cộng
C26: DTR | D26: =VLOOKUP($C24,'Capex TT 2020'!$E$5:$G$86,2,0) -> 4317651482 | E26: =VLOOKUP($C24,'Capex TT 2021'!$E$5:$G$86,2,0) -> 214888211254 | F26: =VLOOKUP($C24,'Capex TT 2022'!$E$5:$G$86,2,0) -> 36050065845 | G26: =VLOOKUP($C24,'Capex TT 2023'!$E$5:$G$86,2,0) -> 47513794431 | H26: =VLOOKUP(C24,'Capex TT 2024'!E5:F79,2,0) -> 69251846447 | I26: =VLOOKUP(C24,'Capex TT 2025'!E5:F92,2,0) -> 52052051838 | J26: =VLOOKUP(C24,'Capex TT 2026'!E5:F96,2,0) -> 26020850224 | K26: =SUM(D26:I26) -> 424073621297
C27: TNHH | D27: 0 | E27: ='TNHH sở hữu'!T1 -> 2116955968 | F27: ='TNHH sở hữu'!T2 -> 140731708597 | G27: =SUM(G28:G29) -> 2.4984809e+11 | H27: 0 | I27: 0 | J27: 0 | K27: =SUM(D27:I27) -> 3.9269676e+11
C28: Phần mềm vi tính | G28: ='TNHH sở hữu'!T4 -> 3483552000
C29: MMTB | G29: ='TNHH sở hữu'!T5 -> 2.4636454e+11
C30: Cộng | D30: =SUM(D26:D27) -> 4317651482 | E30: =SUM(E26:E27) -> 217005167222 | F30: =SUM(F26:F27) -> 176781774442 | G30: =SUM(G26:G27) -> 2.9736189e+11 | H30: =SUM(H26:H27) -> 69251846447 | I30: =SUM(I26:I27) -> 52052051838 | J30: =SUM(J26:J27) -> 26020850224 | K30: =SUM(K26:K27) -> 8.1677038e+11

Sheet Slide
A1: Nhóm tài sản (SAP) | B1: Tên Nhóm tài sản (SAP)
C2: STT | D2: Nội dung | E2: Giá trị đầu tư VND | F2: Giá trị đầu tư USD
C3: 1 | D3: Máy móc thiết bị | E3: ='Capex TT 2025'!F15 -> 52052051838 | F3: ='Capex TT 2025'!G15 -> 2041256.9
C4: 2 | D4: Nhà cửa, vật kiến trúc | E4: ='Capex TT 2025'!F5 -> 1842503798 | F4: ='Capex TT 2025'!G5 -> 72255.051
C5: 3 | D5: Thiết bị quản lí | E5: ='Capex TT 2025'!F90 -> 68076000 | F5: ='Capex TT 2025'!G90 -> 2669.6471
C6: 4 | D6: Khác | E6: ='Capex TT 2025'!F97 -> 0 | F6: ='Capex TT 2025'!G97 -> 0
C7: 5 | D7: Phần mềm vi tính | E7: ='Capex TT 2025'!F93 -> 2485202733 | F7: ='Capex TT 2025'!G93 -> 97458.931
C8: 6 | D8: Khuôn đầu tư sản phẩm mới | E8: ='Capex TT 2025'!F77 -> 0 | F8: ='Capex TT 2025'!G77 -> 0
C9: 7 | D9: Khuôn đầu tư thay thế | E9: ='Capex TT 2025'!F80 -> 0 | F9: ='Capex TT 2025'!G80 -> 0
C10: 8 | D10: Phương tiện vận tải | E10: ='Capex TT 2025'!F81 -> 589564815 | F10: ='Capex TT 2025'!G81 -> 23120.189
D11: CỘNG | E11: =SUM(E3:E10) -> 57037399184 | F11: =SUM(F3:F10) -> 2236760.8
C14: STT | D14: Bộ Phận | E14: Giá trị đầu tư VND | F14: Giá trị đầu tư USD
C15: 1 | D15: Cung ứng | E15: 546708775 | F15: =E15/25500 -> 21439.56
C16: 2 | D16: HCNS | E16: 192107000 | F16: =E16/25500 -> 7533.6078
C17: 3 | D17: Kế Toán | E17: 248763230 | F17: =E17/25500 -> 9755.4208
C18: 4 | D18: Kinh doanh | E18: 1938493958 | F18: =E18/25500 -> 76019.371
C19: 5 | D19: Kỹ thuật | E19: 2641290458 | F19: =E19/25500 -> 103580.02
C20: 6 | D20: QC | E20: 291950000 | F20: =E20/25500 -> 11449.02
C21: 7 | D21: R&D | E21: 1025280138 | F21: =E21/25500 -> 40207.064
C22: 8 | D22: Sản xuất | E22: 41990040054 | F22: =E22/25500 -> 1646668.2
D23: CỘNG | E23: =SUM(E15:E22) -> 48874633613 | F23: =SUM(F15:F22) -> 1916652.3 | G23: =E11-E23 -> 8162765571 | H23: =F11-F23 -> 320108.45

Sheet Capex TT 2026
E1: ĐẦU TƯ CAPEX THỰC TẾ 2026 | G1: Cập nhật | H1: 11.04.2026
F2: Tỷ giá: | G2: 26500 | H2: Lấy theo tỉ giá kế hoạch 2026
F3: =SUM(F5,F15,F77,F80,F81,F90,F97,F101) -> 33085550910 | G3: =SUM(G5,G15,G77,G80,G81,G90,G97,G101) -> 1248511.4
A4: Nhóm tài sản (SAP) | B4: Tên Nhóm tài sản (SAP) | C4: STT | D4: Mã TS | E4: Nội dung | F4: số tiền VND | G4: số tiền USD
C5: 1 | E5: Nhà cửa, vật kiến trúc | F5: =SUM(F6:F14) -> 1087426293 | G5: =F5/$G$2 -> 41034.954
A6: Z21110P | B6: Nhà cửa, vật kiến trúc - SX 627 | C6: =SUBTOTAL(3,$E$6:E6) -> 1 | D6: 101000030 | E6: TC lắp thông gió Xưởng F2 (Kỹ thuật) | F6: 722538166 | G6: =F6/$G$2 -> 27265.591
A7: Z21110P | B7: Nhà cửa, vật kiến trúc - SX 627 | C7: =SUBTOTAL(3,$E$6:E7) -> 2 | D7: 101000032 | E7: Mái che hồ nước sản xuất F3 | F7: 364888127 | G7: =F7/$G$2 -> 13769.363
C8: =SUBTOTAL(3,$E$6:E8) -> 2 | G8: =F8/$G$2 -> 0
C9: =SUBTOTAL(3,$E$6:E9) -> 2 | G9: =F9/$G$2 -> 0
C10: =SUBTOTAL(3,$E$6:E10) -> 2 | G10: =F10/$G$2 -> 0
C11: =SUBTOTAL(3,$E$6:E11) -> 2 | G11: =F11/$G$2 -> 0
C12: =SUBTOTAL(3,$E$6:E12) -> 2 | G12: =F12/$G$2 -> 0
C13: =SUBTOTAL(3,$E$6:E13) -> 2 | G13: =F13/$G$2 -> 0
C15: 2 | E15: Máy móc thiết bị | F15: =SUM(F16:F76) -> 26020850224 | G15: =F15/$G$2 -> 981918.88
A16: Z211201P | B16: Máy móc, thiết bị phụ - SX 627 | C16: =SUBTOTAL(3,$E$16:E16) -> 1 | D16: 104600162 | E16: Sàng rung hạt cho chuyền STAR-01 F03 | F16: 247617183 | G16: =F16/$G$2 -> 9344.0446
A17: Z211201P | B17: Máy móc, thiết bị phụ - SX 627 | C17: =SUBTOTAL(3,$E$16:E17) -> 2 | D17: 104600163 | E17: Sàng rung hạt chuyền STAR-03 F03 Sàng 1 | F17: 246437220 | G17: =F17/$G$2 -> 9299.5177
A18: Z211201P | B18: Máy móc, thiết bị phụ - SX 627 | C18: =SUBTOTAL(3,$E$16:E18) -> 3 | D18: 104600164 | E18: Sàng rung hạt chuyền STAR-03 F03 Sàng 2 | F18: 242357220 | G18: =F18/$G$2 -> 9145.5555
A19: Z211201P | B19: Máy móc, thiết bị phụ - SX 627 | C19: =SUBTOTAL(3,$E$16:E19) -> 4 | D19: 104600165 | E19: Sàng rung hạt cho máy MIX-03 F02 | F19: 225996893 | G19: =F19/$G$2 -> 8528.1846
A20: Z211201P | B20: Máy móc, thiết bị phụ - SX 627 | C20: =SUBTOTAL(3,$E$16:E20) -> 5 | D20: 104600166 | E20: Sàng rung hạt cho máy MEYE-01 F02 | F20: 225996893 | G20: =F20/$G$2 -> 8528.1846
A21: Z211201P | B21: Máy móc, thiết bị phụ - SX 627 | C21: =SUBTOTAL(3,$E$16:E21) -> 6 | D21: 104600178 | E21: Lắp đặt sàn lấy mẫu F03 | F21: 516564328 | G21: =F21/$G$2 -> 19492.994
A22: Z21120P | B22: Máy móc, thiết bị - SX 627 | C22: =SUBTOTAL(3,$E$16:E22) -> 7 | D22: 104000199 | E22: Nâng cấp hệ chân không SSP Star-01(F3) | F22: 1665768146 | G22: =F22/$G$2 -> 62859.175
A23: Z21180P | B23: TSCĐ khác - SX 627 | C23: =SUBTOTAL(3,$E$16:E23) -> 8 | D23: 115000040 | E23: Máy ép phun riêng Thử nghiệm HD-PP F2 | F23: 38275500 | G23: =F23/$G$2 -> 1444.3585
A24: Z21120P | B24: Máy móc, thiết bị - SX 627 | C24: =SUBTOTAL(3,$E$16:E24) -> 9 | D24: 104000200 | E24: Chuyền rửa Boretech 3 tấn/giờ F5 | F24: 22443634993 | G24: =F24/$G$2 -> 846929.62
A25: Z211201P | B25: Máy móc, thiết bị phụ - SX 627 | C25: =SUBTOTAL(3,$E$16:E25) -> 10 | D25: 104600180 | E25: Băng tải chuyển chai lựa KL Băm3 (F3) | F25: 96247486 | G25: =F25/$G$2 -> 3631.9806
A26: Z211201P | B26: Máy móc, thiết bị phụ - SX 627 | C26: =SUBTOTAL(3,$E$16:E26) -> 11 | D26: 104600184 | E26: Trục vít tải liệu 01 CHWO-B01 (F3) | F26: 71954362 | G26: =F26/$G$2 -> 2715.2589
C27: =SUBTOTAL(3,$E$16:E27) -> 11 | G27: =F27/$G$2 -> 0
C28: =SUBTOTAL(3,$E$16:E28) -> 11 | G28: =F28/$G$2 -> 0
C29: =SUBTOTAL(3,$E$16:E29) -> 11 | G29: =F29/$G$2 -> 0
C30: =SUBTOTAL(3,$E$16:E30) -> 11 | G30: =F30/$G$2 -> 0
C31: =SUBTOTAL(3,$E$16:E31) -> 11 | G31: =F31/$G$2 -> 0
C32: =SUBTOTAL(3,$E$16:E32) -> 11 | G32: =F32/$G$2 -> 0
C33: =SUBTOTAL(3,$E$16:E33) -> 11 | G33: =F33/$G$2 -> 0
C34: =SUBTOTAL(3,$E$16:E34) -> 11 | G34: =F34/$G$2 -> 0
C35: =SUBTOTAL(3,$E$16:E35) -> 11 | G35: =F35/$G$2 -> 0
C36: =SUBTOTAL(3,$E$16:E36) -> 11 | G36: =F36/$G$2 -> 0
C37: =SUBTOTAL(3,$E$16:E37) -> 11 | G37: =F37/$G$2 -> 0
C38: =SUBTOTAL(3,$E$16:E38) -> 11 | G38: =F38/$G$2 -> 0
... C75: =SUBTOTAL(3,$E$16:E75) -> 11 | G75: =F75/$G$2 -> 0
C77: 3 | E77: Khuôn đầu tư sản phẩm mới | F77: =SUM(F78:F79) -> 0 | G77: =F77/$G$2 -> 0
C78: =SUBTOTAL(3,$E$78:E78) -> 0 | G78: =F78/$G$2 -> 0
...

Sheet Capex TT 2025
E1: ĐẦU TƯ CAPEX THỰC TẾ 2025 | G1: Cập nhật | H1: 12.01.2026
F2: Tỷ giá: | G2: 25500 | H2: Lấy theo tỉ giá kế hoạch 2025
F3: =SUM(F5,F15,F77,F80,F81,F90,F93,F97) -> 57037399184 | G3: =SUM(G5,G15,G77,G80,G81,G90,G93,G97) -> 2236760.8
A4: Nhóm tài sản (SAP) | B4: Tên Nhóm tài sản (SAP) | C4: STT | D4: Mã TS | E4: Nội dung | F4: số tiền VND | G4: số tiền USD
C5: 1 | E5: Nhà cửa, vật kiến trúc | F5: =SUM(F6:F14) -> 1842503798 | G5: =F5/$G$2 -> 72255.051
A6: Z21110A | B6: Nhà cửa, vật kiến trúc - QL 642 | C6: =SUBTOTAL(3,$E$6:E6) -> 1 | D6: 103000016 | E6: Hạ tầng mạng cho 5 chốt chặn | F6: 140570000 | G6: =F6/$G$2 -> 5512.549
A7: Z21110A | B7: Nhà cửa, vật kiến trúc - QL 642 | C7: =SUBTOTAL(3,$E$6:E7) -> 2 | D7: 103000017 | E7: Nhà chờ cổng 1 | F7: 72217040 | G7: =F7/$G$2 -> 2832.0408
A8: Z211201P | B8: Máy móc, thiết bị phụ - SX 627 | C8: =SUBTOTAL(3,$E$6:E8) -> 3 | D8: 104600117 | E8: Nhà chống côn trùng Meyer F2 | F8: 127088350 | G8: =F8/$G$2 -> 4983.8569
A9: Z21180P | B9: TSCĐ khác - SX 627 | C9: =SUBTOTAL(3,$E$6:E9) -> 4 | D9: 115000029 | E9: Lắp đặt Vách bạt cuốn di động F2 và F3 | F9: 90591075 | G9: =F9/$G$2 -> 3552.5912
A10: Z21110A | B10: Nhà cửa, vật kiến trúc - QL 642 | C10: =SUBTOTAL(3,$E$6:E10) -> 5 | D10: 103000018 | E10: Chốt chặn F5 | F10: 108193230 | G10: =F10/$G$2 -> 4242.8718
A11: Z21110P | B11: Nhà cửa, vật kiến trúc - SX 627 | C11: =SUBTOTAL(3,$E$6:E11) -> 6 | D11: 101000026 | E11: Lắp mái che di động trục giữa F1 và F2 | F11: 723140800 | G11: =F11/$G$2 -> 28358.463
A12: Z21180P | B12: TSCĐ khác - SX 627 | C12: =SUBTOTAL(3,$E$6:E12) -> 7 | D12: 115000032 | E12: Thi công mới nhà vệ sinh Văn phòng F02 | F12: 248009202 | G12: =F12/$G$2 -> 9725.8511
A13: Z21180P | B13: TSCĐ khác - SX 627 | C13: =SUBTOTAL(3,$E$6:E13) -> 8 | D13: 115000035 | E13: Trạm sạc xe nâng-F5 | F13: 332694101 | G13: =F13/$G$2 -> 13046.827
C15: 2 | E15: Máy móc thiết bị | F15: =SUM(F16:F76) -> 52052051838 | G15: =F15/$G$2 -> 2041256.9
A16: Z21120P | B16: Máy móc, thiết bị - SX 627 | C16: =SUBTOTAL(3,$E$16:E16) -> 1 | D16: 104000158 | E16: Máy lọc bụi Cartridge CDC -PL-6 (QLCL) | F16: 36200000 | G16: =F16/$G$2 -> 1419.6078
A17: Z211201P | B17: Máy móc, thiết bị phụ - SX 627 | C17: =SUBTOTAL(3,$E$16:E17) -> 2 | D17: 104600123 | E17: Tủ hút H.chất Bestlab PhượngHải BL.H-2.0 | F17: 185000000 | G17: =F17/$G$2 -> 7254.902
A18: Z21120P | B18: Máy móc, thiết bị - SX 627 | C18: =SUBTOTAL(3,$E$16:E18) -> 3 | D18: 104000173 | E18: lắp chuyền rửa lạnh mới F03 | F18: 2745703965 | G18: =F18/$G$2 -> 107674.67
A19: Z21120P | B19: Máy móc, thiết bị - SX 627 | C19: =SUBTOTAL(3,$E$16:E19) -> 4 | D19: 104000176 | E19: TC máy tách liệu chuyền rửa lạnh F3 BRT | F19: 1300467332 | G19: =F19/$G$2 -> 50998.719
A20: Z21120P | B20: Máy móc, thiết bị - SX 627 | C20: =SUBTOTAL(3,$E$16:E20) -> 5 | D20: 104000179 | E20: Hệ khung sàn cho chuyền rửa lạnh mới F03 | F20: 486411454 | G20: =F20/$G$2 -> 19074.959
A21: Z21120P | B21: Máy móc, thiết bị - SX 627 | C21: =SUBTOTAL(3,$E$16:E21) -> 6 | D21: 104000183 | E21: TỦ ĐIỆN HỆ RỬA NÓNG CHWO-R02 | F21: 432632369 | G21: =F21/$G$2 -> 16965.975
A22: Z21120P | B22: Máy móc, thiết bị - SX 627 | C22: =SUBTOTAL(3,$E$16:E22) -> 7 | D22: 104000184 | E22: Máy tạo hạt nhựa Gran (HD02)(TLP) F2 | F22: 6670000000 | G22: =F22/$G$2 -> 261568.63
A23: Z211201P | B23: Máy móc, thiết bị phụ - SX 627 | C23: =SUBTOTAL(3,$E$16:E23) -> 8 | D23: 104600106 | E23: Sàng rung 2000x800 công suất 2000kg/h (F2) | F23: 118000000 | G23: =F23/$G$2 -> 4627.451
A24: Z211201P | B24: Máy móc, thiết bị phụ - SX 627 | C24: =SUBTOTAL(3,$E$16:E24) -> 9 | D24: 104600107 | E24: Sàng rung 2000x800 công suất 2000kg/h (F4) | F24: 118000000 | G24: =F24/$G$2 -> 4627.451
A25: Z211201P | B25: Máy móc, thiết bị phụ - SX 627 | C25: =SUBTOTAL(3,$E$16:E25) -> 10 | D25: 104600110 | E25: Máy móc tăng cường CHWO-R01 | F25: 1590298692 | G25: =F25/$G$2 -> 62364.655
A26: Z211201P | B26: Máy móc, thiết bị phụ - SX 627 | C26: =SUBTOTAL(3,$E$16:E26) -> 11 | D26: 104600111 | E26: HTxả bao Jumbo1 tấn tự động-Rửa nóng R01 | F26: 504861258 | G26: =F26/$G$2 -> 19798.481
A27: Z211201P | B27: Máy móc, thiết bị phụ - SX 627 | C27: =SUBTOTAL(3,$E$16:E27) -> 12 | D27: 104600112 | E27: HTxả bao Jumbo1 tấn tự động-Rửa lạnh R01 | F27: 500738186 | G27: =F27/$G$2 -> 19636.792
... A75: Z211201P | B75: Máy móc, thiết bị phụ - SX 627 | C75: =SUBTOTAL(3,$E$16:E75) -> 60 | D75: 104600161 | E75: Máy sấy bụi 1 tấn-F05 | F75: 453547830 | G75: =F75/$G$2 -> 17786.189
C77: 3 | E77: Khuôn đầu tư sản phẩm mới | F77: =SUM(F78:F79) -> 0 | G77: =F77/$G$2 -> 0
C78: =SUBTOTAL(3,$E$78:E78) -> 0 | G78: =F78/$G$2 -> 0
C79: =SUBTOTAL(3,$E$78:E79) -> 0 | G79: =F79/$G$2 -> 0
C80: 4 | E80: Khuôn đầu tư thay thế | F80: 0 | G80: =F80/$G$2 -> 0
C81: 5 | E81: Phương tiện vận tải | F81: =SUM(F82:F89) -> 589564815 | G81: =F81/$G$2 -> 23120.189
A82: Z21130P | B82: Phương tiện vận tải , truyền dẫn - SX 627 | C82: =SUBTOTAL(3,$E$82:E82) -> 1 | D82: 107000047 | E82: Xe nâng người GTJZ-10 (BYD) (PET) | F82: 290000000 | G82: =F82/$G$2 -> 11372.549
A83: Z21130P | B83: Phương tiện vận tải , truyền dẫn - SX 627 | C83: =SUBTOTAL(3,$E$82:E83) -> 2 | D83: 107000048 | E83: Xe AGV Chở hàng mẫu | F83: 70750000 | G83: =F83/$G$2 -> 2774.5098
A84: Z21130P | B84: Phương tiện vận tải , truyền dẫn - SX 627 | C84: =SUBTOTAL(3,$E$82:E84) -> 3 | D84: 107000049 | E84: Xe nâng tay điện HeliCBD20-ALH số 8 vị trí BORE-02 | F84: 37962963 | G84: =F84/$G$2 -> 1488.7436
A85: Z21130P | B85: Phương tiện vận tải , truyền dẫn - SX 627 | C85: =SUBTOTAL(3,$E$82:E85) -> 4 | D85: 107000050 | E85: Xe nâng tay điện Heli CBD20-ALH (F2-HD) (1) | F85: 37962963 | G85: =F85/$G$2 -> 1488.7436
A86: Z21130P | B86: Phương tiện vận tải , truyền dẫn - SX 627 | C86: =SUBTOTAL(3,$E$82:E86) -> 5 | D86: 107000051 | E86: Xe nâng tay điện Heli CBD20-ALH (F4-HD) (2) | F86: 37962963 | G86: =F86/$G$2 -> 1488.7436
A87: Z21130P | B87: Phương tiện vận tải , truyền dẫn - SX 627 | C87: =SUBTOTAL(3,$E$82:E87) -> 6 | D87: 107000052 | E87: Xe nâng tay điện Heli CBD20-ALH (MIX-09 -F3) | F87: 37962963 | G87: =F87/$G$2 -> 1488.7436
A88: Z21130P | B88: Phương tiện vận tải , truyền dẫn - SX 627 | C88: =SUBTOTAL(3,$E$82:E88) -> 7 | D88: 107000053 | E88: Xe nâng tay điện Heli CBD20-ALH (F5) | F88: 37962963 | G88: =F88/$G$2 -> 1488.7436
A89: Z21130P | B89: Phương tiện vận tải , truyền dẫn - SX 627 | C89: =SUBTOTAL(3,$E$82:E89) -> 8 | D89: 107000054 | E89: Xe nâng tay điện PTE20Q-A Noblelift (F5) | F89: 39000000 | G89: =F89/$G$2 -> 1529.4118
...

Sheet Capex TT 2024
E1: ĐẦU TƯ CAPEX THỰC TẾ 2024
F2: Tỷ giá: | G2: 25000
F3: =SUM(F5,F12,F55,F66,F67,F74,F76,F79) -> 74499769001 | G3: =SUM(G5,G12,G55,G66,G67,G74,G76,G79) -> 2979990.8
A4: Nhóm tài sản (SAP) | B4: Tên Nhóm tài sản (SAP) | C4: STT | D4: Mã TS | E4: Nội dung | F4: số tiền VND | G4: số tiền USD
C5: 1 | E5: Nhà cửa, vật kiến trúc | F5: =SUM(F6:F11) -> 2816980160 | G5: =F5/$G$2 -> 112679.21
A6: Z21180P | B6: TSCĐ khác - SX 627 | C6: =SUBTOTAL(3,$E$6:E6) -> 1 | D6: 115000018 | E6: Cung cấp lắp đặt chiller mở rộng | F6: 1744151201 | G6: =F6/$G$2 -> 69766.048
A7: Z21180P | B7: TSCĐ khác - SX 627 | C7: =SUBTOTAL(3,$E$6:E7) -> 2 | D7: 115000017 | E7: Hệ thống làm mát nhà xưởng (Đợt 3) | F7: 185719645 | G7: =F7/$G$2 -> 7428.7858
A8: Z21110A | B8: Nhà cửa, vật kiến trúc - QL 642 | C8: =SUBTOTAL(3,$E$6:E8) -> 3 | D8: 103000014 | E8: Trồng cỏ, cây xung quanh nhà máy | F8: 160781500 | G8: =F8/$G$2 -> 6431.26
A9: Z21110P | B9: Nhà cửa, vật kiến trúc - SX 627 | C9: =SUBTOTAL(3,$E$6:E9) -> 4 | D9: 101000022 | E9: Phòng thử nghiệm F03 | F9: 33811200 | G9: =F9/$G$2 -> 1352.448
A10: Z21110P | B10: Nhà cửa, vật kiến trúc - SX 627 | C10: =SUBTOTAL(3,$E$6:E10) -> 5 | D10: 101000023 | E10: Lắp đặt mái bạt xếp giữa F2 và E3 | F10: 621093014 | G10: =F10/$G$2 -> 24843.721
A11: Z21110A | B11: Nhà cửa, vật kiến trúc - QL 642 | D11: 103000015 | E11: Phòng Kế toán kho TĐH | F11: 71423600 | G11: =F11/$G$2 -> 2856.944
C12: 2 | E12: Máy móc thiết bị | F12: =SUM(F13:F54) -> 69251846447 | G12: =F12/$G$2 -> 2770073.9
A13: Z21180P | B13: TSCĐ khác - SX 627 | C13: =SUBTOTAL(3,$E$13:E13) -> 1 | D13: 115000016 | E13: Hệ thống XLNT 500 m3/ngày đêm | F13: 22957791544 | G13: =F13/$G$2 -> 918311.66
A14: Z21120P | B14: Máy móc, thiết bị - SX 627 | C14: =SUBTOTAL(3,$E$13:E14) -> 2 | D14: 104000162 | E14: Máy lựa chai Tomra (F4) | F14: 7378320048 | G14: =F14/$G$2 -> 295132.8
A15: Z21120P | B15: Máy móc, thiết bị - SX 627 | C15: =SUBTOTAL(3,$E$13:E15) -> 3 | D15: 104000149 | E15: Trạm điện SX xưởng F03, 05 | F15: 6912429918 | G15: =F15/$G$2 -> 276497.2
A16: Z21120P | B16: Máy móc, thiết bị - SX 627 | C16: =SUBTOTAL(3,$E$13:E16) -> 4 | D16: 104000161 | E16: Máy trộn nhựa KN L10000KG+ | F16: 1896886694 | G16: =F16/$G$2 -> 75875.468
A17: Z211201P | B17: Máy móc, thiết bị phụ - SX 627 | C17: =SUBTOTAL(3,$E$13:E17) -> 5 | D17: 104600091 | E17: Thi công Chuyền máy rửa PP MOOGETECH | F17: 1500556886 | G17: =F17/$G$2 -> 60022.275
A18: Z21120P | B18: Máy móc, thiết bị - SX 627 | C18: =SUBTOTAL(3,$E$13:E18) -> 6 | D18: 104000154 | E18: Chuyền băm rửa PET 03 (Lê Trần) | F18: 1470802869 | G18: =F18/$G$2 -> 58832.115
A19: Z211201P | B19: Máy móc, thiết bị phụ - SX 627 | C19: =SUBTOTAL(3,$E$13:E19) -> 7 | D19: 104600103 | E19: Băng tải+Vít tải phân loại vảy đầu vào W800 (TC) | F19: 1256000000 | G19: =F19/$G$2 -> 50240
A20: Z21120P | B20: Máy móc, thiết bị - SX 627 | C20: =SUBTOTAL(3,$E$13:E20) -> 8 | D20: 104000159 | E20: Máy Tạo Hạt Xơ Sợi YPET-01 | F20: 1128375223 | G20: =F20/$G$2 -> 45135.009
A21: Z21120P | B21: Máy móc, thiết bị - SX 627 | C21: =SUBTOTAL(3,$E$13:E21) -> 9 | D21: 104000160 | E21: Máy Tạo Hạt rPP YEI PP-01 | F21: 936402136 | G21: =F21/$G$2 -> 37456.085
A22: Z21120P | B22: Máy móc, thiết bị - SX 627 | C22: =SUBTOTAL(3,$E$13:E22) -> 10 | D22: 104000150 | E22: Máy Zig-Zag Mooge | F22: 751500302 | G22: =F22/$G$2 -> 30060.012
A23: Z21120P | B23: Máy móc, thiết bị - SX 627 | C23: =SUBTOTAL(3,$E$13:E23) -> 11 | D23: 104000156 | E23: HT Máy tách vảy Taiho Phó sản HD 5 máy (Taiho 3) | F23: 700209603 | G23: =F23/$G$2 -> 28008.384
A24: Z211201P | B24: Máy móc, thiết bị phụ - SX 627 | C24: =SUBTOTAL(3,$E$13:E24) -> 12 | D24: 104600094 | E24: Máy tạo hạt rPP dùng cho phòng Lab | F24: 400000000 | G24: =F24/$G$2 -> 16000
... A53: Z21140A | B53: Thiết bị, dụng cụ quản lý - QL 642 | C53: =SUBTOTAL(3,$E$13:E53) -> 41 | D53: 112000021 | E53: Hệ thống camera DTR (49 cái) | F53: 351402508 | G53: =F53/$G$2 -> 14056.1
C55: 3 | E55: Khuôn đầu tư sản phẩm mới | F55: =SUM(F56:F65) -> 1164204641 | G55: =F55/$G$2 -> 46568.186
A56: Z21180A | B56: TSCĐ khác - QL 642 | C56: =SUBTOTAL(3,$E$56:E56) -> 1 | D56: 117000008 | E56: Khuôn Đầu bút & Thân bút (MIDA) | F56: 235000000 | G56: =F56/$G$2 -> 9400
A57: Z21180A | B57: TSCĐ khác - QL 642 | C57: =SUBTOTAL(3,$E$56:E57) -> 2 | D57: 117000010 | E57: Khuôn lõi bấm & lõi xoay (MIDA) | F57: 211500000 | G57: =F57/$G$2 -> 8460
A58: Z21180A | B58: TSCĐ khác - QL 642 | C58: =SUBTOTAL(3,$E$56:E58) -> 3 | D58: 117000009 | E58: Khuôn đầu ren | F58: 188000000 | G58: =F58/$G$2 -> 7520
A59: Z21180P | B59: TSCĐ khác - SX 627 | C59: =SUBTOTAL(3,$E$56:E59) -> 4 | D59: 115000013 | E59: Khuôn miếng lót ly(F03) | F59: 85500000 | G59: =F59/$G$2 -> 3420
A60: Z21120P | B60: Máy móc, thiết bị - SX 627 | C60: =SUBTOTAL(3,$E$56:E60) -> 5 | D60: 104000153 | E60: Khuôn phôi D28 P19.5 (F03) | F60: 82950000 | G60: =F60/$G$2 -> 3318
A61: Z21180P | B61: TSCĐ khác - SX 627 | C61: =SUBTOTAL(3,$E$56:E61) -> 6 | D61: 115000012 | E61: Khuôn chai nhớt(F02) | F61: 82154641 | G61: =F61/$G$2 -> 3286.1856
A62: Z21180P | B62: TSCĐ khác - SX 627 | C62: =SUBTOTAL(3,$E$56:E62) -> 7 | D62: 115000011 | E62: Khuôn chai nước sưới 350ml(F03) | F62: 62000000 | G62: =F62/$G$2 -> 2480
A63: Z21180P | B63: TSCĐ khác - SX 627 | C63: =SUBTOTAL(3,$E$56:E63) -> 8 | D63: 115000014 | E63: Khuôn chai coca(F03) | F63: 62000000 | G63: =F63/$G$2 -> 2480
A64: Z21180P | B64: TSCĐ khác - SX 627 | C64: =SUBTOTAL(3,$E$56:E64) -> 9 | D64: 115000022 | E64: Bơm chân không Vacuubrand MZ 2C NT+AK+EK | F64: 95100000 | G64: =F64/$G$2 -> 3804
A65: Z21180P | B65: TSCĐ khác - SX 627 | C65: =SUBTOTAL(3,$E$56:E65) -> 10 | D65: 115000024 | E65: Máy ghi điện 3P FLUKE 1730 iFlex6000-36 | F65: 60000000 | G65: =F65/$G$2 -> 2400
C66: 4 | E66: Khuôn đầu tư thay thế | F66: 0 | G66: =F66/$G$2 -> 0
C67: 5 | E67: Phương tiện vận tải | F67: =SUM(F68:F73) -> 306314815 | G67: =F67/$G$2 -> 12252.593
A68: Z21130P | B68: Phương tiện vận tải , truyền dẫn - SX 627 | C68: =SUBTOTAL(3,$E$68:E68) -> 1 | D68: 107000040 | E68: Xe nâng tay điện Heli CBD20-AliH 1 | F68: 37962963 | G68: =F68/$G$2 -> 1518.5185
A69: Z21130P | B69: Phương tiện vận tải , truyền dẫn - SX 627 | C69: =SUBTOTAL(3,$E$68:E69) -> 2 | D69: 107000042 | E69: Xe nâng tay điện Heli CBD20-AliH 2 | F69: 37962963 | G69: =F69/$G$2 -> 1518.5185
...

Sheet Capex TT 2023
E1: ĐẦU TƯ CAPEX THỰC TẾ 2023
F2: Tỷ giá: | G2: 24700
F3: =SUM(F5,F24,F86,F88,F89,F104,F110,F112) -> 57892496559 | G3: =SUM(G5,G24,G86,G88,G89,G104,G110,G112) -> 2343825.8
A4: Nhóm tài sản (SAP) | B4: Tên Nhóm tài sản (SAP) | C4: STT | D4: Mã TS | E4: Nội dung | F4: số tiền VND | G4: số tiền USD
C5: 1 | E5: Nhà cửa, vật kiến trúc | F5: =SUM(F6:F23) -> 4510827128 | G5: =F5/$G$2 -> 182624.58
A6: Z21110P | B6: Nhà cửa, vật kiến trúc - SX 627 | C6: =SUBTOTAL(3,$E$6:E6) -> 1 | D6: 101000019 | E6: Hệ thống làm mát nhà xưởng | F6: 958076791 | G6: =F6/$G$2 -> 38788.534
A7: Z21180A | B7: TSCĐ khác - QL 642 | C7: =SUBTOTAL(3,$E$6:E7) -> 2 | D7: 117000002 | E7: Hạng mục phụ nhà xưởng (VP F02, bó vĩa, điện, sơn) | F7: 807761229 | G7: =F7/$G$2 -> 32702.884
A8: Z21110A | B8: Nhà cửa, vật kiến trúc - QL 642 | C8: =SUBTOTAL(3,$E$6:E8) -> 3 | D8: 103000008 | E8: Ốp gạch và trồng cỏ nhà xưởng | F8: 309657600 | G8: =F8/$G$2 -> 12536.745
A9: Z21180A | B9: TSCĐ khác - QL 642 | C9: =SUBTOTAL(3,$E$6:E9) -> 4 | D9: 117000001 | E9: Nguồn bơm giếng và tưới cỏ | F9: 308593906 | G9: =F9/$G$2 -> 12493.68
A10: Z21110P | B10: Nhà cửa, vật kiến trúc - SX 627 | C10: =SUBTOTAL(3,$E$6:E10) -> 5 | D10: 101000018 | E10: Lắp vít tải phân loại vảy đầu vào | F10: 304857717 | G10: =F10/$G$2 -> 12342.418
A11: Z21110A | B11: Nhà cửa, vật kiến trúc - QL 642 | C11: =SUBTOTAL(3,$E$6:E11) -> 6 | D11: 103000009 | E11: Thi công các hạng mục xây dựng nhà xưởng | F11: 278150000 | G11: =F11/$G$2 -> 11261.134
A12: Z21110A | B12: Nhà cửa, vật kiến trúc - QL 642 | C12: =SUBTOTAL(3,$E$6:E12) -> 7 | D12: 103000007 | E12: Đường nước tưới cây xung quanh nhà máy | F12: 267942150 | G12: =F12/$G$2 -> 10847.86
A13: Z21180A | B13: TSCĐ khác - QL 642 | C13: =SUBTOTAL(3,$E$6:E13) -> 8 | D13: 117000007 | E13: Lắp đặt cáp thoại nhà bảo vệ 1 và 3 | F13: 261991507 | G13: =F13/$G$2 -> 10606.944
A14: Z21110A | B14: Nhà cửa, vật kiến trúc - QL 642 | C14: =SUBTOTAL(3,$E$6:E14) -> 9 | D14: 103000005 | E14: Cửa cổng chính số 02 và 03 | F14: 184508875 | G14: =F14/$G$2 -> 7469.9949
A15: Z21110A | B15: Nhà cửa, vật kiến trúc - QL 642 | C15: =SUBTOTAL(3,$E$6:E15) -> 10 | D15: 103000006 | E15: Lắp đặt nhôm kính phòng Kỹ Thuật | F15: 174699000 | G15: =F15/$G$2 -> 7072.834
A16: Z21110A | B16: Nhà cửa, vật kiến trúc - QL 642 | C16: =SUBTOTAL(3,$E$6:E16) -> 11 | D16: 103000010 | E16: Nhà chứa bùn F05 | F16: 118791283 | G16: =F16/$G$2 -> 4809.3637
A17: Z21110A | B17: Nhà cửa, vật kiến trúc - QL 642 | C17: =SUBTOTAL(3,$E$6:E17) -> 12 | D17: 103000011 | E17: Hệ thống giữ xe | F17: 117700000 | G17: =F17/$G$2 -> 4765.1822
... A23: Z21180P | B23: TSCĐ khác - SX 627 | C23: =SUBTOTAL(3,$E$6:E23) -> 18 | D23: 115000008 | E23: Thi công nhà bạt F6 | F23: 53030000 | G23: =F23/$G$2 -> 2146.9636
C24: 2 | E24: Máy móc thiết bị | F24: =SUM(F25:F85) -> 47513794431 | G24: =F24/$G$2 -> 1923635.4
A25: Z21180P | B25: TSCĐ khác - SX 627 | C25: =SUBTOTAL(3,$E$25:E25) -> 1 | D25: 115000010 | E25: Hệ thống XLNT 400m3/ngày đêm | F25: 6445602086 | G25: =F25/$G$2 -> 260955.55
A26: Z21120P | B26: Máy móc, thiết bị - SX 627 | C26: =SUBTOTAL(3,$E$25:E26) -> 2 | D26: 104000097 | E26: Thiết bị phụ chuyền máy Starlinger 2 | F26: 4460334770 | G26: =F26/$G$2 -> 180580.36
A27: Z21120P | B27: Máy móc, thiết bị - SX 627 | C27: =SUBTOTAL(3,$E$25:E27) -> 3 | D27: 104000125 | E27: Chuyền băm PET số 02 | F27: 3033103521 | G27: =F27/$G$2 -> 122797.71
A28: Z21120P | B28: Máy móc, thiết bị - SX 627 | C28: =SUBTOTAL(3,$E$25:E28) -> 4 | D28: 104000124 | E28: Máy lựa vảy UV Meyer | F28: 2396767041 | G28: =F28/$G$2 -> 97035.103
A29: Z21120P | B29: Máy móc, thiết bị - SX 627 | C29: =SUBTOTAL(3,$E$25:E29) -> 5 | D29: 104000126 | E29: Chuyền rửa vảy CW2 | F29: 2381394958 | G29: =F29/$G$2 -> 96412.751
A30: Z21120P | B30: Máy móc, thiết bị - SX 627 | C30: =SUBTOTAL(3,$E$25:E30) -> 6 | D30: 104000113 | E30: Hệ thống phối trộn tự động WSB - 3000T | F30: 2135314321 | G30: =F30/$G$2 -> 86449.973
A31: Z21120P | B31: Máy móc, thiết bị - SX 627 | C31: =SUBTOTAL(3,$E$25:E31) -> 7 | D31: 104000102 | E31: Máy tách màu Taiho 6SXM-10008FS | F31: 1885681729 | G31: =F31/$G$2 -> 76343.39
A32: Z21120P | B32: Máy móc, thiết bị - SX 627 | C32: =SUBTOTAL(3,$E$25:E32) -> 8 | D32: 104000098 | E32: Máy tách màu Taiho 6SXM-10008FS - 2 | F32: 1856733952 | G32: =F32/$G$2 -> 75171.415
A33: Z21120P | B33: Máy móc, thiết bị - SX 627 | C33: =SUBTOTAL(3,$E$25:E33) -> 9 | D33: 104000109 | E33: Máy tách màu Taiho số 3 | F33: 1849055197 | G33: =F33/$G$2 -> 74860.534
A34: Z21120P | B34: Máy móc, thiết bị - SX 627 | C34: =SUBTOTAL(3,$E$25:E34) -> 10 | D34: 104000140 | E34: Chuyền tạo hạt rPP số 2 (Yei) | F34: 1798575168 | G34: =F34/$G$2 -> 72816.808
A35: Z21120P | B35: Máy móc, thiết bị - SX 627 | C35: =SUBTOTAL(3,$E$25:E35) -> 11 | D35: 104000135 | E35: Trạm điện 4x3000kVA-22V/0,4kV | F35: 1782611000 | G35: =F35/$G$2 -> 72170.486
A36: Z211201P | B36: Máy móc, thiết bị phụ - SX 627 | C36: =SUBTOTAL(3,$E$25:E36) -> 12 | D36: 104600079 | E36: Máy đo độ nhớt nội hạt nhựa - 1 | F36: 1495635731 | G36: =F36/$G$2 -> 60552.054
... A45: Z21120P | B45: Máy móc, thiết bị - SX 627 | C45: =SUBTOTAL(3,$E$25:E45) -> 21 | D45: 104000121 | E45: Tủ điện 1600A (Yei) | F45: 460772000 | G45: =F45/$G$2 -> 18654.737
A46: Z211201P | B46: Máy móc, thiết bị phụ - SX 627 | C46: =SUBTOTAL(3,$E$25:E46) -> 22 | D46: 104600082 | E46: Chi phí vận chuyển lắp đặt máy | F46: 422500000 | G46: =F46/$G$2 -> 17105.263 | H46: ???
A47: Z21120P | B47: Máy móc, thiết bị - SX 627 | C47: =SUBTOTAL(3,$E$25:E47) -> 23 | D47: 104000141 | E47: Máy tạo hạt trục vít đôi CJWH25-42D-11Kw | F47: 411877593 | G47: =F47/$G$2 -> 16675.206
A48: Z21120P | B48: Máy móc, thiết bị - SX 627 | C48: =SUBTOTAL(3,$E$25:E48) -> 24 | D48: 104000130 | E48: Máy đo chỉ số chảy MI nhựa HDPE | F48: 409250000 | G48: =F48/$G$2 -> 16568.826
A49: Z21120P | B49: Máy móc, thiết bị - SX 627 | C49: =SUBTOTAL(3,$E$25:E49) -> 25 | D49: 104000112 | E49: Máy băm rửa Changwoen | F49: 380542065 | G49: =F49/$G$2 -> 15406.561
A50: Z21120P | B50: Máy móc, thiết bị - SX 627 | C50: =SUBTOTAL(3,$E$25:E50) -> 26 | D50: 104000139 | E50: Cấp nguồn xưởng F2 | F50: 374180000 | G50: =F50/$G$2 -> 15148.988
A51: Z21120P | B51: Máy móc, thiết bị - SX 627 | C51: =SUBTOTAL(3,$E$25:E51) -> 27 | D51: 104000132 | E51: Máy đo chỉ số chảy MI nhựa PP | F51: 366850000 | G51: =F51/$G$2 -> 14852.227
A52: Z21120P | B52: Máy móc, thiết bị - SX 627 | C52: =SUBTOTAL(3,$E$25:E52) -> 28 | D52: 104000115 | E52: Máy trộn nhựa KLN 500kg | F52: 365416370 | G52: =F52/$G$2 -> 14794.185
A53: Z21120P | B53: Máy móc, thiết bị - SX 627 | C53: =SUBTOTAL(3,$E$25:E53) -> 29 | D53: 104000119 | E53: Máy thổi Chumpower | F53: 360577908 | G53: =F53/$G$2 -> 14598.296
...

Sheet Capex TT 2022
E1: ĐẦU TƯ CAPEX THỰC TẾ 2022
F2: Tỷ giá: | G2: 24500
F3: =SUM(F5,F9,F57,F59,F60,F72,F80,F85) -> 46331487657 | G3: =SUM(G5,G9,G57,G59,G60,G72,G80,G85) -> 1891081.1
A4: Nhóm tài sản (SAP) | B4: Tên Nhóm tài sản (SAP) | C4: STT | D4: Mã TS | E4: Nội dung | F4: số tiền VND | G4: số tiền USD
C5: 1 | E5: Nhà cửa, vật kiến trúc | F5: =SUM(F6:F8) -> 430790000 | G5: =F5/$G$2 -> 17583.265
A6: Z21140A | B6: Thiết bị, dụng cụ quản lý - QL 642 | C6: 1 | D6: 113000001 | E6: Thi công hồ cá | F6: 322740000 | G6: =F6/$G$2 -> 13173.061
A7: Z21140A | B7: Thiết bị, dụng cụ quản lý - QL 642 | C7: 2 | D7: 115000004 | E7: Mái che xếp di động (Nam Trần) | F7: 60800000 | G7: =F7/$G$2 -> 2481.6327
A8: Z21140A | B8: Thiết bị, dụng cụ quản lý - QL 642 | C8: 3 | D8: 159000058 | E8: Thi công đường bê tông nhựa | F8: 47250000 | G8: =F8/$G$2 -> 1928.5714
C9: 2 | E9: Máy móc thiết bị | F9: =SUM(F10:F56) -> 36050065845 | G9: =F9/$G$2 -> 1471431.3
A10: Z21140P | B10: Thiết bị, dụng cụ quản lý - SX 627 | C10: =SUBTOTAL(3,$E$10:E10) -> 1 | D10: 158000050 | E10: Chuyền băm rửa Boretech | F10: 16147060879 | G10: =F10/$G$2 -> 659063.71
A11: Z21120P | B11: Máy móc, thiết bị - SX 627 | C11: =SUBTOTAL(3,$E$10:E11) -> 2 | D11: 104000094 | E11: Chuyền băm rửa chai HDPE | F11: 4051850083 | G11: =F11/$G$2 -> 165381.64
A12: Z211201P | B12: Máy móc, thiết bị phụ - SX 627 | C12: =SUBTOTAL(3,$E$10:E12) -> 3 | D12: 104600058 | E12: Máy làm lạnh nước- nước giải nhiệt | F12: 1667705806 | G12: =F12/$G$2 -> 68069.625
A13: Z21120P | B13: Máy móc, thiết bị - SX 627 | C13: =SUBTOTAL(3,$E$10:E13) -> 4 | D13: 104000084 | E13: Máy tạo hạt rHDPE 03 (Polystar) | F13: 1414330740 | G13: =F13/$G$2 -> 57727.785
A14: Z211201P | B14: Máy móc, thiết bị phụ - SX 627 | C14: =SUBTOTAL(3,$E$10:E14) -> 5 | D14: 104600067 | E14: Hệ thống Silo vảy PET | F14: 1119518319 | G14: =F14/$G$2 -> 45694.625
A15: Z211201P | B15: Máy móc, thiết bị phụ - SX 627 | C15: =SUBTOTAL(3,$E$10:E15) -> 6 | D15: 104600059 | E15: Thiết bị cân xe Mettler Toledo | F15: 1067096720 | G15: =F15/$G$2 -> 43554.968
A16: Z21120P | B16: Máy móc, thiết bị - SX 627 | C16: =SUBTOTAL(3,$E$10:E16) -> 7 | D16: 104000080 | E16: Kính hiển vi Keyence | F16: 1062500000 | G16: =F16/$G$2 -> 43367.347
A17: Z21120P | B17: Máy móc, thiết bị - SX 627 | C17: =SUBTOTAL(3,$E$10:E17) -> 8 | D17: 104000092 | E17: Máy ép kiện XTY-600WB10080, seri 22203835 | F17: 941175390 | G17: =F17/$G$2 -> 38415.322
A18: Z21130P | B18: Phương tiện vận tải , truyền dẫn - SX 627 | C18: =SUBTOTAL(3,$E$10:E18) -> 9 | D18: 107000018 | E18: Băng tải nghiêng cấp chai vào máy 21108 | F18: 600000000 | G18: =F18/$G$2 -> 24489.796
A19: Z211201P | B19: Máy móc, thiết bị phụ - SX 627 | C19: =SUBTOTAL(3,$E$10:E19) -> 10 | D19: 104600074 | E19: Máy phân tích màu quang phổ CM-36DG | F19: 559630200 | G19: =F19/$G$2 -> 22842.049
A20: Z21120P | B20: Máy móc, thiết bị - SX 627 | C20: =SUBTOTAL(3,$E$10:E20) -> 11 | D20: 104000081 | E20: Phòng tiêu âm máy nghiền nhựa | F20: 551292212 | G20: =F20/$G$2 -> 22501.723
A21: Z21130P | B21: Phương tiện vận tải , truyền dẫn - SX 627 | C21: =SUBTOTAL(3,$E$10:E21) -> 12 | D21: 107000021 | E21: Băng tải nối tiếp chuyền lựa chai CW (Plenma) | F21: 472000000 | G21: =F21/$G$2 -> 19265.306
... A56: Z21120P | B56: Máy móc, thiết bị - SX 627 | C56: =SUBTOTAL(3,$E$10:E56) -> 47 | D56: 104000074 | E56: Máy khuấy đũa (cơ) | F56: 33250000 | G56: =F56/$G$2 -> 1357.1429
C57: 3 | E57: Khuôn đầu tư sản phẩm mới | F57: =F58 -> 60000000 | G57: =F57/$G$2 -> 2448.9796
A58: Z211201P | B58: Máy móc, thiết bị phụ - SX 627 | C58: =SUBTOTAL(3,$E$10:E58) -> 49 | D58: 104600049 | E58: Khuôn thẻ nhựa PET | F58: 60000000 | G58: =F58/$G$2 -> 2448.9796
C59: 4 | E59: Khuôn đầu tư thay thế | F59: 0 | G59: =F59/$G$2 -> 0
C60: 5 | E60: Phương tiện vận tải | F60: =SUM(F61:F71) -> 7797835728 | G60: =F60/$G$2 -> 318279.01
A61: Z21130P | B61: Phương tiện vận tải , truyền dẫn - SX 627 | C61: =SUBTOTAL(3,$E$61:E61) -> 1 | D61: 107000027 | E61: Xe ô tô tải ISUZU FVR34UE4 - 62C-179.12 | F61: 1309027251 | G61: =F61/$G$2 -> 53429.684
A62: Z21130P | B62: Phương tiện vận tải , truyền dẫn - SX 627 | C62: =SUBTOTAL(3,$E$61:E62) -> 2 | D62: 107000028 | E62: Xe ô tô tải ISUZU FVR34UE4 - 62C-179.36 | F62: 1309027247 | G62: =F62/$G$2 -> 53429.684
A63: Z21130P | B63: Phương tiện vận tải , truyền dẫn - SX 627 | C63: =SUBTOTAL(3,$E$61:E63) -> 3 | D63: 107000020 | E63: Xe ôtô tải hiệu Chenglong LZ1250M5DBT | F63: 1191602171 | G63: =F63/$G$2 -> 48636.823
A64: Z21130P | B64: Phương tiện vận tải , truyền dẫn - SX 627 | C64: =SUBTOTAL(3,$E$61:E64) -> 4 | D64: 107000022 | E64: Xe nâng hiệu KomatsuFD25C-16 M228-742540 | F64: 877179059 | G64: =F64/$G$2 -> 35803.227
A65: Z21130P | B65: Phương tiện vận tải , truyền dẫn - SX 627 | C65: =SUBTOTAL(3,$E$61:E65) -> 5 | D65: 107000010 | E65: Xe nâng hiệu Komatsu, Model:FD30T-17 (Nhật Bản) | F65: 555000000 | G65: =F65/$G$2 -> 22653.061
A66: Z21130P | B66: Phương tiện vận tải , truyền dẫn - SX 627 | C66: =SUBTOTAL(3,$E$61:E66) -> 6 | D66: 107000023 | E66: Xe nâng dầu Komatsu 3 tấn - xe 13 | F66: 480000000 | G66: =F66/$G$2 -> 19591.837
A67: Z21130P | B67: Phương tiện vận tải , truyền dẫn - SX 627 | C67: =SUBTOTAL(3,$E$61:E67) -> 7 | D67: 107000024 | E67: Xe nâng dầu Komatsu 3 tấn - xe 14 | F67: 475000000 | G67: =F67/$G$2 -> 19387.755
A68: Z21130P | B68: Phương tiện vận tải , truyền dẫn - SX 627 | C68: =SUBTOTAL(3,$E$61:E68) -> 8 | D68: 107000017 | E68: Xe nâng dầu Komatsu FD30C-17, M229-319893, 4D94LE | F68: 470000000 | G68: =F68/$G$2 -> 19183.673
A69: Z21130P | B69: Phương tiện vận tải , truyền dẫn - SX 627 | C69: =SUBTOTAL(3,$E$61:E69) -> 9 | D69: 107000025 | E69: Xe nâng dầu 2.5 tấn Komatsu - 15 | F69: 450000000 | G69: =F69/$G$2 -> 18367.347
A70: Z21130P | B70: Phương tiện vận tải , truyền dẫn - SX 627 | C70: =SUBTOTAL(3,$E$61:E70) -> 10 | D70: 108000000 | E70: Xe nâng hiệu Komatsu đã qua sử dụng FD30T-17 | F70: 390000000 | G70: =F70/$G$2 -> 15918.367
A71: Z21130P | B71: Phương tiện vận tải , truyền dẫn - SX 627 | C71: =SUBTOTAL(3,$E$61:E71) -> 11 | D71: 107000016 | E71: Xe nâng điện Komatsu Model : FB18RL-15 | F71: 291000000 | G71: =F71/$G$2 -> 11877.551
C72: 6 | E72: Thiết bị quản lý | F72: =SUM(F73:F79) -> 1208647832 | G72: =F72/$G$2 -> 49332.565
A73: Z21140A | B73: Thiết bị, dụng cụ quản lý - QL 642 | C73: =SUBTOTAL(3,$E$11:E73) -> 63 | D73: 151000004 | E73: Hệ thống Server ERP SAP và Network SDWAN | F73: 987208013 | G73: =F73/$G$2 -> 40294.205
A74: Z21140A | B74: Thiết bị, dụng cụ quản lý - QL 642 | C74: =SUBTOTAL(3,$E$11:E74) -> 64 | D74: 112000003 | E74: Tivi Sony 4K 85 inch KD-85X86J+vật tư - số 1 | F74: 46318182 | G74: =F74/$G$2 -> 1890.538
...

Sheet Capex TT 2021
E1: ĐẦU TƯ CAPEX THỰC TẾ 2021
F2: Tỷ giá: | G2: 24300
F3: =SUM(F5,F13,F53,F55,F56,F64,F68,F71) -> 262891909295 | G3: =SUM(G5,G13,G53,G55,G56,G64,G68,G71) -> 10818597
A4: Nhóm tài sản (SAP) | B4: Tên Nhóm tài sản (SAP) | C4: STT | D4: Mã TS | E4: Nội dung | F4: số tiền VND | G4: số tiền USD
C5: 1 | E5: Nhà cửa, vật kiến trúc | F5: =SUM(F6:F12) -> 43511003207 | G5: =F5/$G$2 -> 1790576.3
A6: Z21110P | B6: Nhà cửa, vật kiến trúc - SX 627 | D6: 101000000 | E6: Nhà xưởng số 03 | F6: 23455092161 | G6: =F6/$G$2 -> 965230.13 | I6: Có trong file Thạnh Phát
A7: Z21110P | B7: Nhà cửa, vật kiến trúc - SX 627 | D7: 103000002 | E7: Văn phòng xưởng 03 | F7: 13526642799 | G7: =F7/$G$2 -> 556651.97 | I7: Có trong file Thạnh Phát
A8: Z21110P | B8: Nhà cửa, vật kiến trúc - SX 627 | D8: 101000001 | E8: Hạng mục làm đường nhà máy | F8: 3206333890 | G8: =F8/$G$2 -> 131947.9 | I8: Có trong file Thạnh Phát
A9: Z21110P | B9: Nhà cửa, vật kiến trúc - SX 627 | D9: 103000001 | E9: Thiết kế nội thất văn phòng xưởng 03 | F9: 2813240158 | G9: =F9/$G$2 -> 115771.2 | I9: Có trong file Thạnh Phát
A10: Z21110P | B10: Nhà cửa, vật kiến trúc - SX 627 | D10: 101000002 | E10: Nhà kho lều bạt | F10: 445541459 | G10: =F10/$G$2 -> 18335.039 | I10: Có trong file Thạnh Phát
A11: Z21110P | B11: Nhà cửa, vật kiến trúc - SX 627 | D11: 103000000 | E11: Nhà để xe CNV | F11: 36001880 | G11: =F11/$G$2 -> 1481.5588 | I11: Có trong file Thạnh Phát
A12: Z21180A | B12: TSCĐ khác - QL 642 | D12: 117000000 | E12: Nhà chứa rác thải nguy hại | F12: 28150860 | G12: =F12/$G$2 -> 1158.4716 | I12: Có trong file Thạnh Phát
C13: 2 | E13: Máy móc thiết bị | F13: =SUM(F14:F52) -> 214888211254 | G13: =F13/$G$2 -> 8843136.3
A14: Z21120P | B14: Máy móc, thiết bị - SX 627 | D14: 104000068 | E14: Hệ thống xử lý nước thải ChengWoen | F14: 46273512763 | G14: =F14/$G$2 -> 1904259.8
A15: Z21120P | B15: Máy móc, thiết bị - SX 627 | D15: 104000070 | E15: Máy nâng IV Starlinger (SSP) | F15: 42617633391 | G15: =F15/$G$2 -> 1753812.1
A16: Z21120P | B16: Máy móc, thiết bị - SX 627 | D16: 104000069 | E16: Máy tạo hạt Starlinger (PET02) | F16: 40239524497 | G16: =F16/$G$2 -> 1655947.5
A17: Z21120P | B17: Máy móc, thiết bị - SX 627 | D17: 104000067 | E17: Chuyền tạo vảy rPET - ChengWoen | F17: 37079055498 | G17: =F17/$G$2 -> 1525887.1
A18: Z21120P | B18: Máy móc, thiết bị - SX 627 | D18: 104000071 | E18: Máy tạo hạt rHDPE - 01 | F18: 8257058918 | G18: =F18/$G$2 -> 339796.66
A19: Z21120P | B19: Máy móc, thiết bị - SX 627 | D19: 104000065 | E19: Máy Tách màu Taiho | F19: 1871585340 | G19: =F19/$G$2 -> 77019.973
A20: Z21120P | B20: Máy móc, thiết bị - SX 627 | D20: 104000066 | E20: Máy trộn hạt nhựa 2 tấn | F20: 150000000 | G20: =F20/$G$2 -> 6172.8395
A21: Z211201P | B21: Máy móc, thiết bị phụ - SX 627 | D21: 104600019 | E21: Máy lựa vảy Tomra (FOS) | F21: 7826007822 | G21: =F21/$G$2 -> 322057.94
A22: Z211201P | B22: Máy móc, thiết bị phụ - SX 627 | D22: 104600031 | E22: Hệ thống Chiller nước lạnh | F22: 4641978681 | G22: =F22/$G$2 -> 191027.93
A23: Z211201P | B23: Máy móc, thiết bị phụ - SX 627 | D23: 104600021 | E23: Hệ thống cách nhiệt bể nước ngầm, Hệ thống PCCC | F23: 3682105850 | G23: =F23/$G$2 -> 151526.99
A24: Z211201P | B24: Máy móc, thiết bị phụ - SX 627 | D24: 104600024 | E24: Trạm điện 3.000 KVA | F24: 3298619772 | G24: =F24/$G$2 -> 135745.67
A25: Z211201P | B25: Máy móc, thiết bị phụ - SX 627 | D25: 104600025 | E25: Tủ điện động lực MSB-1 (3200A) | F25: 2414319168 | G25: =F25/$G$2 -> 99354.698
... A52: Z21120A | B52: Máy móc, thiết bị - QL 642 | D52: 106000002 | E52: Bộ lưu điện UPS 10KVA | F52: 72000000 | G52: =F52/$G$2 -> 2962.963
C53: 3 | E53: Khuôn đầu tư sản phẩm mới | F53: =F54 -> 0 | G53: =F53/$G$2 -> 0
G54: =F54/$G$2 -> 0
C55: 4 | E55: Khuôn đầu tư thay thế | F55: 0 | G55: =F55/$G$2 -> 0
C56: 5 | E56: Phương tiện vận tải | F56: =SUM(F57:F63) -> 2573766789 | G56: =F56/$G$2 -> 105916.33
A57: Z21130P | B57: Phương tiện vận tải , truyền dẫn - SX 627 | D57: 107000002 | E57: Xe nâng dầu 2,5 tấn (Xe số 4) | F57: 800000000 | G57: =F57/$G$2 -> 32921.811
A58: Z21130P | B58: Phương tiện vận tải , truyền dẫn - SX 627 | D58: 107000004 | E58: Xe nâng dầu 2.5 Tấn TCM Unicarriers FD25T4 | F58: 400000000 | G58: =F58/$G$2 -> 16460.905
A59: Z21130P | B59: Phương tiện vận tải , truyền dẫn - SX 627 | D59: 107000003 | E59: Xe nâng dầu 2.5 Tấn TCM FD25T3 (Xe số 6) | F59: 390000000 | G59: =F59/$G$2 -> 16049.383
A60: Z21130P | B60: Phương tiện vận tải , truyền dẫn - SX 627 | D60: 107000007 | E60: Hệ thống băng tải cân & may bao cho chuyền HDPE | F60: 165000000 | G60: =F60/$G$2 -> 6790.1235
A61: Z21130P | B61: Phương tiện vận tải , truyền dẫn - SX 627 | D61: 107000006 | E61: Thang máng cáp | F61: 127934000 | G61: =F61/$G$2 -> 5264.7737
A62: Z21130P | B62: Phương tiện vận tải , truyền dẫn - SX 627 | D62: 107000005 | E62: Cầu xe nâng | F62: 125000000 | G62: =F62/$G$2 -> 5144.0329
A63: Z21130A | B63: Phương tiện vận tải , truyền dẫn - QL 642 | D63: 109000000 | E63: Xe ôtô tải hiệu HINO (62C-131.00) | F63: 565832789 | G63: =F63/$G$2 -> 23285.3
C64: 6 | E64: Thiết bị quản lý | F64: =SUM(F65:F67) -> 105866000 | G64: =F64/$G$2 -> 4356.6255
A65: Z21140P | B65: Thiết bị, dụng cụ quản lý - SX 627 | D65: 110000002 | E65: Cân phân tích + Cốc đo tỉ trọng (Mettler Toledo) | F65: 53350000 | G65: =F65/$G$2 -> 2195.4733
A66: Z21140A | B66: Thiết bị, dụng cụ quản lý - QL 642 | D66: 112000001 | E66: Bộ máy tính Dell Presicion 3640 Tower | F66: 52516000 | G66: =F66/$G$2 -> 2161.1523
...

Sheet  2021 Kim ANh
A5: Nhóm tài sản | B5: Tên Nhóm tài sản | C5: Mã tài sản | D5: Diễn giải tài sản 1 | E5: TT sở hữu | F5: Ngày ghi nhận TS | G5: Ngày bắt đầu KH | H5: T/G Khấu hao | I5: Cost center | J5: Tài khoản KH | K5: Nguyên giá đầu kỳ | L5: Tăng TS | M5: Chuyển TS | N5: Thanh lý | O5: Nguyên giá cuối kỳ | P5: KHLK – Năm trước | Q5: KH – Kỳ này | R5: KHLK –Năm nay | S5: GTCL – Năm nay | T5: Tình trạng sở hữu | U5: Nguyên giá USD | V5: Ngày ngưng SD
A6: Z21110P | B6: Nhà cửa, vật kiến trúc - SX 627 | L6: =SUM(L7:L12) -> 43482852347 | N6: 0
C7: 101000000 | D7: Nhà xưởng số 03 | E7: DH01 | F7: 44288 | G7: 44287 | H7: 300 | I7: 1001602000 | J7: 6274001901 | K7: 0 | L7: 23455092161 | M7: 0 | N7: 0 | O7: 23455092161 | P7: 0 | Q7: -703652765 | R7: -703652765 | S7: 22751439396 | T7: NM Đức Hòa | U7: 0 | V7: 44910
C8: 103000002 | D8: Văn phòng xưởng 03 | E8: DH01 | F8: 44439 | G8: 44438 | H8: 240 | I8: 1001202000 | J8: 6424001901 | K8: 0 | L8: 13526642799 | M8: 0 | N8: 0 | O8: 3206333890 | P8: 0 | Q8: -66798623 | R8: -66798623 | S8: 3139535267 | T8: NM Đức Hòa | U8: 0 | V8: 44910
C9: 101000001 | D9: Hạng mục làm đường nhà máy | E9: DH01 | F9: 44439 | G9: 44438 | H9: 240 | I9: 1001602000 | J9: 6274001901 | K9: 0 | L9: 3206333890 | M9: 0 | N9: 0 | O9: 445541459 | P9: 0 | Q9: -37128455 | R9: -37128455 | S9: 408413004 | T9: NM Đức Hòa | U9: 0 | V9: 44909
C10: 103000001 | D10: Thiết kế nội thất văn phòng xưởng 03 | E10: DH01 | F10: 44439 | G10: 44438 | H10: 120 | I10: 1001202000 | J10: 6424001901 | K10: 0 | L10: 2813240158 | M10: 0 | N10: 0 | O10: 36001880 | P10: 0 | Q10: -3000157 | R10: -3000157 | S10: 33001723 | T10: NM Đức Hòa | U10: 0 | V10: 44910
C11: 101000002 | D11: Nhà kho lều bạt | E11: DH01 | F11: 44439 | G11: 44438 | H11: 60 | I11: 1001602000 | J11: 6274001901 | K11: 0 | L11: 445541459 | M11: 0 | N11: 0 | O11: 2813240158 | P11: 0 | Q11: -117218340 | R11: -117218340 | S11: 2696021818 | T11: NM Đức Hòa | U11: 0 | V11: 44910
C12: 103000000 | D12: Nhà để xe CNV | E12: DH01 | F12: 44439 | G12: 44438 | H12: 60 | I12: 1001202000 | J12: 6424001901 | K12: 0 | L12: 36001880 | M12: 0 | N12: 0 | O12: 13526642799 | P12: 0 | Q12: -281805058 | R12: -281805058 | S12: 13244837741 | T12: NM Đức Hòa | U12: 0 | V12: 44910
A13: Z21120P | B13: Máy móc, thiết bị - SX 627 | L13: =SUM(L14:L20) -> 176488370407 | N13: 0
C14: 104000068 | D14: Hệ thống xử lý nước thải ChengWoen | E14: DH01 | F14: 44417 | G14: 44417 | H14: 120 | I14: 1001602101 | J14: 6274001903 | K14: 0 | L14: 46273512763 | M14: 0 | N14: 0 | O14: 1871585340 | P14: 0 | Q14: -124772356 | R14: -124772356 | S14: 1746812984 | T14: NM Đức Hòa | U14: 0
C15: 104000070 | D15: Máy nâng IV Starlinger (SSP) | E15: DH01 | F15: 44417 | G15: 44417 | H15: 120 | I15: 1001602105 | J15: 6274001903 | K15: 0 | L15: 42617633391 | M15: 0 | N15: 0 | O15: 150000000 | P15: 0 | Q15: -10000000 | R15: -10000000 | S15: 140000000 | T15: NM Đức Hòa | U15: 0
C16: 104000069 | D16: Máy tạo hạt Starlinger (PET02) | E16: DH01 | F16: 44417 | G16: 44417 | H16: 120 | I16: 1001602104 | J16: 6274001903 | K16: 0 | L16: 40239524497 | M16: 0 | N16: 0 | O16: 37079055498 | P16: 0 | Q16: -1544960646 | R16: -1544960646 | S16: 35534094852 | T16: NM Đức Hòa | U16: 0
C17: 104000067 | D17: Chuyền tạo vảy rPET - ChengWoen | E17: DH01 | F17: 44417 | G17: 44417 | H17: 120 | I17: 1001602101 | J17: 6274001903 | K17: 0 | L17: 37079055498 | M17: 0 | N17: 0 | O17: 46273512763 | P17: 0 | Q17: -1928063032 | R17: -1928063032 | S17: 44345449731 | T17: NM Đức Hòa | U17: 0 | V17: 44910
C18: 104000071 | D18: Máy tạo hạt rHDPE - 01 | E18: DH01 | F18: 44417 | G18: 44417 | H18: 120 | I18: 1001602103 | J18: 6274001903 | K18: 0 | L18: 8257058918 | M18: 0 | N18: 0 | O18: 40239524497 | P18: 0 | Q18: -1676646854 | R18: -1676646854 | S18: 38562877643 | T18: NM Đức Hòa | U18: 0
C19: 104000065 | D19: Máy Tách màu Taiho | E19: DH01 | F19: 44408 | G19: 44378 | H19: 90 | I19: 1001602107 | J19: 6274001903 | K19: 0 | L19: 1871585340 | M19: 0 | N19: 0 | O19: 42617633391 | P19: 0 | Q19: -1775734725 | R19: -1775734725 | S19: 40841898666 | T19: NM Đức Hòa | U19: 0
C20: 104000066 | D20: Máy trộn hạt nhựa 2 tấn | E20: DH01 | F20: 44378 | G20: 44389 | H20: 90 | I20: 1001602116 | J20: 6274001903 | K20: 0 | L20: 150000000 | M20: 0 | N20: 0 | O20: 8257058918 | P20: 0 | Q20: -344044122 | R20: -344044122 | S20: 7913014796 | T20: NM Đức Hòa | U20: 0
A21: Z211201P | B21: Máy móc, thiết bị phụ - SX 627 | L21: =SUM(L22:L50) -> 35953846529 | N21: =SUM(N22:N50) -> 875679600
C22: 104600019 | D22: Máy lựa vảy Tomra (FOS) | E22: DH01 | F22: 44417 | G22: 44417 | H22: 120 | I22: 1001602101 | J22: 6274001906 | K22: 0 | L22: 7826007822 | M22: 0 | N22: 0 | O22: 125658000 | P22: 0 | Q22: -25131600 | R22: -25131600 | S22: 100526400 | T22: NM Đức Hòa | U22: 0
C23: 104600031 | D23: Hệ thống Chiller nước lạnh | E23: DH01 | F23: 44439 | G23: 44438 | H23: 120 | I23: 1001602000 | J23: 6274001906 | K23: 0 | L23: 4641978681 | M23: 0 | N23: 0 | O23: 130079300 | P23: 0 | Q23: -26015860 | R23: -26015860 | S23: 104063440 | T23: NM Đức Hòa | U23: 0
C24: 104600021 | D24: Hệ thống cách nhiệt bể nước ngầm, Hệ thống PCCC | E24: DH01 | F24: 44439 | G24: 44438 | H24: 120 | I24: 1001602000 | J24: 6274001906 | K24: 0 | L24: 3682105850 | M24: 0 | N24: 0 | O24: 146100000 | P24: 0 | Q24: -26785000 | R24: -26785000 | S24: 119315000 | T24: NM Đức Hòa | U24: 0
C25: 104600024 | D25: Trạm điện 3.000 KVA | E25: DH01 | F25: 44439 | G25: 44438 | H25: 120 | I25: 1001602000 | J25: 6274001906 | K25: 0 | L25: 3298619772 | M25: 0 | N25: 0 | O25: 616655000 | P25: 0 | Q25: -68517222 | R25: -68517222 | S25: 548137778 | T25: NM Đức Hòa | U25: 0 | V25: 45525
C26: 104600025 | D26: Tủ điện động lực MSB-1 (3200A) | E26: DH01 | F26: 44439 | G26: 44438 | H26: 120 | I26: 1001602000 | J26: 6274001906 | K26: 0 | L26: 2414319168 | M26: 0 | N26: 0 | O26: 1129934700 | P26: 0 | Q26: -112993470 | R26: -112993470 | S26: 1016941230 | T26: NM Đức Hòa | U26: 0
C27: 104600026 | D27: Hệ thống điện xưởng 03 | E27: DH01 | F27: 44439 | G27: 44438 | H27: 120 | I27: 1001602000 | J27: 6274001906 | K27: 0 | L27: 1931331475 | M27: 0 | N27: 0 | O27: 60000000 | P27: 0 | Q27: -13333333 | R27: -13333333 | S27: 46666667 | T27: NM Đức Hòa | U27: 0
C28: 104600016 | D28: Hệ thống sắc ký khí ghép nối khối phổ GC/MS - USA | E28: DH01 | F28: 44397 | G28: 44397 | H28: 90 | I28: 1001602000 | J28: 6274001906 | K28: 0 | L28: 1818450000 | M28: 0 | N28: 0 | O28: 319400000 | P28: 0 | Q28: -21293333 | R28: -21293333 | S28: 298106667 | T28: NM Đức Hòa | U28: 0
C29: 104600022 | D29: Hệ thống Điện, cấp thoát Nước xưởng 03 | E29: DH01 | F29: 44439 | G29: 44438 | H29: 120 | I29: 1001602000 | J29: 6274001906 | K29: 0 | L29: 1729306981 | M29: 0 | N29: 0 | O29: 1818450000 | P29: 0 | Q29: -121230000 | R29: -121230000 | S29: 1697220000 | T29: NM Đức Hòa | U29: 0
C30: 104600028 | D30: Lò nước nóng Martech | E30: DH01 | F30: 44439 | G30: 44438 | H30: 120 | I30: 1001602000 | J30: 6274001906 | K30: 0 | L30: 1577222005 | M30: 0 | N30: 0 | O30: 433134526 | P30: 0 | Q30: -43313453 | R30: -43313453 | S30: 389821073 | T30: NM Đức Hòa | U30: 0
C31: 104600013 | D31: Máy nén khí Ingersol Rand | E31: DH01 | F31: 44288 | G31: 44287 | H31: 90 | I31: 1001602000 | J31: 6274001906 | K31: 0 | L31: 1129934700 | M31: 0 | N31: 0 | O31: 350000000 | P31: 0 | Q31: -14583333 | R31: -14583333 | S31: 335416667 | T31: NM Đức Hòa | U31: 0
C32: 104600037 | D32: Máy ép kiện XTY-600WB10080+ băng tải XTS-1000T | E32: DH01 | F32: 44554 | G32: 44562 | H32: 72 | I32: 1001602000 | J32: 6274001906 | K32: 0 | L32: 875679600 | M32: 0 | N32: 875679600 | O32: 7826007822 | P32: 0 | Q32: -326083659 | R32: -326083659 | S32: 7499924163 | T32: NM Đức Hòa | U32: 0
C33: 104600020 | D33: Đường ống nén khí xưởng 03 | E33: DH01 | F33: 44439 | G33: 44438 | H33: 120 | I33: 1001602000 | J33: 6274001906 | K33: 0 | L33: 758031567 | M33: 0 | N33: 0 | O33: 758031567 | P33: 0 | Q33: -31584649 | R33: -31584649 | S33: 726446918 | T33: NM Đức Hòa | U33: 0 | V33: 44910
C34: 104600012 | D34: Máy tách nhãn PVN-600, Băng tải nạp liệu | E34: DH01 | F34: 44263 | G34: 44263 | H34: 90 | I34: 1001602101 | J34: 6274001906 | K34: 0 | L34: 616655000 | M34: 0 | N34: 0 | O34: 3682105850 | P34: 0 | Q34: -153421077 | R34: -153421077 | S34: 3528684773 | T34: NM Đức Hòa | U34: 0 | V34: 44910
C35: 104600023 | D35: Tủ điện động lực MSB-2 | E35: DH01 | F35: 44439 | G35: 44438 | H35: 120 | I35: 1001602000 | J35: 6274001906 | K35: 0 | L35: 558511800 | M35: 0 | N35: 0 | O35: 1729306981 | P35: 0 | Q35: -72054458 | R35: -72054458 | S35: 1657252523 | T35: NM Đức Hòa | U35: 0 | V35: 44910
C36: 104600038 | D36: Máy đo độ nhớt IV LOVIS 2000 M/ME(Model:LOVIS 2000 | E36: DH01 | F36: 44531 | G36: 44531 | H36: 72 | I36: 1001602000 | J36: 6274001906 | K36: 0 | L36: 439248612 | M36: 0 | N36: 0 | O36: 558511800 | P36: 0 | Q36: -23271325 | R36: -23271325 | S36: 535240475 | T36: NM Đức Hòa | U36: 0
C37: 104600017 | D37: Thiết bị phòng LAB | E37: DH01 | F37: 44408 | G37: 44378 | H37: 60 | I37: 1001602000 | J37: 6274001906 | K37: 0 | L37: 433134526 | M37: 0 | N37: 0 | O37: 3298619772 | P37: 0 | Q37: -137442491 | R37: -137442491 | S37: 3161177281 | T37: NM Đức Hòa | U37: 0
C38: 104600029 | D38: Tháp giải nhiệt LRC-N-200 | F38: 44439 | G38: 44438 | H38: 120 | I38: 1001602000 | J38: 6274001906 | K38: 0 | L38: 397073670 | M38: 0 | N38: 0 | O38: 2414319168 | P38: 0 | Q38: -100596632 | R38: -100596632 | S38: 2313722536 | T38: NM Đức Hòa | U38: 0
C39: 104600018 | D39: Bồn SILO | E39: DH01 | F39: 44417 | G39: 44417 | H39: 120 | I39: 1001602101 | J39: 6274001906 | K39: 0 | L39: 350000000 | M39: 0 | N39: 0 | O39: 1931331475 | P39: 0 | Q39: -80472145 | R39: -80472145 | S39: 1850859330 | T39: NM Đức Hòa | U39: 0 | V39: 44910
C40: 104600015 | D40: Máy nghiền mẫu thí nghiệm Model CryoMill - Đức | E40: DH01 | F40: 44397 | G40: 44397 | H40: 90 | I40: 1001602000 | J40: 6274001906 | K40: 0 | L40: 319400000 | M40: 0 | N40: 0 | O40: 310000000 | P40: 0 | Q40: -25833333 | R40: -25833333 | S40: 284166667 | T40: NM Đức Hòa | U40: 0
C41: 104600027 | D41: Máy ép kiện (BLR) | E41: DH01 | F41: 44439 | G41: 44438 | H41: 60 | I41: 1001602000 | J41: 6274001906 | K41: 0 | L41: 310000000 | M41: 0 | N41: 0 | O41: 1577222005 | P41: 0 | Q41: -65717584 | R41: -65717584 | S41: 1511504421 | T41: NM Đức Hòa | U41: 0
C42: 104600011 | D42: Bồn chứa Inox 0,3m3 cân tự động + Thiết bị tủ điện | E42: DH01 | F42: 44228 | G42: 44228 | H42: 60 | I42: 1001602102 | J42: 6274001906 | K42: 0 | L42: 146100000 | M42: 0 | N42: 0 | O42: 397073670 | P42: 0 | Q42: -16544736 | R42: -16544736 | S42: 380528934 | U42: 0
C43: 104600010 | D43: Silo 1000L, Quạt thổi, Phễu chứa liệu, Đường ống | E43: DH01 | F43: 44198 | G43: 44198 | H43: 60 | I43: 1001602102 | J43: 6274001906 | K43: 0 | L43: 130079300 | M43: 0 | N43: 0 | O43: 73500000 | P43: 0 | Q43: -6125000 | R43: -6125000 | S43: 67375000 | T43: NM Đức Hòa | U43: 0
C44: 104600009 | D44: Vít tải liệu AF-4600 | E44: DH01 | F44: 44198 | G44: 44198 | H44: 60 | I44: 1001602102 | J44: 6274001906 | K44: 0 | L44: 125658000 | M44: 0 | N44: 0 | O44: 4641978681 | P44: 0 | Q44: -193415778 | R44: -193415778 | S44: 4448562903 | T44: NM Đức Hòa | U44: 0
...

Sheet Capex TT 2020
E1: ĐẦU TƯ CAPEX THỰC TẾ 2020
F2: Tỷ giá: | G2: 24000
F3: =SUM(F5,F8,F23,F25,F26,F29,F31,F33) -> 4697651482 | G3: =SUM(G5,G8,G23,G25,G26,G29,G31,G33) -> 195735.48
A4: Nhóm tài sản (SAP) | B4: Tên Nhóm tài sản (SAP) | C4: STT | D4: Mã TS | E4: Nội dung | F4: số tiền VND | G4: số tiền USD
C5: 1 | E5: Nhà cửa, vật kiến trúc | F5: =SUM(F6:F7) -> 0 | G5: =F5/$G$2 -> 0
G6: =F6/$G$2 -> 0
G7: =F7/$G$2 -> 0
C8: 2 | E8: Máy móc thiết bị | F8: =SUM(F9:F22) -> 4317651482 | G8: =F8/$G$2 -> 179902.15
A9: Z21120P | B9: Máy móc, thiết bị - SX 627 | D9: 104000062 | E9: Máy tạo hạt rPET HTL 1 | F9: 1985420682 | G9: =F9/$G$2 -> 82725.862
A10: Z21120P | B10: Máy móc, thiết bị - SX 627 | D10: 104000063 | E10: Bộ dao cắt hạt và máy thổi khô (YE I) | F10: 465140000 | G10: =F10/$G$2 -> 19380.833
A11: Z21120P | B11: Máy móc, thiết bị - SX 627 | D11: 104000064 | E11: Máy nghiền nhựa HGP-800 | F11: 140400000 | G11: =F11/$G$2 -> 5850
A12: Z211201P | B12: Máy móc, thiết bị phụ - SX 627 | D12: 104600008 | E12: Máy tách kim loại Sesotec | F12: 365324800 | G12: =F12/$G$2 -> 15221.867
