Workbook
Name \T: #REF!
Name __dao1: #REF!
Name __dao2: #REF!
Name __dap2: #REF!
Name __day1: #REF!
Name __day2: #REF!
Name __dbu1: #REF!
Name __dbu2: #REF!
Name __doi3: #REF!
Name __E99999: #REF!
Name __Jan02: #REF!
Name __lap1: #REF!
Name __lap2: #REF!
Name __vc1: #REF!
Name __vc2: #REF!
Name __vc3: #REF!
Name _01_01_99: #REF!
Name _01_02_99: #REF!
Name _01_03_99: #REF!
Name _01_04_99: #REF!
Name _01_05_99: #REF!
Name _01_06_99: #REF!
Name _01_07_99: #REF!
Name _01_08_1999: #REF!
Name _1CAP002: #REF!
Name _2STREO7: #REF!
Name _4GOIC01: #REF!
Name _4OSLCTT: #REF!
Name _6BNTTTH: #REF!
Name _6DCTTBO: #REF!
Name _6DD24TT: #REF!
Name _6FCOTBU: #REF!
Name _6LATUBU: #REF!
Name _6SDTT24: #REF!
Name _6TBUDTT: #REF!
Name _6TDDDTT: #REF!
Name _6TLTTTH: #REF!
Name _6TUBUTT: #REF!
Name _6UCLVIS: #REF!
Name _7DNCABC: #REF!
Name _7HDCTBU: #REF!
Name _7PKTUBU: #REF!
Name _7TBHT20: #REF!
Name _7TBHT30: #REF!
Name _7TDCABC: #REF!
Name _dao1: #REF!
Name _dao2: #REF!
Name _dap2: #REF!
Name _day1: #REF!
Name _day2: #REF!
Name _dbu1: #REF!
Name _dbu2: #REF!
Name _doi3: #REF!
Name _E99999: #REF!
Name _Jan02: #REF!
Name _lap1: #REF!
Name _lap2: #REF!
Name _vc1: #REF!
Name _vc2: #REF!
Name _vc3: #REF!

Sheet 1. 2020-2025
D1: DANH MỤC TÀI SẢN CỐ ĐỊNH | G1: MMTB chính | H1: =SUMIF($C$9:$C$500,$G$1,$S$9:$S$500) -> 0 | S1: Hết khấu hao
D2: 45961 | G2: MMTB phụ | K2: 323120 | L2: 273154 | M2: =K2-L2 -> 49966
G3: TSCĐ vô hình | H3: =SUMIF($C$9:$C$500,$G$3,$S$9:$S$500) -> 0 | K3: =26000 -> 26000 | L3: =26000 -> 26000 | M3: =K3-L3 -> 0
K4: =K2*K3 -> 8401120000 | L4: =L2*L3 -> 7102004000 | M4: =K4-L4 -> 1299116000 | CL4: 2025
S5: =S8+S42 -> 1.4016614e+09 | T5: 2020 | AH5: 2021 | AV5: 2022 | BJ5: 2023 | BX5: 2024 | CL5: =SUM(CL7,CL86,CL159,CL280) -> 7.6952557e+09 | CM5: =SUM(CM7,CM86,CM159,CM280) -> 7.7199311e+09 | CN5: =SUM(CN7,CN86,CN159,CN280) -> 7.9127276e+09 | CO5: =SUM(CO7,CO86,CO159,CO280) -> 8.0468246e+09 | CP5: =SUM(CP7,CP86,CP159,CP280) -> 8.0692514e+09 | CQ5: =SUM(CQ7,CQ86,CQ159,CQ280) -> 8.0638617e+09 | CR5: =SUM(CR7,CR86,CR159,CR280) -> 8.0704204e+09 | CS5: =SUM(CS7,CS86,CS159,CS280) -> 8.0769039e+09 | ... CY5: =SUM(CY7,CY86,CY159,CY280) -> 4.0789988e+11
A6: Phân loại | B6: Phân nhóm SP | C6: Công đoạn | D6: Nhóm tài sản | E6: Mã tài sản | F6: Diễn giải tài sản 1 | G6: Ngày ghi nhận TS | H6: Ngày bắt đầu KH | I6: T/G Khấu hao | J6: Cost center | L6: Work center | M6: Nhóm TK | N6: Tài khoản KH | O6: Tài khoản KH KTQT xác định | P6: Nguyên giá đầu kỳ (ngoại tệ) | Q6: Loại ngoại tê | R6: Nguyên giá đầu kỳ (VNĐ) | S6: Gía trị khấu hao 1 tháng | T6: 1 | U6: =+T6+1 -> 2 | V6: =+U6+1 -> 3 | W6: =+V6+1 -> 4 | X6: =+W6+1 -> 5 | Y6: =+X6+1 -> 6 | Z6: =+Y6+1 -> 7 | AA6: =+Z6+1 -> 8 | AB6: =+AA6+1 -> 9 | ... AE6: =+AD6+1 -> 12 | AF6: Số tiền khấu hao năm 2020 | AG6: Giá trị còn lại năm 2020 | AH6: 1 | AI6: 2 | AJ6: 3 | AK6: 4 | AL6: 5 | AM6: 6 | AN6: 7 | AO6: 8 | AP6: 9 | AQ6: 10 | AR6: 11 | AS6: 12 | AT6: Số tiền khấu hao năm 2021 | AU6: Giá trị còn lại năm 2021 | AV6: 1 | AW6: 2 | AX6: 3 | AY6: 4 | AZ6: 5 | BA6: 6 | BB6: 7 | BC6: 8 | BD6: 9 | BE6: 10 | BF6: 11 | BG6: 12 | BH6: Số tiền khấu hao năm 2022 | BI6: Giá trị còn lại năm 2022 | BJ6: 1 | BK6: 2 | BL6: 3 | BM6: 4 | BN6: 5 | BO6: 6 | BP6: 7 | BQ6: 8 | BR6: 9 | BS6: 10 | BT6: 11 | BU6: 12 | BV6: Số tiền khấu hao năm 2023 | BW6: Giá trị còn lại năm 2023 | BX6: 1 | BY6: 2 | BZ6: 3 | CA6: 4 | CB6: 5 | CC6: 6 | CD6: 7 | CE6: 8 | CF6: 9 | CG6: 10 | CH6: 11 | CI6: 12 | CJ6: Số tiền khấu hao năm 2024 | CK6: Giá trị còn lại năm 2024 | CL6: 1 | CM6: 2 | CN6: 3 | CO6: 4 | CP6: 5 | CQ6: 6 | CR6: 7 | CS6: 8 | CT6: 9 | CU6: 10 | CV6: 11 | CW6: 12 | CX6: Số tiền khấu hao năm 2025 | CY6: Giá trị còn lại năm 2025
E7: 1 | F7: DANH MỤC TSCĐ NHÀ XƯỞNG | S7: =+S8+S42 -> 1.4016614e+09 | T7: =+T8+T42 -> 41638573 | U7: =+U8+U42 -> 41638573 | V7: =+V8+V42 -> 41638573 | W7: =+W8+W42 -> 41638573 | X7: =+X8+X42 -> 41638573 | Y7: =+Y8+Y42 -> 41638573 | Z7: =+Z8+Z42 -> 41638573 | ... CY7: =+CY8+CY42 -> 1.6787466e+11
E8: 1.1 | F8: DTR SỞ HỮU | S8: =SUM(S9:S41) -> 1.6186341e+08 | T8: =SUM(T9:T41) -> 0 | U8: =SUM(U9:U41) -> 0 | V8: =SUM(V9:V41) -> 0 | W8: =SUM(W9:W41) -> 0 | X8: =SUM(X9:X41) -> 0 | Y8: =SUM(Y9:Y41) -> 0 | Z8: =SUM(Z9:Z41) -> 0 | ... CY8: =SUM(CY9:CY41) -> 3.8966693e+09
B9: Chung | C9: =_xlfn.XLOOKUP(E9,'[1]TH_CC (3)'!$E:$E,'[1]TH_CC (3)'!$E:$E) -> #N/A | D9: Z21150A | E9: 113000001 | F9: Thi công hồ cá | G9: 44896 | H9: 44896 | I9: 36 | J9: 1001202000 | K9: Hành chánh nhân sự | M9: =+LEFT(N9,4) -> 6424 | N9: 6424001901 | O9: 6274001901 | R9: 322740000 | S9: 8965000 | T9: =+IF(YEAR($H9)<$T$5,$S9,IF(AND(YEAR($H9)=$T$5,MONTH($H9)<=T$6),$S9,0)) -> 0 | U9: =+IF(YEAR($H9)<$T$5,$S9,IF(AND(YEAR($H9)=$T$5,MONTH($H9)<=U$6),$S9,0)) -> 0 | V9: =+IF(YEAR($H9)<$T$5,$S9,IF(AND(YEAR($H9)=$T$5,MONTH($H9)<=V$6),$S9,0)) -> 0 | W9: =+IF(YEAR($H9)<$T$5,$S9,IF(AND(YEAR($H9)=$T$5,MONTH($H9)<=W$6),$S9,0)) -> 0 | X9: =+IF(YEAR($H9)<$T$5,$S9,IF(AND(YEAR($H9)=$T$5,MONTH($H9)<=X$6),$S9,0)) -> 0 | Y9: =+IF(YEAR($H9)<$T$5,$S9,IF(AND(YEAR($H9)=$T$5,MONTH($H9)<=Y$6),$S9,0)) -> 0 | Z9: =+IF(YEAR($H9)<$T$5,$S9,IF(AND(YEAR($H9)=$T$5,MONTH($H9)<=Z$6),$S9,0)) -> 0 | AA9: =+IF(YEAR($H9)<$T$5,$S9,IF(AND(YEAR($H9)=$T$5,MONTH($H9)<=AA$6),$S9,0)) -> 0 | ... AE9: =+IF(YEAR($H9)<$T$5,$S9,IF(AND(YEAR($H9)=$T$5,MONTH($H9)<=AE$6),$S9,0)) -> 0 | AF9: =+SUM(T9:AE9) -> 0 | AG9: 0 | AH9: =+IF(YEAR($H9)<$AH$5,$S9,IF(AND(YEAR($H9)=$AH$5,MONTH($H9)<=AH$6),$S9,0)) -> 0 | AI9: =+IF(YEAR($H9)<$AH$5,$S9,IF(AND(YEAR($H9)=$AH$5,MONTH($H9)<=AI$6),$S9,0)) -> 0 | AJ9: =+IF(YEAR($H9)<$AH$5,$S9,IF(AND(YEAR($H9)=$AH$5,MONTH($H9)<=AJ$6),$S9,0)) -> 0 | AK9: =+IF(YEAR($H9)<$AH$5,$S9,IF(AND(YEAR($H9)=$AH$5,MONTH($H9)<=AK$6),$S9,0)) -> 0 | AL9: =+IF(YEAR($H9)<$AH$5,$S9,IF(AND(YEAR($H9)=$AH$5,MONTH($H9)<=AL$6),$S9,0)) -> 0 | AM9: =+IF(YEAR($H9)<$AH$5,$S9,IF(AND(YEAR($H9)=$AH$5,MONTH($H9)<=AM$6),$S9,0)) -> 0 | AN9: =+IF(YEAR($H9)<$AH$5,$S9,IF(AND(YEAR($H9)=$AH$5,MONTH($H9)<=AN$6),$S9,0)) -> 0 | AO9: =+IF(YEAR($H9)<$AH$5,$S9,IF(AND(YEAR($H9)=$AH$5,MONTH($H9)<=AO$6),$S9,0)) -> 0 | ... AS9: =+IF(YEAR($H9)<$AH$5,$S9,IF(AND(YEAR($H9)=$AH$5,MONTH($H9)<=AS$6),$S9,0)) -> 0 | AT9: =+SUM(AH9:AS9) -> 0 | AU9: 0 | AV9: =+IF(YEAR($H9)<$AV$5,$S9,IF(AND(YEAR($H9)=$AV$5,MONTH($H9)<=AV$6),$S9,0)) -> 0 | AW9: =+IF(YEAR($H9)<$AV$5,$S9,IF(AND(YEAR($H9)=$AV$5,MONTH($H9)<=AW$6),$S9,0)) -> 0 | AX9: =+IF(YEAR($H9)<$AV$5,$S9,IF(AND(YEAR($H9)=$AV$5,MONTH($H9)<=AX$6),$S9,0)) -> 0 | AY9: =+IF(YEAR($H9)<$AV$5,$S9,IF(AND(YEAR($H9)=$AV$5,MONTH($H9)<=AY$6),$S9,0)) -> 0 | AZ9: =+IF(YEAR($H9)<$AV$5,$S9,IF(AND(YEAR($H9)=$AV$5,MONTH($H9)<=AZ$6),$S9,0)) -> 0 | BA9: =+IF(YEAR($H9)<$AV$5,$S9,IF(AND(YEAR($H9)=$AV$5,MONTH($H9)<=BA$6),$S9,0)) -> 0 | BB9: =+IF(YEAR($H9)<$AV$5,$S9,IF(AND(YEAR($H9)=$AV$5,MONTH($H9)<=BB$6),$S9,0)) -> 0 | BC9: =+IF(YEAR($H9)<$AV$5,$S9,IF(AND(YEAR($H9)=$AV$5,MONTH($H9)<=BC$6),$S9,0)) -> 0 | ... BG9: =+IF(YEAR($H9)<$AV$5,$S9,IF(AND(YEAR($H9)=$AV$5,MONTH($H9)<=BG$6),$S9,0)) -> 8965000 | BH9: =+SUM(AV9:BG9) -> 8965000 | BI9: =+R9-BH9 -> 313775000 | BJ9: =+IF(YEAR($H9)<$BJ$5,$S9,IF(AND(YEAR($H9)=$BJ$5,MONTH($H9)<=BJ$6),$S9,0)) -> 8965000 | BK9: =+IF(YEAR($H9)<$BJ$5,$S9,IF(AND(YEAR($H9)=$BJ$5,MONTH($H9)<=BK$6),$S9,0)) -> 8965000 | BL9: =+IF(YEAR($H9)<$BJ$5,$S9,IF(AND(YEAR($H9)=$BJ$5,MONTH($H9)<=BL$6),$S9,0)) -> 8965000 | BM9: =+IF(YEAR($H9)<$BJ$5,$S9,IF(AND(YEAR($H9)=$BJ$5,MONTH($H9)<=BM$6),$S9,0)) -> 8965000 | BN9: =+IF(YEAR($H9)<$BJ$5,$S9,IF(AND(YEAR($H9)=$BJ$5,MONTH($H9)<=BN$6),$S9,0)) -> 8965000 | BO9: =+IF(YEAR($H9)<$BJ$5,$S9,IF(AND(YEAR($H9)=$BJ$5,MONTH($H9)<=BO$6),$S9,0)) -> 8965000 | BP9: =+IF(YEAR($H9)<$BJ$5,$S9,IF(AND(YEAR($H9)=$BJ$5,MONTH($H9)<=BP$6),$S9,0)) -> 8965000 | BQ9: =+IF(YEAR($H9)<$BJ$5,$S9,IF(AND(YEAR($H9)=$BJ$5,MONTH($H9)<=BQ$6),$S9,0)) -> 8965000 | ... BU9: =+IF(YEAR($H9)<$BJ$5,$S9,IF(AND(YEAR($H9)=$BJ$5,MONTH($H9)<=BU$6),$S9,0)) -> 8965000 | BV9: =+SUM(BJ9:BU9) -> 107580000 | BW9: =+BI9-BV9 -> 206195000 | BX9: =+$S9 -> 8965000 | BY9: =+$S9 -> 8965000 | BZ9: =+$S9 -> 8965000 | CA9: =+$S9 -> 8965000 | CB9: =+$S9 -> 8965000 | CC9: =+$S9 -> 8965000 | CD9: =+$S9 -> 8965000 | CE9: =+$S9 -> 8965000 | ... CI9: =+$S9 -> 8965000 | CJ9: =+SUM(BX9:CI9) -> 107580000 | CK9: =+BW9-CJ9 -> 98615000 | CL9: =+IF(YEAR($H9)<$CL$4,$S9,IF(AND(YEAR($H9)=$CL$4,MONTH($H9)<=CL$6),$S9,0)) -> 8965000 | CM9: =+IF(YEAR($H9)<$CL$4,$S9,IF(AND(YEAR($H9)=$CL$4,MONTH($H9)<=CM$6),$S9,0)) -> 8965000 | CN9: =+IF(YEAR($H9)<$CL$4,$S9,IF(AND(YEAR($H9)=$CL$4,MONTH($H9)<=CN$6),$S9,0)) -> 8965000 | CO9: =+IF(YEAR($H9)<$CL$4,$S9,IF(AND(YEAR($H9)=$CL$4,MONTH($H9)<=CO$6),$S9,0)) -> 8965000 | CP9: =+IF(YEAR($H9)<$CL$4,$S9,IF(AND(YEAR($H9)=$CL$4,MONTH($H9)<=CP$6),$S9,0)) -> 8965000 | CQ9: =+IF(YEAR($H9)<$CL$4,$S9,IF(AND(YEAR($H9)=$CL$4,MONTH($H9)<=CQ$6),$S9,0)) -> 8965000 | CR9: =+IF(YEAR($H9)<$CL$4,$S9,IF(AND(YEAR($H9)=$CL$4,MONTH($H9)<=CR$6),$S9,0)) -> 8965000 | CS9: =+IF(YEAR($H9)<$CL$4,$S9,IF(AND(YEAR($H9)=$CL$4,MONTH($H9)<=CS$6),$S9,0)) -> 8965000 | ... CV9: =+IF(YEAR($H9)<$CL$4,$S9,IF(AND(YEAR($H9)=$CL$4,MONTH($H9)<=CV$6),$S9,0)) -> 8965000 | CX9: =+SUM(CL9:CW9) -> 98615000 | CY9: =+CK9-CX9 -> 0
B10: Chung | C10: =_xlfn.XLOOKUP(E10,'[1]TH_CC (3)'!$E:$E,'[1]TH_CC (3)'!$E:$E) -> 103000005 | D10: Z21110A | E10: 103000005 | F10: Cửa cổng chính số 02 và 03 | G10: 44985 | H10: 44986 | I10: 36 | J10: 1001202000 | K10: Hành chánh nhân sự | M10: =+LEFT(N10,4) -> 6424 | N10: 6424001901 | R10: 184508875 | S10: 5125246.5 | T10: =+IF(YEAR($H10)<$T$5,$S10,IF(AND(YEAR($H10)=$T$5,MONTH($H10)<=T$6),$S10,0)) -> 0 | U10: =+IF(YEAR($H10)<$T$5,$S10,IF(AND(YEAR($H10)=$T$5,MONTH($H10)<=U$6),$S10,0)) -> 0 | V10: =+IF(YEAR($H10)<$T$5,$S10,IF(AND(YEAR($H10)=$T$5,MONTH($H10)<=V$6),$S10,0)) -> 0 | W10: =+IF(YEAR($H10)<$T$5,$S10,IF(AND(YEAR($H10)=$T$5,MONTH($H10)<=W$6),$S10,0)) -> 0 | X10: =+IF(YEAR($H10)<$T$5,$S10,IF(AND(YEAR($H10)=$T$5,MONTH($H10)<=X$6),$S10,0)) -> 0 | Y10: =+IF(YEAR($H10)<$T$5,$S10,IF(AND(YEAR($H10)=$T$5,MONTH($H10)<=Y$6),$S10,0)) -> 0 | Z10: =+IF(YEAR($H10)<$T$5,$S10,IF(AND(YEAR($H10)=$T$5,MONTH($H10)<=Z$6),$S10,0)) -> 0 | AA10: =+IF(YEAR($H10)<$T$5,$S10,IF(AND(YEAR($H10)=$T$5,MONTH($H10)<=AA$6),$S10,0)) -> 0 | ... AE10: =+IF(YEAR($H10)<$T$5,$S10,IF(AND(YEAR($H10)=$T$5,MONTH($H10)<=AE$6),$S10,0)) -> 0 | AF10: =+SUM(T10:AE10) -> 0 | AG10: 0 | AH10: =+IF(YEAR($H10)<$AH$5,$S10,IF(AND(YEAR($H10)=$AH$5,MONTH($H10)<=AH$6),$S10,0)) -> 0 | AI10: =+IF(YEAR($H10)<$AH$5,$S10,IF(AND(YEAR($H10)=$AH$5,MONTH($H10)<=AI$6),$S10,0)) -> 0 | AJ10: =+IF(YEAR($H10)<$AH$5,$S10,IF(AND(YEAR($H10)=$AH$5,MONTH($H10)<=AJ$6),$S10,0)) -> 0 | AK10: =+IF(YEAR($H10)<$AH$5,$S10,IF(AND(YEAR($H10)=$AH$5,MONTH($H10)<=AK$6),$S10,0)) -> 0 | AL10: =+IF(YEAR($H10)<$AH$5,$S10,IF(AND(YEAR($H10)=$AH$5,MONTH($H10)<=AL$6),$S10,0)) -> 0 | AM10: =+IF(YEAR($H10)<$AH$5,$S10,IF(AND(YEAR($H10)=$AH$5,MONTH($H10)<=AM$6),$S10,0)) -> 0 | AN10: =+IF(YEAR($H10)<$AH$5,$S10,IF(AND(YEAR($H10)=$AH$5,MONTH($H10)<=AN$6),$S10,0)) -> 0 | AO10: =+IF(YEAR($H10)<$AH$5,$S10,IF(AND(YEAR($H10)=$AH$5,MONTH($H10)<=AO$6),$S10,0)) -> 0 | ... AS10: =+IF(YEAR($H10)<$AH$5,$S10,IF(AND(YEAR($H10)=$AH$5,MONTH($H10)<=AS$6),$S10,0)) -> 0 | AT10: =+SUM(AH10:AS10) -> 0 | AU10: 0 | AV10: =+IF(YEAR($H10)<$AV$5,$S10,IF(AND(YEAR($H10)=$AV$5,MONTH($H10)<=AV$6),$S10,0)) -> 0 | AW10: =+IF(YEAR($H10)<$AV$5,$S10,IF(AND(YEAR($H10)=$AV$5,MONTH($H10)<=AW$6),$S10,0)) -> 0 | AX10: =+IF(YEAR($H10)<$AV$5,$S10,IF(AND(YEAR($H10)=$AV$5,MONTH($H10)<=AX$6),$S10,0)) -> 0 | AY10: =+IF(YEAR($H10)<$AV$5,$S10,IF(AND(YEAR($H10)=$AV$5,MONTH($H10)<=AY$6),$S10,0)) -> 0 | AZ10: =+IF(YEAR($H10)<$AV$5,$S10,IF(AND(YEAR($H10)=$AV$5,MONTH($H10)<=AZ$6),$S10,0)) -> 0 | BA10: =+IF(YEAR($H10)<$AV$5,$S10,IF(AND(YEAR($H10)=$AV$5,MONTH($H10)<=BA$6),$S10,0)) -> 0 | BB10: =+IF(YEAR($H10)<$AV$5,$S10,IF(AND(YEAR($H10)=$AV$5,MONTH($H10)<=BB$6),$S10,0)) -> 0 | BC10: =+IF(YEAR($H10)<$AV$5,$S10,IF(AND(YEAR($H10)=$AV$5,MONTH($H10)<=BC$6),$S10,0)) -> 0 | ... BG10: =+IF(YEAR($H10)<$AV$5,$S10,IF(AND(YEAR($H10)=$AV$5,MONTH($H10)<=BG$6),$S10,0)) -> 0 | BH10: =+SUM(AV10:BG10) -> 0 | BI10: 0 | BJ10: =+IF(YEAR($H10)<$BJ$5,$S10,IF(AND(YEAR($H10)=$BJ$5,MONTH($H10)<=BJ$6),$S10,0)) -> 0 | BK10: =+IF(YEAR($H10)<$BJ$5,$S10,IF(AND(YEAR($H10)=$BJ$5,MONTH($H10)<=BK$6),$S10,0)) -> 0 | BL10: =+IF(YEAR($H10)<$BJ$5,$S10,IF(AND(YEAR($H10)=$BJ$5,MONTH($H10)<=BL$6),$S10,0)) -> 5125246.5 | BM10: =+IF(YEAR($H10)<$BJ$5,$S10,IF(AND(YEAR($H10)=$BJ$5,MONTH($H10)<=BM$6),$S10,0)) -> 5125246.5 | BN10: =+IF(YEAR($H10)<$BJ$5,$S10,IF(AND(YEAR($H10)=$BJ$5,MONTH($H10)<=BN$6),$S10,0)) -> 5125246.5 | BO10: =+IF(YEAR($H10)<$BJ$5,$S10,IF(AND(YEAR($H10)=$BJ$5,MONTH($H10)<=BO$6),$S10,0)) -> 5125246.5 | BP10: =+IF(YEAR($H10)<$BJ$5,$S10,IF(AND(YEAR($H10)=$BJ$5,MONTH($H10)<=BP$6),$S10,0)) -> 5125246.5 | BQ10: =+IF(YEAR($H10)<$BJ$5,$S10,IF(AND(YEAR($H10)=$BJ$5,MONTH($H10)<=BQ$6),$S10,0)) -> 5125246.5 | ... BU10: =+IF(YEAR($H10)<$BJ$5,$S10,IF(AND(YEAR($H10)=$BJ$5,MONTH($H10)<=BU$6),$S10,0)) -> 5125246.5 | BV10: =+SUM(BJ10:BU10) -> 51252465 | BW10: =+R10-BV10 -> 1.3325641e+08 | BX10: =+IF(YEAR($H10)<$BX$5,$S10,IF(AND(YEAR($H10)=$BX$5,MONTH($H10)<=BX$6),$S10,0)) -> 5125246.5 | BY10: =+IF(YEAR($H10)<$BX$5,$S10,IF(AND(YEAR($H10)=$BX$5,MONTH($H10)<=BY$6),$S10,0)) -> 5125246.5 | BZ10: =+IF(YEAR($H10)<$BX$5,$S10,IF(AND(YEAR($H10)=$BX$5,MONTH($H10)<=BZ$6),$S10,0)) -> 5125246.5 | CA10: =+IF(YEAR($H10)<$BX$5,$S10,IF(AND(YEAR($H10)=$BX$5,MONTH($H10)<=CA$6),$S10,0)) -> 5125246.5 | CB10: =+IF(YEAR($H10)<$BX$5,$S10,IF(AND(YEAR($H10)=$BX$5,MONTH($H10)<=CB$6),$S10,0)) -> 5125246.5 | CC10: =+IF(YEAR($H10)<$BX$5,$S10,IF(AND(YEAR($H10)=$BX$5,MONTH($H10)<=CC$6),$S10,0)) -> 5125246.5 | CD10: =+IF(YEAR($H10)<$BX$5,$S10,IF(AND(YEAR($H10)=$BX$5,MONTH($H10)<=CD$6),$S10,0)) -> 5125246.5 | CE10: =+IF(YEAR($H10)<$BX$5,$S10,IF(AND(YEAR($H10)=$BX$5,MONTH($H10)<=CE$6),$S10,0)) -> 5125246.5 | ... CI10: =+IF(YEAR($H10)<$BX$5,$S10,IF(AND(YEAR($H10)=$BX$5,MONTH($H10)<=CI$6),$S10,0)) -> 5125246.5 | CJ10: =+SUM(BX10:CI10) -> 61502958 | CK10: =+BW10-CJ10 -> 71753451 | CL10: =+IF(YEAR($H10)<$CL$4,$S10,IF(AND(YEAR($H10)=$CL$4,MONTH($H10)<=CL$6),$S10,0)) -> 5125246.5 | CM10: =+IF(YEAR($H10)<$CL$4,$S10,IF(AND(YEAR($H10)=$CL$4,MONTH($H10)<=CM$6),$S10,0)) -> 5125246.5 | CN10: =+IF(YEAR($H10)<$CL$4,$S10,IF(AND(YEAR($H10)=$CL$4,MONTH($H10)<=CN$6),$S10,0)) -> 5125246.5 | CO10: =+IF(YEAR($H10)<$CL$4,$S10,IF(AND(YEAR($H10)=$CL$4,MONTH($H10)<=CO$6),$S10,0)) -> 5125246.5 | CP10: =+IF(YEAR($H10)<$CL$4,$S10,IF(AND(YEAR($H10)=$CL$4,MONTH($H10)<=CP$6),$S10,0)) -> 5125246.5 | CQ10: =+IF(YEAR($H10)<$CL$4,$S10,IF(AND(YEAR($H10)=$CL$4,MONTH($H10)<=CQ$6),$S10,0)) -> 5125246.5 | CR10: =+IF(YEAR($H10)<$CL$4,$S10,IF(AND(YEAR($H10)=$CL$4,MONTH($H10)<=CR$6),$S10,0)) -> 5125246.5 | CS10: =+IF(YEAR($H10)<$CL$4,$S10,IF(AND(YEAR($H10)=$CL$4,MONTH($H10)<=CS$6),$S10,0)) -> 5125246.5 | ... CW10: =+IF(YEAR($H10)<$CL$4,$S10,IF(AND(YEAR($H10)=$CL$4,MONTH($H10)<=CW$6),$S10,0)) -> 5125246.5 | CX10: =+SUM(CL10:CW10) -> 61502958 | CY10: =+CK10-CX10 -> 10250493
B11: Chung | C11: =_xlfn.XLOOKUP(E11,'[1]TH_CC (3)'!$E:$E,'[1]TH_CC (3)'!$E:$E) -> 117000001 | D11: Z21180A | E11: 117000001 | F11: Nguồn bơm giếng và tưới cỏ | G11: 44985 | H11: 44986 | I11: 36 | J11: 1001202000 | K11: Hành chánh nhân sự | M11: =+LEFT(N11,4) -> 6424 | N11: 6424001909 | O11: 6424001909 | R11: 308593906 | S11: 8572053 | T11: =+IF(YEAR($H11)<$T$5,$S11,IF(AND(YEAR($H11)=$T$5,MONTH($H11)<=T$6),$S11,0)) -> 0 | U11: =+IF(YEAR($H11)<$T$5,$S11,IF(AND(YEAR($H11)=$T$5,MONTH($H11)<=U$6),$S11,0)) -> 0 | V11: =+IF(YEAR($H11)<$T$5,$S11,IF(AND(YEAR($H11)=$T$5,MONTH($H11)<=V$6),$S11,0)) -> 0 | W11: =+IF(YEAR($H11)<$T$5,$S11,IF(AND(YEAR($H11)=$T$5,MONTH($H11)<=W$6),$S11,0)) -> 0 | X11: =+IF(YEAR($H11)<$T$5,$S11,IF(AND(YEAR($H11)=$T$5,MONTH($H11)<=X$6),$S11,0)) -> 0 | Y11: =+IF(YEAR($H11)<$T$5,$S11,IF(AND(YEAR($H11)=$T$5,MONTH($H11)<=Y$6),$S11,0)) -> 0 | Z11: =+IF(YEAR($H11)<$T$5,$S11,IF(AND(YEAR($H11)=$T$5,MONTH($H11)<=Z$6),$S11,0)) -> 0 | AA11: =+IF(YEAR($H11)<$T$5,$S11,IF(AND(YEAR($H11)=$T$5,MONTH($H11)<=AA$6),$S11,0)) -> 0 | ... AE11: =+IF(YEAR($H11)<$T$5,$S11,IF(AND(YEAR($H11)=$T$5,MONTH($H11)<=AE$6),$S11,0)) -> 0 | AF11: =+SUM(T11:AE11) -> 0 | AG11: 0 | AH11: =+IF(YEAR($H11)<$AH$5,$S11,IF(AND(YEAR($H11)=$AH$5,MONTH($H11)<=AH$6),$S11,0)) -> 0 | AI11: =+IF(YEAR($H11)<$AH$5,$S11,IF(AND(YEAR($H11)=$AH$5,MONTH($H11)<=AI$6),$S11,0)) -> 0 | AJ11: =+IF(YEAR($H11)<$AH$5,$S11,IF(AND(YEAR($H11)=$AH$5,MONTH($H11)<=AJ$6),$S11,0)) -> 0 | AK11: =+IF(YEAR($H11)<$AH$5,$S11,IF(AND(YEAR($H11)=$AH$5,MONTH($H11)<=AK$6),$S11,0)) -> 0 | AL11: =+IF(YEAR($H11)<$AH$5,$S11,IF(AND(YEAR($H11)=$AH$5,MONTH($H11)<=AL$6),$S11,0)) -> 0 | AM11: =+IF(YEAR($H11)<$AH$5,$S11,IF(AND(YEAR($H11)=$AH$5,MONTH($H11)<=AM$6),$S11,0)) -> 0 | AN11: =+IF(YEAR($H11)<$AH$5,$S11,IF(AND(YEAR($H11)=$AH$5,MONTH($H11)<=AN$6),$S11,0)) -> 0 | AO11: =+IF(YEAR($H11)<$AH$5,$S11,IF(AND(YEAR($H11)=$AH$5,MONTH($H11)<=AO$6),$S11,0)) -> 0 | ... AS11: =+IF(YEAR($H11)<$AH$5,$S11,IF(AND(YEAR($H11)=$AH$5,MONTH($H11)<=AS$6),$S11,0)) -> 0 | AT11: =+SUM(AH11:AS11) -> 0 | AU11: 0 | AV11: =+IF(YEAR($H11)<$AV$5,$S11,IF(AND(YEAR($H11)=$AV$5,MONTH($H11)<=AV$6),$S11,0)) -> 0 | AW11: =+IF(YEAR($H11)<$AV$5,$S11,IF(AND(YEAR($H11)=$AV$5,MONTH($H11)<=AW$6),$S11,0)) -> 0 | AX11: =+IF(YEAR($H11)<$AV$5,$S11,IF(AND(YEAR($H11)=$AV$5,MONTH($H11)<=AX$6),$S11,0)) -> 0 | AY11: =+IF(YEAR($H11)<$AV$5,$S11,IF(AND(YEAR($H11)=$AV$5,MONTH($H11)<=AY$6),$S11,0)) -> 0 | AZ11: =+IF(YEAR($H11)<$AV$5,$S11,IF(AND(YEAR($H11)=$AV$5,MONTH($H11)<=AZ$6),$S11,0)) -> 0 | BA11: =+IF(YEAR($H11)<$AV$5,$S11,IF(AND(YEAR($H11)=$AV$5,MONTH($H11)<=BA$6),$S11,0)) -> 0 | BB11: =+IF(YEAR($H11)<$AV$5,$S11,IF(AND(YEAR($H11)=$AV$5,MONTH($H11)<=BB$6),$S11,0)) -> 0 | BC11: =+IF(YEAR($H11)<$AV$5,$S11,IF(AND(YEAR($H11)=$AV$5,MONTH($H11)<=BC$6),$S11,0)) -> 0 | ... BG11: =+IF(YEAR($H11)<$AV$5,$S11,IF(AND(YEAR($H11)=$AV$5,MONTH($H11)<=BG$6),$S11,0)) -> 0 | BH11: =+SUM(AV11:BG11) -> 0 | BI11: 0 | BJ11: =+IF(YEAR($H11)<$BJ$5,$S11,IF(AND(YEAR($H11)=$BJ$5,MONTH($H11)<=BJ$6),$S11,0)) -> 0 | BK11: =+IF(YEAR($H11)<$BJ$5,$S11,IF(AND(YEAR($H11)=$BJ$5,MONTH($H11)<=BK$6),$S11,0)) -> 0 | BL11: =+IF(YEAR($H11)<$BJ$5,$S11,IF(AND(YEAR($H11)=$BJ$5,MONTH($H11)<=BL$6),$S11,0)) -> 8572053 | BM11: =+IF(YEAR($H11)<$BJ$5,$S11,IF(AND(YEAR($H11)=$BJ$5,MONTH($H11)<=BM$6),$S11,0)) -> 8572053 | BN11: =+IF(YEAR($H11)<$BJ$5,$S11,IF(AND(YEAR($H11)=$BJ$5,MONTH($H11)<=BN$6),$S11,0)) -> 8572053 | BO11: =+IF(YEAR($H11)<$BJ$5,$S11,IF(AND(YEAR($H11)=$BJ$5,MONTH($H11)<=BO$6),$S11,0)) -> 8572053 | BP11: =+IF(YEAR($H11)<$BJ$5,$S11,IF(AND(YEAR($H11)=$BJ$5,MONTH($H11)<=BP$6),$S11,0)) -> 8572053 | BQ11: =+IF(YEAR($H11)<$BJ$5,$S11,IF(AND(YEAR($H11)=$BJ$5,MONTH($H11)<=BQ$6),$S11,0)) -> 8572053 | ... BU11: =+IF(YEAR($H11)<$BJ$5,$S11,IF(AND(YEAR($H11)=$BJ$5,MONTH($H11)<=BU$6),$S11,0)) -> 8572053 | BV11: =+SUM(BJ11:BU11) -> 85720530 | BW11: =+R11-BV11 -> 222873376 | BX11: =+$S11 -> 8572053 | BY11: =+$S11 -> 8572053 | BZ11: =+$S11 -> 8572053 | CA11: =+$S11 -> 8572053 | CB11: =+$S11 -> 8572053 | CC11: =+$S11 -> 8572053 | CD11: =+$S11 -> 8572053 | CE11: =+$S11 -> 8572053 | ... CI11: =+$S11 -> 8572053 | CJ11: =+SUM(BX11:CI11) -> 102864636 | CK11: =+BW11-CJ11 -> 120008740 | CL11: =+IF(YEAR($H11)<$CL$4,$S11,IF(AND(YEAR($H11)=$CL$4,MONTH($H11)<=CL$6),$S11,0)) -> 8572053 | CM11: =+IF(YEAR($H11)<$CL$4,$S11,IF(AND(YEAR($H11)=$CL$4,MONTH($H11)<=CM$6),$S11,0)) -> 8572053 | CN11: =+IF(YEAR($H11)<$CL$4,$S11,IF(AND(YEAR($H11)=$CL$4,MONTH($H11)<=CN$6),$S11,0)) -> 8572053 | CO11: =+IF(YEAR($H11)<$CL$4,$S11,IF(AND(YEAR($H11)=$CL$4,MONTH($H11)<=CO$6),$S11,0)) -> 8572053 | CP11: =+IF(YEAR($H11)<$CL$4,$S11,IF(AND(YEAR($H11)=$CL$4,MONTH($H11)<=CP$6),$S11,0)) -> 8572053 | CQ11: =+IF(YEAR($H11)<$CL$4,$S11,IF(AND(YEAR($H11)=$CL$4,MONTH($H11)<=CQ$6),$S11,0)) -> 8572053 | CR11: =+IF(YEAR($H11)<$CL$4,$S11,IF(AND(YEAR($H11)=$CL$4,MONTH($H11)<=CR$6),$S11,0)) -> 8572053 | CS11: =+IF(YEAR($H11)<$CL$4,$S11,IF(AND(YEAR($H11)=$CL$4,MONTH($H11)<=CS$6),$S11,0)) -> 8572053 | ... CW11: =+IF(YEAR($H11)<$CL$4,$S11,IF(AND(YEAR($H11)=$CL$4,MONTH($H11)<=CW$6),$S11,0)) -> 8572053 | CX11: =+SUM(CL11:CW11) -> 102864636 | CY11: =+CK11-CX11 -> 17144104
B12: Chung | C12: =_xlfn.XLOOKUP(E12,'[1]TH_CC (3)'!$E:$E,'[1]TH_CC (3)'!$E:$E) -> 117000002 | D12: Z21180A | E12: 117000002 | F12: Hạng mục phụ nhà xưởng (VP F02, bó vĩa, điện, sơn) | G12: 45016 | H12: 45017 | I12: 36 | J12: 1001202000 | K12: Hành chánh nhân sự | M12: =+LEFT(N12,4) -> 6424 | N12: 6424001909 | O12: 6424001909 | R12: 807761229 | S12: 22437812 | T12: =+IF(YEAR($H12)<$T$5,$S12,IF(AND(YEAR($H12)=$T$5,MONTH($H12)<=T$6),$S12,0)) -> 0 | U12: =+IF(YEAR($H12)<$T$5,$S12,IF(AND(YEAR($H12)=$T$5,MONTH($H12)<=U$6),$S12,0)) -> 0 | V12: =+IF(YEAR($H12)<$T$5,$S12,IF(AND(YEAR($H12)=$T$5,MONTH($H12)<=V$6),$S12,0)) -> 0 | W12: =+IF(YEAR($H12)<$T$5,$S12,IF(AND(YEAR($H12)=$T$5,MONTH($H12)<=W$6),$S12,0)) -> 0 | X12: =+IF(YEAR($H12)<$T$5,$S12,IF(AND(YEAR($H12)=$T$5,MONTH($H12)<=X$6),$S12,0)) -> 0 | Y12: =+IF(YEAR($H12)<$T$5,$S12,IF(AND(YEAR($H12)=$T$5,MONTH($H12)<=Y$6),$S12,0)) -> 0 | Z12: =+IF(YEAR($H12)<$T$5,$S12,IF(AND(YEAR($H12)=$T$5,MONTH($H12)<=Z$6),$S12,0)) -> 0 | AA12: =+IF(YEAR($H12)<$T$5,$S12,IF(AND(YEAR($H12)=$T$5,MONTH($H12)<=AA$6),$S12,0)) -> 0 | ... AE12: =+IF(YEAR($H12)<$T$5,$S12,IF(AND(YEAR($H12)=$T$5,MONTH($H12)<=AE$6),$S12,0)) -> 0 | AF12: =+SUM(T12:AE12) -> 0 | AG12: 0 | AH12: =+IF(YEAR($H12)<$AH$5,$S12,IF(AND(YEAR($H12)=$AH$5,MONTH($H12)<=AH$6),$S12,0)) -> 0 | AI12: =+IF(YEAR($H12)<$AH$5,$S12,IF(AND(YEAR($H12)=$AH$5,MONTH($H12)<=AI$6),$S12,0)) -> 0 | AJ12: =+IF(YEAR($H12)<$AH$5,$S12,IF(AND(YEAR($H12)=$AH$5,MONTH($H12)<=AJ$6),$S12,0)) -> 0 | AK12: =+IF(YEAR($H12)<$AH$5,$S12,IF(AND(YEAR($H12)=$AH$5,MONTH($H12)<=AK$6),$S12,0)) -> 0 | AL12: =+IF(YEAR($H12)<$AH$5,$S12,IF(AND(YEAR($H12)=$AH$5,MONTH($H12)<=AL$6),$S12,0)) -> 0 | AM12: =+IF(YEAR($H12)<$AH$5,$S12,IF(AND(YEAR($H12)=$AH$5,MONTH($H12)<=AM$6),$S12,0)) -> 0 | AN12: =+IF(YEAR($H12)<$AH$5,$S12,IF(AND(YEAR($H12)=$AH$5,MONTH($H12)<=AN$6),$S12,0)) -> 0 | AO12: =+IF(YEAR($H12)<$AH$5,$S12,IF(AND(YEAR($H12)=$AH$5,MONTH($H12)<=AO$6),$S12,0)) -> 0 | ... AS12: =+IF(YEAR($H12)<$AH$5,$S12,IF(AND(YEAR($H12)=$AH$5,MONTH($H12)<=AS$6),$S12,0)) -> 0 | AT12: =+SUM(AH12:AS12) -> 0 | AU12: 0 | AV12: =+IF(YEAR($H12)<$AV$5,$S12,IF(AND(YEAR($H12)=$AV$5,MONTH($H12)<=AV$6),$S12,0)) -> 0 | AW12: =+IF(YEAR($H12)<$AV$5,$S12,IF(AND(YEAR($H12)=$AV$5,MONTH($H12)<=AW$6),$S12,0)) -> 0 | AX12: =+IF(YEAR($H12)<$AV$5,$S12,IF(AND(YEAR($H12)=$AV$5,MONTH($H12)<=AX$6),$S12,0)) -> 0 | AY12: =+IF(YEAR($H12)<$AV$5,$S12,IF(AND(YEAR($H12)=$AV$5,MONTH($H12)<=AY$6),$S12,0)) -> 0 | AZ12: =+IF(YEAR($H12)<$AV$5,$S12,IF(AND(YEAR($H12)=$AV$5,MONTH($H12)<=AZ$6),$S12,0)) -> 0 | BA12: =+IF(YEAR($H12)<$AV$5,$S12,IF(AND(YEAR($H12)=$AV$5,MONTH($H12)<=BA$6),$S12,0)) -> 0 | BB12: =+IF(YEAR($H12)<$AV$5,$S12,IF(AND(YEAR($H12)=$AV$5,MONTH($H12)<=BB$6),$S12,0)) -> 0 | BC12: =+IF(YEAR($H12)<$AV$5,$S12,IF(AND(YEAR($H12)=$AV$5,MONTH($H12)<=BC$6),$S12,0)) -> 0 | ... BG12: =+IF(YEAR($H12)<$AV$5,$S12,IF(AND(YEAR($H12)=$AV$5,MONTH($H12)<=BG$6),$S12,0)) -> 0 | BH12: =+SUM(AV12:BG12) -> 0 | BI12: 0 | BJ12: =+IF(YEAR($H12)<$BJ$5,$S12,IF(AND(YEAR($H12)=$BJ$5,MONTH($H12)<=BJ$6),$S12,0)) -> 0 | BK12: =+IF(YEAR($H12)<$BJ$5,$S12,IF(AND(YEAR($H12)=$BJ$5,MONTH($H12)<=BK$6),$S12,0)) -> 0 | BL12: =+IF(YEAR($H12)<$BJ$5,$S12,IF(AND(YEAR($H12)=$BJ$5,MONTH($H12)<=BL$6),$S12,0)) -> 0 | BM12: =+IF(YEAR($H12)<$BJ$5,$S12,IF(AND(YEAR($H12)=$BJ$5,MONTH($H12)<=BM$6),$S12,0)) -> 22437812 | BN12: =+IF(YEAR($H12)<$BJ$5,$S12,IF(AND(YEAR($H12)=$BJ$5,MONTH($H12)<=BN$6),$S12,0)) -> 22437812 | BO12: =+IF(YEAR($H12)<$BJ$5,$S12,IF(AND(YEAR($H12)=$BJ$5,MONTH($H12)<=BO$6),$S12,0)) -> 22437812 | BP12: =+IF(YEAR($H12)<$BJ$5,$S12,IF(AND(YEAR($H12)=$BJ$5,MONTH($H12)<=BP$6),$S12,0)) -> 22437812 | BQ12: =+IF(YEAR($H12)<$BJ$5,$S12,IF(AND(YEAR($H12)=$BJ$5,MONTH($H12)<=BQ$6),$S12,0)) -> 22437812 | ... BU12: =+IF(YEAR($H12)<$BJ$5,$S12,IF(AND(YEAR($H12)=$BJ$5,MONTH($H12)<=BU$6),$S12,0)) -> 22437812 | BV12: =+SUM(BJ12:BU12) -> 201940308 | BW12: =+R12-BV12 -> 605820921 | BX12: =+$S12 -> 22437812 | BY12: =+$S12 -> 22437812 | BZ12: =+$S12 -> 22437812 | CA12: =+$S12 -> 22437812 | CB12: =+$S12 -> 22437812 | CC12: =+$S12 -> 22437812 | CD12: =+$S12 -> 22437812 | CE12: =+$S12 -> 22437812 | ... CI12: =+$S12 -> 22437812 | CJ12: =+SUM(BX12:CI12) -> 269253744 | CK12: =+BW12-CJ12 -> 336567177 | CL12: =+IF(YEAR($H12)<$CL$4,$S12,IF(AND(YEAR($H12)=$CL$4,MONTH($H12)<=CL$6),$S12,0)) -> 22437812 | CM12: =+IF(YEAR($H12)<$CL$4,$S12,IF(AND(YEAR($H12)=$CL$4,MONTH($H12)<=CM$6),$S12,0)) -> 22437812 | CN12: =+IF(YEAR($H12)<$CL$4,$S12,IF(AND(YEAR($H12)=$CL$4,MONTH($H12)<=CN$6),$S12,0)) -> 22437812 | CO12: =+IF(YEAR($H12)<$CL$4,$S12,IF(AND(YEAR($H12)=$CL$4,MONTH($H12)<=CO$6),$S12,0)) -> 22437812 | CP12: =+IF(YEAR($H12)<$CL$4,$S12,IF(AND(YEAR($H12)=$CL$4,MONTH($H12)<=CP$6),$S12,0)) -> 22437812 | CQ12: =+IF(YEAR($H12)<$CL$4,$S12,IF(AND(YEAR($H12)=$CL$4,MONTH($H12)<=CQ$6),$S12,0)) -> 22437812 | CR12: =+IF(YEAR($H12)<$CL$4,$S12,IF(AND(YEAR($H12)=$CL$4,MONTH($H12)<=CR$6),$S12,0)) -> 22437812 | CS12: =+IF(YEAR($H12)<$CL$4,$S12,IF(AND(YEAR($H12)=$CL$4,MONTH($H12)<=CS$6),$S12,0)) -> 22437812 | ... CW12: =+IF(YEAR($H12)<$CL$4,$S12,IF(AND(YEAR($H12)=$CL$4,MONTH($H12)<=CW$6),$S12,0)) -> 22437812 | CX12: =+SUM(CL12:CW12) -> 269253744 | CY12: =+CK12-CX12 -> 67313433
A13: 6274.4 | B13: Chung | C13: =_xlfn.XLOOKUP(E13,'[1]TH_CC (3)'!$E:$E,'[1]TH_CC (3)'!$E:$E) -> 115000006 | D13: Z21180P | E13: 115000006 | F13: Bãi tập kết rác F6 | G13: 45141 | H13: 45108 | I13: 36 | J13: 1001602000 | K13: Xưởng sản xuất PET | M13: =+LEFT(N13,4) -> 6274 | N13: 6274001909 | O13: 6274001909 | R13: 102096978 | S13: 2836027 | T13: =+IF(YEAR($H13)<$T$5,$S13,IF(AND(YEAR($H13)=$T$5,MONTH($H13)<=T$6),$S13,0)) -> 0 | U13: =+IF(YEAR($H13)<$T$5,$S13,IF(AND(YEAR($H13)=$T$5,MONTH($H13)<=U$6),$S13,0)) -> 0 | V13: =+IF(YEAR($H13)<$T$5,$S13,IF(AND(YEAR($H13)=$T$5,MONTH($H13)<=V$6),$S13,0)) -> 0 | W13: =+IF(YEAR($H13)<$T$5,$S13,IF(AND(YEAR($H13)=$T$5,MONTH($H13)<=W$6),$S13,0)) -> 0 | X13: =+IF(YEAR($H13)<$T$5,$S13,IF(AND(YEAR($H13)=$T$5,MONTH($H13)<=X$6),$S13,0)) -> 0 | Y13: =+IF(YEAR($H13)<$T$5,$S13,IF(AND(YEAR($H13)=$T$5,MONTH($H13)<=Y$6),$S13,0)) -> 0 | Z13: =+IF(YEAR($H13)<$T$5,$S13,IF(AND(YEAR($H13)=$T$5,MONTH($H13)<=Z$6),$S13,0)) -> 0 | AA13: =+IF(YEAR($H13)<$T$5,$S13,IF(AND(YEAR($H13)=$T$5,MONTH($H13)<=AA$6),$S13,0)) -> 0 | ... AE13: =+IF(YEAR($H13)<$T$5,$S13,IF(AND(YEAR($H13)=$T$5,MONTH($H13)<=AE$6),$S13,0)) -> 0 | AF13: =+SUM(T13:AE13) -> 0 | AG13: 0 | AH13: =+IF(YEAR($H13)<$AH$5,$S13,IF(AND(YEAR($H13)=$AH$5,MONTH($H13)<=AH$6),$S13,0)) -> 0 | AI13: =+IF(YEAR($H13)<$AH$5,$S13,IF(AND(YEAR($H13)=$AH$5,MONTH($H13)<=AI$6),$S13,0)) -> 0 | AJ13: =+IF(YEAR($H13)<$AH$5,$S13,IF(AND(YEAR($H13)=$AH$5,MONTH($H13)<=AJ$6),$S13,0)) -> 0 | AK13: =+IF(YEAR($H13)<$AH$5,$S13,IF(AND(YEAR($H13)=$AH$5,MONTH($H13)<=AK$6),$S13,0)) -> 0 | AL13: =+IF(YEAR($H13)<$AH$5,$S13,IF(AND(YEAR($H13)=$AH$5,MONTH($H13)<=AL$6),$S13,0)) -> 0 | AM13: =+IF(YEAR($H13)<$AH$5,$S13,IF(AND(YEAR($H13)=$AH$5,MONTH($H13)<=AM$6),$S13,0)) -> 0 | AN13: =+IF(YEAR($H13)<$AH$5,$S13,IF(AND(YEAR($H13)=$AH$5,MONTH($H13)<=AN$6),$S13,0)) -> 0 | AO13: =+IF(YEAR($H13)<$AH$5,$S13,IF(AND(YEAR($H13)=$AH$5,MONTH($H13)<=AO$6),$S13,0)) -> 0 | ... AS13: =+IF(YEAR($H13)<$AH$5,$S13,IF(AND(YEAR($H13)=$AH$5,MONTH($H13)<=AS$6),$S13,0)) -> 0 | AT13: =+SUM(AH13:AS13) -> 0 | AU13: 0 | AV13: =+IF(YEAR($H13)<$AV$5,$S13,IF(AND(YEAR($H13)=$AV$5,MONTH($H13)<=AV$6),$S13,0)) -> 0 | AW13: =+IF(YEAR($H13)<$AV$5,$S13,IF(AND(YEAR($H13)=$AV$5,MONTH($H13)<=AW$6),$S13,0)) -> 0 | AX13: =+IF(YEAR($H13)<$AV$5,$S13,IF(AND(YEAR($H13)=$AV$5,MONTH($H13)<=AX$6),$S13,0)) -> 0 | AY13: =+IF(YEAR($H13)<$AV$5,$S13,IF(AND(YEAR($H13)=$AV$5,MONTH($H13)<=AY$6),$S13,0)) -> 0 | AZ13: =+IF(YEAR($H13)<$AV$5,$S13,IF(AND(YEAR($H13)=$AV$5,MONTH($H13)<=AZ$6),$S13,0)) -> 0 | BA13: =+IF(YEAR($H13)<$AV$5,$S13,IF(AND(YEAR($H13)=$AV$5,MONTH($H13)<=BA$6),$S13,0)) -> 0 | BB13: =+IF(YEAR($H13)<$AV$5,$S13,IF(AND(YEAR($H13)=$AV$5,MONTH($H13)<=BB$6),$S13,0)) -> 0 | BC13: =+IF(YEAR($H13)<$AV$5,$S13,IF(AND(YEAR($H13)=$AV$5,MONTH($H13)<=BC$6),$S13,0)) -> 0 | ... BG13: =+IF(YEAR($H13)<$AV$5,$S13,IF(AND(YEAR($H13)=$AV$5,MONTH($H13)<=BG$6),$S13,0)) -> 0 | BH13: =+SUM(AV13:BG13) -> 0 | BI13: 0 | BJ13: =+IF(YEAR($H13)<$BJ$5,$S13,IF(AND(YEAR($H13)=$BJ$5,MONTH($H13)<=BJ$6),$S13,0)) -> 0 | BK13: =+IF(YEAR($H13)<$BJ$5,$S13,IF(AND(YEAR($H13)=$BJ$5,MONTH($H13)<=BK$6),$S13,0)) -> 0 | BL13: =+IF(YEAR($H13)<$BJ$5,$S13,IF(AND(YEAR($H13)=$BJ$5,MONTH($H13)<=BL$6),$S13,0)) -> 0 | BM13: =+IF(YEAR($H13)<$BJ$5,$S13,IF(AND(YEAR($H13)=$BJ$5,MONTH($H13)<=BM$6),$S13,0)) -> 0 | BN13: =+IF(YEAR($H13)<$BJ$5,$S13,IF(AND(YEAR($H13)=$BJ$5,MONTH($H13)<=BN$6),$S13,0)) -> 0 | BO13: =+IF(YEAR($H13)<$BJ$5,$S13,IF(AND(YEAR($H13)=$BJ$5,MONTH($H13)<=BO$6),$S13,0)) -> 0 | BP13: =+IF(YEAR($H13)<$BJ$5,$S13,IF(AND(YEAR($H13)=$BJ$5,MONTH($H13)<=BP$6),$S13,0)) -> 2836027 | BQ13: =+IF(YEAR($H13)<$BJ$5,$S13,IF(AND(YEAR($H13)=$BJ$5,MONTH($H13)<=BQ$6),$S13,0)) -> 2836027 | ... BU13: =+IF(YEAR($H13)<$BJ$5,$S13,IF(AND(YEAR($H13)=$BJ$5,MONTH($H13)<=BU$6),$S13,0)) -> 2836027 | BV13: =+SUM(BJ13:BU13) -> 17016162 | BW13: =+R13-BV13 -> 85080816 | BX13: =+$S13 -> 2836027 | BY13: =+$S13 -> 2836027 | BZ13: =+$S13 -> 2836027 | CA13: =+$S13 -> 2836027 | CB13: =+$S13 -> 2836027 | CC13: =+$S13 -> 2836027 | CD13: =+$S13 -> 2836027 | CE13: =+$S13 -> 2836027 | ... CI13: =+$S13 -> 2836027 | CJ13: =+SUM(BX13:CI13) -> 34032324 | CK13: =+BW13-CJ13 -> 51048492 | CL13: =+IF(YEAR($H13)<$CL$4,$S13,IF(AND(YEAR($H13)=$CL$4,MONTH($H13)<=CL$6),$S13,0)) -> 2836027 | CM13: =+IF(YEAR($H13)<$CL$4,$S13,IF(AND(YEAR($H13)=$CL$4,MONTH($H13)<=CM$6),$S13,0)) -> 2836027 | CN13: =+IF(YEAR($H13)<$CL$4,$S13,IF(AND(YEAR($H13)=$CL$4,MONTH($H13)<=CN$6),$S13,0)) -> 2836027 | CO13: =+IF(YEAR($H13)<$CL$4,$S13,IF(AND(YEAR($H13)=$CL$4,MONTH($H13)<=CO$6),$S13,0)) -> 2836027 | CP13: =+IF(YEAR($H13)<$CL$4,$S13,IF(AND(YEAR($H13)=$CL$4,MONTH($H13)<=CP$6),$S13,0)) -> 2836027 | CQ13: =+IF(YEAR($H13)<$CL$4,$S13,IF(AND(YEAR($H13)=$CL$4,MONTH($H13)<=CQ$6),$S13,0)) -> 2836027 | CR13: =+IF(YEAR($H13)<$CL$4,$S13,IF(AND(YEAR($H13)=$CL$4,MONTH($H13)<=CR$6),$S13,0)) -> 2836027 | CS13: =+IF(YEAR($H13)<$CL$4,$S13,IF(AND(YEAR($H13)=$CL$4,MONTH($H13)<=CS$6),$S13,0)) -> 2836027 | ... CW13: =+IF(YEAR($H13)<$CL$4,$S13,IF(AND(YEAR($H13)=$CL$4,MONTH($H13)<=CW$6),$S13,0)) -> 2836027 | CX13: =+SUM(CL13:CW13) -> 34032324 | CY13: =+CK13-CX13 -> 17016168
A14: 6274.4 | B14: Chung | C14: =_xlfn.XLOOKUP(E14,'[1]TH_CC (3)'!$E:$E,'[1]TH_CC (3)'!$E:$E) -> 115000008 | D14: Z21180P | E14: 115000008 | F14: Thi công nhà bạt F6 | G14: 45141 | H14: 45108 | I14: 36 | J14: 1001602000 | K14: Xưởng sản xuất PET | M14: =+LEFT(N14,4) -> 6274 | N14: 6274001909 | O14: 6274001909 | R14: 53030000 | S14: 1473055 | T14: =+IF(YEAR($H14)<$T$5,$S14,IF(AND(YEAR($H14)=$T$5,MONTH($H14)<=T$6),$S14,0)) -> 0 | U14: =+IF(YEAR($H14)<$T$5,$S14,IF(AND(YEAR($H14)=$T$5,MONTH($H14)<=U$6),$S14,0)) -> 0 | V14: =+IF(YEAR($H14)<$T$5,$S14,IF(AND(YEAR($H14)=$T$5,MONTH($H14)<=V$6),$S14,0)) -> 0 | W14: =+IF(YEAR($H14)<$T$5,$S14,IF(AND(YEAR($H14)=$T$5,MONTH($H14)<=W$6),$S14,0)) -> 0 | X14: =+IF(YEAR($H14)<$T$5,$S14,IF(AND(YEAR($H14)=$T$5,MONTH($H14)<=X$6),$S14,0)) -> 0 | Y14: =+IF(YEAR($H14)<$T$5,$S14,IF(AND(YEAR($H14)=$T$5,MONTH($H14)<=Y$6),$S14,0)) -> 0 | Z14: =+IF(YEAR($H14)<$T$5,$S14,IF(AND(YEAR($H14)=$T$5,MONTH($H14)<=Z$6),$S14,0)) -> 0 | AA14: =+IF(YEAR($H14)<$T$5,$S14,IF(AND(YEAR($H14)=$T$5,MONTH($H14)<=AA$6),$S14,0)) -> 0 | ... AE14: =+IF(YEAR($H14)<$T$5,$S14,IF(AND(YEAR($H14)=$T$5,MONTH($H14)<=AE$6),$S14,0)) -> 0 | AF14: =+SUM(T14:AE14) -> 0 | AG14: 0 | AH14: =+IF(YEAR($H14)<$AH$5,$S14,IF(AND(YEAR($H14)=$AH$5,MONTH($H14)<=AH$6),$S14,0)) -> 0 | AI14: =+IF(YEAR($H14)<$AH$5,$S14,IF(AND(YEAR($H14)=$AH$5,MONTH($H14)<=AI$6),$S14,0)) -> 0 | AJ14: =+IF(YEAR($H14)<$AH$5,$S14,IF(AND(YEAR($H14)=$AH$5,MONTH($H14)<=AJ$6),$S14,0)) -> 0 | AK14: =+IF(YEAR($H14)<$AH$5,$S14,IF(AND(YEAR($H14)=$AH$5,MONTH($H14)<=AK$6),$S14,0)) -> 0 | AL14: =+IF(YEAR($H14)<$AH$5,$S14,IF(AND(YEAR($H14)=$AH$5,MONTH($H14)<=AL$6),$S14,0)) -> 0 | AM14: =+IF(YEAR($H14)<$AH$5,$S14,IF(AND(YEAR($H14)=$AH$5,MONTH($H14)<=AM$6),$S14,0)) -> 0 | AN14: =+IF(YEAR($H14)<$AH$5,$S14,IF(AND(YEAR($H14)=$AH$5,MONTH($H14)<=AN$6),$S14,0)) -> 0 | AO14: =+IF(YEAR($H14)<$AH$5,$S14,IF(AND(YEAR($H14)=$AH$5,MONTH($H14)<=AO$6),$S14,0)) -> 0 | ... AS14: =+IF(YEAR($H14)<$AH$5,$S14,IF(AND(YEAR($H14)=$AH$5,MONTH($H14)<=AS$6),$S14,0)) -> 0 | AT14: =+SUM(AH14:AS14) -> 0 | AU14: 0 | AV14: =+IF(YEAR($H14)<$AV$5,$S14,IF(AND(YEAR($H14)=$AV$5,MONTH($H14)<=AV$6),$S14,0)) -> 0 | AW14: =+IF(YEAR($H14)<$AV$5,$S14,IF(AND(YEAR($H14)=$AV$5,MONTH($H14)<=AW$6),$S14,0)) -> 0 | AX14: =+IF(YEAR($H14)<$AV$5,$S14,IF(AND(YEAR($H14)=$AV$5,MONTH($H14)<=AX$6),$S14,0)) -> 0 | AY14: =+IF(YEAR($H14)<$AV$5,$S14,IF(AND(YEAR($H14)=$AV$5,MONTH($H14)<=AY$6),$S14,0)) -> 0 | AZ14: =+IF(YEAR($H14)<$AV$5,$S14,IF(AND(YEAR($H14)=$AV$5,MONTH($H14)<=AZ$6),$S14,0)) -> 0 | BA14: =+IF(YEAR($H14)<$AV$5,$S14,IF(AND(YEAR($H14)=$AV$5,MONTH($H14)<=BA$6),$S14,0)) -> 0 | BB14: =+IF(YEAR($H14)<$AV$5,$S14,IF(AND(YEAR($H14)=$AV$5,MONTH($H14)<=BB$6),$S14,0)) -> 0 | BC14: =+IF(YEAR($H14)<$AV$5,$S14,IF(AND(YEAR($H14)=$AV$5,MONTH($H14)<=BC$6),$S14,0)) -> 0 | ... BG14: =+IF(YEAR($H14)<$AV$5,$S14,IF(AND(YEAR($H14)=$AV$5,MONTH($H14)<=BG$6),$S14,0)) -> 0 | BH14: =+SUM(AV14:BG14) -> 0 | BI14: 0 | BJ14: =+IF(YEAR($H14)<$BJ$5,$S14,IF(AND(YEAR($H14)=$BJ$5,MONTH($H14)<=BJ$6),$S14,0)) -> 0 | BK14: =+IF(YEAR($H14)<$BJ$5,$S14,IF(AND(YEAR($H14)=$BJ$5,MONTH($H14)<=BK$6),$S14,0)) -> 0 | BL14: =+IF(YEAR($H14)<$BJ$5,$S14,IF(AND(YEAR($H14)=$BJ$5,MONTH($H14)<=BL$6),$S14,0)) -> 0 | BM14: =+IF(YEAR($H14)<$BJ$5,$S14,IF(AND(YEAR($H14)=$BJ$5,MONTH($H14)<=BM$6),$S14,0)) -> 0 | BN14: =+IF(YEAR($H14)<$BJ$5,$S14,IF(AND(YEAR($H14)=$BJ$5,MONTH($H14)<=BN$6),$S14,0)) -> 0 | BO14: =+IF(YEAR($H14)<$BJ$5,$S14,IF(AND(YEAR($H14)=$BJ$5,MONTH($H14)<=BO$6),$S14,0)) -> 0 | BP14: =+IF(YEAR($H14)<$BJ$5,$S14,IF(AND(YEAR($H14)=$BJ$5,MONTH($H14)<=BP$6),$S14,0)) -> 1473055 | BQ14: =+IF(YEAR($H14)<$BJ$5,$S14,IF(AND(YEAR($H14)=$BJ$5,MONTH($H14)<=BQ$6),$S14,0)) -> 1473055 | ... BU14: =+IF(YEAR($H14)<$BJ$5,$S14,IF(AND(YEAR($H14)=$BJ$5,MONTH($H14)<=BU$6),$S14,0)) -> 1473055 | BV14: =+SUM(BJ14:BU14) -> 8838330 | BW14: =+R14-BV14 -> 44191670 | BX14: =+$S14 -> 1473055 | BY14: =+$S14 -> 1473055 | BZ14: =+$S14 -> 1473055 | CA14: =+$S14 -> 1473055 | CB14: =+$S14 -> 1473055 | CC14: =+$S14 -> 1473055 | CD14: =+$S14 -> 1473055 | CE14: =+$S14 -> 1473055 | ... CI14: =+$S14 -> 1473055 | CJ14: =+SUM(BX14:CI14) -> 17676660 | CK14: =+BW14-CJ14 -> 26515010 | CL14: =+IF(YEAR($H14)<$CL$4,$S14,IF(AND(YEAR($H14)=$CL$4,MONTH($H14)<=CL$6),$S14,0)) -> 1473055 | CM14: =+IF(YEAR($H14)<$CL$4,$S14,IF(AND(YEAR($H14)=$CL$4,MONTH($H14)<=CM$6),$S14,0)) -> 1473055 | CN14: =+IF(YEAR($H14)<$CL$4,$S14,IF(AND(YEAR($H14)=$CL$4,MONTH($H14)<=CN$6),$S14,0)) -> 1473055 | CO14: =+IF(YEAR($H14)<$CL$4,$S14,IF(AND(YEAR($H14)=$CL$4,MONTH($H14)<=CO$6),$S14,0)) -> 1473055 | CP14: =+IF(YEAR($H14)<$CL$4,$S14,IF(AND(YEAR($H14)=$CL$4,MONTH($H14)<=CP$6),$S14,0)) -> 1473055 | CQ14: =+IF(YEAR($H14)<$CL$4,$S14,IF(AND(YEAR($H14)=$CL$4,MONTH($H14)<=CQ$6),$S14,0)) -> 1473055 | CR14: =+IF(YEAR($H14)<$CL$4,$S14,IF(AND(YEAR($H14)=$CL$4,MONTH($H14)<=CR$6),$S14,0)) -> 1473055 | CS14: =+IF(YEAR($H14)<$CL$4,$S14,IF(AND(YEAR($H14)=$CL$4,MONTH($H14)<=CS$6),$S14,0)) -> 1473055 | ... CW14: =+IF(YEAR($H14)<$CL$4,$S14,IF(AND(YEAR($H14)=$CL$4,MONTH($H14)<=CW$6),$S14,0)) -> 1473055 | CX14: =+SUM(CL14:CW14) -> 17676660 | CY14: =+CK14-CX14 -> 8838350
B15: Chung | C15: =_xlfn.XLOOKUP(E15,'[1]TH_CC (3)'!$E:$E,'[1]TH_CC (3)'!$E:$E) -> 117000003 | D15: Z21180A | E15: 117000003 | F15: Thi công phim cách nhiệt cho vách kính F02 | G15: 45086 | H15: 45108 | I15: 36 | J15: 1001202000 | K15: Hành chánh nhân sự | M15: =+LEFT(N15,4) -> 6424 | N15: 6424001909 | O15: 6424001909 | R15: 59068700 | S15: 1640797 | T15: =+IF(YEAR($H15)<$T$5,$S15,IF(AND(YEAR($H15)=$T$5,MONTH($H15)<=T$6),$S15,0)) -> 0 | U15: =+IF(YEAR($H15)<$T$5,$S15,IF(AND(YEAR($H15)=$T$5,MONTH($H15)<=U$6),$S15,0)) -> 0 | V15: =+IF(YEAR($H15)<$T$5,$S15,IF(AND(YEAR($H15)=$T$5,MONTH($H15)<=V$6),$S15,0)) -> 0 | W15: =+IF(YEAR($H15)<$T$5,$S15,IF(AND(YEAR($H15)=$T$5,MONTH($H15)<=W$6),$S15,0)) -> 0 | X15: =+IF(YEAR($H15)<$T$5,$S15,IF(AND(YEAR($H15)=$T$5,MONTH($H15)<=X$6),$S15,0)) -> 0 | Y15: =+IF(YEAR($H15)<$T$5,$S15,IF(AND(YEAR($H15)=$T$5,MONTH($H15)<=Y$6),$S15,0)) -> 0 | Z15: =+IF(YEAR($H15)<$T$5,$S15,IF(AND(YEAR($H15)=$T$5,MONTH($H15)<=Z$6),$S15,0)) -> 0 | AA15: =+IF(YEAR($H15)<$T$5,$S15,IF(AND(YEAR($H15)=$T$5,MONTH($H15)<=AA$6),$S15,0)) -> 0 | ... AE15: =+IF(YEAR($H15)<$T$5,$S15,IF(AND(YEAR($H15)=$T$5,MONTH($H15)<=AE$6),$S15,0)) -> 0 | AF15: =+SUM(T15:AE15) -> 0 | AG15: 0 | AH15: =+IF(YEAR($H15)<$AH$5,$S15,IF(AND(YEAR($H15)=$AH$5,MONTH($H15)<=AH$6),$S15,0)) -> 0 | AI15: =+IF(YEAR($H15)<$AH$5,$S15,IF(AND(YEAR($H15)=$AH$5,MONTH($H15)<=AI$6),$S15,0)) -> 0 | AJ15: =+IF(YEAR($H15)<$AH$5,$S15,IF(AND(YEAR($H15)=$AH$5,MONTH($H15)<=AJ$6),$S15,0)) -> 0 | AK15: =+IF(YEAR($H15)<$AH$5,$S15,IF(AND(YEAR($H15)=$AH$5,MONTH($H15)<=AK$6),$S15,0)) -> 0 | AL15: =+IF(YEAR($H15)<$AH$5,$S15,IF(AND(YEAR($H15)=$AH$5,MONTH($H15)<=AL$6),$S15,0)) -> 0 | AM15: =+IF(YEAR($H15)<$AH$5,$S15,IF(AND(YEAR($H15)=$AH$5,MONTH($H15)<=AM$6),$S15,0)) -> 0 | AN15: =+IF(YEAR($H15)<$AH$5,$S15,IF(AND(YEAR($H15)=$AH$5,MONTH($H15)<=AN$6),$S15,0)) -> 0 | AO15: =+IF(YEAR($H15)<$AH$5,$S15,IF(AND(YEAR($H15)=$AH$5,MONTH($H15)<=AO$6),$S15,0)) -> 0 | ... AS15: =+IF(YEAR($H15)<$AH$5,$S15,IF(AND(YEAR($H15)=$AH$5,MONTH($H15)<=AS$6),$S15,0)) -> 0 | AT15: =+SUM(AH15:AS15) -> 0 | AU15: 0 | AV15: =+IF(YEAR($H15)<$AV$5,$S15,IF(AND(YEAR($H15)=$AV$5,MONTH($H15)<=AV$6),$S15,0)) -> 0 | AW15: =+IF(YEAR($H15)<$AV$5,$S15,IF(AND(YEAR($H15)=$AV$5,MONTH($H15)<=AW$6),$S15,0)) -> 0 | AX15: =+IF(YEAR($H15)<$AV$5,$S15,IF(AND(YEAR($H15)=$AV$5,MONTH($H15)<=AX$6),$S15,0)) -> 0 | AY15: =+IF(YEAR($H15)<$AV$5,$S15,IF(AND(YEAR($H15)=$AV$5,MONTH($H15)<=AY$6),$S15,0)) -> 0 | AZ15: =+IF(YEAR($H15)<$AV$5,$S15,IF(AND(YEAR($H15)=$AV$5,MONTH($H15)<=AZ$6),$S15,0)) -> 0 | BA15: =+IF(YEAR($H15)<$AV$5,$S15,IF(AND(YEAR($H15)=$AV$5,MONTH($H15)<=BA$6),$S15,0)) -> 0 | BB15: =+IF(YEAR($H15)<$AV$5,$S15,IF(AND(YEAR($H15)=$AV$5,MONTH($H15)<=BB$6),$S15,0)) -> 0 | BC15: =+IF(YEAR($H15)<$AV$5,$S15,IF(AND(YEAR($H15)=$AV$5,MONTH($H15)<=BC$6),$S15,0)) -> 0 | ... BG15: =+IF(YEAR($H15)<$AV$5,$S15,IF(AND(YEAR($H15)=$AV$5,MONTH($H15)<=BG$6),$S15,0)) -> 0 | BH15: =+SUM(AV15:BG15) -> 0 | BI15: 0 | BJ15: =+IF(YEAR($H15)<$BJ$5,$S15,IF(AND(YEAR($H15)=$BJ$5,MONTH($H15)<=BJ$6),$S15,0)) -> 0 | BK15: =+IF(YEAR($H15)<$BJ$5,$S15,IF(AND(YEAR($H15)=$BJ$5,MONTH($H15)<=BK$6),$S15,0)) -> 0 | BL15: =+IF(YEAR($H15)<$BJ$5,$S15,IF(AND(YEAR($H15)=$BJ$5,MONTH($H15)<=BL$6),$S15,0)) -> 0 | BM15: =+IF(YEAR($H15)<$BJ$5,$S15,IF(AND(YEAR($H15)=$BJ$5,MONTH($H15)<=BM$6),$S15,0)) -> 0 | BN15: =+IF(YEAR($H15)<$BJ$5,$S15,IF(AND(YEAR($H15)=$BJ$5,MONTH($H15)<=BN$6),$S15,0)) -> 0 | BO15: =+IF(YEAR($H15)<$BJ$5,$S15,IF(AND(YEAR($H15)=$BJ$5,MONTH($H15)<=BO$6),$S15,0)) -> 0 | BP15: =+IF(YEAR($H15)<$BJ$5,$S15,IF(AND(YEAR($H15)=$BJ$5,MONTH($H15)<=BP$6),$S15,0)) -> 1640797 | BQ15: =+IF(YEAR($H15)<$BJ$5,$S15,IF(AND(YEAR($H15)=$BJ$5,MONTH($H15)<=BQ$6),$S15,0)) -> 1640797 | ... BU15: =+IF(YEAR($H15)<$BJ$5,$S15,IF(AND(YEAR($H15)=$BJ$5,MONTH($H15)<=BU$6),$S15,0)) -> 1640797 | BV15: =+SUM(BJ15:BU15) -> 9844782 | BW15: =+R15-BV15 -> 49223918 | BX15: =+$S15 -> 1640797 | BY15: =+$S15 -> 1640797 | BZ15: =+$S15 -> 1640797 | CA15: =+$S15 -> 1640797 | CB15: =+$S15 -> 1640797 | CC15: =+$S15 -> 1640797 | CD15: =+$S15 -> 1640797 | CE15: =+$S15 -> 1640797 | ... CI15: =+$S15 -> 1640797 | CJ15: =+SUM(BX15:CI15) -> 19689564 | CK15: =+BW15-CJ15 -> 29534354 | CL15: =+IF(YEAR($H15)<$CL$4,$S15,IF(AND(YEAR($H15)=$CL$4,MONTH($H15)<=CL$6),$S15,0)) -> 1640797 | CM15: =+IF(YEAR($H15)<$CL$4,$S15,IF(AND(YEAR($H15)=$CL$4,MONTH($H15)<=CM$6),$S15,0)) -> 1640797 | CN15: =+IF(YEAR($H15)<$CL$4,$S15,IF(AND(YEAR($H15)=$CL$4,MONTH($H15)<=CN$6),$S15,0)) -> 1640797 | CO15: =+IF(YEAR($H15)<$CL$4,$S15,IF(AND(YEAR($H15)=$CL$4,MONTH($H15)<=CO$6),$S15,0)) -> 1640797 | CP15: =+IF(YEAR($H15)<$CL$4,$S15,IF(AND(YEAR($H15)=$CL$4,MONTH($H15)<=CP$6),$S15,0)) -> 1640797 | CQ15: =+IF(YEAR($H15)<$CL$4,$S15,IF(AND(YEAR($H15)=$CL$4,MONTH($H15)<=CQ$6),$S15,0)) -> 1640797 | CR15: =+IF(YEAR($H15)<$CL$4,$S15,IF(AND(YEAR($H15)=$CL$4,MONTH($H15)<=CR$6),$S15,0)) -> 1640797 | CS15: =+IF(YEAR($H15)<$CL$4,$S15,IF(AND(YEAR($H15)=$CL$4,MONTH($H15)<=CS$6),$S15,0)) -> 1640797 | ... CW15: =+IF(YEAR($H15)<$CL$4,$S15,IF(AND(YEAR($H15)=$CL$4,MONTH($H15)<=CW$6),$S15,0)) -> 1640797 | CX15: =+SUM(CL15:CW15) -> 19689564 | CY15: =+CK15-CX15 -> 9844790
B16: Chung | C16: =_xlfn.XLOOKUP(E16,'[1]TH_CC (3)'!$E:$E,'[1]TH_CC (3)'!$E:$E) -> 117000006 | D16: Z21180A | E16: 117000006 | F16: Giếng nước ngầm số 2 | G16: 45110 | H16: 45110 | I16: 36 | J16: 1001202000 | K16: Hành chánh nhân sự | M16: =+LEFT(N16,4) -> 6424 | N16: 6424001909 | O16: 6424001909 | R16: 69288347 | S16: 1924677 | T16: =+IF(YEAR($H16)<$T$5,$S16,IF(AND(YEAR($H16)=$T$5,MONTH($H16)<=T$6),$S16,0)) -> 0 | U16: =+IF(YEAR($H16)<$T$5,$S16,IF(AND(YEAR($H16)=$T$5,MONTH($H16)<=U$6),$S16,0)) -> 0 | V16: =+IF(YEAR($H16)<$T$5,$S16,IF(AND(YEAR($H16)=$T$5,MONTH($H16)<=V$6),$S16,0)) -> 0 | W16: =+IF(YEAR($H16)<$T$5,$S16,IF(AND(YEAR($H16)=$T$5,MONTH($H16)<=W$6),$S16,0)) -> 0 | X16: =+IF(YEAR($H16)<$T$5,$S16,IF(AND(YEAR($H16)=$T$5,MONTH($H16)<=X$6),$S16,0)) -> 0 | Y16: =+IF(YEAR($H16)<$T$5,$S16,IF(AND(YEAR($H16)=$T$5,MONTH($H16)<=Y$6),$S16,0)) -> 0 | Z16: =+IF(YEAR($H16)<$T$5,$S16,IF(AND(YEAR($H16)=$T$5,MONTH($H16)<=Z$6),$S16,0)) -> 0 | AA16: =+IF(YEAR($H16)<$T$5,$S16,IF(AND(YEAR($H16)=$T$5,MONTH($H16)<=AA$6),$S16,0)) -> 0 | ... AE16: =+IF(YEAR($H16)<$T$5,$S16,IF(AND(YEAR($H16)=$T$5,MONTH($H16)<=AE$6),$S16,0)) -> 0 | AF16: =+SUM(T16:AE16) -> 0 | AG16: 0 | AH16: =+IF(YEAR($H16)<$AH$5,$S16,IF(AND(YEAR($H16)=$AH$5,MONTH($H16)<=AH$6),$S16,0)) -> 0 | AI16: =+IF(YEAR($H16)<$AH$5,$S16,IF(AND(YEAR($H16)=$AH$5,MONTH($H16)<=AI$6),$S16,0)) -> 0 | AJ16: =+IF(YEAR($H16)<$AH$5,$S16,IF(AND(YEAR($H16)=$AH$5,MONTH($H16)<=AJ$6),$S16,0)) -> 0 | AK16: =+IF(YEAR($H16)<$AH$5,$S16,IF(AND(YEAR($H16)=$AH$5,MONTH($H16)<=AK$6),$S16,0)) -> 0 | AL16: =+IF(YEAR($H16)<$AH$5,$S16,IF(AND(YEAR($H16)=$AH$5,MONTH($H16)<=AL$6),$S16,0)) -> 0 | AM16: =+IF(YEAR($H16)<$AH$5,$S16,IF(AND(YEAR($H16)=$AH$5,MONTH($H16)<=AM$6),$S16,0)) -> 0 | AN16: =+IF(YEAR($H16)<$AH$5,$S16,IF(AND(YEAR($H16)=$AH$5,MONTH($H16)<=AN$6),$S16,0)) -> 0 | AO16: =+IF(YEAR($H16)<$AH$5,$S16,IF(AND(YEAR($H16)=$AH$5,MONTH($H16)<=AO$6),$S16,0)) -> 0 | ... AS16: =+IF(YEAR($H16)<$AH$5,$S16,IF(AND(YEAR($H16)=$AH$5,MONTH($H16)<=AS$6),$S16,0)) -> 0 | AT16: =+SUM(AH16:AS16) -> 0 | AU16: 0 | AV16: =+IF(YEAR($H16)<$AV$5,$S16,IF(AND(YEAR($H16)=$AV$5,MONTH($H16)<=AV$6),$S16,0)) -> 0 | AW16: =+IF(YEAR($H16)<$AV$5,$S16,IF(AND(YEAR($H16)=$AV$5,MONTH($H16)<=AW$6),$S16,0)) -> 0 | AX16: =+IF(YEAR($H16)<$AV$5,$S16,IF(AND(YEAR($H16)=$AV$5,MONTH($H16)<=AX$6),$S16,0)) -> 0 | AY16: =+IF(YEAR($H16)<$AV$5,$S16,IF(AND(YEAR($H16)=$AV$5,MONTH($H16)<=AY$6),$S16,0)) -> 0 | AZ16: =+IF(YEAR($H16)<$AV$5,$S16,IF(AND(YEAR($H16)=$AV$5,MONTH($H16)<=AZ$6),$S16,0)) -> 0 | BA16: =+IF(YEAR($H16)<$AV$5,$S16,IF(AND(YEAR($H16)=$AV$5,MONTH($H16)<=BA$6),$S16,0)) -> 0 | BB16: =+IF(YEAR($H16)<$AV$5,$S16,IF(AND(YEAR($H16)=$AV$5,MONTH($H16)<=BB$6),$S16,0)) -> 0 | BC16: =+IF(YEAR($H16)<$AV$5,$S16,IF(AND(YEAR($H16)=$AV$5,MONTH($H16)<=BC$6),$S16,0)) -> 0 | ... BG16: =+IF(YEAR($H16)<$AV$5,$S16,IF(AND(YEAR($H16)=$AV$5,MONTH($H16)<=BG$6),$S16,0)) -> 0 | BH16: =+SUM(AV16:BG16) -> 0 | BI16: 0 | BJ16: =+IF(YEAR($H16)<$BJ$5,$S16,IF(AND(YEAR($H16)=$BJ$5,MONTH($H16)<=BJ$6),$S16,0)) -> 0 | BK16: =+IF(YEAR($H16)<$BJ$5,$S16,IF(AND(YEAR($H16)=$BJ$5,MONTH($H16)<=BK$6),$S16,0)) -> 0 | BL16: =+IF(YEAR($H16)<$BJ$5,$S16,IF(AND(YEAR($H16)=$BJ$5,MONTH($H16)<=BL$6),$S16,0)) -> 0 | BM16: =+IF(YEAR($H16)<$BJ$5,$S16,IF(AND(YEAR($H16)=$BJ$5,MONTH($H16)<=BM$6),$S16,0)) -> 0 | BN16: =+IF(YEAR($H16)<$BJ$5,$S16,IF(AND(YEAR($H16)=$BJ$5,MONTH($H16)<=BN$6),$S16,0)) -> 0 | BO16: =+IF(YEAR($H16)<$BJ$5,$S16,IF(AND(YEAR($H16)=$BJ$5,MONTH($H16)<=BO$6),$S16,0)) -> 0 | BP16: =+IF(YEAR($H16)<$BJ$5,$S16,IF(AND(YEAR($H16)=$BJ$5,MONTH($H16)<=BP$6),$S16,0)) -> 1924677 | BQ16: =+IF(YEAR($H16)<$BJ$5,$S16,IF(AND(YEAR($H16)=$BJ$5,MONTH($H16)<=BQ$6),$S16,0)) -> 1924677 | ... BU16: =+IF(YEAR($H16)<$BJ$5,$S16,IF(AND(YEAR($H16)=$BJ$5,MONTH($H16)<=BU$6),$S16,0)) -> 1924677 | BV16: =+SUM(BJ16:BU16) -> 11548062 | BW16: =+R16-BV16 -> 57740285 | BX16: =+$S16 -> 1924677 | BY16: =+$S16 -> 1924677 | BZ16: =+$S16 -> 1924677 | CA16: =+$S16 -> 1924677 | CB16: =+$S16 -> 1924677 | CC16: =+$S16 -> 1924677 | CD16: =+$S16 -> 1924677 | CE16: =+$S16 -> 1924677 | ... CI16: =+$S16 -> 1924677 | CJ16: =+SUM(BX16:CI16) -> 23096124 | CK16: =+BW16-CJ16 -> 34644161 | CL16: =+IF(YEAR($H16)<$CL$4,$S16,IF(AND(YEAR($H16)=$CL$4,MONTH($H16)<=CL$6),$S16,0)) -> 1924677 | CM16: =+IF(YEAR($H16)<$CL$4,$S16,IF(AND(YEAR($H16)=$CL$4,MONTH($H16)<=CM$6),$S16,0)) -> 1924677 | CN16: =+IF(YEAR($H16)<$CL$4,$S16,IF(AND(YEAR($H16)=$CL$4,MONTH($H16)<=CN$6),$S16,0)) -> 1924677 | CO16: =+IF(YEAR($H16)<$CL$4,$S16,IF(AND(YEAR($H16)=$CL$4,MONTH($H16)<=CO$6),$S16,0)) -> 1924677 | CP16: =+IF(YEAR($H16)<$CL$4,$S16,IF(AND(YEAR($H16)=$CL$4,MONTH($H16)<=CP$6),$S16,0)) -> 1924677 | CQ16: =+IF(YEAR($H16)<$CL$4,$S16,IF(AND(YEAR($H16)=$CL$4,MONTH($H16)<=CQ$6),$S16,0)) -> 1924677 | CR16: =+IF(YEAR($H16)<$CL$4,$S16,IF(AND(YEAR($H16)=$CL$4,MONTH($H16)<=CR$6),$S16,0)) -> 1924677 | CS16: =+IF(YEAR($H16)<$CL$4,$S16,IF(AND(YEAR($H16)=$CL$4,MONTH($H16)<=CS$6),$S16,0)) -> 1924677 | ... CW16: =+IF(YEAR($H16)<$CL$4,$S16,IF(AND(YEAR($H16)=$CL$4,MONTH($H16)<=CW$6),$S16,0)) -> 1924677 | CX16: =+SUM(CL16:CW16) -> 23096124 | CY16: =+CK16-CX16 -> 11548037
A17: 6274.4 | B17: Chung | C17: =_xlfn.XLOOKUP(E17,'[1]TH_CC (3)'!$E:$E,'[1]TH_CC (3)'!$E:$E) -> 104000111 | D17: Z21120P | E17: 104000111 | F17: CP lắp đặt ống thoát khí thải F2, F3 | G17: 45110 | H17: 45110 | I17: 36 | J17: 1001602000 | K17: Xưởng sản xuất PET | M17: =+LEFT(N17,4) -> 6274 | N17: 6274001903 | O17: 6274001901 | R17: 72217040 | S17: =+R17/I17 -> 2006028.9 | BP17: =+IF(YEAR($H17)<$BJ$5,$S17,IF(AND(YEAR($H17)=$BJ$5,MONTH($H17)<=BP$6),$S17,0)) -> 2006028.9 | BQ17: =+IF(YEAR($H17)<$BJ$5,$S17,IF(AND(YEAR($H17)=$BJ$5,MONTH($H17)<=BQ$6),$S17,0)) -> 2006028.9 | BR17: =+IF(YEAR($H17)<$BJ$5,$S17,IF(AND(YEAR($H17)=$BJ$5,MONTH($H17)<=BR$6),$S17,0)) -> 2006028.9 | BS17: =+IF(YEAR($H17)<$BJ$5,$S17,IF(AND(YEAR($H17)=$BJ$5,MONTH($H17)<=BS$6),$S17,0)) -> 2006028.9 | BT17: =+IF(YEAR($H17)<$BJ$5,$S17,IF(AND(YEAR($H17)=$BJ$5,MONTH($H17)<=BT$6),$S17,0)) -> 2006028.9 | BU17: =+IF(YEAR($H17)<$BJ$5,$S17,IF(AND(YEAR($H17)=$BJ$5,MONTH($H17)<=BU$6),$S17,0)) -> 2006028.9 | BV17: =+SUM(BJ17:BU17) -> 12036173 | BW17: =+R17-BV17 -> 60180867 | BX17: =+IF(YEAR($H17)<$BX$5,$S17,IF(AND(YEAR($H17)=$BX$5,MONTH($H17)<=BX$6),$S17,0)) -> 2006028.9 | BY17: =+IF(YEAR($H17)<$BX$5,$S17,IF(AND(YEAR($H17)=$BX$5,MONTH($H17)<=BY$6),$S17,0)) -> 2006028.9 | BZ17: =+IF(YEAR($H17)<$BX$5,$S17,IF(AND(YEAR($H17)=$BX$5,MONTH($H17)<=BZ$6),$S17,0)) -> 2006028.9 | CA17: =+IF(YEAR($H17)<$BX$5,$S17,IF(AND(YEAR($H17)=$BX$5,MONTH($H17)<=CA$6),$S17,0)) -> 2006028.9 | CB17: =+IF(YEAR($H17)<$BX$5,$S17,IF(AND(YEAR($H17)=$BX$5,MONTH($H17)<=CB$6),$S17,0)) -> 2006028.9 | CC17: =+IF(YEAR($H17)<$BX$5,$S17,IF(AND(YEAR($H17)=$BX$5,MONTH($H17)<=CC$6),$S17,0)) -> 2006028.9 | CD17: =+IF(YEAR($H17)<$BX$5,$S17,IF(AND(YEAR($H17)=$BX$5,MONTH($H17)<=CD$6),$S17,0)) -> 2006028.9 | CE17: =+IF(YEAR($H17)<$BX$5,$S17,IF(AND(YEAR($H17)=$BX$5,MONTH($H17)<=CE$6),$S17,0)) -> 2006028.9 | ... CI17: =+IF(YEAR($H17)<$BX$5,$S17,IF(AND(YEAR($H17)=$BX$5,MONTH($H17)<=CI$6),$S17,0)) -> 2006028.9 | CJ17: =+SUM(BX17:CI17) -> 24072347 | CK17: =+BW17-CJ17 -> 36108520 | CL17: =+IF(YEAR($H17)<$CL$4,$S17,IF(AND(YEAR($H17)=$CL$4,MONTH($H17)<=CL$6),$S17,0)) -> 2006028.9 | CM17: =+IF(YEAR($H17)<$CL$4,$S17,IF(AND(YEAR($H17)=$CL$4,MONTH($H17)<=CM$6),$S17,0)) -> 2006028.9 | CN17: =+IF(YEAR($H17)<$CL$4,$S17,IF(AND(YEAR($H17)=$CL$4,MONTH($H17)<=CN$6),$S17,0)) -> 2006028.9 | CO17: =+IF(YEAR($H17)<$CL$4,$S17,IF(AND(YEAR($H17)=$CL$4,MONTH($H17)<=CO$6),$S17,0)) -> 2006028.9 | CP17: =+IF(YEAR($H17)<$CL$4,$S17,IF(AND(YEAR($H17)=$CL$4,MONTH($H17)<=CP$6),$S17,0)) -> 2006028.9 | CQ17: =+IF(YEAR($H17)<$CL$4,$S17,IF(AND(YEAR($H17)=$CL$4,MONTH($H17)<=CQ$6),$S17,0)) -> 2006028.9 | CR17: =+IF(YEAR($H17)<$CL$4,$S17,IF(AND(YEAR($H17)=$CL$4,MONTH($H17)<=CR$6),$S17,0)) -> 2006028.9 | CS17: =+IF(YEAR($H17)<$CL$4,$S17,IF(AND(YEAR($H17)=$CL$4,MONTH($H17)<=CS$6),$S17,0)) -> 2006028.9 | ... CW17: =+IF(YEAR($H17)<$CL$4,$S17,IF(AND(YEAR($H17)=$CL$4,MONTH($H17)<=CW$6),$S17,0)) -> 2006028.9 | CX17: =+SUM(CL17:CW17) -> 24072347 | CY17: =+CK17-CX17 -> 12036173
A18: 6274.4 | B18: Chung | C18: =_xlfn.XLOOKUP(E18,'[1]TH_CC (3)'!$E:$E,'[1]TH_CC (3)'!$E:$E) -> 115000009 | D18: Z21180P | E18: 115000009 | F18: Kho chứa vật tư KT (F5) | G18: 45141 | H18: 45141 | I18: 36 | J18: 1001602000 | K18: Xưởng sản xuất PET | M18: =+LEFT(N18,4) -> 6274 | N18: 6274001909 | O18: 6274001909 | R18: 81154545 | S18: 2254293 | T18: =+IF(YEAR($H18)<$T$5,$S18,IF(AND(YEAR($H18)=$T$5,MONTH($H18)<=T$6),$S18,0)) -> 0 | U18: =+IF(YEAR($H18)<$T$5,$S18,IF(AND(YEAR($H18)=$T$5,MONTH($H18)<=U$6),$S18,0)) -> 0 | V18: =+IF(YEAR($H18)<$T$5,$S18,IF(AND(YEAR($H18)=$T$5,MONTH($H18)<=V$6),$S18,0)) -> 0 | W18: =+IF(YEAR($H18)<$T$5,$S18,IF(AND(YEAR($H18)=$T$5,MONTH($H18)<=W$6),$S18,0)) -> 0 | X18: =+IF(YEAR($H18)<$T$5,$S18,IF(AND(YEAR($H18)=$T$5,MONTH($H18)<=X$6),$S18,0)) -> 0 | Y18: =+IF(YEAR($H18)<$T$5,$S18,IF(AND(YEAR($H18)=$T$5,MONTH($H18)<=Y$6),$S18,0)) -> 0 | Z18: =+IF(YEAR($H18)<$T$5,$S18,IF(AND(YEAR($H18)=$T$5,MONTH($H18)<=Z$6),$S18,0)) -> 0 | AA18: =+IF(YEAR($H18)<$T$5,$S18,IF(AND(YEAR($H18)=$T$5,MONTH($H18)<=AA$6),$S18,0)) -> 0 | ... AE18: =+IF(YEAR($H18)<$T$5,$S18,IF(AND(YEAR($H18)=$T$5,MONTH($H18)<=AE$6),$S18,0)) -> 0 | AF18: =+SUM(T18:AE18) -> 0 | AG18: 0 | AH18: =+IF(YEAR($H18)<$AH$5,$S18,IF(AND(YEAR($H18)=$AH$5,MONTH($H18)<=AH$6),$S18,0)) -> 0 | AI18: =+IF(YEAR($H18)<$AH$5,$S18,IF(AND(YEAR($H18)=$AH$5,MONTH($H18)<=AI$6),$S18,0)) -> 0 | AJ18: =+IF(YEAR($H18)<$AH$5,$S18,IF(AND(YEAR($H18)=$AH$5,MONTH($H18)<=AJ$6),$S18,0)) -> 0 | AK18: =+IF(YEAR($H18)<$AH$5,$S18,IF(AND(YEAR($H18)=$AH$5,MONTH($H18)<=AK$6),$S18,0)) -> 0 | AL18: =+IF(YEAR($H18)<$AH$5,$S18,IF(AND(YEAR($H18)=$AH$5,MONTH($H18)<=AL$6),$S18,0)) -> 0 | AM18: =+IF(YEAR($H18)<$AH$5,$S18,IF(AND(YEAR($H18)=$AH$5,MONTH($H18)<=AM$6),$S18,0)) -> 0 | AN18: =+IF(YEAR($H18)<$AH$5,$S18,IF(AND(YEAR($H18)=$AH$5,MONTH($H18)<=AN$6),$S18,0)) -> 0 | AO18: =+IF(YEAR($H18)<$AH$5,$S18,IF(AND(YEAR($H18)=$AH$5,MONTH($H18)<=AO$6),$S18,0)) -> 0 | ... AS18: =+IF(YEAR($H18)<$AH$5,$S18,IF(AND(YEAR($H18)=$AH$5,MONTH($H18)<=AS$6),$S18,0)) -> 0 | AT18: =+SUM(AH18:AS18) -> 0 | AU18: 0 | AV18: =+IF(YEAR($H18)<$AV$5,$S18,IF(AND(YEAR($H18)=$AV$5,MONTH($H18)<=AV$6),$S18,0)) -> 0 | AW18: =+IF(YEAR($H18)<$AV$5,$S18,IF(AND(YEAR($H18)=$AV$5,MONTH($H18)<=AW$6),$S18,0)) -> 0 | AX18: =+IF(YEAR($H18)<$AV$5,$S18,IF(AND(YEAR($H18)=$AV$5,MONTH($H18)<=AX$6),$S18,0)) -> 0 | AY18: =+IF(YEAR($H18)<$AV$5,$S18,IF(AND(YEAR($H18)=$AV$5,MONTH($H18)<=AY$6),$S18,0)) -> 0 | AZ18: =+IF(YEAR($H18)<$AV$5,$S18,IF(AND(YEAR($H18)=$AV$5,MONTH($H18)<=AZ$6),$S18,0)) -> 0 | BA18: =+IF(YEAR($H18)<$AV$5,$S18,IF(AND(YEAR($H18)=$AV$5,MONTH($H18)<=BA$6),$S18,0)) -> 0 | BB18: =+IF(YEAR($H18)<$AV$5,$S18,IF(AND(YEAR($H18)=$AV$5,MONTH($H18)<=BB$6),$S18,0)) -> 0 | BC18: =+IF(YEAR($H18)<$AV$5,$S18,IF(AND(YEAR($H18)=$AV$5,MONTH($H18)<=BC$6),$S18,0)) -> 0 | ... BG18: =+IF(YEAR($H18)<$AV$5,$S18,IF(AND(YEAR($H18)=$AV$5,MONTH($H18)<=BG$6),$S18,0)) -> 0 | BH18: =+SUM(AV18:BG18) -> 0 | BI18: 0 | BJ18: =+IF(YEAR($H18)<$BJ$5,$S18,IF(AND(YEAR($H18)=$BJ$5,MONTH($H18)<=BJ$6),$S18,0)) -> 0 | BK18: =+IF(YEAR($H18)<$BJ$5,$S18,IF(AND(YEAR($H18)=$BJ$5,MONTH($H18)<=BK$6),$S18,0)) -> 0 | BL18: =+IF(YEAR($H18)<$BJ$5,$S18,IF(AND(YEAR($H18)=$BJ$5,MONTH($H18)<=BL$6),$S18,0)) -> 0 | BM18: =+IF(YEAR($H18)<$BJ$5,$S18,IF(AND(YEAR($H18)=$BJ$5,MONTH($H18)<=BM$6),$S18,0)) -> 0 | BN18: =+IF(YEAR($H18)<$BJ$5,$S18,IF(AND(YEAR($H18)=$BJ$5,MONTH($H18)<=BN$6),$S18,0)) -> 0 | BO18: =+IF(YEAR($H18)<$BJ$5,$S18,IF(AND(YEAR($H18)=$BJ$5,MONTH($H18)<=BO$6),$S18,0)) -> 0 | BP18: =+IF(YEAR($H18)<$BJ$5,$S18,IF(AND(YEAR($H18)=$BJ$5,MONTH($H18)<=BP$6),$S18,0)) -> 0 | BQ18: =+IF(YEAR($H18)<$BJ$5,$S18,IF(AND(YEAR($H18)=$BJ$5,MONTH($H18)<=BQ$6),$S18,0)) -> 2254293 | ... BU18: =+IF(YEAR($H18)<$BJ$5,$S18,IF(AND(YEAR($H18)=$BJ$5,MONTH($H18)<=BU$6),$S18,0)) -> 2254293 | BV18: =+SUM(BJ18:BU18) -> 11271465 | BW18: =+R18-BV18 -> 69883080 | BX18: =+$S18 -> 2254293 | BY18: =+$S18 -> 2254293 | BZ18: =+$S18 -> 2254293 | CA18: =+$S18 -> 2254293 | CB18: =+$S18 -> 2254293 | CC18: =+$S18 -> 2254293 | CD18: =+$S18 -> 2254293 | CE18: =+$S18 -> 2254293 | ... CI18: =+$S18 -> 2254293 | CJ18: =+SUM(BX18:CI18) -> 27051516 | CK18: =+BW18-CJ18 -> 42831564 | CL18: =+IF(YEAR($H18)<$CL$4,$S18,IF(AND(YEAR($H18)=$CL$4,MONTH($H18)<=CL$6),$S18,0)) -> 2254293 | CM18: =+IF(YEAR($H18)<$CL$4,$S18,IF(AND(YEAR($H18)=$CL$4,MONTH($H18)<=CM$6),$S18,0)) -> 2254293 | CN18: =+IF(YEAR($H18)<$CL$4,$S18,IF(AND(YEAR($H18)=$CL$4,MONTH($H18)<=CN$6),$S18,0)) -> 2254293 | CO18: =+IF(YEAR($H18)<$CL$4,$S18,IF(AND(YEAR($H18)=$CL$4,MONTH($H18)<=CO$6),$S18,0)) -> 2254293 | CP18: =+IF(YEAR($H18)<$CL$4,$S18,IF(AND(YEAR($H18)=$CL$4,MONTH($H18)<=CP$6),$S18,0)) -> 2254293 | CQ18: =+IF(YEAR($H18)<$CL$4,$S18,IF(AND(YEAR($H18)=$CL$4,MONTH($H18)<=CQ$6),$S18,0)) -> 2254293 | CR18: =+IF(YEAR($H18)<$CL$4,$S18,IF(AND(YEAR($H18)=$CL$4,MONTH($H18)<=CR$6),$S18,0)) -> 2254293 | CS18: =+IF(YEAR($H18)<$CL$4,$S18,IF(AND(YEAR($H18)=$CL$4,MONTH($H18)<=CS$6),$S18,0)) -> 2254293 | ... CW18: =+IF(YEAR($H18)<$CL$4,$S18,IF(AND(YEAR($H18)=$CL$4,MONTH($H18)<=CW$6),$S18,0)) -> 2254293 | CX18: =+SUM(CL18:CW18) -> 27051516 | CY18: =+CK18-CX18 -> 15780048
B19: Chung | C19: =_xlfn.XLOOKUP(E19,'[1]TH_CC (3)'!$E:$E,'[1]TH_CC (3)'!$E:$E) -> 117000007 | D19: Z21180A | E19: 117000007 | F19: Lắp đặt cáp thoại nhà bảo vệ 1 và 3 | G19: 45170 | H19: 45170 | I19: 60 | J19: 1001202000 | K19: Hành chánh nhân sự | M19: =+LEFT(N19,4) -> 6424 | N19: 6424001909 | O19: 6424001909 | R19: 261991507 | S19: 4366525 | T19: =+IF(YEAR($H19)<$T$5,$S19,IF(AND(YEAR($H19)=$T$5,MONTH($H19)<=T$6),$S19,0)) -> 0 | U19: =+IF(YEAR($H19)<$T$5,$S19,IF(AND(YEAR($H19)=$T$5,MONTH($H19)<=U$6),$S19,0)) -> 0 | V19: =+IF(YEAR($H19)<$T$5,$S19,IF(AND(YEAR($H19)=$T$5,MONTH($H19)<=V$6),$S19,0)) -> 0 | W19: =+IF(YEAR($H19)<$T$5,$S19,IF(AND(YEAR($H19)=$T$5,MONTH($H19)<=W$6),$S19,0)) -> 0 | X19: =+IF(YEAR($H19)<$T$5,$S19,IF(AND(YEAR($H19)=$T$5,MONTH($H19)<=X$6),$S19,0)) -> 0 | Y19: =+IF(YEAR($H19)<$T$5,$S19,IF(AND(YEAR($H19)=$T$5,MONTH($H19)<=Y$6),$S19,0)) -> 0 | Z19: =+IF(YEAR($H19)<$T$5,$S19,IF(AND(YEAR($H19)=$T$5,MONTH($H19)<=Z$6),$S19,0)) -> 0 | AA19: =+IF(YEAR($H19)<$T$5,$S19,IF(AND(YEAR($H19)=$T$5,MONTH($H19)<=AA$6),$S19,0)) -> 0 | ... AE19: =+IF(YEAR($H19)<$T$5,$S19,IF(AND(YEAR($H19)=$T$5,MONTH($H19)<=AE$6),$S19,0)) -> 0 | AF19: =+SUM(T19:AE19) -> 0 | AG19: 0 | AH19: =+IF(YEAR($H19)<$AH$5,$S19,IF(AND(YEAR($H19)=$AH$5,MONTH($H19)<=AH$6),$S19,0)) -> 0 | AI19: =+IF(YEAR($H19)<$AH$5,$S19,IF(AND(YEAR($H19)=$AH$5,MONTH($H19)<=AI$6),$S19,0)) -> 0 | AJ19: =+IF(YEAR($H19)<$AH$5,$S19,IF(AND(YEAR($H19)=$AH$5,MONTH($H19)<=AJ$6),$S19,0)) -> 0 | AK19: =+IF(YEAR($H19)<$AH$5,$S19,IF(AND(YEAR($H19)=$AH$5,MONTH($H19)<=AK$6),$S19,0)) -> 0 | AL19: =+IF(YEAR($H19)<$AH$5,$S19,IF(AND(YEAR($H19)=$AH$5,MONTH($H19)<=AL$6),$S19,0)) -> 0 | AM19: =+IF(YEAR($H19)<$AH$5,$S19,IF(AND(YEAR($H19)=$AH$5,MONTH($H19)<=AM$6),$S19,0)) -> 0 | AN19: =+IF(YEAR($H19)<$AH$5,$S19,IF(AND(YEAR($H19)=$AH$5,MONTH($H19)<=AN$6),$S19,0)) -> 0 | AO19: =+IF(YEAR($H19)<$AH$5,$S19,IF(AND(YEAR($H19)=$AH$5,MONTH($H19)<=AO$6),$S19,0)) -> 0 | ... AS19: =+IF(YEAR($H19)<$AH$5,$S19,IF(AND(YEAR($H19)=$AH$5,MONTH($H19)<=AS$6),$S19,0)) -> 0 | AT19: =+SUM(AH19:AS19) -> 0 | AU19: 0 | AV19: =+IF(YEAR($H19)<$AV$5,$S19,IF(AND(YEAR($H19)=$AV$5,MONTH($H19)<=AV$6),$S19,0)) -> 0 | AW19: =+IF(YEAR($H19)<$AV$5,$S19,IF(AND(YEAR($H19)=$AV$5,MONTH($H19)<=AW$6),$S19,0)) -> 0 | AX19: =+IF(YEAR($H19)<$AV$5,$S19,IF(AND(YEAR($H19)=$AV$5,MONTH($H19)<=AX$6),$S19,0)) -> 0 | AY19: =+IF(YEAR($H19)<$AV$5,$S19,IF(AND(YEAR($H19)=$AV$5,MONTH($H19)<=AY$6),$S19,0)) -> 0 | AZ19: =+IF(YEAR($H19)<$AV$5,$S19,IF(AND(YEAR($H19)=$AV$5,MONTH($H19)<=AZ$6),$S19,0)) -> 0 | BA19: =+IF(YEAR($H19)<$AV$5,$S19,IF(AND(YEAR($H19)=$AV$5,MONTH($H19)<=BA$6),$S19,0)) -> 0 | BB19: =+IF(YEAR($H19)<$AV$5,$S19,IF(AND(YEAR($H19)=$AV$5,MONTH($H19)<=BB$6),$S19,0)) -> 0 | BC19: =+IF(YEAR($H19)<$AV$5,$S19,IF(AND(YEAR($H19)=$AV$5,MONTH($H19)<=BC$6),$S19,0)) -> 0 | ... BG19: =+IF(YEAR($H19)<$AV$5,$S19,IF(AND(YEAR($H19)=$AV$5,MONTH($H19)<=BG$6),$S19,0)) -> 0 | BH19: =+SUM(AV19:BG19) -> 0 | BI19: 0 | BJ19: =+IF(YEAR($H19)<$BJ$5,$S19,IF(AND(YEAR($H19)=$BJ$5,MONTH($H19)<=BJ$6),$S19,0)) -> 0 | BK19: =+IF(YEAR($H19)<$BJ$5,$S19,IF(AND(YEAR($H19)=$BJ$5,MONTH($H19)<=BK$6),$S19,0)) -> 0 | BL19: =+IF(YEAR($H19)<$BJ$5,$S19,IF(AND(YEAR($H19)=$BJ$5,MONTH($H19)<=BL$6),$S19,0)) -> 0 | BM19: =+IF(YEAR($H19)<$BJ$5,$S19,IF(AND(YEAR($H19)=$BJ$5,MONTH($H19)<=BM$6),$S19,0)) -> 0 | BN19: =+IF(YEAR($H19)<$BJ$5,$S19,IF(AND(YEAR($H19)=$BJ$5,MONTH($H19)<=BN$6),$S19,0)) -> 0 | BO19: =+IF(YEAR($H19)<$BJ$5,$S19,IF(AND(YEAR($H19)=$BJ$5,MONTH($H19)<=BO$6),$S19,0)) -> 0 | BP19: =+IF(YEAR($H19)<$BJ$5,$S19,IF(AND(YEAR($H19)=$BJ$5,MONTH($H19)<=BP$6),$S19,0)) -> 0 | BQ19: =+IF(YEAR($H19)<$BJ$5,$S19,IF(AND(YEAR($H19)=$BJ$5,MONTH($H19)<=BQ$6),$S19,0)) -> 0 | ... BU19: =+IF(YEAR($H19)<$BJ$5,$S19,IF(AND(YEAR($H19)=$BJ$5,MONTH($H19)<=BU$6),$S19,0)) -> 4366525 | BV19: =+SUM(BJ19:BU19) -> 17466100 | BW19: =+R19-BV19 -> 244525407 | BX19: =+$S19 -> 4366525 | BY19: =+$S19 -> 4366525 | BZ19: =+$S19 -> 4366525 | CA19: =+$S19 -> 4366525 | CB19: =+$S19 -> 4366525 | CC19: =+$S19 -> 4366525 | CD19: =+$S19 -> 4366525 | CE19: =+$S19 -> 4366525 | ... CI19: =+$S19 -> 4366525 | CJ19: =+SUM(BX19:CI19) -> 52398300 | CK19: =+BW19-CJ19 -> 192127107 | CL19: =+IF(YEAR($H19)<$CL$4,$S19,IF(AND(YEAR($H19)=$CL$4,MONTH($H19)<=CL$6),$S19,0)) -> 4366525 | CM19: =+IF(YEAR($H19)<$CL$4,$S19,IF(AND(YEAR($H19)=$CL$4,MONTH($H19)<=CM$6),$S19,0)) -> 4366525 | CN19: =+IF(YEAR($H19)<$CL$4,$S19,IF(AND(YEAR($H19)=$CL$4,MONTH($H19)<=CN$6),$S19,0)) -> 4366525 | CO19: =+IF(YEAR($H19)<$CL$4,$S19,IF(AND(YEAR($H19)=$CL$4,MONTH($H19)<=CO$6),$S19,0)) -> 4366525 | CP19: =+IF(YEAR($H19)<$CL$4,$S19,IF(AND(YEAR($H19)=$CL$4,MONTH($H19)<=CP$6),$S19,0)) -> 4366525 | CQ19: =+IF(YEAR($H19)<$CL$4,$S19,IF(AND(YEAR($H19)=$CL$4,MONTH($H19)<=CQ$6),$S19,0)) -> 4366525 | CR19: =+IF(YEAR($H19)<$CL$4,$S19,IF(AND(YEAR($H19)=$CL$4,MONTH($H19)<=CR$6),$S19,0)) -> 4366525 | CS19: =+IF(YEAR($H19)<$CL$4,$S19,IF(AND(YEAR($H19)=$CL$4,MONTH($H19)<=CS$6),$S19,0)) -> 4366525 | ... CW19: =+IF(YEAR($H19)<$CL$4,$S19,IF(AND(YEAR($H19)=$CL$4,MONTH($H19)<=CW$6),$S19,0)) -> 4366525 | CX19: =+SUM(CL19:CW19) -> 52398300 | CY19: =+CK19-CX19 -> 139728807
