Workbook
Name __accountcodevg__X: #REF!
Name __disaccountcode1__X: #REF!
Name __disaccountcode2__X: #REF!
Name __disaccountcode3__X: #REF!
Name __lookup1__X: #REF!
Name __lookup2__X: #REF!
Name __params__: #REF!
Name thang10: #REF!
Name thang12: #REF!

Sheet 00. DM
C1: DANH MỤC
A3: STT | C3: Tên sheet | D3: Cập nhật | E3: Ghi chú
A4: 1 | B4: Data>> | C4: 01. CP Nhân sự | D4: Diễm
A5: 2 | C5: 02. ĐỊNH BIÊN | D5: Diễm
A6: 3
A7: 4 | B7: Báo cáo >> | C7: 03. Chart | D7: Tự động cập nhật
A8: 5 | C8: 04. CP nhân sự thuê ngoài | D8: Diễm
A9: 6 | C9: 05. Giờ công | D9: Diễm
A10: 7 | C10: 06. Chart giờ công | D10: Tự động cập nhật
C11: Chart nghỉ việc | D11: Tự động cập nhật

Sheet Data>> 2025
N1: =SUBTOTAL(9,N3:N9980) -> 173250515310
B2: Bộ phận | C2: KM | D2: Posting Date | E2: Document Number | F2: Cost Element | G2: Cost element name | H2: Cost Center | I2: CO object name | J2: Name | K2: Document Header Text | L2: Period | M2: Fiscal Year | N2: Val/COArea Crcy | O2: Ref Document Number | P2: Reversal document | Q2: User Name | R2: Material | S2: Material Description | T2: Total quantity
B3: Ban Giám Đốc | C3: Lương Chính +T13 | D3: 45716 | E3: 1013535130 | F3: 6421002604 | G3: CP lương chính-Gián | H3: 1001101000 | I3: Ban giám đốc | J3: CHI PHÍ LƯƠNG THÁNG 02.2025 | K3: CP LƯƠNG T2.2025 | L3: 2 | M3: 2025 | N3: 1178412592 | O3: 5100001271 | Q3: CUC.NT | T3: 0
B4: Ban Giám Đốc | C4: Lương Chính +T13 | D4: 45716 | E4: 1013535130 | F4: 6421002605 | G4: CP Lương tháng 13, P | H4: 1001101000 | I4: Ban giám đốc | J4: CHI PHÍ LƯƠNG THÁNG 02.2025 | K4: CP LƯƠNG T2.2025 | L4: 2 | M4: 2025 | N4: 10777046 | O4: 5100001271 | Q4: CUC.NT | T4: 0
B5: Ban Giám Đốc | C5: Lương Chính +T13 | D5: 45716 | E5: 1013535132 | F5: 6421002605 | G5: CP Lương tháng 13, P | H5: 1001101000 | I5: Ban giám đốc | J5: TRÍCH LƯƠNG T13, PHÉP NĂM T02.2025 | K5: CP LƯƠNG T2.2025 | L5: 2 | M5: 2025 | N5: 93775083 | O5: 5100001273 | Q5: CUC.NT | T5: 0
B6: Ban Giám Đốc | C6: Thưởng | D6: 45716 | E6: 1013535130 | F6: 6421002802 | G6: Chi phí Khen thưởng | H6: 1001101000 | I6: Ban giám đốc | J6: CHI PHÍ LƯƠNG THÁNG 02.2025 | K6: CP LƯƠNG T2.2025 | L6: 2 | M6: 2025 | N6: 9720000 | O6: 5100001271 | Q6: CUC.NT | T6: 0
B7: Ban Giám Đốc | C7: Thưởng | D7: 45716 | E7: 1013535132 | F7: 6421002806 | G7: Thưởng danh hiệu | H7: 1001101000 | I7: Ban giám đốc | J7: TRÍCH DANH HIỆU T02.2025 | K7: CP LƯƠNG T2.2025 | L7: 2 | M7: 2025 | N7: 86272326 | O7: 5100001273 | Q7: CUC.NT | T7: 0
B8: Ban Giám Đốc | C8: BHXH, BHYT, KPCĐ | D8: 45716 | E8: 1013535131 | F8: 6421003401 | G8: BHXH, BHYT, KPCĐ, BH | H8: 1001101000 | I8: Ban giám đốc | J8: BHXH,BHYT,KPCĐ,BHTN T2.25 | K8: CP LƯƠNG T2.2025 | L8: 2 | M8: 2025 | N8: 112158010 | O8: 5100001272 | Q8: CUC.NT | T8: 0
B9: Hành Chánh Nhân Sự | C9: Khen thưởng BD khác | D9: 45694 | E9: 1013521257 | F9: 6421007202 | G9: Khen thưởng BD khác | H9: 1001202000 | I9: Hành chánh nhân sự | J9: Khen thưởng ý tưởng cải tiến T9+10.2024 - H.T.Nhâm | K9: CP khen thưởng ý tưởng | L9: 2 | M9: 2025 | N9: 400000 | O9: 5100000759 | Q9: NHI.NHN | T9: 0
B10: Hành Chánh Nhân Sự | C10: Khen thưởng BD khác | D10: 45694 | E10: 1013521257 | F10: 6421007202 | G10: Khen thưởng BD khác | H10: 1001202000 | I10: Hành chánh nhân sự | J10: Khen thưởng ý tưởng cải tiến T9+10.2024 - M.H.Nhân | K10: CP khen thưởng ý tưởng | L10: 2 | M10: 2025 | N10: 200000 | O10: 5100000759 | Q10: NHI.NHN | T10: 0
B11: Hành Chánh Nhân Sự | C11: Khen thưởng BD khác | D11: 45694 | E11: 1013521257 | F11: 6421007202 | G11: Khen thưởng BD khác | H11: 1001202000 | I11: Hành chánh nhân sự | J11: Khen thưởng ý tưởng cải tiến T9+10.2024- L.M.Thanh | K11: CP khen thưởng ý tưởng | L11: 2 | M11: 2025 | N11: 200000 | O11: 5100000759 | Q11: NHI.NHN | T11: 0
B12: Hành Chánh Nhân Sự | C12: Khen thưởng BD khác | D12: 45694 | E12: 1013521257 | F12: 6421007202 | G12: Khen thưởng BD khác | H12: 1001202000 | I12: Hành chánh nhân sự | J12: Khen thưởng ý tưởng cải tiến T9+10.2024 - N.V.Tú | K12: CP khen thưởng ý tưởng | L12: 2 | M12: 2025 | N12: 200000 | O12: 5100000759 | Q12: NHI.NHN | T12: 0
B13: Hành Chánh Nhân Sự | C13: Khen thưởng BD khác | D13: 45694 | E13: 1013521257 | F13: 6421007202 | G13: Khen thưởng BD khác | H13: 1001202000 | I13: Hành chánh nhân sự | J13: Khen thưởng ý tưởng cải tiến T9+10.2024 - T.V.Hiền | K13: CP khen thưởng ý tưởng | L13: 2 | M13: 2025 | N13: 1400000 | O13: 5100000759 | Q13: NHI.NHN | T13: 0
B14: Hành Chánh Nhân Sự | C14: Khen thưởng BD khác | D14: 45694 | E14: 1013521257 | F14: 6421007202 | G14: Khen thưởng BD khác | H14: 1001202000 | I14: Hành chánh nhân sự | J14: Khen thưởng ý tưởng cải tiến T9+10.2024-N.T.P.Hằng | K14: CP khen thưởng ý tưởng | L14: 2 | M14: 2025 | N14: 200000 | O14: 5100000759 | Q14: NHI.NHN | T14: 0
... B109: Hành Chánh Nhân Sự | C109: Khen thưởng BD khác | D109: 45716 | E109: 1013536241 | F109: 6421007202 | G109: Khen thưởng BD khác | H109: 1001204000 | I109: Tổ 5S & an toàn | J109: Bồi dưỡng ATVSV T1/25 | K109: Bồi dưỡng ATVSV T1/25 | L109: 2 | M109: 2025 | N109: 2981191 | O109: 5100001292 | Q109: DIEM.NTT | T109: 0
A110: 622 | B110: Xưởng Sản Xuất | C110: Lương Chính +T13 | D110: 45695 | E110: 1013531766 | F110: 6220002601 | G110: CP lương chính-Trực | H110: 1001602000 | I110: Xưởng sản xuất PET | J110: CP công nhân thuê ngoài T01.2025 (14 PET) | K110: CP công nhân thuê ngoài T | L110: 2 | M110: 2025 | N110: 102130449 | O110: 3500000700 | Q110: NHI.NHN | T110: 0
A111: 622 | B111: Xưởng Sản Xuất | C111: Lương Chính +T13 | D111: 45695 | E111: 1013531766 | F111: 6220002601 | G111: CP lương chính-Trực | H111: 1001602000 | I111: Xưởng sản xuất PET | J111: CP công nhân thuê ngoài T01.2025 (9 PET) | K111: CP công nhân thuê ngoài T | L111: 2 | M111: 2025 | N111: 9000000 | O111: 3500000700 | Q111: NHI.NHN | T111: 0
A112: 622 | B112: Xưởng Sản Xuất | C112: Lương Chính +T13 | D112: 45696 | E112: 1013532601 | F112: 6220002601 | G112: CP lương chính-Trực | H112: 1001602000 | I112: Xưởng sản xuất PET | J112: CP công nhân thuê ngoài T01.2025 (2 PET) | K112: CP công nhân thuê ngoài T | L112: 2 | M112: 2025 | N112: 8333333 | O112: 3500000726 | Q112: NHI.NHN | T112: 0
B113: Kiểm Soát Chất Lượng | C113: Phụ Cấp | D113: 45715 | E113: 1013532775 | F113: 6271003202 | G113: Tiền ăn giữa ca-Gián | H113: 1001601400 | I113: Kiểm soát chất lượng | J113: chi phí suất ăn - Đắc Bảo An tháng 02/2025 | K113: chi phí suất ăn - Đắc Bảo | L113: 2 | M113: 2025 | N113: 24425000 | O113: 3500000749 | Q113: NHI.NHN | T113: 0
A114: 622 | B114: Xưởng Sản Xuất | C114: Phụ Cấp | D114: 45716 | E114: 1013533313 | F114: 6220003201 | G114: Tiền ăn giữa ca-Trực | H114: 1001602000 | I114: Xưởng sản xuất PET | J114: CHUYỂN GL TIỀN CƠM | K114: CHUYỂN GL TIỀN CƠM | L114: 2 | M114: 2025 | N114: 81650000 | O114: 5100000871 | Q114: DIEM.NTT | T114: 0
B115: Kiểm Soát Chất Lượng | C115: Phụ Cấp | D115: 45716 | E115: 1013535130 | F115: 6271002603 | G115: Phụ cấp ca đêm | H115: 1001601400 | I115: Kiểm soát chất lượng | J115: CHI PHÍ LƯƠNG THÁNG 02.2025 | K115: CP LƯƠNG T2.2025 | L115: 2 | M115: 2025 | N115: 19448803 | O115: 5100001271 | Q115: CUC.NT | T115: 0
B116: Kiểm Soát Chất Lượng | C116: Lương Chính +T13 | D116: 45716 | E116: 1013535130 | F116: 6271002604 | G116: CP lương chính-Gián | H116: 1001601400 | I116: Kiểm soát chất lượng | J116: CHI PHÍ LƯƠNG THÁNG 02.2025 | K116: CP LƯƠNG T2.2025 | L116: 2 | M116: 2025 | N116: 450069010 | O116: 5100001271 | Q116: CUC.NT | T116: 0
B117: Kiểm Soát Chất Lượng | C117: Lương Chính +T13 | D117: 45716 | E117: 1013535130 | F117: 6271002605 | G117: CP Lương tháng 13, P | H117: 1001601400 | I117: Kiểm soát chất lượng | J117: CHI PHÍ LƯƠNG THÁNG 02.2025 | K117: CP LƯƠNG T2.2025 | L117: 2 | M117: 2025 | N117: 26400136 | O117: 5100001271 | Q117: CUC.NT | T117: 0
B118: Kiểm Soát Chất Lượng | C118: Lương Ngoài giờ | D118: 45716 | E118: 1013535130 | F118: 6271002703 | G118: CP lương ngoài giờ - | H118: 1001601400 | I118: Kiểm soát chất lượng | J118: CHI PHÍ LƯƠNG THÁNG 02.2025 | K118: CP LƯƠNG T2.2025 | L118: 2 | M118: 2025 | N118: 134337444 | O118: 5100001271 | Q118: CUC.NT | T118: 0
B119: Kiểm Soát Chất Lượng | C119: Thưởng | D119: 45716 | E119: 1013535130 | F119: 6271002802 | G119: Chi phí Khen thưởng | H119: 1001601400 | I119: Kiểm soát chất lượng | J119: CHI PHÍ LƯƠNG THÁNG 02.2025 | K119: CP LƯƠNG T2.2025 | L119: 2 | M119: 2025 | N119: 31440000 | O119: 5100001271 | Q119: CUC.NT | T119: 0
B120: Kiểm Soát Chất Lượng | C120: Phụ Cấp | D120: 45716 | E120: 1013535130 | F120: 6271003202 | G120: Tiền ăn giữa ca-Gián | H120: 1001601400 | I120: Kiểm soát chất lượng | J120: CHI PHÍ LƯƠNG THÁNG 02.2025 | K120: CP LƯƠNG T2.2025 | L120: 2 | M120: 2025 | N120: 6400000 | O120: 5100001271 | Q120: CUC.NT | T120: 0
B121: Nghiên Cứu & Phát Triển | C121: Lương Chính +T13 | D121: 45716 | E121: 1013535130 | F121: 6271002604 | G121: CP lương chính-Gián | H121: 1001601500 | I121: Nghiên Cứu & PT | J121: CHI PHÍ LƯƠNG THÁNG 02.2025 | K121: CP LƯƠNG T2.2025 | L121: 2 | M121: 2025 | N121: 139172326 | O121: 5100001271 | Q121: CUC.NT | T121: 0
B122: Nghiên Cứu & Phát Triển | C122: Lương Chính +T13 | D122: 45716 | E122: 1013535130 | F122: 6271002605 | G122: CP Lương tháng 13, P | H122: 1001601500 | I122: Nghiên Cứu & PT | J122: CHI PHÍ LƯƠNG THÁNG 02.2025 | K122: CP LƯƠNG T2.2025 | L122: 2 | M122: 2025 | N122: 4664808 | O122: 5100001271 | Q122: CUC.NT | T122: 0
B123: Nghiên Cứu & Phát Triển | C123: Thưởng | D123: 45716 | E123: 1013535130 | F123: 6271002802 | G123: Chi phí Khen thưởng | H123: 1001601500 | I123: Nghiên Cứu & PT | J123: CHI PHÍ LƯƠNG THÁNG 02.2025 | K123: CP LƯƠNG T2.2025 | L123: 2 | M123: 2025 | N123: 3000000 | O123: 5100001271 | Q123: CUC.NT | T123: 0
A124: 622 | B124: Xưởng Sản Xuất | C124: Lương Chính +T13 | D124: 45716 | E124: 1013535130 | F124: 6220002601 | G124: CP lương chính-Trực | H124: 1001602000 | I124: Xưởng sản xuất PET | J124: CHI PHÍ LƯƠNG THÁNG 02.2025 | K124: CP LƯƠNG T2.2025 | L124: 2 | M124: 2025 | N124: 1400002480 | O124: 5100001271 | Q124: CUC.NT | T124: 0
A125: 622 | B125: Xưởng Sản Xuất | C125: Lương Chính +T13 | D125: 45716 | E125: 1013535130 | F125: 6220002602 | G125: CP Lương tháng 13, P | H125: 1001602000 | I125: Xưởng sản xuất PET | J125: CHI PHÍ LƯƠNG THÁNG 02.2025 | K125: CP LƯƠNG T2.2025 | L125: 2 | M125: 2025 | N125: 33470186 | O125: 5100001271 | Q125: CUC.NT | T125: 0
A126: 622 | B126: Xưởng Sản Xuất | C126: Phụ Cấp | D126: 45716 | E126: 1013535130 | F126: 6220002603 | G126: Phụ cấp ca đêm | H126: 1001602000 | I126: Xưởng sản xuất PET | J126: CHI PHÍ LƯƠNG THÁNG 02.2025 | K126: CP LƯƠNG T2.2025 | L126: 2 | M126: 2025 | N126: 92249649 | O126: 5100001271 | Q126: CUC.NT | T126: 0
A127: 622 | B127: Xưởng Sản Xuất | C127: Lương Ngoài giờ | D127: 45716 | E127: 1013535130 | F127: 6220002701 | G127: CP lương ngoài giờ | H127: 1001602000 | I127: Xưởng sản xuất PET | J127: CHI PHÍ LƯƠNG THÁNG 02.2025 | K127: CP LƯƠNG T2.2025 | L127: 2 | M127: 2025 | N127: 259898689 | O127: 5100001271 | Q127: CUC.NT | T127: 0
A128: 622 | B128: Xưởng Sản Xuất | C128: Thưởng | D128: 45716 | E128: 1013535130 | F128: 6220002802 | G128: Chi phí Khen thưởng | H128: 1001602000 | I128: Xưởng sản xuất PET | J128: CHI PHÍ LƯƠNG THÁNG 02.2025 | K128: CP LƯƠNG T2.2025 | L128: 2 | M128: 2025 | N128: 84500000 | O128: 5100001271 | Q128: CUC.NT | T128: 0
A129: 622 | B129: Xưởng Sản Xuất | C129: Phụ Cấp | D129: 45716 | E129: 1013535130 | F129: 6220003201 | G129: Tiền ăn giữa ca-Trực | H129: 1001602000 | I129: Xưởng sản xuất PET | J129: CHI PHÍ LƯƠNG THÁNG 02.2025 | K129: CP LƯƠNG T2.2025 | L129: 2 | M129: 2025 | N129: 27890000 | O129: 5100001271 | Q129: CUC.NT | T129: 0
A130: 627 | B130: Xưởng Sản Xuất | C130: Phụ Cấp | D130: 45716 | E130: 1013535130 | F130: 6271002603 | G130: Phụ cấp ca đêm | H130: 1001602000 | I130: Xưởng sản xuất PET | J130: CHI PHÍ LƯƠNG THÁNG 02.2025 | K130: CP LƯƠNG T2.2025 | L130: 2 | M130: 2025 | N130: 11105572 | O130: 5100001271 | Q130: CUC.NT | T130: 0
A131: 627 | B131: Xưởng Sản Xuất | C131: Lương Chính +T13 | D131: 45716 | E131: 1013535130 | F131: 6271002604 | G131: CP lương chính-Gián | H131: 1001602000 | I131: Xưởng sản xuất PET | J131: CHI PHÍ LƯƠNG THÁNG 02.2025 | K131: CP LƯƠNG T2.2025 | L131: 2 | M131: 2025 | N131: 411544399 | O131: 5100001271 | Q131: CUC.NT | T131: 0
A132: 627 | B132: Xưởng Sản Xuất | C132: Lương Chính +T13 | D132: 45716 | E132: 1013535130 | F132: 6271002605 | G132: CP Lương tháng 13, P | H132: 1001602000 | I132: Xưởng sản xuất PET | J132: CHI PHÍ LƯƠNG THÁNG 02.2025 | K132: CP LƯƠNG T2.2025 | L132: 2 | M132: 2025 | N132: 17666383 | O132: 5100001271 | Q132: CUC.NT | T132: 0
A133: 627 | B133: Xưởng Sản Xuất | C133: Lương Ngoài giờ | D133: 45716 | E133: 1013535130 | F133: 6271002703 | G133: CP lương ngoài giờ - | H133: 1001602000 | I133: Xưởng sản xuất PET | J133: CHI PHÍ LƯƠNG THÁNG 02.2025 | K133: CP LƯƠNG T2.2025 | L133: 2 | M133: 2025 | N133: 35669591 | O133: 5100001271 | Q133: CUC.NT | T133: 0
A134: 627 | B134: Xưởng Sản Xuất | C134: Thưởng | D134: 45716 | E134: 1013535130 | F134: 6271002802 | G134: Chi phí Khen thưởng | H134: 1001602000 | I134: Xưởng sản xuất PET | J134: CHI PHÍ LƯƠNG THÁNG 02.2025 | K134: CP LƯƠNG T2.2025 | L134: 2 | M134: 2025 | N134: 15500000 | O134: 5100001271 | Q134: CUC.NT | T134: 0
...

Sheet Mapping
A1: Cost Element | B1: Cost element name | C1: Cost Center | D1: CO object name | E1: Bộ phận | F1: KM
A2: 6421002604 | B2: CP lương chính-Gián | C2: 1001101000 | D2: Ban giám đốc | E2: Ban Giám Đốc | F2: Lương Chính +T13
A3: 6421002605 | B3: CP Lương tháng 13, P | C3: 1001101000 | D3: Ban giám đốc | E3: Ban Giám Đốc | F3: Lương Chính +T13
A4: 6421002802 | B4: Chi phí Khen thưởng | C4: 1001101000 | D4: Ban giám đốc | E4: Ban Giám Đốc | F4: Thưởng
A5: 6421002806 | B5: Thưởng danh hiệu | C5: 1001101000 | D5: Ban giám đốc | E5: Ban Giám Đốc | F5: Thưởng
A6: 6421003401 | B6: BHXH, BHYT, KPCĐ, BH | C6: 1001101000 | D6: Ban giám đốc | E6: Ban Giám Đốc | F6: BHXH, BHYT, KPCĐ
A7: 6421007202 | B7: Khen thưởng BD khác | C7: 1001202000 | D7: Hành chánh nhân sự | E7: Hành Chánh Nhân Sự | F7: Khen thưởng BD khác
A8: 6421007202 | B8: Khen thưởng BD khác | C8: 1001201000 | D8: Văn phòng giám đốc | E8: Văn Phòng Giám Đốc | F8: Khen thưởng BD khác
A9: 6421002604 | B9: CP lương chính-Gián | C9: 1001202000 | D9: Hành chánh nhân sự | E9: Hành Chánh Nhân Sự | F9: Lương Chính +T13
A10: 6421003202 | B10: Tiền ăn giữa ca-Gián | C10: 1001202000 | D10: Hành chánh nhân sự | E10: Hành Chánh Nhân Sự | F10: Phụ Cấp
A11: 6421003202 | B11: Tiền ăn giữa ca-Gián | C11: 1001201000 | D11: Văn phòng giám đốc | E11: Văn Phòng Giám Đốc | F11: Phụ Cấp
A12: 6421002604 | B12: CP lương chính-Gián | C12: 1001201000 | D12: Văn phòng giám đốc | E12: Văn Phòng Giám Đốc | F12: Lương Chính +T13
... A137: 6271003202 | B137: Tiền ăn giữa ca-Gián | C137: 1001601500 | D137: Nghiên Cứu & PT | E137: Nghiên Cứu & Phát Triển | F137: Phụ Cấp
A138: 6421002801 | B138: Chi phí bồi dưỡng | F138: Khen thưởng BD khác
C139: 1001206000 | D139: Chiến Lược CCU | E139: Chiến Lược CCU
C140: 1001103000 | D140: Ban tổng giám đốc | E140: Ban Giám Đốc

Sheet Data 2025 >>
N1: =SUBTOTAL(9,N3:N9999) -> 168377071168
B2: Bộ phận | C2: KM | D2: Posting Date | E2: Document Number | F2: Cost Element | G2: Cost element name | H2: Cost Center | I2: CO object name | J2: Name | K2: Document Header Text | L2: Period | M2: Fiscal Year | N2: Val/COArea Crcy | O2: Ref Document Number | P2: Reversal document | Q2: User Name | R2: Material | S2: Material Description | T2: Total quantity
B3: Ban Giám Đốc | C3: Lương Chính +T13 | D3: 45716 | E3: 1013535130 | F3: 6421002604 | G3: CP lương chính-Gián | H3: 1001101000 | I3: Ban giám đốc | J3: CHI PHÍ LƯƠNG THÁNG 02.2025 | K3: CP LƯƠNG T2.2025 | L3: 2 | M3: 2025 | N3: 1178412592 | O3: 5100001271 | Q3: CUC.NT | T3: 0
B4: Ban Giám Đốc | C4: Lương Chính +T13 | D4: 45716 | E4: 1013535130 | F4: 6421002605 | G4: CP Lương tháng 13, P | H4: 1001101000 | I4: Ban giám đốc | J4: CHI PHÍ LƯƠNG THÁNG 02.2025 | K4: CP LƯƠNG T2.2025 | L4: 2 | M4: 2025 | N4: 10777046 | O4: 5100001271 | Q4: CUC.NT | T4: 0
B5: Ban Giám Đốc | C5: Lương Chính +T13 | D5: 45716 | E5: 1013535132 | F5: 6421002605 | G5: CP Lương tháng 13, P | H5: 1001101000 | I5: Ban giám đốc | J5: TRÍCH LƯƠNG T13, PHÉP NĂM T02.2025 | K5: CP LƯƠNG T2.2025 | L5: 2 | M5: 2025 | N5: 93775083 | O5: 5100001273 | Q5: CUC.NT | T5: 0
B6: Ban Giám Đốc | C6: Thưởng | D6: 45716 | E6: 1013535130 | F6: 6421002802 | G6: Chi phí Khen thưởng | H6: 1001101000 | I6: Ban giám đốc | J6: CHI PHÍ LƯƠNG THÁNG 02.2025 | K6: CP LƯƠNG T2.2025 | L6: 2 | M6: 2025 | N6: 9720000 | O6: 5100001271 | Q6: CUC.NT | T6: 0
B7: Ban Giám Đốc | C7: Thưởng | D7: 45716 | E7: 1013535132 | F7: 6421002806 | G7: Thưởng danh hiệu | H7: 1001101000 | I7: Ban giám đốc | J7: TRÍCH DANH HIỆU T02.2025 | K7: CP LƯƠNG T2.2025 | L7: 2 | M7: 2025 | N7: 86272326 | O7: 5100001273 | Q7: CUC.NT | T7: 0
B8: Ban Giám Đốc | C8: BHXH, BHYT, KPCĐ | D8: 45716 | E8: 1013535131 | F8: 6421003401 | G8: BHXH, BHYT, KPCĐ, BH | H8: 1001101000 | I8: Ban giám đốc | J8: BHXH,BHYT,KPCĐ,BHTN T2.25 | K8: CP LƯƠNG T2.2025 | L8: 2 | M8: 2025 | N8: 112158010 | O8: 5100001272 | Q8: CUC.NT | T8: 0
B9: Hành Chánh Nhân Sự | C9: Khen thưởng BD khác | D9: 45694 | E9: 1013521257 | F9: 6421007202 | G9: Khen thưởng BD khác | H9: 1001202000 | I9: Hành chánh nhân sự | J9: Khen thưởng ý tưởng cải tiến T9+10.2024 - H.T.Nhâm | K9: CP khen thưởng ý tưởng | L9: 2 | M9: 2025 | N9: 400000 | O9: 5100000759 | Q9: NHI.NHN | T9: 0
B10: Hành Chánh Nhân Sự | C10: Khen thưởng BD khác | D10: 45694 | E10: 1013521257 | F10: 6421007202 | G10: Khen thưởng BD khác | H10: 1001202000 | I10: Hành chánh nhân sự | J10: Khen thưởng ý tưởng cải tiến T9+10.2024 - M.H.Nhân | K10: CP khen thưởng ý tưởng | L10: 2 | M10: 2025 | N10: 200000 | O10: 5100000759 | Q10: NHI.NHN | T10: 0
B11: Hành Chánh Nhân Sự | C11: Khen thưởng BD khác | D11: 45694 | E11: 1013521257 | F11: 6421007202 | G11: Khen thưởng BD khác | H11: 1001202000 | I11: Hành chánh nhân sự | J11: Khen thưởng ý tưởng cải tiến T9+10.2024- L.M.Thanh | K11: CP khen thưởng ý tưởng | L11: 2 | M11: 2025 | N11: 200000 | O11: 5100000759 | Q11: NHI.NHN | T11: 0
B12: Hành Chánh Nhân Sự | C12: Khen thưởng BD khác | D12: 45694 | E12: 1013521257 | F12: 6421007202 | G12: Khen thưởng BD khác | H12: 1001202000 | I12: Hành chánh nhân sự | J12: Khen thưởng ý tưởng cải tiến T9+10.2024 - N.V.Tú | K12: CP khen thưởng ý tưởng | L12: 2 | M12: 2025 | N12: 200000 | O12: 5100000759 | Q12: NHI.NHN | T12: 0
B13: Hành Chánh Nhân Sự | C13: Khen thưởng BD khác | D13: 45694 | E13: 1013521257 | F13: 6421007202 | G13: Khen thưởng BD khác | H13: 1001202000 | I13: Hành chánh nhân sự | J13: Khen thưởng ý tưởng cải tiến T9+10.2024 - T.V.Hiền | K13: CP khen thưởng ý tưởng | L13: 2 | M13: 2025 | N13: 1400000 | O13: 5100000759 | Q13: NHI.NHN | T13: 0
B14: Hành Chánh Nhân Sự | C14: Khen thưởng BD khác | D14: 45694 | E14: 1013521257 | F14: 6421007202 | G14: Khen thưởng BD khác | H14: 1001202000 | I14: Hành chánh nhân sự | J14: Khen thưởng ý tưởng cải tiến T9+10.2024-N.T.P.Hằng | K14: CP khen thưởng ý tưởng | L14: 2 | M14: 2025 | N14: 200000 | O14: 5100000759 | Q14: NHI.NHN | T14: 0
... B109: Hành Chánh Nhân Sự | C109: Khen thưởng BD khác | D109: 45716 | E109: 1013536241 | F109: 6421007202 | G109: Khen thưởng BD khác | H109: 1001204000 | I109: Tổ 5S & an toàn | J109: Bồi dưỡng ATVSV T1/25 | K109: Bồi dưỡng ATVSV T1/25 | L109: 2 | M109: 2025 | N109: 2981191 | O109: 5100001292 | Q109: DIEM.NTT | T109: 0
A110: 622 | B110: Xưởng Sản Xuất | C110: Lương Chính +T13 | D110: 45695 | E110: 1013531766 | F110: 6220002601 | G110: CP lương chính-Trực | H110: 1001602000 | I110: Xưởng sản xuất PET | J110: CP công nhân thuê ngoài T01.2025 (14 PET) | K110: CP công nhân thuê ngoài T | L110: 2 | M110: 2025 | N110: 102130449 | O110: 3500000700 | Q110: NHI.NHN | T110: 0
A111: 622 | B111: Xưởng Sản Xuất | C111: Lương Chính +T13 | D111: 45695 | E111: 1013531766 | F111: 6220002601 | G111: CP lương chính-Trực | H111: 1001602000 | I111: Xưởng sản xuất PET | J111: CP công nhân thuê ngoài T01.2025 (9 PET) | K111: CP công nhân thuê ngoài T | L111: 2 | M111: 2025 | N111: 9000000 | O111: 3500000700 | Q111: NHI.NHN | T111: 0
A112: 622 | B112: Xưởng Sản Xuất | C112: Lương Chính +T13 | D112: 45696 | E112: 1013532601 | F112: 6220002601 | G112: CP lương chính-Trực | H112: 1001602000 | I112: Xưởng sản xuất PET | J112: CP công nhân thuê ngoài T01.2025 (2 PET) | K112: CP công nhân thuê ngoài T | L112: 2 | M112: 2025 | N112: 8333333 | O112: 3500000726 | Q112: NHI.NHN | T112: 0
B113: Kiểm Soát Chất Lượng | C113: Phụ Cấp | D113: 45715 | E113: 1013532775 | F113: 6271003202 | G113: Tiền ăn giữa ca-Gián | H113: 1001601400 | I113: Kiểm soát chất lượng | J113: chi phí suất ăn - Đắc Bảo An tháng 02/2025 | K113: chi phí suất ăn - Đắc Bảo | L113: 2 | M113: 2025 | N113: 24425000 | O113: 3500000749 | Q113: NHI.NHN | T113: 0
A114: 622 | B114: Xưởng Sản Xuất | C114: Phụ Cấp | D114: 45716 | E114: 1013533313 | F114: 6220003201 | G114: Tiền ăn giữa ca-Trực | H114: 1001602000 | I114: Xưởng sản xuất PET | J114: CHUYỂN GL TIỀN CƠM | K114: CHUYỂN GL TIỀN CƠM | L114: 2 | M114: 2025 | N114: 81650000 | O114: 5100000871 | Q114: DIEM.NTT | T114: 0
B115: Kiểm Soát Chất Lượng | C115: Phụ Cấp | D115: 45716 | E115: 1013535130 | F115: 6271002603 | G115: Phụ cấp ca đêm | H115: 1001601400 | I115: Kiểm soát chất lượng | J115: CHI PHÍ LƯƠNG THÁNG 02.2025 | K115: CP LƯƠNG T2.2025 | L115: 2 | M115: 2025 | N115: 19448803 | O115: 5100001271 | Q115: CUC.NT | T115: 0
B116: Kiểm Soát Chất Lượng | C116: Lương Chính +T13 | D116: 45716 | E116: 1013535130 | F116: 6271002604 | G116: CP lương chính-Gián | H116: 1001601400 | I116: Kiểm soát chất lượng | J116: CHI PHÍ LƯƠNG THÁNG 02.2025 | K116: CP LƯƠNG T2.2025 | L116: 2 | M116: 2025 | N116: 450069010 | O116: 5100001271 | Q116: CUC.NT | T116: 0
B117: Kiểm Soát Chất Lượng | C117: Lương Chính +T13 | D117: 45716 | E117: 1013535130 | F117: 6271002605 | G117: CP Lương tháng 13, P | H117: 1001601400 | I117: Kiểm soát chất lượng | J117: CHI PHÍ LƯƠNG THÁNG 02.2025 | K117: CP LƯƠNG T2.2025 | L117: 2 | M117: 2025 | N117: 26400136 | O117: 5100001271 | Q117: CUC.NT | T117: 0
B118: Kiểm Soát Chất Lượng | C118: Lương Ngoài giờ | D118: 45716 | E118: 1013535130 | F118: 6271002703 | G118: CP lương ngoài giờ - | H118: 1001601400 | I118: Kiểm soát chất lượng | J118: CHI PHÍ LƯƠNG THÁNG 02.2025 | K118: CP LƯƠNG T2.2025 | L118: 2 | M118: 2025 | N118: 134337444 | O118: 5100001271 | Q118: CUC.NT | T118: 0
B119: Kiểm Soát Chất Lượng | C119: Thưởng | D119: 45716 | E119: 1013535130 | F119: 6271002802 | G119: Chi phí Khen thưởng | H119: 1001601400 | I119: Kiểm soát chất lượng | J119: CHI PHÍ LƯƠNG THÁNG 02.2025 | K119: CP LƯƠNG T2.2025 | L119: 2 | M119: 2025 | N119: 31440000 | O119: 5100001271 | Q119: CUC.NT | T119: 0
B120: Kiểm Soát Chất Lượng | C120: Phụ Cấp | D120: 45716 | E120: 1013535130 | F120: 6271003202 | G120: Tiền ăn giữa ca-Gián | H120: 1001601400 | I120: Kiểm soát chất lượng | J120: CHI PHÍ LƯƠNG THÁNG 02.2025 | K120: CP LƯƠNG T2.2025 | L120: 2 | M120: 2025 | N120: 6400000 | O120: 5100001271 | Q120: CUC.NT | T120: 0
B121: Nghiên Cứu & Phát Triển | C121: Lương Chính +T13 | D121: 45716 | E121: 1013535130 | F121: 6271002604 | G121: CP lương chính-Gián | H121: 1001601500 | I121: Nghiên Cứu & PT | J121: CHI PHÍ LƯƠNG THÁNG 02.2025 | K121: CP LƯƠNG T2.2025 | L121: 2 | M121: 2025 | N121: 139172326 | O121: 5100001271 | Q121: CUC.NT | T121: 0
B122: Nghiên Cứu & Phát Triển | C122: Lương Chính +T13 | D122: 45716 | E122: 1013535130 | F122: 6271002605 | G122: CP Lương tháng 13, P | H122: 1001601500 | I122: Nghiên Cứu & PT | J122: CHI PHÍ LƯƠNG THÁNG 02.2025 | K122: CP LƯƠNG T2.2025 | L122: 2 | M122: 2025 | N122: 4664808 | O122: 5100001271 | Q122: CUC.NT | T122: 0
B123: Nghiên Cứu & Phát Triển | C123: Thưởng | D123: 45716 | E123: 1013535130 | F123: 6271002802 | G123: Chi phí Khen thưởng | H123: 1001601500 | I123: Nghiên Cứu & PT | J123: CHI PHÍ LƯƠNG THÁNG 02.2025 | K123: CP LƯƠNG T2.2025 | L123: 2 | M123: 2025 | N123: 3000000 | O123: 5100001271 | Q123: CUC.NT | T123: 0
A124: 622 | B124: Xưởng Sản Xuất | C124: Lương Chính +T13 | D124: 45716 | E124: 1013535130 | F124: 6220002601 | G124: CP lương chính-Trực | H124: 1001602000 | I124: Xưởng sản xuất PET | J124: CHI PHÍ LƯƠNG THÁNG 02.2025 | K124: CP LƯƠNG T2.2025 | L124: 2 | M124: 2025 | N124: 1400002480 | O124: 5100001271 | Q124: CUC.NT | T124: 0
A125: 622 | B125: Xưởng Sản Xuất | C125: Lương Chính +T13 | D125: 45716 | E125: 1013535130 | F125: 6220002602 | G125: CP Lương tháng 13, P | H125: 1001602000 | I125: Xưởng sản xuất PET | J125: CHI PHÍ LƯƠNG THÁNG 02.2025 | K125: CP LƯƠNG T2.2025 | L125: 2 | M125: 2025 | N125: 33470186 | O125: 5100001271 | Q125: CUC.NT | T125: 0
A126: 622 | B126: Xưởng Sản Xuất | C126: Phụ Cấp | D126: 45716 | E126: 1013535130 | F126: 6220002603 | G126: Phụ cấp ca đêm | H126: 1001602000 | I126: Xưởng sản xuất PET | J126: CHI PHÍ LƯƠNG THÁNG 02.2025 | K126: CP LƯƠNG T2.2025 | L126: 2 | M126: 2025 | N126: 92249649 | O126: 5100001271 | Q126: CUC.NT | T126: 0
A127: 622 | B127: Xưởng Sản Xuất | C127: Lương Ngoài giờ | D127: 45716 | E127: 1013535130 | F127: 6220002701 | G127: CP lương ngoài giờ | H127: 1001602000 | I127: Xưởng sản xuất PET | J127: CHI PHÍ LƯƠNG THÁNG 02.2025 | K127: CP LƯƠNG T2.2025 | L127: 2 | M127: 2025 | N127: 259898689 | O127: 5100001271 | Q127: CUC.NT | T127: 0
A128: 622 | B128: Xưởng Sản Xuất | C128: Thưởng | D128: 45716 | E128: 1013535130 | F128: 6220002802 | G128: Chi phí Khen thưởng | H128: 1001602000 | I128: Xưởng sản xuất PET | J128: CHI PHÍ LƯƠNG THÁNG 02.2025 | K128: CP LƯƠNG T2.2025 | L128: 2 | M128: 2025 | N128: 84500000 | O128: 5100001271 | Q128: CUC.NT | T128: 0
A129: 622 | B129: Xưởng Sản Xuất | C129: Phụ Cấp | D129: 45716 | E129: 1013535130 | F129: 6220003201 | G129: Tiền ăn giữa ca-Trực | H129: 1001602000 | I129: Xưởng sản xuất PET | J129: CHI PHÍ LƯƠNG THÁNG 02.2025 | K129: CP LƯƠNG T2.2025 | L129: 2 | M129: 2025 | N129: 27890000 | O129: 5100001271 | Q129: CUC.NT | T129: 0
A130: 627 | B130: Xưởng Sản Xuất | C130: Phụ Cấp | D130: 45716 | E130: 1013535130 | F130: 6271002603 | G130: Phụ cấp ca đêm | H130: 1001602000 | I130: Xưởng sản xuất PET | J130: CHI PHÍ LƯƠNG THÁNG 02.2025 | K130: CP LƯƠNG T2.2025 | L130: 2 | M130: 2025 | N130: 11105572 | O130: 5100001271 | Q130: CUC.NT | T130: 0
A131: 627 | B131: Xưởng Sản Xuất | C131: Lương Chính +T13 | D131: 45716 | E131: 1013535130 | F131: 6271002604 | G131: CP lương chính-Gián | H131: 1001602000 | I131: Xưởng sản xuất PET | J131: CHI PHÍ LƯƠNG THÁNG 02.2025 | K131: CP LƯƠNG T2.2025 | L131: 2 | M131: 2025 | N131: 411544399 | O131: 5100001271 | Q131: CUC.NT | T131: 0
A132: 627 | B132: Xưởng Sản Xuất | C132: Lương Chính +T13 | D132: 45716 | E132: 1013535130 | F132: 6271002605 | G132: CP Lương tháng 13, P | H132: 1001602000 | I132: Xưởng sản xuất PET | J132: CHI PHÍ LƯƠNG THÁNG 02.2025 | K132: CP LƯƠNG T2.2025 | L132: 2 | M132: 2025 | N132: 17666383 | O132: 5100001271 | Q132: CUC.NT | T132: 0
A133: 627 | B133: Xưởng Sản Xuất | C133: Lương Ngoài giờ | D133: 45716 | E133: 1013535130 | F133: 6271002703 | G133: CP lương ngoài giờ - | H133: 1001602000 | I133: Xưởng sản xuất PET | J133: CHI PHÍ LƯƠNG THÁNG 02.2025 | K133: CP LƯƠNG T2.2025 | L133: 2 | M133: 2025 | N133: 35669591 | O133: 5100001271 | Q133: CUC.NT | T133: 0
A134: 627 | B134: Xưởng Sản Xuất | C134: Thưởng | D134: 45716 | E134: 1013535130 | F134: 6271002802 | G134: Chi phí Khen thưởng | H134: 1001602000 | I134: Xưởng sản xuất PET | J134: CHI PHÍ LƯƠNG THÁNG 02.2025 | K134: CP LƯƠNG T2.2025 | L134: 2 | M134: 2025 | N134: 15500000 | O134: 5100001271 | Q134: CUC.NT | T134: 0
...

Sheet 01. CP Nhân sự 2025
A1: 00. DM | B1: CHI PHÍ NHÂN SỰ 2025
K3: =SUM(K18,K32,K46,K60,K74,K88,K102,K116,K130,K144,K158) -> 152749563246 | N3: =SUM(N18:N158) -> 1.4377677e+12 | O3: =K3/$N$3 -> 0.10624078
A4: THÁNG | B4: STT | C4: Bộ phận | D4: Định biên | E4: Lương Chính +T13 | F4: Lương Ngoài giờ | G4: Thưởng | H4: Phụ Cấp | I4: BHXH, BHYT, KPCĐ | J4: Khen thưởng BD khác | K4: Cộng | L4: Tỷ lệ tăng | N4: Doanh thu | O4: % lương / doanh thu
A5: 1 | B5: 1 | C5: Ban Giám Đốc | D5: 11 | E5: 1264140856 | G5: 87812330 | I5: 101568010 | K5: =SUM(E5:J5) -> 1453521196 | O5: =K5/$N$18 -> 0.012698666
A6: 1 | B6: 2 | C6: Kinh doanh | D6: 9 | E6: 266365959 | G6: 66215507 | I6: 51324945 | K6: =SUM(E6:J6) -> 383906411 | O6: =K6/$N$18 -> 0.0033539926
A7: 1 | B7: 3 | C7: Mua Hàng & XNK | D7: 6 | E7: 164395004 | G7: 8470467 | H7: 3850000 | I7: 16645755 | K7: =SUM(E7:J7) -> 193361226 | O7: =K7/$N$18 -> 0.0016892974
A8: 1 | B8: 4 | C8: Kế Toán | D8: 24 | E8: 473875397 | F8: 46152955 | G8: 38217504 | H8: 16375385 | I8: 86246195 | K8: =SUM(E8:J8) -> 660867436 | O8: =K8/$N$18 -> 0.0057736584
A9: 1 | B9: 5 | C9: Nghiên Cứu & Phát Triển | D9: 6 | E9: 158791577 | G9: 13123786 | H9: 50000 | I9: 35154315 | K9: =SUM(E9:J9) -> 207119678 | O9: =K9/$N$18 -> 0.001809498
A10: 1 | B10: 6 | C10: Văn Phòng Giám Đốc | D10: 4 | E10: 99254688 | G10: 8838430 | H10: 5550000 | I10: 30888225 | J10: 4792753 | K10: =SUM(E10:J10) -> 149324096 | O10: =K10/$N$18 -> 0.0013045677
A11: 1 | B11: 7 | C11: Kiểm Soát Chất Lượng | D11: 47 | E11: 534769107 | F11: 158408018 | G11: 52061339 | H11: 59537328 | I11: 101945350 | K11: =SUM(E11:J11) -> 906721142 | O11: =K11/$N$18 -> 0.0079215556
A12: 1 | B12: 8 | C12: Kỹ Thuật | D12: 72 | E12: 1110867901 | F12: 275691629 | G12: 99942604 | H12: 93620134 | I12: 228967370 | J12: 4500000 | K12: =SUM(E12:J12) -> 1813589638 | O12: =K12/$N$18 -> 0.015844399
A13: 1 | B13: 9 | C13: Hành Chánh Nhân Sự | D13: 43 | E13: 727256871 | F13: 100517421 | G13: 54907749 | H13: 44467681 | I13: 103648325 | J13: 5400000 | K13: =SUM(E13:J13) -> 1036198047 | O13: =K13/$N$18 -> 0.0090527286
A14: 1 | B14: 10 | C14: Cung Ứng | D14: 36 | E14: 543777219 | G14: 198877610 | H14: 13970000 | I14: 98662635 | K14: =SUM(E14:J14) -> 855287464 | O14: =K14/$N$18 -> 0.0074722061
A15: 1 | B15: 11 | C15: Xưởng Sản Xuất | D15: 91 | E15: 1231903621 | F15: 121068303 | G15: 91899296 | H15: 107240314 | I15: 188011260 | J15: 5150000 | K15: =SUM(E15:J15) -> 1745272794 | L15: =K15+K16 -> 4703024708 | O15: =K15/$N$18 -> 0.01524755
A16: 1 | B16: 12 | C16: Xưởng Sản Xuất | D16: 218 | E16: 1950381801 | F16: 326525959 | G16: 131737986 | H16: 258406333 | I16: 290699835 | K16: =SUM(E16:J16) -> 2957751914 | O16: =K16/$N$18 -> 0.025840355
A17: 1 | B17: 13 | C17: Tư vấn dịch vụ | D17: 2 | E17: 113750000 | G17: 8049930 | K17: =SUM(E17:J17) -> 121799930 | O17: =K17/$N$18 -> 0.0010641033
A18: 1 | C18: CỘNG | D18: 569 | E18: 8639530001 | F18: 1028364285 | G18: 860154538 | H18: 603067175 | I18: 1333762220 | J18: 19842753 | K18: =SUM(K5:K17) -> 12484720972 | N18: 114462510402 | O18: =K18/$N$18 -> 0.10907258
A19: 2 | B19: 1 | C19: Ban Giám Đốc | D19: 11 | E19: 1282964721 | G19: 95992326 | I19: 112158010 | K19: =SUM(E19:J19) -> 1491115057 | O19: =K19/$N$32 -> 0.0079314858
A20: 2 | B20: 2 | C20: Kinh doanh | D20: 9 | E20: 256598460 | G20: 58223048 | H20: 50000 | I20: 57199945 | K20: =SUM(E20:J20) -> 372071453 | O20: =K20/$N$32 -> 0.0019791091
A21: 2 | B21: 3 | C21: Mua Hàng & XNK | D21: 7 | E21: 100998488 | F21: 10838778 | H21: 2900000 | I21: 22638255 | K21: =SUM(E21:J21) -> 137375521 | O21: =K21/$N$32 -> 0.00073072295
A22: 2 | B22: 4 | C22: Kế Toán | D22: 23 | E22: 449665471 | F22: 36055040 | G22: 42644566 | H22: 12820000 | I22: 87773695 | K22: =SUM(E22:J22) -> 628958772 | O22: =K22/$N$32 -> 0.003345535
A23: 2 | B23: 5 | C23: Nghiên Cứu & Phát Triển | D23: 6 | E23: 156797884 | G23: 14923786 | I23: 35154315 | K23: =SUM(E23:J23) -> 206875985 | O23: =K23/$N$32 -> 0.0011004073
A24: 2 | B24: 6 | C24: Văn Phòng Giám Đốc | D24: 3 | E24: 87674558 | G24: 8189109 | H24: 2400000 | I24: 20503750 | K24: =SUM(E24:J24) -> 118767417 | O24: =K24/$N$32 -> 0.00063174339
A25: 2 | B25: 7 | C25: Kiểm Soát Chất Lượng | D25: 47 | E25: 514268646 | F25: 134337444 | G25: 66215238 | H25: 50273803 | I25: 106643940 | K25: =SUM(E25:J25) -> 871739071 | O25: =K25/$N$32 -> 0.0046369232
A26: 2 | B26: 8 | C26: Kỹ Thuật | D26: 71 | E26: 1030234344 | F26: 279940724 | G26: 189713746 | H26: 82048756 | I26: 217149870 | K26: =SUM(E26:J26) -> 1799087440 | O26: =K26/$N$32 -> 0.0095696415
A27: 2 | B27: 9 | C27: Hành Chánh Nhân Sự | D27: 43 | E27: 697796771 | F27: 141925157 | G27: 62132823 | H27: 46573980 | I27: 132056975 | J27: 13881191 | K27: =SUM(E27:J27) -> 1094366897 | O27: =K27/$N$32 -> 0.0058211172
A28: 2 | B28: 10 | C28: Cung Ứng | D28: 37 | E28: 527553705 | G28: 280249130 | H28: 11800000 | I28: 98662635 | K28: =SUM(E28:J28) -> 918265470 | O28: =K28/$N$32 -> 0.0048844048
A29: 2 | B29: 11 | C29: Xưởng Sản Xuất | D29: 92 | E29: 2002581833 | F29: 301395737 | G29: 128601782 | H29: 240936665 | I29: 282778795 | K29: =SUM(E29:J29) -> 2956294812 | O29: =K29/$N$32 -> 0.015725017
A30: 2 | B30: 12 | C30: Xưởng Sản Xuất | D30: 233 | E30: 1097100836 | F30: 118641454 | G30: 102701901 | H30: 74369452 | I30: 184031815 | J30: 7500000 | K30: =SUM(E30:J30) -> 1584345458 | O30: =K30/$N$32 -> 0.0084273936
A31: 2 | B31: 13 | C31: Tư vấn dịch vụ | D31: 3 | E31: 243750000 | G31: 17249850 | K31: =SUM(E31:J31) -> 260999850 | O31: =K31/$N$32 -> 0.0013883011
A32: 2 | C32: CỘNG | D32: =SUM(D19:D31) -> 585 | E32: =SUM(E19:E31) -> 8447985717 | F32: =SUM(F19:F31) -> 1023134334 | G32: =SUM(G19:G31) -> 1066837305 | H32: =SUM(H19:H31) -> 524172656 | I32: =SUM(I19:I31) -> 1356752000 | J32: =SUM(J19:J31) -> 21381191 | K32: =SUM(K19:K31) -> 12440263203 | L32: =K32/K18 -> 0.99643903 | N32: 187999461059 | O32: =K32/$N$32 -> 0.066171802
A33: 3 | B33: 1 | C33: Ban Giám Đốc | D33: 11 | E33: 1290464719 | G33: 86272326 | I33: 123680010 | K33: =SUM(E33:J33) -> 1500417055 | O33: =K33/$N$46 -> 0.0099859153
A34: 3 | B34: 2 | C34: Kinh doanh | D34: 9 | E34: 247831117 | G34: 348973474 | H34: 10262739 | I34: 62369945 | K34: =SUM(E34:J34) -> 669437275 | O34: =K34/$N$46 -> 0.0044553905
A35: 3 | B35: 3 | C35: Mua Hàng & XNK | D35: 7 | E35: 116437913 | G35: 9838778 | H35: 4550000 | I35: 22638255 | K35: =SUM(E35:J35) -> 153464946 | O35: =K35/$N$46 -> 0.0010213747
A36: 3 | B36: 4 | C36: Kế Toán | D36: 23 | E36: 420976789 | F36: 43454986 | G36: 30991234 | H36: 13730000 | I36: 85188695 | K36: =SUM(E36:J36) -> 594341704 | O36: =K36/$N$46 -> 0.0039555975
A37: 3 | B37: 5 | C37: Nghiên Cứu & Phát Triển | D37: 7 | E37: 161901104 | G37: 12805445 | I37: 35154315 | K37: =SUM(E37:J37) -> 209860864 | O37: =K37/$N$46 -> 0.0013967135
A38: 3 | B38: 6 | C38: Văn Phòng Giám Đốc | D38: 3 | E38: 84618789 | G38: 6689109 | H38: 1750000 | I38: 20503750 | K38: =SUM(E38:J38) -> 113561648 | O38: =K38/$N$46 -> 0.00075580119
A39: 3 | B39: 7 | C39: Kiểm Soát Chất Lượng | D39: 53 | E39: 538848633 | F39: 176485897 | G39: 38457122 | H39: 63690810 | I39: 105552365 | K39: =SUM(E39:J39) -> 923034827 | O39: =K39/$N$46 -> 0.0061431904
A40: 3 | B40: 8 | C40: Kỹ Thuật | D40: 76 | E40: 985747351 | F40: 291038225 | G40: 73263716 | H40: 92181120 | I40: 213996170 | K40: =SUM(E40:J40) -> 1656226582 | O40: =K40/$N$46 -> 0.011022894
A41: 3 | B41: 9 | C41: Hành Chánh Nhân Sự | D41: 43 | E41: 716066208 | F41: 85045966 | G41: 43613230 | H41: 48658512 | I41: 139741165 | J41: 14276937 | K41: =SUM(E41:J41) -> 1047402018 | O41: =K41/$N$46 -> 0.0069709071
...

Sheet Sheet3
B4: STT | C4: Bộ phận | D4: Định biên | E4: Lương Chính +T13 | F4: Lương Ngoài giờ | G4: Thưởng | H4: Phụ Cấp | I4: BHXH, BHYT, KPCĐ | J4: Khen thưởng BD khác | K4: Cộng
B5: 1 | C5: Ban Giám Đốc | K5: =SUM(E5:J5) -> 0
B6: 2 | C6: Kinh doanh | K6: =SUM(E6:J6) -> 0
B7: 3 | C7: Mua Hàng & XNK | K7: =SUM(E7:J7) -> 0
B8: 4 | C8: Kế Toán | K8: =SUM(E8:J8) -> 0
B9: 5 | C9: Nghiên Cứu & Phát Triển | K9: =SUM(E9:J9) -> 0
B10: 6 | C10: Văn Phòng Giám Đốc | K10: =SUM(E10:J10) -> 0
B11: 7 | C11: Kiểm Soát Chất Lượng | K11: =SUM(E11:J11) -> 0
B12: 8 | C12: Kỹ Thuật | K12: =SUM(E12:J12) -> 0
B13: 9 | C13: Hành Chánh Nhân Sự | K13: =SUM(E13:J13) -> 0
B14: 10 | C14: Cung Ứng | K14: =SUM(E14:J14) -> 0
B15: 11 | C15: Xưởng Sản Xuất | K15: =SUM(E15:J15) -> 0
B16: 12 | C16: Xưởng Sản Xuất | K16: =SUM(E16:J16) -> 0
B17: 13 | C17: Tư vấn dịch vụ | K17: =SUM(E17:J17) -> 0
C18: CỘNG | D18: =SUM(D5:D17) -> 0 | E18: =SUM(E5:E17) -> 0 | F18: =SUM(F5:F17) -> 0 | G18: =SUM(G5:G17) -> 0 | H18: =SUM(H5:H17) -> 0 | I18: =SUM(I5:I17) -> 0 | J18: =SUM(J5:J17) -> 0 | K18: =SUM(K5:K17) -> 0

Sheet Data 2026>>
N1: =SUBTOTAL(9,N3:N7942) -> 65553003
B2: Bộ phận | C2: KM | D2: Posting Date | E2: Document Number | F2: Cost Element | G2: Cost element name | H2: Cost Center | I2: CO object name | J2: Name | K2: Document Header Text | L2: Period | M2: Fiscal Year | N2: Val/COArea Crcy | O2: Ref Document Number | P2: Reversal document | Q2: User Name | R2: Material | S2: Material Description | T2: Total quantity
A3: =LEFT(F3,3) -> 642 | B3: =_xlfn.XLOOKUP(I3,Mapping!D:D,Mapping!E:E) -> Ban Giám Đốc | C3: =_xlfn.XLOOKUP(F3,Mapping!A:A,Mapping!F:F) -> Lương Chính +T13 | D3: 46053 | E3: 1013795681 | F3: 6421002604 | G3: CP lương chính-Gián | H3: 1001101000 | I3: Ban giám đốc | J3: CHI PHÍ LƯƠNG THÁNG 01.2026 | K3: CP LƯƠNGT01.2026 | L3: 1 | M3: 2026 | N3: 1477717709 | O3: 5100000220 | Q3: CUC.NT | T3: 0
A4: =LEFT(F4,3) -> 642 | B4: =_xlfn.XLOOKUP(I4,Mapping!D:D,Mapping!E:E) -> Ban Giám Đốc | C4: =_xlfn.XLOOKUP(F4,Mapping!A:A,Mapping!F:F) -> Lương Chính +T13 | D4: 46053 | E4: 1013795681 | F4: 6421002605 | G4: CP Lương tháng 13, P | H4: 1001101000 | I4: Ban giám đốc | J4: CHI PHÍ LƯƠNG THÁNG 01.2026 | K4: CP LƯƠNGT01.2026 | L4: 1 | M4: 2026 | N4: 147679271 | O4: 5100000220 | Q4: CUC.NT | T4: 0
A5: =LEFT(F5,3) -> 642 | B5: =_xlfn.XLOOKUP(I5,Mapping!D:D,Mapping!E:E) -> Ban Giám Đốc | C5: =_xlfn.XLOOKUP(F5,Mapping!A:A,Mapping!F:F) -> Lương Chính +T13 | D5: 46053 | E5: 1013795738 | F5: 6421002605 | G5: CP Lương tháng 13, P | H5: 1001101000 | I5: Ban giám đốc | J5: TRÍCH LƯƠNG T13, PHÉP NĂM T01.2026 | K5: CP LƯƠNGT01.2026 | L5: 1 | M5: 2026 | N5: 121138496 | O5: 5100000242 | Q5: CUC.NT | T5: 0
A6: =LEFT(F6,3) -> 642 | B6: =_xlfn.XLOOKUP(I6,Mapping!D:D,Mapping!E:E) -> Ban Giám Đốc | C6: =_xlfn.XLOOKUP(F6,Mapping!A:A,Mapping!F:F) -> Thưởng | D6: 46053 | E6: 1013795681 | F6: 6421002802 | G6: Chi phí Khen thưởng | H6: 1001101000 | I6: Ban giám đốc | J6: CHI PHÍ LƯƠNG THÁNG 01.2026 | K6: CP LƯƠNGT01.2026 | L6: 1 | M6: 2026 | N6: 2400000 | O6: 5100000220 | Q6: CUC.NT | T6: 0
A7: =LEFT(F7,3) -> 642 | B7: =_xlfn.XLOOKUP(I7,Mapping!D:D,Mapping!E:E) -> Ban Giám Đốc | C7: =_xlfn.XLOOKUP(F7,Mapping!A:A,Mapping!F:F) -> Thưởng | D7: 46053 | E7: 1013795738 | F7: 6421002806 | G7: Thưởng danh hiệu | H7: 1001101000 | I7: Ban giám đốc | J7: TRÍCH DANH HIỆU T01.2026 | K7: CP LƯƠNGT01.2026 | L7: 1 | M7: 2026 | N7: 111446447 | O7: 5100000242 | Q7: CUC.NT | T7: 0
A8: =LEFT(F8,3) -> 642 | B8: =_xlfn.XLOOKUP(I8,Mapping!D:D,Mapping!E:E) -> Ban Giám Đốc | C8: =_xlfn.XLOOKUP(F8,Mapping!A:A,Mapping!F:F) -> BHXH, BHYT, KPCĐ | D8: 46053 | E8: 1013795740 | F8: 6421003401 | G8: BHXH, BHYT, KPCĐ, BH | H8: 1001101000 | I8: Ban giám đốc | J8: BHXH,BHYT,KPCĐ,BHTN T01.2026 | K8: CP LƯƠNGT01.2026 | L8: 1 | M8: 2026 | N8: 126294310 | O8: 5100000245 | Q8: CUC.NT | T8: 0
A9: =LEFT(F9,3) -> 627 | B9: =_xlfn.XLOOKUP(I9,Mapping!D:D,Mapping!E:E) -> Hành Chánh Nhân Sự | C9: =_xlfn.XLOOKUP(F9,Mapping!A:A,Mapping!F:F) -> Lương Chính +T13 | D9: 46031 | E9: 1013785076 | F9: 6271002604 | G9: CP lương chính-Gián | H9: 1001202000 | I9: Hành chánh nhân sự | J9: TT LƯƠNG 12/2025 CHO TRAN TRUNG HIEU | K9: TT LƯƠNG TV ĐỢT 1 | L9: 1 | M9: 2026 | N9: 8168124 | O9: 5100000060 | Q9: OANH.THT | T9: 0
A10: =LEFT(F10,3) -> 627 | B10: =_xlfn.XLOOKUP(I10,Mapping!D:D,Mapping!E:E) -> Hành Chánh Nhân Sự | C10: =_xlfn.XLOOKUP(F10,Mapping!A:A,Mapping!F:F) -> Lương Chính +T13 | D10: 46031 | E10: 1013785082 | F10: 6271002605 | G10: CP Lương tháng 13, P | H10: 1001202000 | I10: Hành chánh nhân sự | J10: TT LƯƠNG T13/2025 CHO TRẦN TRUNG HIẾU | K10: TT LƯƠNG T13/2025 | L10: 1 | M10: 2026 | N10: 5100000 | O10: 5100000061 | Q10: OANH.THT | T10: 0
A11: =LEFT(F11,3) -> 627 | B11: =_xlfn.XLOOKUP(I11,Mapping!D:D,Mapping!E:E) -> Hành Chánh Nhân Sự | C11: =_xlfn.XLOOKUP(F11,Mapping!A:A,Mapping!F:F) -> Lương Chính +T13 | D11: 46031 | E11: 1013785090 | F11: 6271002604 | G11: CP lương chính-Gián | H11: 1001202000 | I11: Hành chánh nhân sự | J11: TT LƯƠNG TV ĐỢT 1 CHO MAI TRỌNG NGHĨA | K11: TT LƯƠNG TV ĐỢT 1 | L11: 1 | M11: 2026 | N11: 2254833 | O11: 5100000062 | Q11: OANH.THT | T11: 0
A12: =LEFT(F12,3) -> 627 | B12: =_xlfn.XLOOKUP(I12,Mapping!D:D,Mapping!E:E) -> Hành Chánh Nhân Sự | C12: =_xlfn.XLOOKUP(F12,Mapping!A:A,Mapping!F:F) -> Lương Chính +T13 | D12: 46031 | E12: 1013786462 | F12: 6271002604 | G12: CP lương chính-Gián | H12: 1001202000 | I12: Hành chánh nhân sự | J12: TT LƯƠNG 12/2025 CHO TRAN TRUNG HIEU | K12: TT LƯƠNG TV ĐỢT 1 | L12: 1 | M12: 2026 | N12: -8168124 | O12: 8500000058 | P12: X | Q12: CUC.NT | T12: 0
A13: =LEFT(F13,3) -> 627 | B13: =_xlfn.XLOOKUP(I13,Mapping!D:D,Mapping!E:E) -> Hành Chánh Nhân Sự | C13: =_xlfn.XLOOKUP(F13,Mapping!A:A,Mapping!F:F) -> Lương Chính +T13 | D13: 46031 | E13: 1013786463 | F13: 6271002604 | G13: CP lương chính-Gián | H13: 1001202000 | I13: Hành chánh nhân sự | J13: TT LƯƠNG TV ĐỢT 1 CHO MAI TRỌNG NGHĨA | K13: TT LƯƠNG TV ĐỢT 1 | L13: 1 | M13: 2026 | N13: -2254833 | O13: 8500000059 | P13: X | Q13: CUC.NT | T13: 0
A14: =LEFT(F14,3) -> 627 | B14: =_xlfn.XLOOKUP(I14,Mapping!D:D,Mapping!E:E) -> Hành Chánh Nhân Sự | C14: =_xlfn.XLOOKUP(F14,Mapping!A:A,Mapping!F:F) -> Lương Chính +T13 | D14: 46031 | E14: 1013786464 | F14: 6271002605 | G14: CP Lương tháng 13, P | H14: 1001202000 | I14: Hành chánh nhân sự | J14: TT LƯƠNG T13/2025 CHO TRẦN TRUNG HIẾU | K14: TT LƯƠNG T13/2025 | L14: 1 | M14: 2026 | N14: -5100000 | O14: 8500000060 | P14: X | Q14: CUC.NT | T14: 0
A15: =LEFT(F15,3) -> 642 | B15: =_xlfn.XLOOKUP(I15,Mapping!D:D,Mapping!E:E) -> Văn Phòng Giám Đốc | C15: =_xlfn.XLOOKUP(F15,Mapping!A:A,Mapping!F:F) -> Lương Chính +T13 | D15: 46053 | E15: 1013795681 | F15: 6421002604 | G15: CP lương chính-Gián | H15: 1001201000 | I15: Văn phòng giám đốc | J15: CHI PHÍ LƯƠNG THÁNG 01.2026 | K15: CP LƯƠNGT01.2026 | L15: 1 | M15: 2026 | N15: 112024602 | O15: 5100000220 | Q15: CUC.NT | T15: 0
A16: =LEFT(F16,3) -> 642 | B16: =_xlfn.XLOOKUP(I16,Mapping!D:D,Mapping!E:E) -> Văn Phòng Giám Đốc | C16: =_xlfn.XLOOKUP(F16,Mapping!A:A,Mapping!F:F) -> Lương Chính +T13 | D16: 46053 | E16: 1013795681 | F16: 6421002605 | G16: CP Lương tháng 13, P | H16: 1001201000 | I16: Văn phòng giám đốc | J16: CHI PHÍ LƯƠNG THÁNG 01.2026 | K16: CP LƯƠNGT01.2026 | L16: 1 | M16: 2026 | N16: 4950693 | O16: 5100000220 | Q16: CUC.NT | T16: 0
A17: =LEFT(F17,3) -> 642 | B17: =_xlfn.XLOOKUP(I17,Mapping!D:D,Mapping!E:E) -> Văn Phòng Giám Đốc | C17: =_xlfn.XLOOKUP(F17,Mapping!A:A,Mapping!F:F) -> Thưởng | D17: 46053 | E17: 1013795681 | F17: 6421002802 | G17: Chi phí Khen thưởng | H17: 1001201000 | I17: Văn phòng giám đốc | J17: CHI PHÍ LƯƠNG THÁNG 01.2026 | K17: CP LƯƠNGT01.2026 | L17: 1 | M17: 2026 | N17: 800000 | O17: 5100000220 | Q17: CUC.NT | T17: 0
A18: =LEFT(F18,3) -> 642 | B18: =_xlfn.XLOOKUP(I18,Mapping!D:D,Mapping!E:E) -> Hành Chánh Nhân Sự | C18: =_xlfn.XLOOKUP(F18,Mapping!A:A,Mapping!F:F) -> Phụ Cấp | D18: 46053 | E18: 1013795681 | F18: 6421002603 | G18: Phụ cấp ca đêm | H18: 1001202000 | I18: Hành chánh nhân sự | J18: CHI PHÍ LƯƠNG THÁNG 01.2026 | K18: CP LƯƠNGT01.2026 | L18: 1 | M18: 2026 | N18: 8259780 | O18: 5100000220 | Q18: CUC.NT | T18: 0
A19: =LEFT(F19,3) -> 642 | B19: =_xlfn.XLOOKUP(I19,Mapping!D:D,Mapping!E:E) -> Hành Chánh Nhân Sự | C19: =_xlfn.XLOOKUP(F19,Mapping!A:A,Mapping!F:F) -> Lương Chính +T13 | D19: 46053 | E19: 1013795681 | F19: 6421002604 | G19: CP lương chính-Gián | H19: 1001202000 | I19: Hành chánh nhân sự | J19: CHI PHÍ LƯƠNG THÁNG 01.2026 | K19: CP LƯƠNGT01.2026 | L19: 1 | M19: 2026 | N19: 473413349 | O19: 5100000220 | Q19: CUC.NT | T19: 0
A20: =LEFT(F20,3) -> 642 | B20: =_xlfn.XLOOKUP(I20,Mapping!D:D,Mapping!E:E) -> Hành Chánh Nhân Sự | C20: =_xlfn.XLOOKUP(F20,Mapping!A:A,Mapping!F:F) -> Lương Chính +T13 | D20: 46053 | E20: 1013795681 | F20: 6421002605 | G20: CP Lương tháng 13, P | H20: 1001202000 | I20: Hành chánh nhân sự | J20: CHI PHÍ LƯƠNG THÁNG 01.2026 | K20: CP LƯƠNGT01.2026 | L20: 1 | M20: 2026 | N20: 40563830 | O20: 5100000220 | Q20: CUC.NT | T20: 0
A21: =LEFT(F21,3) -> 642 | B21: =_xlfn.XLOOKUP(I21,Mapping!D:D,Mapping!E:E) -> Hành Chánh Nhân Sự | C21: =_xlfn.XLOOKUP(F21,Mapping!A:A,Mapping!F:F) -> Lương Ngoài giờ | D21: 46053 | E21: 1013795681 | F21: 6421002703 | G21: CP lương ngoài giờ-G | H21: 1001202000 | I21: Hành chánh nhân sự | J21: CHI PHÍ LƯƠNG THÁNG 01.2026 | K21: CP LƯƠNGT01.2026 | L21: 1 | M21: 2026 | N21: 88828583 | O21: 5100000220 | Q21: CUC.NT | T21: 0
A22: =LEFT(F22,3) -> 642 | B22: =_xlfn.XLOOKUP(I22,Mapping!D:D,Mapping!E:E) -> Hành Chánh Nhân Sự | C22: =_xlfn.XLOOKUP(F22,Mapping!A:A,Mapping!F:F) -> Thưởng | D22: 46053 | E22: 1013795681 | F22: 6421002802 | G22: Chi phí Khen thưởng | H22: 1001202000 | I22: Hành chánh nhân sự | J22: CHI PHÍ LƯƠNG THÁNG 01.2026 | K22: CP LƯƠNGT01.2026 | L22: 1 | M22: 2026 | N22: 7000000 | O22: 5100000220 | Q22: CUC.NT | T22: 0
A23: =LEFT(F23,3) -> 642 | B23: =_xlfn.XLOOKUP(I23,Mapping!D:D,Mapping!E:E) -> Hành Chánh Nhân Sự | C23: =_xlfn.XLOOKUP(F23,Mapping!A:A,Mapping!F:F) -> Phụ Cấp | D23: 46053 | E23: 1013795681 | F23: 6421003202 | G23: Tiền ăn giữa ca-Gián | H23: 1001202000 | I23: Hành chánh nhân sự | J23: CHI PHÍ LƯƠNG THÁNG 01.2026 | K23: CP LƯƠNGT01.2026 | L23: 1 | M23: 2026 | N23: 3630000 | O23: 5100000220 | Q23: CUC.NT | T23: 0
A24: =LEFT(F24,3) -> 642 | B24: =_xlfn.XLOOKUP(I24,Mapping!D:D,Mapping!E:E) -> Văn Phòng Giám Đốc | C24: =_xlfn.XLOOKUP(F24,Mapping!A:A,Mapping!F:F) -> Lương Chính +T13 | D24: 46053 | E24: 1013795738 | F24: 6421002605 | G24: CP Lương tháng 13, P | H24: 1001201000 | I24: Văn phòng giám đốc | J24: TRÍCH LƯƠNG T13, PHÉP NĂM T01.2026 | K24: CP LƯƠNGT01.2026 | L24: 1 | M24: 2026 | N24: 10234500 | O24: 5100000242 | Q24: CUC.NT | T24: 0
A25: =LEFT(F25,3) -> 642 | B25: =_xlfn.XLOOKUP(I25,Mapping!D:D,Mapping!E:E) -> Văn Phòng Giám Đốc | C25: =_xlfn.XLOOKUP(F25,Mapping!A:A,Mapping!F:F) -> Thưởng | D25: 46053 | E25: 1013795738 | F25: 6421002806 | G25: Thưởng danh hiệu | H25: 1001201000 | I25: Văn phòng giám đốc | J25: TRÍCH DANH HIỆU T01.2026 | K25: CP LƯƠNGT01.2026 | L25: 1 | M25: 2026 | N25: 9415658 | O25: 5100000242 | Q25: CUC.NT | T25: 0
A26: =LEFT(F26,3) -> 642 | B26: =_xlfn.XLOOKUP(I26,Mapping!D:D,Mapping!E:E) -> Hành Chánh Nhân Sự | C26: =_xlfn.XLOOKUP(F26,Mapping!A:A,Mapping!F:F) -> Lương Chính +T13 | D26: 46053 | E26: 1013795738 | F26: 6421002605 | G26: CP Lương tháng 13, P | H26: 1001202000 | I26: Hành chánh nhân sự | J26: TRÍCH LƯƠNG T13, PHÉP NĂM T01.2026 | K26: CP LƯƠNGT01.2026 | L26: 1 | M26: 2026 | N26: 41795750 | O26: 5100000242 | Q26: CUC.NT | T26: 0
... A78: =LEFT(F78,3) -> 641 | B78: =_xlfn.XLOOKUP(I78,Mapping!D:D,Mapping!E:E) -> Kinh doanh | C78: =_xlfn.XLOOKUP(F78,Mapping!A:A,Mapping!F:F) -> Thưởng | D78: 46053 | E78: 1013795917 | F78: 6411002802 | G78: Chi phí Khen thưởng | H78: 1001400000 | I78: Kinh doanh | J78: TRÍCH THƯỞNG NVKD T01/26 | K78: TRÍCH TRƯỚC THƯỞNG PKD | L78: 1 | M78: 2026 | N78: 125000000 | O78: 5100000259 | Q78: MY.DTT | T78: 0
A79: =LEFT(F79,3) -> 641 | B79: =_xlfn.XLOOKUP(I79,Mapping!D:D,Mapping!E:E) -> Kinh doanh | C79: =_xlfn.XLOOKUP(F79,Mapping!A:A,Mapping!F:F) -> Thưởng | D79: 46023 | E79: 1013795926 | F79: 6411002802 | G79: Chi phí Khen thưởng | H79: 1001400000 | I79: Kinh doanh | J79: TRÍCH THƯỞNG PHÒNG KINH DOANH T12/25 | K79: TRÍCH TRƯỚC THƯỞNG PKD | L79: 1 | M79: 2026 | N79: -93802143 | O79: 8500000117 | P79: X | Q79: CUC.NT | T79: 0
A80: =LEFT(F80,3) -> 642 | B80: =_xlfn.XLOOKUP(I80,Mapping!D:D,Mapping!E:E) -> Chiến Lược CCU | C80: =_xlfn.XLOOKUP(F80,Mapping!A:A,Mapping!F:F) -> BHXH, BHYT, KPCĐ | D80: 46053 | E80: 1013795978 | F80: 6421003401 | G80: BHXH, BHYT, KPCĐ, BH | H80: 1001206000 | I80: Chiến Lược CCU | J80: Chuyển cost T01.26 bp cung ứng sang CLCU | K80: Chuyển cost T01.26 | L80: 1 | M80: 2026 | N80: 20035865 | O80: 5100000265 | Q80: CUC.NT | T80: 0
A81: =LEFT(F81,3) -> 642 | B81: =_xlfn.XLOOKUP(I81,Mapping!D:D,Mapping!E:E) -> Chiến Lược CCU | C81: =_xlfn.XLOOKUP(F81,Mapping!A:A,Mapping!F:F) -> Lương Chính +T13 | D81: 46053 | E81: 1013795978 | F81: 6421002604 | G81: CP lương chính-Gián | H81: 1001206000 | I81: Chiến Lược CCU | J81: Chuyển cost T01.26 bp cung ứng sang CLCU | K81: Chuyển cost T01.26 | L81: 1 | M81: 2026 | N81: 76693553 | O81: 5100000265 | Q81: CUC.NT | T81: 0
A82: =LEFT(F82,3) -> 642 | B82: =_xlfn.XLOOKUP(I82,Mapping!D:D,Mapping!E:E) -> Chiến Lược CCU | C82: =_xlfn.XLOOKUP(F82,Mapping!A:A,Mapping!F:F) -> Lương Chính +T13 | D82: 46053 | E82: 1013795978 | F82: 6421002605 | G82: CP Lương tháng 13, P | H82: 1001206000 | I82: Chiến Lược CCU | J82: Chuyển cost T01.26 bp cung ứng sang CLCU | K82: Chuyển cost T01.26 | L82: 1 | M82: 2026 | N82: 9261846 | O82: 5100000265 | Q82: CUC.NT | T82: 0
A83: =LEFT(F83,3) -> 642 | B83: =_xlfn.XLOOKUP(I83,Mapping!D:D,Mapping!E:E) -> Chiến Lược CCU | C83: =_xlfn.XLOOKUP(F83,Mapping!A:A,Mapping!F:F) -> Thưởng | D83: 46053 | E83: 1013795978 | F83: 6421002802 | G83: Chi phí Khen thưởng | H83: 1001206000 | I83: Chiến Lược CCU | J83: Chuyển cost T01.26 bp cung ứng sang CLCU | K83: Chuyển cost T01.26 | L83: 1 | M83: 2026 | N83: 600000 | O83: 5100000265 | Q83: CUC.NT | T83: 0
A84: =LEFT(F84,3) -> 642 | B84: =_xlfn.XLOOKUP(I84,Mapping!D:D,Mapping!E:E) -> Chiến Lược CCU | C84: =_xlfn.XLOOKUP(F84,Mapping!A:A,Mapping!F:F) -> Lương Chính +T13 | D84: 46053 | E84: 1013795978 | F84: 6421002605 | G84: CP Lương tháng 13, P | H84: 1001206000 | I84: Chiến Lược CCU | J84: Chuyển cost T01.26 bp cung ứng sang CLCU | K84: Chuyển cost T01.26 | L84: 1 | M84: 2026 | N84: 7104917 | O84: 5100000265 | Q84: CUC.NT | T84: 0
A85: =LEFT(F85,3) -> 642 | B85: =_xlfn.XLOOKUP(I85,Mapping!D:D,Mapping!E:E) -> Chiến Lược CCU | C85: =_xlfn.XLOOKUP(F85,Mapping!A:A,Mapping!F:F) -> Thưởng | D85: 46053 | E85: 1013795978 | F85: 6421002806 | G85: Thưởng danh hiệu | H85: 1001206000 | I85: Chiến Lược CCU | J85: Chuyển cost T01.26 bp cung ứng sang CLCU | K85: Chuyển cost T01.26 | L85: 1 | M85: 2026 | N85: 6536466 | O85: 5100000265 | Q85: CUC.NT | T85: 0
A86: =LEFT(F86,3) -> 642 | B86: =_xlfn.XLOOKUP(I86,Mapping!D:D,Mapping!E:E) -> Hành Chánh Nhân Sự | C86: =_xlfn.XLOOKUP(F86,Mapping!A:A,Mapping!F:F) -> Phụ Cấp | D86: 46051 | E86: 1013797037 | F86: 6421003202 | G86: Tiền ăn giữa ca-Gián | H86: 1001205000 | I86: Tổ Quản Trị Hệ Thống | J86: chi phí suất ăn - Ba Anh Em tháng 12/2025 | K86: chi phí suất ăn - Ba Anh | L86: 1 | M86: 2026 | N86: 1417000 | O86: 3500000621 | Q86: NHI.NHN | T86: 0
A87: =LEFT(F87,3) -> 642 | B87: =_xlfn.XLOOKUP(I87,Mapping!D:D,Mapping!E:E) -> Hành Chánh Nhân Sự | C87: =_xlfn.XLOOKUP(F87,Mapping!A:A,Mapping!F:F) -> Phụ Cấp | D87: 46051 | E87: 1013797037 | F87: 6421003202 | G87: Tiền ăn giữa ca-Gián | H87: 1001204000 | I87: Tổ 5S & an toàn | J87: chi phí suất ăn - Ba Anh Em tháng 12/2025 | K87: chi phí suất ăn - Ba Anh | L87: 1 | M87: 2026 | N87: 2980000 | O87: 3500000621 | Q87: NHI.NHN | T87: 0
A88: =LEFT(F88,3) -> 642 | B88: =_xlfn.XLOOKUP(I88,Mapping!D:D,Mapping!E:E) -> Hành Chánh Nhân Sự | C88: =_xlfn.XLOOKUP(F88,Mapping!A:A,Mapping!F:F) -> Khen thưởng BD khác | D88: 46053 | E88: 1013797405 | F88: 6421007202 | G88: Khen thưởng BD khác | H88: 1001204000 | I88: Tổ 5S & an toàn | J88: TRÍCH TRƯỚC 5S T01/2026 | K88: TRÍCH TRƯỚC 5S T01.26 | L88: 1 | M88: 2026 | N88: -1500000 | O88: 5100000615 | Q88: BINH.DV | T88: 0
A89: =LEFT(F89,3) -> 642 | B89: =_xlfn.XLOOKUP(I89,Mapping!D:D,Mapping!E:E) -> Cung Ứng | C89: =_xlfn.XLOOKUP(F89,Mapping!A:A,Mapping!F:F) -> Lương Chính +T13 | D89: 46053 | E89: 1013795681 | F89: 6421002604 | G89: CP lương chính-Gián | H89: 1001404000 | I89: Cung ứng | J89: CHI PHÍ LƯƠNG THÁNG 01.2026 | K89: CP LƯƠNGT01.2026 | L89: 1 | M89: 2026 | N89: 544453522 | O89: 5100000220 | Q89: CUC.NT | T89: 0
A90: =LEFT(F90,3) -> 642 | B90: =_xlfn.XLOOKUP(I90,Mapping!D:D,Mapping!E:E) -> Cung Ứng | C90: =_xlfn.XLOOKUP(F90,Mapping!A:A,Mapping!F:F) -> Lương Chính +T13 | D90: 46053 | E90: 1013795681 | F90: 6421002605 | G90: CP Lương tháng 13, P | H90: 1001404000 | I90: Cung ứng | J90: CHI PHÍ LƯƠNG THÁNG 01.2026 | K90: CP LƯƠNGT01.2026 | L90: 1 | M90: 2026 | N90: 32606442 | O90: 5100000220 | Q90: CUC.NT | T90: 0
A91: =LEFT(F91,3) -> 642 | B91: =_xlfn.XLOOKUP(I91,Mapping!D:D,Mapping!E:E) -> Cung Ứng | C91: =_xlfn.XLOOKUP(F91,Mapping!A:A,Mapping!F:F) -> Thưởng | D91: 46053 | E91: 1013795681 | F91: 6421002802 | G91: Chi phí Khen thưởng | H91: 1001404000 | I91: Cung ứng | J91: CHI PHÍ LƯƠNG THÁNG 01.2026 | K91: CP LƯƠNGT01.2026 | L91: 1 | M91: 2026 | N91: 341083228 | O91: 5100000220 | Q91: CUC.NT | T91: 0
...

Sheet 01. CP Nhân sự 
A1: 00. DM | B1: CHI PHÍ NHÂN SỰ 2025
C3: 2026 | N3: =SUM(N19:N189) -> 3.1485771e+12 | O3: =K3/$N$71 -> 0
A4: THÁNG | B4: STT | C4: Bộ phận | D4: Định biên | E4: Lương Chính +T13 | F4: Lương Ngoài giờ | G4: Thưởng | H4: Phụ Cấp | I4: BHXH, BHYT, KPCĐ | J4: Khen thưởng BD khác | K4: Cộng | L4: Tỷ lệ tăng | N4: Doanh thu | O4: % lương / doanh thu
A5: 1 | B5: 1 | C5: Ban Giám Đốc | D5: =VLOOKUP(C5,'02. ĐỊNH BIÊN'!$C$6:$P$48,3,0) -> 12 | E5: =SUMIFS('Data 2026>>'!$N:$N,'Data 2026>>'!$L:$L,'01. CP Nhân sự '!$A5,'Data 2026>>'!$B:$B,'01. CP Nhân sự '!$C5,'Data 2026>>'!$C:$C,'01. CP Nhân sự '!E$4) -> 1746535476 | F5: =SUMIFS('Data 2026>>'!$N:$N,'Data 2026>>'!$L:$L,'01. CP Nhân sự '!$A5,'Data 2026>>'!$B:$B,'01. CP Nhân sự '!$C5,'Data 2026>>'!$C:$C,'01. CP Nhân sự '!F$4) -> 0 | G5: =SUMIFS('Data 2026>>'!$N:$N,'Data 2026>>'!$L:$L,'01. CP Nhân sự '!$A5,'Data 2026>>'!$B:$B,'01. CP Nhân sự '!$C5,'Data 2026>>'!$C:$C,'01. CP Nhân sự '!G$4) -> 113846447 | H5: =SUMIFS('Data 2026>>'!$N:$N,'Data 2026>>'!$L:$L,'01. CP Nhân sự '!$A5,'Data 2026>>'!$B:$B,'01. CP Nhân sự '!$C5,'Data 2026>>'!$C:$C,'01. CP Nhân sự '!H$4) -> 0 | I5: =SUMIFS('Data 2026>>'!$N:$N,'Data 2026>>'!$L:$L,'01. CP Nhân sự '!$A5,'Data 2026>>'!$B:$B,'01. CP Nhân sự '!$C5,'Data 2026>>'!$C:$C,'01. CP Nhân sự '!I$4) -> 126294310 | J5: =SUMIFS('Data 2026>>'!$N:$N,'Data 2026>>'!$L:$L,'01. CP Nhân sự '!$A5,'Data 2026>>'!$B:$B,'01. CP Nhân sự '!$C5,'Data 2026>>'!$C:$C,'01. CP Nhân sự '!J$4) -> 0 | K5: =SUM(E5:J5) -> 1986676233 | O5: =K5/N$19 -> 0.015754888
A6: 1 | B6: 2 | C6: Kinh doanh | D6: =VLOOKUP(C6,'02. ĐỊNH BIÊN'!$C$6:$P$48,3,0) -> 9 | E6: =SUMIFS('Data 2026>>'!$N:$N,'Data 2026>>'!$L:$L,'01. CP Nhân sự '!$A6,'Data 2026>>'!$B:$B,'01. CP Nhân sự '!$C6,'Data 2026>>'!$C:$C,'01. CP Nhân sự '!E$4) -> 318673280 | F6: =SUMIFS('Data 2026>>'!$N:$N,'Data 2026>>'!$L:$L,'01. CP Nhân sự '!$A6,'Data 2026>>'!$B:$B,'01. CP Nhân sự '!$C6,'Data 2026>>'!$C:$C,'01. CP Nhân sự '!F$4) -> 0 | G6: =SUMIFS('Data 2026>>'!$N:$N,'Data 2026>>'!$L:$L,'01. CP Nhân sự '!$A6,'Data 2026>>'!$B:$B,'01. CP Nhân sự '!$C6,'Data 2026>>'!$C:$C,'01. CP Nhân sự '!G$4) -> 154838337 | H6: =SUMIFS('Data 2026>>'!$N:$N,'Data 2026>>'!$L:$L,'01. CP Nhân sự '!$A6,'Data 2026>>'!$B:$B,'01. CP Nhân sự '!$C6,'Data 2026>>'!$C:$C,'01. CP Nhân sự '!H$4) -> 7162000 | I6: =SUMIFS('Data 2026>>'!$N:$N,'Data 2026>>'!$L:$L,'01. CP Nhân sự '!$A6,'Data 2026>>'!$B:$B,'01. CP Nhân sự '!$C6,'Data 2026>>'!$C:$C,'01. CP Nhân sự '!I$4) -> 63587000 | J6: =SUMIFS('Data 2026>>'!$N:$N,'Data 2026>>'!$L:$L,'01. CP Nhân sự '!$A6,'Data 2026>>'!$B:$B,'01. CP Nhân sự '!$C6,'Data 2026>>'!$C:$C,'01. CP Nhân sự '!J$4) -> 0 | K6: =SUM(E6:J6) -> 544260617 | O6: =K6/N$19 -> 0.0043161362
A7: 1 | B7: 3 | C7: Mua Hàng & XNK | D7: =VLOOKUP(C7,'02. ĐỊNH BIÊN'!$C$6:$P$48,3,0) -> 9 | E7: =SUMIFS('Data 2026>>'!$N:$N,'Data 2026>>'!$L:$L,'01. CP Nhân sự '!$A7,'Data 2026>>'!$B:$B,'01. CP Nhân sự '!$C7,'Data 2026>>'!$C:$C,'01. CP Nhân sự '!E$4) -> 201719490 | F7: =SUMIFS('Data 2026>>'!$N:$N,'Data 2026>>'!$L:$L,'01. CP Nhân sự '!$A7,'Data 2026>>'!$B:$B,'01. CP Nhân sự '!$C7,'Data 2026>>'!$C:$C,'01. CP Nhân sự '!F$4) -> 0 | G7: =SUMIFS('Data 2026>>'!$N:$N,'Data 2026>>'!$L:$L,'01. CP Nhân sự '!$A7,'Data 2026>>'!$B:$B,'01. CP Nhân sự '!$C7,'Data 2026>>'!$C:$C,'01. CP Nhân sự '!G$4) -> 17382748 | H7: =SUMIFS('Data 2026>>'!$N:$N,'Data 2026>>'!$L:$L,'01. CP Nhân sự '!$A7,'Data 2026>>'!$B:$B,'01. CP Nhân sự '!$C7,'Data 2026>>'!$C:$C,'01. CP Nhân sự '!H$4) -> 5447000 | I7: =SUMIFS('Data 2026>>'!$N:$N,'Data 2026>>'!$L:$L,'01. CP Nhân sự '!$A7,'Data 2026>>'!$B:$B,'01. CP Nhân sự '!$C7,'Data 2026>>'!$C:$C,'01. CP Nhân sự '!I$4) -> 45919925 | J7: =SUMIFS('Data 2026>>'!$N:$N,'Data 2026>>'!$L:$L,'01. CP Nhân sự '!$A7,'Data 2026>>'!$B:$B,'01. CP Nhân sự '!$C7,'Data 2026>>'!$C:$C,'01. CP Nhân sự '!J$4) -> 0 | K7: =SUM(E7:J7) -> 270469163 | O7: =K7/N$19 -> 0.0021448948
A8: 1 | B8: 4 | C8: Kế Toán | D8: =VLOOKUP(C8,'02. ĐỊNH BIÊN'!$C$6:$P$48,3,0) -> 29 | E8: =SUMIFS('Data 2026>>'!$N:$N,'Data 2026>>'!$L:$L,'01. CP Nhân sự '!$A8,'Data 2026>>'!$B:$B,'01. CP Nhân sự '!$C8,'Data 2026>>'!$C:$C,'01. CP Nhân sự '!E$4) -> 615389473 | F8: =SUMIFS('Data 2026>>'!$N:$N,'Data 2026>>'!$L:$L,'01. CP Nhân sự '!$A8,'Data 2026>>'!$B:$B,'01. CP Nhân sự '!$C8,'Data 2026>>'!$C:$C,'01. CP Nhân sự '!F$4) -> 52518781 | G8: =SUMIFS('Data 2026>>'!$N:$N,'Data 2026>>'!$L:$L,'01. CP Nhân sự '!$A8,'Data 2026>>'!$B:$B,'01. CP Nhân sự '!$C8,'Data 2026>>'!$C:$C,'01. CP Nhân sự '!G$4) -> 48792781 | H8: =SUMIFS('Data 2026>>'!$N:$N,'Data 2026>>'!$L:$L,'01. CP Nhân sự '!$A8,'Data 2026>>'!$B:$B,'01. CP Nhân sự '!$C8,'Data 2026>>'!$C:$C,'01. CP Nhân sự '!H$4) -> 19303000 | I8: =SUMIFS('Data 2026>>'!$N:$N,'Data 2026>>'!$L:$L,'01. CP Nhân sự '!$A8,'Data 2026>>'!$B:$B,'01. CP Nhân sự '!$C8,'Data 2026>>'!$C:$C,'01. CP Nhân sự '!I$4) -> 120509265 | J8: =SUMIFS('Data 2026>>'!$N:$N,'Data 2026>>'!$L:$L,'01. CP Nhân sự '!$A8,'Data 2026>>'!$B:$B,'01. CP Nhân sự '!$C8,'Data 2026>>'!$C:$C,'01. CP Nhân sự '!J$4) -> 1600000 | K8: =SUM(E8:J8) -> 858113300 | O8: =K8/N$19 -> 0.0068050742
A9: 1 | B9: 5 | C9: Nghiên Cứu & Phát Triển | D9: =VLOOKUP(C9,'02. ĐỊNH BIÊN'!$C$6:$P$48,3,0) -> 8 | E9: =SUMIFS('Data 2026>>'!$N:$N,'Data 2026>>'!$L:$L,'01. CP Nhân sự '!$A9,'Data 2026>>'!$B:$B,'01. CP Nhân sự '!$C9,'Data 2026>>'!$C:$C,'01. CP Nhân sự '!E$4) -> 220722113 | F9: =SUMIFS('Data 2026>>'!$N:$N,'Data 2026>>'!$L:$L,'01. CP Nhân sự '!$A9,'Data 2026>>'!$B:$B,'01. CP Nhân sự '!$C9,'Data 2026>>'!$C:$C,'01. CP Nhân sự '!F$4) -> 0 | G9: =SUMIFS('Data 2026>>'!$N:$N,'Data 2026>>'!$L:$L,'01. CP Nhân sự '!$A9,'Data 2026>>'!$B:$B,'01. CP Nhân sự '!$C9,'Data 2026>>'!$C:$C,'01. CP Nhân sự '!G$4) -> 17976241 | H9: =SUMIFS('Data 2026>>'!$N:$N,'Data 2026>>'!$L:$L,'01. CP Nhân sự '!$A9,'Data 2026>>'!$B:$B,'01. CP Nhân sự '!$C9,'Data 2026>>'!$C:$C,'01. CP Nhân sự '!H$4) -> 750000 | I9: =SUMIFS('Data 2026>>'!$N:$N,'Data 2026>>'!$L:$L,'01. CP Nhân sự '!$A9,'Data 2026>>'!$B:$B,'01. CP Nhân sự '!$C9,'Data 2026>>'!$C:$C,'01. CP Nhân sự '!I$4) -> 48086675 | J9: =SUMIFS('Data 2026>>'!$N:$N,'Data 2026>>'!$L:$L,'01. CP Nhân sự '!$A9,'Data 2026>>'!$B:$B,'01. CP Nhân sự '!$C9,'Data 2026>>'!$C:$C,'01. CP Nhân sự '!J$4) -> 0 | K9: =SUM(E9:J9) -> 287535029 | O9: =K9/N$19 -> 0.0022802318
