Workbook

Sheet DM
B3: Tên sheet | C3: Nội dung | D3: Ghi chú
B4: I. TỔNG HỢP
B5: 1. CS Hỗ trợ vận chuyển
B6: 2.1. Thưởng NCC - ver1
B7: 2.2. Thưởng NCC - ver2
B8: 3. DS NCC đồng hành

Sheet I. TỔNG HỢP
A1: Quay lại
B2: MA TRẬN CHÍNH SÁCH GIÁ MUA 3 TRẠM ĐẠI LỘC - ĐỒNG LÂM - KHÁNH NGA
A4: Lưu ý: | B4: Chính sách chỉ áp dụng cho NCC đồng hành
B5: Chính sách có hiệu lực từ 01.01.2026
A7: STT | B7: NỘI DUNG | C7: ĐVT | D7: ĐƠN GIÁ HỖ TRỢ | G7: NỘI DUNG CHÍNH SÁCH | H7: LƯU Ý
D8: ĐẠI LỘC | E8: ĐỒNG LÂM | F8: KHÁNH NGA
A9: 1 | B9: Giá mua | C9: đồng/kg
B10: Chai B0 | C10: đồng/kg | D10: 9500 | E10: 9500 | F10: 9500 | G10: Giá mua đã bao gồm các khoản hỗ trợ phải thấp hơn giá trần TGĐ duyệt từng tháng
A11: 2 | B11: Giá bán về DTR
B12: Chai B1.1, Chai B1.2 | C12: đồng/kg | D12: =D$10+5000 -> 14500 | E12: =E$10+5000 -> 14500 | F12: =F$10+5000 -> 14500 | G12: GAP giữa thành phẩm sv chai B0: + 5.000đ
B13: Chai B2.1, Chai B6.1 | C13: đồng/kg | D13: =D$10+5000 -> 14500 | E13: =E$10+5000 -> 14500 | F13: =F$10+5000 -> 14500 | G13: GAP giữa thành phẩm sv chai B0: + 5.000đ
B14: Chai B2.2, Chai B6.2 | C14: đồng/kg | D14: =D$10+3500 -> 13000 | E14: =E$10+3500 -> 13000 | F14: =F$10+3500 -> 13000 | G14: GAP giữa thành phẩm sv chai B0: + 3.500đ
B15: Chai B4, Chai B5 | C15: đồng/kg | D15: =D$10+2000 -> 11500 | E15: =E$10+2000 -> 11500 | F15: =F$10+2000 -> 11500 | G15: GAP giữa thành phẩm sv chai B0: + 2.000đ
B16: Vảy B6.2 | C16: đồng/kg | D16: =D$10+6500 -> 16000 | E16: =E$10+6500 -> 16000 | F16: =F$10+6500 -> 16000 | G16: GAP giữa thành phẩm sv chai B0: + 6.500đ
B17: Hỗ hợp B6.2 vảy - nắp | C17: đồng/kg | D17: =D$10+1250 -> 10750 | E17: =E$10+1250 -> 10750 | F17: =F$10+1250 -> 10750 | G17: GAP giữa thành phẩm sv chai B0: + 1.250đ
B18: Cổ chai PET | C18: đồng/kg | D18: =D$10-3500 -> 6000 | E18: =E$10-3500 -> 6000 | F18: =F$10-3500 -> 6000 | G18: GAP giữa thành phẩm sv chai B0: - 3.500đ
B19: Nắp HD ép các màu, PP quai | C19: đồng/kg | D19: =D$10-3500 -> 6000 | E19: =E$10-3500 -> 6000 | F19: =F$10-3500 -> 6000 | G19: GAP giữa thành phẩm sv chai B0: - 3.500đ
A20: 3.1 | B20: Chính sách thưởng sản lượng tháng | C20: đồng/kg/tháng | D20: 150 | E20: 150 | F20: 150 | G20: Căn cứ vào mức sản lượng được ký kết trong hợp đồng/Phụ lục/PO Kết quả dựa trên giá trị lũy kế đạt được trong tháng | H20: PL03: Thưởng sản lượng (có quy định sản lượng cam kết giao từng tháng)
A21: 3.2 | B21: Chính sách thưởng sản lượng quý | C21: đồng/kg/quý | D21: 50 | E21: 50 | F21: 50 | G21: Căn cứ vào mức sản lượng được ký kết trong hợp đồng/Phụ lục/PO Kết quả dựa trên giá trị lũy kế đạt được trong quý | H21: PL03: Thưởng sản lượng (có quy định sản lượng cam kết giao từng quý)
A22: 3.3 | B22: Chính sách thưởng sản lượng năm | C22: đồng/kg/năm | D22: 50 | E22: 50 | F22: 50 | G22: Căn cứ vào mức sản lượng được ký kết trong hợp đồng/Phụ lục/PO Kết quả dựa trên giá trị lũy kế đạt được trong năm | H22: PL03: Thưởng sản lượng (có quy định sản lượng cam kết giao từng năm)
A23: 4 | B23: Hỗ trợ vận chuyển | C23: đồng/chuyến | G23: Áp dụng cho NCC nằm trong khu vực được cấp thẩm quyền phê duyệt | H23: PL04: Vận chuyển hàng hóa + NCC tự vận chuyển: Áp dụng theo chính sách định mức hỗ trợ vận chuyển, số hiệu PU-CS-52 + Trạm/DTR tự lấy hàng: Không chi trả khoản hỗ trợ này
A24: 5 | B24: Hỗ trợ bì tạp | C24: %/chuyến | D24: 1 | E24: 1 | F24: 1 | G24: Áp dụng đối với chai B0 ép kiện (không trả bì tạp cho NCC) Tổng số lượng bì tạp sẽ được hỗ trợ tối đa 1% (Đối với chai B0 tròn: trừ bì tạp theo thực tế, trả lại bì tạp cho NCC) | H24: PL02: Thỏa thuận nhập hàng + % bì tạp < 1%: Không trừ bì tạp + % bì tạp > 1%: Trừ 1% bì tạp
A25: 6 | B25: Hỗ trợ chi phí lương cho nhân sự hành chính của đối tác | C25: đồng/tháng/NCC | D25: 5000000 | E25: 5000000 | F25: 5000000 | G25: Khoản hỗ trợ áp dụng theo hình thức khoán trọn gói. không căn cứ trên số lượng nhân sự thực tế Thời gian áp dụng: T01.2026-T06.2026 | H25: PL05: Thỏa thuận hợp tác Chi trả một phần lương mỗi tháng cho nhân viên hành chính (quản lý, kế toán, admin,…) phía NCC để yêu cầu báo cáo và cung cấp dữ liệu tuyến dưới theo yêu cầu
A26: 7 | B26: Bao tiêu sản lượng | C26: dịch vụ/tháng | G26: Cam kết nhận hàng ổn định từ đối tác, được xác định theo hợp đồng/phụ lục đã ký kết | H26: Chính sách nội bộ của DTR
A27: 8 | B27: Hỗ trợ đào tạo huấn luyện về nghiệp vụ và thị trường | C27: linh hoạt | G27: Theo kế hoạch triển khai với đối tác | H27: Chính sách nội bộ của DTR
A28: 9 | B28: Hỗ trợ chi phí thuê mặt bằng | C28: đồng/tháng | D28: 20000000 | E28: 20000000 | F28: 20000000 | G28: Áp dụng cho đối tượng theo danh sách được cấp thẩm quyền phê duyệt Mức hỗ trợ tối đa: 20.000.000 (tùy NCC) Thời gian hỗ trợ: 6 tháng | H28: PL05: Thỏa thuận hợp tác
A29: 10 | B29: Hỗ trợ bảo trì máy móc thiết bị | C29: đồng/quý | D29: 1000000 | E29: 1000000 | F29: 1000000 | G29: Khi đối tác có ký hợp đồng thuê máy móc thiết bị giá 1.000.000đ | H29: Hỏi lại có phát sinh NCC nào được thưởng chưa

Sheet 1. CS Hỗ trợ vận chuyển
A1: Quay lại
B2: ĐỊNH MỨC HỖ TRỢ VẬN CHUYỂN NCC TUYẾN DƯỚI CỦA 3 TRẠM
A4: Lưu ý: | B4: NCC tự vận chuyển: Áp dụng theo chính sách định mức hỗ trợ vận chuyển
B5: Trạm/DTR tự lấy hàng: Không chi trả khoản hỗ trợ này
A7: STT | B7: Khu vực | C7: Tỉnh mới | D7: Tỉnh cũ | E7: Trạm | F7: Khoảng cách trung bình (km) | G7: Cước vận chuyển tham khảo thực tế (đồng/kg) | H7: Mức hỗ trợ (đồng/kg)
A8: =ROWS($A$8:A8) -> 1 | B8: Bắc miền Trung | C8: Quảng Trị | D8: Quảng Trị | E8: Đại Lộc | F8: 1020 | G8: 1000 | H8: 500
A9: =ROWS($A$8:A9) -> 2 | B9: Bắc miền Trung | C9: Quảng Trị | D9: Quảng Bình | E9: Đại Lộc | F9: 1120 | G9: 1000 | H9: 500
A10: =ROWS($A$8:A10) -> 3 | B10: Bắc miền Trung | C10: Huế | D10: Huế | E10: Đại Lộc | F10: 944 | G10: 900 | H10: 500
A11: =ROWS($A$8:A11) -> 4 | B11: Bắc miền Trung | C11: Đà Nẵng | D11: Đà Nẵng | E11: Đại Lộc | F11: 861 | G11: 800 | H11: 500
A12: =ROWS($A$8:A12) -> 5 | B12: Bắc miền Trung | C12: Đà Nẵng | D12: Quảng Nam | E12: Đại Lộc | F12: 838 | G12: 800 | H12: 500
A13: =ROWS($A$8:A13) -> 6 | B13: Bắc miền Trung | C13: Quảng Ngãi | D13: Quảng Ngãi | E13: Đại Lộc | F13: 715 | G13: 700 | H13: 500
A14: =ROWS($A$8:A14) -> 7 | B14: Bắc miền Trung | C14: Quảng Ngãi | D14: Kon Tum | E14: Đại Lộc | F14: 709 | G14: 800 | H14: 500
A15: =ROWS($A$8:A15) -> 8 | B15: Nam miền Trung | C15: Khánh Hòa | D15: Khánh Hòa | E15: Đại Lộc | F15: 336 | G15: 500 | H15: 400
A16: =ROWS($A$8:A16) -> 9 | B16: Nam miền Trung | C16: Khánh Hòa | D16: Ninh Thuận | E16: Đại Lộc | F16: 262 | G16: 400 | H16: 400
A17: =ROWS($A$8:A17) -> 10 | B17: Nam miền Trung | C17: Đak Lak | D17: Đak Lak | E17: Đại Lộc | F17: 321 | G17: 600 | H17: 400
A18: =ROWS($A$8:A18) -> 11 | B18: Nam miền Trung | C18: Đak Lak | D18: Phú Yên | E18: Đại Lộc | F18: 445 | G18: 600 | H18: 400
A19: =ROWS($A$8:A19) -> 12 | B19: Nam miền Trung | C19: Lâm Đồng | D19: Lâm Đồng | E19: Đại Lộc | F19: 232 | G19: 500 | H19: 400
... A42: =ROWS($A$8:A42) -> 35 | B42: TPHCM | C42: TPHCM 3 | D42: Bình Dương | E42: Đại Lộc | F42: 100 | G42: 300 | H42: 300

Sheet 2.1. Thưởng NCC - ver1
A1: Quay lại
B2: THEO DÕI THƯỞNG NCC ĐỒNG HÀNH 3 TRẠM - ver 1
F4: Đvt: tấn | AT4: Đvt: đồng/kg | AW4: Đvt: triệu đồng | BA4: Đvt: đồng/kg | BH4: Đvt: triệu đồng | BY4: Đvt: đồng/kg
A5: STT | B5: Trạm | C5: Mã VMS | D5: NCC | E5: Khu vực | F5: Sản lượng ký kết | R5: Sản lượng thực tế | AD5: Sản lượng NCC tự VC | AP5: % TH sv TT | AT5: Giá mua TB | AW5: Thành tiền mua NVL | BA5: Mức thưởng sản lượng | BD5: Mức hỗ trợ vận chuyển | BH5: Thưởng SL | BK5: Hỗ trợ VC | BN5: Hỗ trợ mặt bằng | BQ5: Hỗ trợ admin | BU5: Tổng hỗ trợ | BY5: Giá mua bao gồm hỗ trợ | CB5: Giá TGĐ duyệt | CE5: Chỉ tiêu quý | CI5: Thực tế quý | CM5: Đơn giá | CN5: Thành tiền
F6: 1 | G6: 2 | H6: 3 | I6: 4 | J6: 5 | K6: 6 | L6: 7 | M6: 8 | N6: 9 | O6: 10 | P6: 11 | Q6: 12 | R6: 1 | S6: 2 | T6: 3 | U6: 4 | V6: 5 | W6: 6 | X6: 7 | Y6: 8 | Z6: 9 | AA6: 10 | AB6: 11 | AC6: 12 | AD6: 1 | AE6: 2 | AF6: 3 | AG6: 4 | AH6: 5 | AI6: 6 | AJ6: 7 | AK6: 8 | AL6: 9 | AM6: 10 | AN6: 11 | AO6: 12 | AP6: 1 | AQ6: 2 | AR6: 3 | AT6: 1 | AU6: 2 | AV6: 3 | AW6: 1 | AX6: 2 | AY6: 3 | BA6: 1 | BB6: 2 | BC6: 3 | BD6: 1 | BE6: 2 | BF6: 3 | BH6: 1 | BI6: 2 | BJ6: 3 | BK6: 1 | BL6: 2 | BM6: 3 | BN6: 1 | BO6: 2 | BP6: 3 | BQ6: 1 | BR6: 2 | BS6: 3 | BU6: 1 | BV6: 2 | BW6: 3 | BY6: 1 | BZ6: 2 | CA6: 3 | CB6: 1 | CC6: 2 | CD6: 3 | CE6: I | CF6: II | CG6: III | CH6: IV | CI6: I | CJ6: II | CK6: III | CL6: IV | CM6: All | CN6: I | CO6: II | CP6: III | CQ6: IV
A7: =ROWS($A$7:A7) -> 1 | B7: Đại Lộc | C7: 001J3000002HLZuIAO | D7: HKD Bùi Văn Dương | E7: Bình Dương | F7: 200 | G7: 100 | H7: 150 | I7: 200 | J7: 200 | K7: 200 | L7: 200 | M7: 200 | N7: 200 | O7: 200 | P7: 200 | Q7: 200 | R7: 286.462 | S7: 279.767 | T7: =143573/10^3 -> 143.573 | AD7: 286.462 | AE7: 279.767 | AF7: 143.573 | AP7: =IFERROR(R7/F7,0) -> 1.43231 | AQ7: =IFERROR(S7/G7,0) -> 2.79767 | AR7: =IFERROR(T7/H7,0) -> 0.95715333 | AT7: 9960.7501 | AU7: 9698.7685 | AW7: =AT7*R7/10^3 -> 2853.3764 | AX7: =AU7*S7/10^3 -> 2713.3954 | BA7: =IF(AP7<95%,0,150) -> 150 | BB7: =IF(AQ7<95%,0,150) -> 150 | BC7: =IF(AR7<95%,0,150) -> 150 | BD7: =_xlfn.XLOOKUP($E7,'1. CS Hỗ trợ vận chuyển'!$D$8:$D$42,'1. CS Hỗ trợ vận chuyển'!$H$8:$H$42) -> 300 | BE7: =_xlfn.XLOOKUP($E7,'1. CS Hỗ trợ vận chuyển'!$D$8:$D$42,'1. CS Hỗ trợ vận chuyển'!$H$8:$H$42) -> 300 | BF7: =_xlfn.XLOOKUP($E7,'1. CS Hỗ trợ vận chuyển'!$D$8:$D$42,'1. CS Hỗ trợ vận chuyển'!$H$8:$H$42) -> 300 | BH7: =BA7*R7/10^3 -> 42.9693 | BI7: =BB7*S7/10^3 -> 41.96505 | BJ7: =BC7*T7/10^3 -> 21.53595 | BK7: =AD7*BD7/10^3 -> 85.9386 | BL7: =AE7*BE7/10^3 -> 83.9301 | BM7: =AF7*BF7/10^3 -> 43.0719 | BU7: =SUM(BH7,BK7,BN7,BQ7) -> 128.9079 | BV7: =SUM(BI7,BL7,BO7,BR7) -> 125.89515 | BW7: =SUM(BJ7,BM7,BP7,BS7) -> 64.60785 | BY7: =IFERROR((SUM(BH7,BK7,BN7,BQ7)+(R7*AT7/10^3))/R7*10^3,0) -> 10410.75 | BZ7: =IFERROR((SUM(BI7,BL7,BO7,BR7)+(S7*AU7/10^3))/S7*10^3,0) -> 10148.768 | CB7: 10000 | CC7: 10000 | CD7: 10000 | CR7: Có note nếu trạm tự vận chuyển thì không tính đơn giá hỗ trợ
A8: =ROWS($A$7:A8) -> 2 | B8: Đại Lộc | C8: 001J3000002HqzBIAS | D8: HKD Vạn Phát | E8: Ninh Thuận | F8: 30 | G8: 30 | H8: 50 | R8: 28.539 | S8: 31.65 | T8: =27878/10^3 -> 27.878 | AD8: 28.539 | AE8: 31.65 | AF8: 27.878 | AP8: =IFERROR(R8/F8,0) -> 0.9513 | AQ8: =IFERROR(S8/G8,0) -> 1.055 | AR8: =IFERROR(T8/H8,0) -> 0.55756 | AT8: 9891.7446 | AU8: 9610.6919 | AW8: =AT8*R8/10^3 -> 282.3005 | AX8: =AU8*S8/10^3 -> 304.1784 | BA8: =IF(AP8<95%,0,150) -> 150 | BB8: =IF(AQ8<95%,0,150) -> 150 | BC8: =IF(AR8<95%,0,150) -> 0 | BD8: =_xlfn.XLOOKUP($E8,'1. CS Hỗ trợ vận chuyển'!$D$8:$D$42,'1. CS Hỗ trợ vận chuyển'!$H$8:$H$42) -> 400 | BE8: =_xlfn.XLOOKUP($E8,'1. CS Hỗ trợ vận chuyển'!$D$8:$D$42,'1. CS Hỗ trợ vận chuyển'!$H$8:$H$42) -> 400 | BF8: =_xlfn.XLOOKUP($E8,'1. CS Hỗ trợ vận chuyển'!$D$8:$D$42,'1. CS Hỗ trợ vận chuyển'!$H$8:$H$42) -> 400 | BH8: =BA8*R8/10^3 -> 4.28085 | BI8: =BB8*S8/10^3 -> 4.7475 | BJ8: =BC8*T8/10^3 -> 0 | BK8: =AD8*BD8/10^3 -> 11.4156 | BL8: =AE8*BE8/10^3 -> 12.66 | BM8: =AF8*BF8/10^3 -> 11.1512 | BU8: =SUM(BH8,BK8,BN8,BQ8) -> 15.69645 | BV8: =SUM(BI8,BL8,BO8,BR8) -> 17.4075 | BW8: =SUM(BJ8,BM8,BP8,BS8) -> 11.1512 | BY8: =IFERROR((SUM(BH8,BK8,BN8,BQ8)+(R8*AT8/10^3))/R8*10^3,0) -> 10441.745 | BZ8: =IFERROR((SUM(BI8,BL8,BO8,BR8)+(S8*AU8/10^3))/S8*10^3,0) -> 10160.692 | CB8: 10000 | CC8: 10000 | CD8: 10000
A9: =ROWS($A$7:A9) -> 3 | B9: Đại Lộc | C9: 001J3000005FztKIAS | D9: HKD Đinh Thị Thúy | E9: Phú Yên | F9: 50 | G9: 30 | H9: 60 | I9: 70 | J9: 90 | K9: 100 | L9: 100 | M9: 100 | N9: 100 | O9: 100 | P9: 100 | Q9: 100 | R9: 62.032 | S9: 32.518 | T9: =78429/10^3 -> 78.429 | AD9: 62.032 | AE9: 32.518 | AF9: 78.429 | AP9: =IFERROR(R9/F9,0) -> 1.24064 | AQ9: =IFERROR(S9/G9,0) -> 1.0839333 | AR9: =IFERROR(T9/H9,0) -> 1.30715 | AT9: 9996.6791 | AU9: 9694.9013 | AW9: =AT9*R9/10^3 -> 620.114 | AX9: =AU9*S9/10^3 -> 315.2588 | BA9: =IF(AP9<95%,0,150) -> 150 | BB9: =IF(AQ9<95%,0,150) -> 150 | BC9: =IF(AR9<95%,0,150) -> 150 | BD9: =_xlfn.XLOOKUP($E9,'1. CS Hỗ trợ vận chuyển'!$D$8:$D$42,'1. CS Hỗ trợ vận chuyển'!$H$8:$H$42) -> 400 | BE9: =_xlfn.XLOOKUP($E9,'1. CS Hỗ trợ vận chuyển'!$D$8:$D$42,'1. CS Hỗ trợ vận chuyển'!$H$8:$H$42) -> 400 | BF9: =_xlfn.XLOOKUP($E9,'1. CS Hỗ trợ vận chuyển'!$D$8:$D$42,'1. CS Hỗ trợ vận chuyển'!$H$8:$H$42) -> 400 | BH9: =BA9*R9/10^3 -> 9.3048 | BI9: =BB9*S9/10^3 -> 4.8777 | BJ9: =BC9*T9/10^3 -> 11.76435 | BK9: =AD9*BD9/10^3 -> 24.8128 | BL9: =AE9*BE9/10^3 -> 13.0072 | BM9: =AF9*BF9/10^3 -> 31.3716 | BU9: =SUM(BH9,BK9,BN9,BQ9) -> 34.1176 | BV9: =SUM(BI9,BL9,BO9,BR9) -> 17.8849 | BW9: =SUM(BJ9,BM9,BP9,BS9) -> 43.13595 | BY9: =IFERROR((SUM(BH9,BK9,BN9,BQ9)+(R9*AT9/10^3))/R9*10^3,0) -> 10546.679 | BZ9: =IFERROR((SUM(BI9,BL9,BO9,BR9)+(S9*AU9/10^3))/S9*10^3,0) -> 10244.901 | CB9: 10000 | CC9: 10000 | CD9: 10000
A10: =ROWS($A$7:A10) -> 4 | B10: Đại Lộc | C10: 001J300000AtDEeIAN | D10: HKD Hoàng Vân - Trần Duy Nhất | E10: Khánh Hòa | F10: 80 | G10: 50 | H10: 80 | I10: 110 | J10: 110 | K10: 120 | L10: 120 | M10: 120 | N10: 120 | O10: 80 | P10: 80 | Q10: 100 | R10: 85.92 | S10: 36.857 | T10: =88111/10^3 -> 88.111 | AD10: 85.92 | AE10: 36.857 | AF10: 88.111 | AP10: =IFERROR(R10/F10,0) -> 1.074 | AQ10: =IFERROR(S10/G10,0) -> 0.73714 | AR10: =IFERROR(T10/H10,0) -> 1.1013875 | AT10: 9704.4693 | AU10: 9369.9514 | AW10: =AT10*R10/10^3 -> 833.808 | AX10: =AU10*S10/10^3 -> 345.3483 | BA10: =IF(AP10<95%,0,150) -> 150 | BB10: =IF(AQ10<95%,0,150) -> 0 | BC10: =IF(AR10<95%,0,150) -> 150 | BD10: =_xlfn.XLOOKUP($E10,'1. CS Hỗ trợ vận chuyển'!$D$8:$D$42,'1. CS Hỗ trợ vận chuyển'!$H$8:$H$42) -> 400 | BE10: =_xlfn.XLOOKUP($E10,'1. CS Hỗ trợ vận chuyển'!$D$8:$D$42,'1. CS Hỗ trợ vận chuyển'!$H$8:$H$42) -> 400 | BF10: =_xlfn.XLOOKUP($E10,'1. CS Hỗ trợ vận chuyển'!$D$8:$D$42,'1. CS Hỗ trợ vận chuyển'!$H$8:$H$42) -> 400 | BH10: =BA10*R10/10^3 -> 12.888 | BI10: =BB10*S10/10^3 -> 0 | BJ10: =BC10*T10/10^3 -> 13.21665 | BK10: =AD10*BD10/10^3 -> 34.368 | BL10: =AE10*BE10/10^3 -> 14.7428 | BM10: =AF10*BF10/10^3 -> 35.2444 | BU10: =SUM(BH10,BK10,BN10,BQ10) -> 47.256 | BV10: =SUM(BI10,BL10,BO10,BR10) -> 14.7428 | BW10: =SUM(BJ10,BM10,BP10,BS10) -> 48.46105 | BY10: =IFERROR((SUM(BH10,BK10,BN10,BQ10)+(R10*AT10/10^3))/R10*10^3,0) -> 10254.469 | BZ10: =IFERROR((SUM(BI10,BL10,BO10,BR10)+(S10*AU10/10^3))/S10*10^3,0) -> 9769.9514 | CB10: 10000 | CC10: 10000 | CD10: 10000
A11: =ROWS($A$7:A11) -> 5 | B11: Đại Lộc | C11: 001J3000002HLfXIAW | D11: HKD Hồ Hoàng | E11: Quảng Nam | F11: 80 | G11: 40 | H11: 60 | I11: 100 | J11: 100 | K11: 100 | L11: 120 | M11: 120 | N11: 120 | O11: 100 | P11: 80 | Q11: 80 | R11: 38.842 | S11: 0 | T11: =40075/10^3 -> 40.075 | AD11: 38.842 | AE11: 0 | AF11: 40.075 | AP11: =IFERROR(R11/F11,0) -> 0.485525 | AQ11: =IFERROR(S11/G11,0) -> 0 | AR11: =IFERROR(T11/H11,0) -> 0.66791667 | AT11: 9659.4485 | AU11: 0 | AW11: =AT11*R11/10^3 -> 375.1923 | AX11: =AU11*S11/10^3 -> 0 | BA11: =IF(AP11<95%,0,150) -> 0 | BB11: =IF(AQ11<95%,0,150) -> 0 | BC11: =IF(AR11<95%,0,150) -> 0 | BD11: =_xlfn.XLOOKUP($E11,'1. CS Hỗ trợ vận chuyển'!$D$8:$D$42,'1. CS Hỗ trợ vận chuyển'!$H$8:$H$42) -> 500 | BE11: =_xlfn.XLOOKUP($E11,'1. CS Hỗ trợ vận chuyển'!$D$8:$D$42,'1. CS Hỗ trợ vận chuyển'!$H$8:$H$42) -> 500 | BF11: =_xlfn.XLOOKUP($E11,'1. CS Hỗ trợ vận chuyển'!$D$8:$D$42,'1. CS Hỗ trợ vận chuyển'!$H$8:$H$42) -> 500 | BH11: =BA11*R11/10^3 -> 0 | BI11: =BB11*S11/10^3 -> 0 | BJ11: =BC11*T11/10^3 -> 0 | BK11: =AD11*BD11/10^3 -> 19.421 | BL11: =AE11*BE11/10^3 -> 0 | BM11: =AF11*BF11/10^3 -> 20.0375 | BU11: =SUM(BH11,BK11,BN11,BQ11) -> 19.421 | BV11: =SUM(BI11,BL11,BO11,BR11) -> 0 | BW11: =SUM(BJ11,BM11,BP11,BS11) -> 20.0375 | BY11: =IFERROR((SUM(BH11,BK11,BN11,BQ11)+(R11*AT11/10^3))/R11*10^3,0) -> 10159.449 | BZ11: =IFERROR((SUM(BI11,BL11,BO11,BR11)+(S11*AU11/10^3))/S11*10^3,0) -> 0 | CB11: 10000 | CC11: 10000 | CD11: 10000
A12: =ROWS($A$7:A12) -> 6 | B12: Đại Lộc | C12: 001J3000002HLjfIAG | D12: HKD Tâm Tường | E12: Quảng Ngãi | F12: 50 | G12: 30 | H12: 60 | I12: 70 | J12: 70 | K12: 70 | L12: 90 | M12: 100 | N12: 100 | O12: 100 | P12: 80 | Q12: 80 | R12: 62.456 | S12: 16.62 | T12: =71823/10^3 -> 71.823 | AD12: 62.456 | AE12: 16.62 | AF12: 71.823 | AP12: =IFERROR(R12/F12,0) -> 1.24912 | AQ12: =IFERROR(S12/G12,0) -> 0.554 | AR12: =IFERROR(T12/H12,0) -> 1.19705 | AT12: 9962.1077 | AU12: 9800 | AW12: =AT12*R12/10^3 -> 622.1934 | AX12: =AU12*S12/10^3 -> 162.876 | BA12: =IF(AP12<95%,0,150) -> 150 | BB12: =IF(AQ12<95%,0,150) -> 0 | BC12: =IF(AR12<95%,0,150) -> 150 | BD12: =_xlfn.XLOOKUP($E12,'1. CS Hỗ trợ vận chuyển'!$D$8:$D$42,'1. CS Hỗ trợ vận chuyển'!$H$8:$H$42) -> 500 | BE12: =_xlfn.XLOOKUP($E12,'1. CS Hỗ trợ vận chuyển'!$D$8:$D$42,'1. CS Hỗ trợ vận chuyển'!$H$8:$H$42) -> 500 | BF12: =_xlfn.XLOOKUP($E12,'1. CS Hỗ trợ vận chuyển'!$D$8:$D$42,'1. CS Hỗ trợ vận chuyển'!$H$8:$H$42) -> 500 | BH12: =BA12*R12/10^3 -> 9.3684 | BI12: =BB12*S12/10^3 -> 0 | BJ12: =BC12*T12/10^3 -> 10.77345 | BK12: =AD12*BD12/10^3 -> 31.228 | BL12: =AE12*BE12/10^3 -> 8.31 | BM12: =AF12*BF12/10^3 -> 35.9115 | BU12: =SUM(BH12,BK12,BN12,BQ12) -> 40.5964 | BV12: =SUM(BI12,BL12,BO12,BR12) -> 8.31 | BW12: =SUM(BJ12,BM12,BP12,BS12) -> 46.68495 | BY12: =IFERROR((SUM(BH12,BK12,BN12,BQ12)+(R12*AT12/10^3))/R12*10^3,0) -> 10612.108 | BZ12: =IFERROR((SUM(BI12,BL12,BO12,BR12)+(S12*AU12/10^3))/S12*10^3,0) -> 10300 | CB12: 10000 | CC12: 10000 | CD12: 10000
A13: =ROWS($A$7:A13) -> 7 | B13: Đại Lộc | C13: 001J3000002HLbQIAW | D13: Thương Viên (Pleiku) | E13: Gia Lai | F13: 80 | G13: 40 | H13: 100 | R13: 136.231 | S13: 47.68 | T13: =131462/10^3 -> 131.462 | AD13: 136.231 | AE13: 47.68 | AF13: 131.462 | AP13: =IFERROR(R13/F13,0) -> 1.7028875 | AQ13: =IFERROR(S13/G13,0) -> 1.192 | AR13: =IFERROR(T13/H13,0) -> 1.31462 | AT13: 10000 | AU13: 9709.633 | AW13: =AT13*R13/10^3 -> 1362.31 | AX13: =AU13*S13/10^3 -> 462.9553 | BA13: =IF(AP13<95%,0,150) -> 150 | BB13: =IF(AQ13<95%,0,150) -> 150 | BC13: =IF(AR13<95%,0,150) -> 150 | BD13: =_xlfn.XLOOKUP($E13,'1. CS Hỗ trợ vận chuyển'!$D$8:$D$42,'1. CS Hỗ trợ vận chuyển'!$H$8:$H$42) -> 500 | BE13: =_xlfn.XLOOKUP($E13,'1. CS Hỗ trợ vận chuyển'!$D$8:$D$42,'1. CS Hỗ trợ vận chuyển'!$H$8:$H$42) -> 500 | BF13: =_xlfn.XLOOKUP($E13,'1. CS Hỗ trợ vận chuyển'!$D$8:$D$42,'1. CS Hỗ trợ vận chuyển'!$H$8:$H$42) -> 500 | BH13: =BA13*R13/10^3 -> 20.43465 | BI13: =BB13*S13/10^3 -> 7.152 | BJ13: =BC13*T13/10^3 -> 19.7193 | BK13: =AD13*BD13/10^3 -> 68.1155 | BL13: =AE13*BE13/10^3 -> 23.84 | BM13: =AF13*BF13/10^3 -> 65.731 | BU13: =SUM(BH13,BK13,BN13,BQ13) -> 88.55015 | BV13: =SUM(BI13,BL13,BO13,BR13) -> 30.992 | BW13: =SUM(BJ13,BM13,BP13,BS13) -> 85.4503 | BY13: =IFERROR((SUM(BH13,BK13,BN13,BQ13)+(R13*AT13/10^3))/R13*10^3,0) -> 10650 | BZ13: =IFERROR((SUM(BI13,BL13,BO13,BR13)+(S13*AU13/10^3))/S13*10^3,0) -> 10359.633 | CB13: 10000 | CC13: 10000 | CD13: 10000
A14: =ROWS($A$7:A14) -> 8 | B14: Đại Lộc | C14: 001J3000002HqzBIAS | D14: Anh Danh (Ninh Thuận) | E14: Ninh Thuận | F14: 15 | R14: 12.453 | S14: 0 | T14: 0 | AD14: 12.453 | AE14: 0 | AF14: 0 | AP14: =IFERROR(R14/F14,0) -> 0.8302 | AQ14: =IFERROR(S14/G14,0) -> 0 | AR14: =IFERROR(T14/H14,0) -> 0 | AW14: =AT14*R14/10^3 -> 0 | AX14: =AU14*S14/10^3 -> 0 | BA14: =IF(AP14<95%,0,150) -> 0 | BB14: =IF(AQ14<95%,0,150) -> 0 | BC14: =IF(AR14<95%,0,150) -> 0 | BD14: =_xlfn.XLOOKUP($E14,'1. CS Hỗ trợ vận chuyển'!$D$8:$D$42,'1. CS Hỗ trợ vận chuyển'!$H$8:$H$42) -> 400 | BE14: =_xlfn.XLOOKUP($E14,'1. CS Hỗ trợ vận chuyển'!$D$8:$D$42,'1. CS Hỗ trợ vận chuyển'!$H$8:$H$42) -> 400 | BF14: =_xlfn.XLOOKUP($E14,'1. CS Hỗ trợ vận chuyển'!$D$8:$D$42,'1. CS Hỗ trợ vận chuyển'!$H$8:$H$42) -> 400 | BH14: =BA14*R14/10^3 -> 0 | BI14: =BB14*S14/10^3 -> 0 | BJ14: =BC14*T14/10^3 -> 0 | BK14: =AD14*BD14/10^3 -> 4.9812 | BL14: =AE14*BE14/10^3 -> 0 | BM14: =AF14*BF14/10^3 -> 0 | BU14: =SUM(BH14,BK14,BN14,BQ14) -> 4.9812 | BV14: =SUM(BI14,BL14,BO14,BR14) -> 0 | BW14: =SUM(BJ14,BM14,BP14,BS14) -> 0
A15: =ROWS($A$7:A15) -> 9 | B15: Đại Lộc | C15: 001J3000002HLlsIAG | D15: HKD Trần Thị Phương | E15: Đà Nẵng | H15: 60 | R15: 0 | S15: 0 | T15: =63790/10^3 -> 63.79 | AD15: 0 | AE15: 0 | AF15: 63.79 | AP15: =IFERROR(R15/F15,0) -> 0 | AQ15: =IFERROR(S15/G15,0) -> 0 | AR15: =IFERROR(T15/H15,0) -> 1.0631667 | AW15: =AT15*R15/10^3 -> 0 | AX15: =AU15*S15/10^3 -> 0 | BA15: =IF(AP15<95%,0,150) -> 0 | BB15: =IF(AQ15<95%,0,150) -> 0 | BC15: =IF(AR15<95%,0,150) -> 150 | BD15: =_xlfn.XLOOKUP($E15,'1. CS Hỗ trợ vận chuyển'!$D$8:$D$42,'1. CS Hỗ trợ vận chuyển'!$H$8:$H$42) -> 500 | BE15: =_xlfn.XLOOKUP($E15,'1. CS Hỗ trợ vận chuyển'!$D$8:$D$42,'1. CS Hỗ trợ vận chuyển'!$H$8:$H$42) -> 500 | BF15: =_xlfn.XLOOKUP($E15,'1. CS Hỗ trợ vận chuyển'!$D$8:$D$42,'1. CS Hỗ trợ vận chuyển'!$H$8:$H$42) -> 500 | BH15: =BA15*R15/10^3 -> 0 | BI15: =BB15*S15/10^3 -> 0 | BJ15: =BC15*T15/10^3 -> 9.5685 | BK15: =AD15*BD15/10^3 -> 0 | BL15: =AE15*BE15/10^3 -> 0 | BM15: =AF15*BF15/10^3 -> 31.895 | BU15: =SUM(BH15,BK15,BN15,BQ15) -> 0 | BV15: =SUM(BI15,BL15,BO15,BR15) -> 0 | BW15: =SUM(BJ15,BM15,BP15,BS15) -> 41.4635
B16: TỔNG ĐẠI LỘC | F16: =SUM(F7:F15) -> 585 | G16: =SUM(G7:G15) -> 320 | H16: =SUM(H7:H15) -> 620 | I16: =SUM(I7:I15) -> 550 | J16: =SUM(J7:J15) -> 570 | K16: =SUM(K7:K15) -> 590 | L16: =SUM(L7:L15) -> 630 | M16: =SUM(M7:M15) -> 640 | ... AO16: =SUM(AO7:AO15) -> 0 | AP16: =IFERROR(R16/F16,0) -> 1.2186923 | AQ16: =IFERROR(S16/G16,0) -> 1.3909125 | AR16: =IFERROR(T16/H16,0) -> 1.04055 | AW16: =SUM(AW7:AW15) -> 6949.2946 | AX16: =SUM(AX7:AX15) -> 4304.0122 | BA16: =SUM(BA7:BA15) -> 900 | BB16: =SUM(BB7:BB15) -> 600 | BC16: =SUM(BC7:BC15) -> 900 | BD16: =SUM(BD7:BD15) -> 3900 | BE16: =SUM(BE7:BE15) -> 3900 | BF16: =SUM(BF7:BF15) -> 3900 | BH16: =SUM(BH7:BH15) -> 99.246 | BI16: =SUM(BI7:BI15) -> 58.74225 | BJ16: =SUM(BJ7:BJ15) -> 86.5782 | BK16: =SUM(BK7:BK15) -> 280.2807 | BL16: =SUM(BL7:BL15) -> 156.4901 | BM16: =SUM(BM7:BM15) -> 274.4141 | BN16: =SUM(BN7:BN15) -> 0 | BO16: =SUM(BO7:BO15) -> 0 | ... BS16: =SUM(BS7:BS15) -> 0 | BU16: =SUM(BU7:BU15) -> 379.5267 | BV16: =SUM(BV7:BV15) -> 215.23235 | BW16: =SUM(BW7:BW15) -> 360.9923
A17: =ROWS($A$7:A17) -> 11 | B17: Đồng Lâm | C17: 001dc000014oE0DAAU | D17: Hộ Kinh Doanh An Tâm | E17: Kiên Giang | F17: 20 | G17: 20 | H17: 30 | I17: 40 | J17: 40 | K17: 40 | L17: 50 | M17: 50 | N17: 50 | O17: 60 | P17: 60 | Q17: 60 | R17: 7.846 | S17: 20.579 | T17: 8.811 | AD17: 7.846 | AE17: 20.579 | AF17: 8.811 | AP17: =IFERROR(R17/F17,0) -> 0.3923 | AQ17: =IFERROR(S17/G17,0) -> 1.02895 | AR17: =IFERROR(T17/H17,0) -> 0.2937 | AT17: 9700 | AU17: 9472.6689 | AW17: =AT17*R17/10^3 -> 76.1062 | AX17: =AU17*S17/10^3 -> 194.93805 | AY17: =AV17*T17/10^3 -> 0 | BA17: =IF(AP17<95%,0,150) -> 0 | BB17: =IF(AQ17<95%,0,150) -> 150 | BC17: =IF(AR17<95%,0,150) -> 0 | BD17: =_xlfn.XLOOKUP($E17,'1. CS Hỗ trợ vận chuyển'!$D$8:$D$42,'1. CS Hỗ trợ vận chuyển'!$H$8:$H$42) -> 400 | BE17: =_xlfn.XLOOKUP($E17,'1. CS Hỗ trợ vận chuyển'!$D$8:$D$42,'1. CS Hỗ trợ vận chuyển'!$H$8:$H$42) -> 400 | BF17: =_xlfn.XLOOKUP($E17,'1. CS Hỗ trợ vận chuyển'!$D$8:$D$42,'1. CS Hỗ trợ vận chuyển'!$H$8:$H$42) -> 400 | BH17: =BA17*R17/10^3 -> 0 | BI17: =BB17*S17/10^3 -> 3.08685 | BJ17: =BC17*T17/10^3 -> 0 | BK17: =AD17*BD17/10^3 -> 3.1384 | BL17: =AE17*BE17/10^3 -> 8.2316 | BM17: =AF17*BF17/10^3 -> 3.5244 | BN17: =10000000/10^6 -> 10 | BO17: =10000000/10^6 -> 10 | BP17: 10 | BQ17: =5000000/10^6 -> 5 | BR17: =5000000/10^6 -> 5 | BS17: 5 | BU17: =SUM(BH17,BK17,BN17,BQ17) -> 18.1384 | BV17: =SUM(BI17,BL17,BO17,BR17) -> 26.31845 | BW17: =SUM(BJ17,BM17,BP17,BS17) -> 18.5244 | BY17: =IFERROR((SUM(BH17,BK17,BN17,BQ17)+(R17*AT17/10^3))/R17*10^3,0) -> 12011.802 | BZ17: =IFERROR((SUM(BI17,BL17,BO17,BR17)+(S17*AU17/10^3))/S17*10^3,0) -> 10751.567 | CB17: 10000 | CC17: 10000 | CD17: 10000 | CE17: =SUM(F17:H17) -> 70 | CI17: =SUM(R17:T17) -> 37.236 | CM17: =IF(OR(CI17/CE17=1,CI17/CE17>1),50,0) -> 0 | CN17: =CI17*CM17*10^3 -> 0
A18: =ROWS($A$7:A18) -> 12 | B18: Đồng Lâm | C18: 001dc000014o4lcAAA | D18: Công Ty TNHH Thiện An Recycling | E18: Cà Mau | F18: 25 | G18: 20 | H18: 40 | I18: 50 | J18: 50 | K18: 50 | L18: 60 | M18: 60 | N18: 60 | O18: 60 | P18: 60 | Q18: 60 | R18: 27.077 | S18: 20.287 | T18: 44.265 | AD18: 0 | AE18: 6.11 | AF18: 0 | AP18: =IFERROR(R18/F18,0) -> 1.08308 | AQ18: =IFERROR(S18/G18,0) -> 1.01435 | AR18: =IFERROR(T18/H18,0) -> 1.106625 | AT18: 9700 | AU18: 9628.8479 | AW18: =AT18*R18/10^3 -> 262.6469 | AX18: =AU18*S18/10^3 -> 195.34044 | AY18: =AV18*T18/10^3 -> 0 | BA18: =IF(AP18<95%,0,150) -> 150 | BB18: =IF(AQ18<95%,0,150) -> 150 | BC18: =IF(AR18<95%,0,150) -> 150 | BD18: =_xlfn.XLOOKUP($E18,'1. CS Hỗ trợ vận chuyển'!$D$8:$D$42,'1. CS Hỗ trợ vận chuyển'!$H$8:$H$42) -> 400 | BE18: =_xlfn.XLOOKUP($E18,'1. CS Hỗ trợ vận chuyển'!$D$8:$D$42,'1. CS Hỗ trợ vận chuyển'!$H$8:$H$42) -> 400 | BF18: =_xlfn.XLOOKUP($E18,'1. CS Hỗ trợ vận chuyển'!$D$8:$D$42,'1. CS Hỗ trợ vận chuyển'!$H$8:$H$42) -> 400 | BH18: =BA18*R18/10^3 -> 4.06155 | BI18: =BB18*S18/10^3 -> 3.04305 | BJ18: =BC18*T18/10^3 -> 6.63975 | BK18: =AD18*BD18/10^3 -> 0 | BL18: =AE18*BE18/10^3 -> 2.444 | BM18: =AF18*BF18/10^3 -> 0 | BN18: =10000000/10^6 -> 10 | BO18: =10000000/10^6 -> 10 | BP18: =10000000/10^6 -> 10 | BQ18: =5000000/10^6 -> 5 | BR18: =5000000/10^6 -> 5 | BS18: =5000000/10^6 -> 5 | BU18: =SUM(BH18,BK18,BN18,BQ18) -> 19.06155 | BV18: =SUM(BI18,BL18,BO18,BR18) -> 20.48705 | BW18: =SUM(BJ18,BM18,BP18,BS18) -> 21.63975 | BY18: =IFERROR((SUM(BH18,BK18,BN18,BQ18)+(R18*AT18/10^3))/R18*10^3,0) -> 10403.976 | BZ18: =IFERROR((SUM(BI18,BL18,BO18,BR18)+(S18*AU18/10^3))/S18*10^3,0) -> 10638.709 | CB18: 10000 | CC18: 10000 | CD18: 10000 | CE18: =SUM(F18:H18) -> 85 | CI18: =SUM(R18:T18) -> 91.629 | CM18: =IF(OR(CI18/CE18=1,CI18/CE18>1),50,0) -> 50 | CN18: =CI18*CM18*10^3 -> 4581450
B19: TỔNG ĐỒNG LÂM | F19: =SUM(F17:F18) -> 45 | G19: =SUM(G17:G18) -> 40 | H19: =SUM(H17:H18) -> 70 | I19: =SUM(I17:I18) -> 90 | J19: =SUM(J17:J18) -> 90 | K19: =SUM(K17:K18) -> 90 | L19: =SUM(L17:L18) -> 110 | M19: =SUM(M17:M18) -> 110 | ... AO19: =SUM(AO17:AO18) -> 0 | AP19: =IFERROR(R19/F19,0) -> 0.77606667 | AQ19: =IFERROR(S19/G19,0) -> 1.02165 | AR19: =IFERROR(T19/H19,0) -> 0.75822857 | AW19: =SUM(AW17:AW18) -> 338.7531 | AX19: =SUM(AX17:AX18) -> 390.27849 | BH19: =SUM(BH17:BH18) -> 4.06155 | BI19: =SUM(BI17:BI18) -> 6.1299 | BJ19: =SUM(BJ17:BJ18) -> 6.63975 | BK19: =SUM(BK17:BK18) -> 3.1384 | BL19: =SUM(BL17:BL18) -> 10.6756 | BM19: =SUM(BM17:BM18) -> 3.5244 | BN19: =SUM(BN17:BN18) -> 20 | BO19: =SUM(BO17:BO18) -> 20 | ... BS19: =SUM(BS17:BS18) -> 10 | BU19: =SUM(BU17:BU18) -> 37.19995 | BV19: =SUM(BV17:BV18) -> 46.8055 | BW19: =SUM(BW17:BW18) -> 40.16415
A20: =ROWS($A$7:A20) -> 14 | B20: Khánh Nga | C20: 001J3000002HLmlIAG | D20: HKD Nguyễn Thị Thúy An | E20: Tây Ninh | F20: 100 | G20: 0 | H20: 0 | I20: 0 | J20: 0 | K20: 0 | L20: 0 | M20: 0 | N20: 0 | O20: 0 | P20: 0 | Q20: 0 | R20: 103.225 | S20: 0 | T20: 0 | AD20: 103.225 | AE20: 0 | AF20: 0 | AP20: =IFERROR(R20/F20,0) -> 1.03225 | AQ20: =IFERROR(S20/G20,0) -> 0 | AR20: =IFERROR(T20/H20,0) -> 0 | AT20: 9700 | AU20: 9615.7426 | AW20: =AT20*R20/10^3 -> 1001.2825 | AX20: =AU20*S20/10^3 -> 0 | BA20: =IF(AP20<95%,0,150) -> 150 | BB20: =IF(AQ20<95%,0,150) -> 0 | BC20: =IF(AR20<95%,0,150) -> 0 | BD20: =_xlfn.XLOOKUP($E20,'1. CS Hỗ trợ vận chuyển'!$D$8:$D$42,'1. CS Hỗ trợ vận chuyển'!$H$8:$H$42) -> 300 | BE20: =_xlfn.XLOOKUP($E20,'1. CS Hỗ trợ vận chuyển'!$D$8:$D$42,'1. CS Hỗ trợ vận chuyển'!$H$8:$H$42) -> 300 | BF20: =_xlfn.XLOOKUP($E20,'1. CS Hỗ trợ vận chuyển'!$D$8:$D$42,'1. CS Hỗ trợ vận chuyển'!$H$8:$H$42) -> 300 | BH20: =BA20*R20/10^3 -> 15.48375 | BI20: =BB20*S20/10^3 -> 0 | BJ20: =BC20*T20/10^3 -> 0 | BK20: =AD20*BD20/10^3 -> 30.9675 | BL20: =AE20*BE20/10^3 -> 0 | BM20: =AF20*BF20/10^3 -> 0 | BN20: 0 | BO20: 0 | BP20: 0 | BQ20: 0 | BR20: 0 | BS20: 0 | BU20: =SUM(BH20,BK20,BN20,BQ20) -> 46.45125 | BV20: =SUM(BI20,BL20,BO20,BR20) -> 0 | BW20: =SUM(BJ20,BM20,BP20,BS20) -> 0 | BY20: =IFERROR((SUM(BH20,BK20,BN20,BQ20)+(R20*AT20/10^3))/R20*10^3,0) -> 10150 | BZ20: =IFERROR((SUM(BI20,BL20,BO20,BR20)+(S20*AU20/10^3))/S20*10^3,0) -> 0 | CB20: 10000 | CC20: 10000 | CD20: 10000 | CE20: =SUM(F20:H20) -> 100 | CI20: =SUM(R20:T20) -> 103.225 | CM20: =IF(OR(CI20/CE20=1,CI20/CE20>1),50,0) -> 50 | CN20: =CI20*CM20*10^3 -> 5161250 | CR20: Từ T2.26 chuyển sang công ty Phước Lộc Tân
B21: Khánh Nga | C21: 001J3000002HLmlIAG | D21: Công ty Phước Lộc Tân | E21: Tây Ninh | F21: 0 | G21: 50 | H21: 100 | I21: 100 | J21: 100 | K21: 100 | L21: 100 | M21: 100 | N21: 100 | O21: 100 | P21: 100 | Q21: 100 | S21: 78.64 | T21: =137630/10^3 -> 137.63 | AE21: 78.64 | AF21: 137.63 | AP21: =IFERROR(R21/F21,0) -> 0 | AQ21: =IFERROR(S21/G21,0) -> 1.5728 | AR21: =IFERROR(T21/H21,0) -> 1.3763 | BA21: =IF(AP21<95%,0,150) -> 0 | BB21: =IF(AQ21<95%,0,150) -> 150 | BC21: =IF(AR21<95%,0,150) -> 150 | BD21: =_xlfn.XLOOKUP($E21,'1. CS Hỗ trợ vận chuyển'!$D$8:$D$42,'1. CS Hỗ trợ vận chuyển'!$H$8:$H$42) -> 300 | BE21: =_xlfn.XLOOKUP($E21,'1. CS Hỗ trợ vận chuyển'!$D$8:$D$42,'1. CS Hỗ trợ vận chuyển'!$H$8:$H$42) -> 300 | BF21: =_xlfn.XLOOKUP($E21,'1. CS Hỗ trợ vận chuyển'!$D$8:$D$42,'1. CS Hỗ trợ vận chuyển'!$H$8:$H$42) -> 300 | BH21: =BA21*R21/10^3 -> 0 | BI21: =BB21*S21/10^3 -> 11.796 | BJ21: =BC21*T21/10^3 -> 20.6445 | BK21: =AD21*BD21/10^3 -> 0 | BL21: =AE21*BE21/10^3 -> 23.592 | BM21: =AF21*BF21/10^3 -> 41.289 | BN21: 0 | BO21: 0 | BP21: 0 | BQ21: 0 | BR21: 0 | BS21: 0 | BU21: =SUM(BH21,BK21,BN21,BQ21) -> 0 | BV21: =SUM(BI21,BL21,BO21,BR21) -> 35.388 | BW21: =SUM(BJ21,BM21,BP21,BS21) -> 61.9335 | CE21: =SUM(F21:H21) -> 150 | CI21: =SUM(R21:T21) -> 216.27 | CM21: =IF(OR(CI21/CE21=1,CI21/CE21>1),50,0) -> 50 | CN21: =CI21*CM21*10^3 -> 10813500
B22: Khánh Nga | C22: 001J3000002HLZuIAO | D22: HKD Bùi Văn Dương | E22: Bình Dương | F22: 0 | G22: 0 | H22: 100 | I22: 100 | J22: 100 | K22: 100 | L22: 100 | M22: 100 | N22: 100 | O22: 100 | P22: 100 | Q22: 100 | T22: =22127/10^3 -> 22.127 | AF22: =22127/10^3 -> 22.127 | AP22: =IFERROR(R22/F22,0) -> 0 | AQ22: =IFERROR(S22/G22,0) -> 0 | AR22: =IFERROR(T22/H22,0) -> 0.22127 | BA22: =IF(AP22<95%,0,150) -> 0 | BB22: =IF(AQ22<95%,0,150) -> 0 | BC22: =IF(AR22<95%,0,150) -> 0 | BD22: =_xlfn.XLOOKUP($E22,'1. CS Hỗ trợ vận chuyển'!$D$8:$D$42,'1. CS Hỗ trợ vận chuyển'!$H$8:$H$42) -> 300 | BE22: =_xlfn.XLOOKUP($E22,'1. CS Hỗ trợ vận chuyển'!$D$8:$D$42,'1. CS Hỗ trợ vận chuyển'!$H$8:$H$42) -> 300 | BF22: =_xlfn.XLOOKUP($E22,'1. CS Hỗ trợ vận chuyển'!$D$8:$D$42,'1. CS Hỗ trợ vận chuyển'!$H$8:$H$42) -> 300 | BH22: =BA22*R22/10^3 -> 0 | BI22: =BB22*S22/10^3 -> 0 | BJ22: =BC22*T22/10^3 -> 0 | BK22: =AD22*BD22/10^3 -> 0 | BL22: =AE22*BE22/10^3 -> 0 | BM22: =AF22*BF22/10^3 -> 6.6381 | BN22: 0 | BO22: 0 | BP22: 0 | BQ22: 0 | BR22: 0 | BS22: 0 | BU22: =SUM(BH22,BK22,BN22,BQ22) -> 0 | BV22: =SUM(BI22,BL22,BO22,BR22) -> 0 | BW22: =SUM(BJ22,BM22,BP22,BS22) -> 6.6381 | CE22: =SUM(F22:H22) -> 100 | CI22: =SUM(R22:T22) -> 22.127 | CM22: =IF(OR(CI22/CE22=1,CI22/CE22>1),50,0) -> 0 | CN22: =CI22*CM22*10^3 -> 0
B23: TỔNG KHÁNH NGA | F23: =SUM(F20:F22) -> 100 | G23: =SUM(G20:G22) -> 50 | H23: =SUM(H20:H22) -> 200 | I23: =SUM(I20:I22) -> 200 | J23: =SUM(J20:J22) -> 200 | K23: =SUM(K20:K22) -> 200 | L23: =SUM(L20:L22) -> 200 | M23: =SUM(M20:M22) -> 200 | ... AO23: =SUM(AO20:AO22) -> 0 | AP23: =IFERROR(R23/F23,0) -> 1.03225 | AQ23: =IFERROR(S23/G23,0) -> 1.5728 | AR23: =IFERROR(T23/H23,0) -> 0.798785 | AW23: =SUM(AW20) -> 1001.2825 | AX23: =SUM(AX20) -> 0 | BH23: =SUM(BH20:BH22) -> 15.48375 | BI23: =SUM(BI20:BI22) -> 11.796 | BJ23: =SUM(BJ20:BJ22) -> 20.6445 | BK23: =SUM(BK20:BK22) -> 30.9675 | BL23: =SUM(BL20:BL22) -> 23.592 | BM23: =SUM(BM20:BM22) -> 47.9271 | BN23: =SUM(BN20:BN22) -> 0 | BO23: =SUM(BO20:BO22) -> 0 | ... BS23: =SUM(BS20:BS22) -> 0 | BU23: =SUM(BU20:BU22) -> 46.45125 | BV23: =SUM(BV20:BV22) -> 35.388 | BW23: =SUM(BW20:BW22) -> 68.5716
B24: TỔNG CỘNG | F24: =SUM(F16,F19,F23) -> 730 | G24: =SUM(G16,G19,G23) -> 410 | H24: =SUM(H16,H19,H23) -> 890 | I24: =SUM(I16,I19,I23) -> 840 | J24: =SUM(J16,J19,J23) -> 860 | K24: =SUM(K16,K19,K23) -> 880 | L24: =SUM(L16,L19,L23) -> 940 | M24: =SUM(M16,M19,M23) -> 950 | ... AO24: =SUM(AO16,AO19,AO23) -> 0 | AP24: =IFERROR(R24/F24,0) -> 1.1658671 | AQ24: =IFERROR(S24/G24,0) -> 1.3770683 | AR24: =IFERROR(T24/H24,0) -> 0.96401573 | AW24: =SUM(AW16,AW19,AW23) -> 8289.3302 | AX24: =SUM(AX16,AX19,AX23) -> 4694.2906 | BH24: =SUM(BH16,BH19,BH23) -> 118.7913 | BI24: =SUM(BI16,BI19,BI23) -> 76.66815 | BJ24: =SUM(BJ16,BJ19,BJ23) -> 113.86245 | BK24: =SUM(BK16,BK19,BK23) -> 314.3866 | BL24: =SUM(BL16,BL19,BL23) -> 190.7577 | BM24: =SUM(BM16,BM19,BM23) -> 325.8656 | BN24: =SUM(BN16,BN19,BN23) -> 20 | BO24: =SUM(BO16,BO19,BO23) -> 20 | ... BS24: =SUM(BS16,BS19,BS23) -> 10 | BU24: =SUM(BU16,BU19,BU23) -> 463.1779 | BV24: =SUM(BV16,BV19,BV23) -> 297.42585 | BW24: =SUM(BW16,BW19,BW23) -> 469.72805
BU27: =SUM(BU24:BW24) -> 1230.3318

Sheet 2.2 Thưởng NCC - ver2
A1: Quay lại
B2: THEO DÕI THƯỞNG NCC ĐỒNG HÀNH 3 TRẠM - ver 2
G4: Đvt: tấn | K4: Đvt: đồng/kg | L4: Đvt: triệu đồng | N4: Đvt: đồng/kg | Q4: Đvt: triệu đồng | W4: Đvt: đồng/kg
A5: STT | B5: Trạm | C5: Mã VMS | D5: Tên NCC | E5: Khu vực | F5: Tháng | G5: Sản lượng ký kết | H5: Sản lượng thực tế | I5: Sản lượng NCC tự VC | J5: % TH sv TT | K5: Giá mua TB | L5: Thành tiền mua NVL | N5: Mức thưởng sản lượng | O5: Mức hỗ trợ vận chuyển | Q5: Thưởng SL | R5: Hỗ trợ VC | S5: Hỗ trợ mặt bằng | T5: Hỗ trợ admin | U5: Tổng hỗ trợ | W5: Giá mua bao gồm hỗ trợ | X5: Giá TGĐ duyệt
A6: =ROWS($A$6:A6) -> 1 | B6: Đại Lộc | C6: 001J3000002HLZuIAO | D6: HKD Bùi Văn Dương | E6: Bình Dương | F6: 1 | G6: {=SUMPRODUCT('2.1. Thưởng NCC - ver1'!$F$7:$Q$24*('2.1. Thưởng NCC - ver1'!$B$7:$B$24='2.2 Thưởng NCC - ver2'!$B6)*('2.1. Thưởng NCC - ver1'!$F$6:$Q$6='2.2 Thưởng NCC - ver2'!$F6)*('2.1. Thưởng NCC - ver1'!$D$7:$D$24='2.2 Thưởng NCC - ver2'!$D6))} -> 200 | H6: {=SUMPRODUCT('2.1. Thưởng NCC - ver1'!$R$7:$AC$24*('2.1. Thưởng NCC - ver1'!$B$7:$B$24='2.2 Thưởng NCC - ver2'!$B6)*('2.1. Thưởng NCC - ver1'!$R$6:$AC$6='2.2 Thưởng NCC - ver2'!$F6)*('2.1. Thưởng NCC - ver1'!$D$7:$D$24='2.2 Thưởng NCC - ver2'!$D6))} -> 286.462 | I6: {=SUMPRODUCT('2.1. Thưởng NCC - ver1'!$AD$7:$AO$24*('2.1. Thưởng NCC - ver1'!$B$7:$B$24='2.2 Thưởng NCC - ver2'!$B6)*('2.1. Thưởng NCC - ver1'!$AD$6:$AO$6='2.2 Thưởng NCC - ver2'!$F6)*('2.1. Thưởng NCC - ver1'!$D$7:$D$24='2.2 Thưởng NCC - ver2'!$D6))} -> 286.462 | J6: =IFERROR(H6/G6,0) -> 1.43231 | K6: 9960.7501 | L6: =K6*H6/10^3 -> 2853.3764 | N6: =IF(J6<95%,0,150) -> 150 | O6: =IF(E6<>"",_xlfn.XLOOKUP($E6,'1. CS Hỗ trợ vận chuyển'!$D$8:$D$42,'1. CS Hỗ trợ vận chuyển'!$H$8:$H$42),0) -> 300 | Q6: =N6*H6/10^3 -> 42.9693 | R6: =I6*O6/10^3 -> 85.9386 | S6: 0 | T6: 0 | U6: =SUM(Q6,R6,S6,T6) -> 128.9079 | W6: =IFERROR((SUM(Q6,R6,S6,T6)+(H6*K6/10^3))/H6*10^3,0) -> 10410.75 | X6: 10000
A7: =ROWS($A$6:A7) -> 2 | B7: Đại Lộc | C7: 001J3000002HqzBIAS | D7: HKD Vạn Phát | E7: Ninh Thuận | F7: 1 | G7: {=SUMPRODUCT('2.1. Thưởng NCC - ver1'!$F$7:$Q$24*('2.1. Thưởng NCC - ver1'!$B$7:$B$24='2.2 Thưởng NCC - ver2'!$B7)*('2.1. Thưởng NCC - ver1'!$F$6:$Q$6='2.2 Thưởng NCC - ver2'!$F7)*('2.1. Thưởng NCC - ver1'!$D$7:$D$24='2.2 Thưởng NCC - ver2'!$D7))} -> 30 | H7: {=SUMPRODUCT('2.1. Thưởng NCC - ver1'!$R$7:$AC$24*('2.1. Thưởng NCC - ver1'!$B$7:$B$24='2.2 Thưởng NCC - ver2'!$B7)*('2.1. Thưởng NCC - ver1'!$R$6:$AC$6='2.2 Thưởng NCC - ver2'!$F7)*('2.1. Thưởng NCC - ver1'!$D$7:$D$24='2.2 Thưởng NCC - ver2'!$D7))} -> 28.539 | I7: {=SUMPRODUCT('2.1. Thưởng NCC - ver1'!$AD$7:$AO$24*('2.1. Thưởng NCC - ver1'!$B$7:$B$24='2.2 Thưởng NCC - ver2'!$B7)*('2.1. Thưởng NCC - ver1'!$AD$6:$AO$6='2.2 Thưởng NCC - ver2'!$F7)*('2.1. Thưởng NCC - ver1'!$D$7:$D$24='2.2 Thưởng NCC - ver2'!$D7))} -> 28.539 | J7: =IFERROR(H7/G7,0) -> 0.9513 | K7: 9891.7446 | L7: =K7*H7/10^3 -> 282.3005 | N7: =IF(J7<95%,0,150) -> 150 | O7: =IF(E7<>"",_xlfn.XLOOKUP($E7,'1. CS Hỗ trợ vận chuyển'!$D$8:$D$42,'1. CS Hỗ trợ vận chuyển'!$H$8:$H$42),0) -> 400 | Q7: =N7*H7/10^3 -> 4.28085 | R7: =I7*O7/10^3 -> 11.4156 | S7: 0 | T7: 0 | U7: =SUM(Q7,R7,S7,T7) -> 15.69645 | W7: =IFERROR((SUM(Q7,R7,S7,T7)+(H7*K7/10^3))/H7*10^3,0) -> 10441.745 | X7: 10000
A8: =ROWS($A$6:A8) -> 3 | B8: Đại Lộc | C8: 001J3000005FztKIAS | D8: HKD Đinh Thị Thúy | E8: Phú Yên | F8: 1 | G8: {=SUMPRODUCT('2.1. Thưởng NCC - ver1'!$F$7:$Q$24*('2.1. Thưởng NCC - ver1'!$B$7:$B$24='2.2 Thưởng NCC - ver2'!$B8)*('2.1. Thưởng NCC - ver1'!$F$6:$Q$6='2.2 Thưởng NCC - ver2'!$F8)*('2.1. Thưởng NCC - ver1'!$D$7:$D$24='2.2 Thưởng NCC - ver2'!$D8))} -> 50 | H8: {=SUMPRODUCT('2.1. Thưởng NCC - ver1'!$R$7:$AC$24*('2.1. Thưởng NCC - ver1'!$B$7:$B$24='2.2 Thưởng NCC - ver2'!$B8)*('2.1. Thưởng NCC - ver1'!$R$6:$AC$6='2.2 Thưởng NCC - ver2'!$F8)*('2.1. Thưởng NCC - ver1'!$D$7:$D$24='2.2 Thưởng NCC - ver2'!$D8))} -> 62.032 | I8: {=SUMPRODUCT('2.1. Thưởng NCC - ver1'!$AD$7:$AO$24*('2.1. Thưởng NCC - ver1'!$B$7:$B$24='2.2 Thưởng NCC - ver2'!$B8)*('2.1. Thưởng NCC - ver1'!$AD$6:$AO$6='2.2 Thưởng NCC - ver2'!$F8)*('2.1. Thưởng NCC - ver1'!$D$7:$D$24='2.2 Thưởng NCC - ver2'!$D8))} -> 62.032 | J8: =IFERROR(H8/G8,0) -> 1.24064 | K8: 9996.6791 | L8: =K8*H8/10^3 -> 620.114 | N8: =IF(J8<95%,0,150) -> 150 | O8: =IF(E8<>"",_xlfn.XLOOKUP($E8,'1. CS Hỗ trợ vận chuyển'!$D$8:$D$42,'1. CS Hỗ trợ vận chuyển'!$H$8:$H$42),0) -> 400 | Q8: =N8*H8/10^3 -> 9.3048 | R8: =I8*O8/10^3 -> 24.8128 | S8: 0 | T8: 0 | U8: =SUM(Q8,R8,S8,T8) -> 34.1176 | W8: =IFERROR((SUM(Q8,R8,S8,T8)+(H8*K8/10^3))/H8*10^3,0) -> 10546.679 | X8: 10000
A9: =ROWS($A$6:A9) -> 4 | B9: Đại Lộc | C9: 001J300000AtDEeIAN | D9: HKD Hoàng Vân - Trần Duy Nhất | E9: Khánh Hòa | F9: 1 | G9: {=SUMPRODUCT('2.1. Thưởng NCC - ver1'!$F$7:$Q$24*('2.1. Thưởng NCC - ver1'!$B$7:$B$24='2.2 Thưởng NCC - ver2'!$B9)*('2.1. Thưởng NCC - ver1'!$F$6:$Q$6='2.2 Thưởng NCC - ver2'!$F9)*('2.1. Thưởng NCC - ver1'!$D$7:$D$24='2.2 Thưởng NCC - ver2'!$D9))} -> 80 | H9: {=SUMPRODUCT('2.1. Thưởng NCC - ver1'!$R$7:$AC$24*('2.1. Thưởng NCC - ver1'!$B$7:$B$24='2.2 Thưởng NCC - ver2'!$B9)*('2.1. Thưởng NCC - ver1'!$R$6:$AC$6='2.2 Thưởng NCC - ver2'!$F9)*('2.1. Thưởng NCC - ver1'!$D$7:$D$24='2.2 Thưởng NCC - ver2'!$D9))} -> 85.92 | I9: {=SUMPRODUCT('2.1. Thưởng NCC - ver1'!$AD$7:$AO$24*('2.1. Thưởng NCC - ver1'!$B$7:$B$24='2.2 Thưởng NCC - ver2'!$B9)*('2.1. Thưởng NCC - ver1'!$AD$6:$AO$6='2.2 Thưởng NCC - ver2'!$F9)*('2.1. Thưởng NCC - ver1'!$D$7:$D$24='2.2 Thưởng NCC - ver2'!$D9))} -> 85.92 | J9: =IFERROR(H9/G9,0) -> 1.074 | K9: 9704.4693 | L9: =K9*H9/10^3 -> 833.808 | N9: =IF(J9<95%,0,150) -> 150 | O9: =IF(E9<>"",_xlfn.XLOOKUP($E9,'1. CS Hỗ trợ vận chuyển'!$D$8:$D$42,'1. CS Hỗ trợ vận chuyển'!$H$8:$H$42),0) -> 400 | Q9: =N9*H9/10^3 -> 12.888 | R9: =I9*O9/10^3 -> 34.368 | S9: 0 | T9: 0 | U9: =SUM(Q9,R9,S9,T9) -> 47.256 | W9: =IFERROR((SUM(Q9,R9,S9,T9)+(H9*K9/10^3))/H9*10^3,0) -> 10254.469 | X9: 10000
A10: =ROWS($A$6:A10) -> 5 | B10: Đại Lộc | C10: 001J3000002HLfXIAW | D10: HKD Hồ Hoàng | E10: Quảng Nam | F10: 1 | G10: {=SUMPRODUCT('2.1. Thưởng NCC - ver1'!$F$7:$Q$24*('2.1. Thưởng NCC - ver1'!$B$7:$B$24='2.2 Thưởng NCC - ver2'!$B10)*('2.1. Thưởng NCC - ver1'!$F$6:$Q$6='2.2 Thưởng NCC - ver2'!$F10)*('2.1. Thưởng NCC - ver1'!$D$7:$D$24='2.2 Thưởng NCC - ver2'!$D10))} -> 80 | H10: {=SUMPRODUCT('2.1. Thưởng NCC - ver1'!$R$7:$AC$24*('2.1. Thưởng NCC - ver1'!$B$7:$B$24='2.2 Thưởng NCC - ver2'!$B10)*('2.1. Thưởng NCC - ver1'!$R$6:$AC$6='2.2 Thưởng NCC - ver2'!$F10)*('2.1. Thưởng NCC - ver1'!$D$7:$D$24='2.2 Thưởng NCC - ver2'!$D10))} -> 38.842 | I10: {=SUMPRODUCT('2.1. Thưởng NCC - ver1'!$AD$7:$AO$24*('2.1. Thưởng NCC - ver1'!$B$7:$B$24='2.2 Thưởng NCC - ver2'!$B10)*('2.1. Thưởng NCC - ver1'!$AD$6:$AO$6='2.2 Thưởng NCC - ver2'!$F10)*('2.1. Thưởng NCC - ver1'!$D$7:$D$24='2.2 Thưởng NCC - ver2'!$D10))} -> 38.842 | J10: =IFERROR(H10/G10,0) -> 0.485525 | K10: 9659.4485 | L10: =K10*H10/10^3 -> 375.1923 | N10: =IF(J10<95%,0,150) -> 0 | O10: =IF(E10<>"",_xlfn.XLOOKUP($E10,'1. CS Hỗ trợ vận chuyển'!$D$8:$D$42,'1. CS Hỗ trợ vận chuyển'!$H$8:$H$42),0) -> 500 | Q10: =N10*H10/10^3 -> 0 | R10: =I10*O10/10^3 -> 19.421 | S10: 0 | T10: 0 | U10: =SUM(Q10,R10,S10,T10) -> 19.421 | W10: =IFERROR((SUM(Q10,R10,S10,T10)+(H10*K10/10^3))/H10*10^3,0) -> 10159.449 | X10: 10000
A11: =ROWS($A$6:A11) -> 6 | B11: Đại Lộc | C11: 001J3000002HLjfIAG | D11: HKD Tâm Tường | E11: Quảng Ngãi | F11: 1 | G11: {=SUMPRODUCT('2.1. Thưởng NCC - ver1'!$F$7:$Q$24*('2.1. Thưởng NCC - ver1'!$B$7:$B$24='2.2 Thưởng NCC - ver2'!$B11)*('2.1. Thưởng NCC - ver1'!$F$6:$Q$6='2.2 Thưởng NCC - ver2'!$F11)*('2.1. Thưởng NCC - ver1'!$D$7:$D$24='2.2 Thưởng NCC - ver2'!$D11))} -> 50 | H11: {=SUMPRODUCT('2.1. Thưởng NCC - ver1'!$R$7:$AC$24*('2.1. Thưởng NCC - ver1'!$B$7:$B$24='2.2 Thưởng NCC - ver2'!$B11)*('2.1. Thưởng NCC - ver1'!$R$6:$AC$6='2.2 Thưởng NCC - ver2'!$F11)*('2.1. Thưởng NCC - ver1'!$D$7:$D$24='2.2 Thưởng NCC - ver2'!$D11))} -> 62.456 | I11: {=SUMPRODUCT('2.1. Thưởng NCC - ver1'!$AD$7:$AO$24*('2.1. Thưởng NCC - ver1'!$B$7:$B$24='2.2 Thưởng NCC - ver2'!$B11)*('2.1. Thưởng NCC - ver1'!$AD$6:$AO$6='2.2 Thưởng NCC - ver2'!$F11)*('2.1. Thưởng NCC - ver1'!$D$7:$D$24='2.2 Thưởng NCC - ver2'!$D11))} -> 62.456 | J11: =IFERROR(H11/G11,0) -> 1.24912 | K11: 9962.1077 | L11: =K11*H11/10^3 -> 622.1934 | N11: =IF(J11<95%,0,150) -> 150 | O11: =IF(E11<>"",_xlfn.XLOOKUP($E11,'1. CS Hỗ trợ vận chuyển'!$D$8:$D$42,'1. CS Hỗ trợ vận chuyển'!$H$8:$H$42),0) -> 500 | Q11: =N11*H11/10^3 -> 9.3684 | R11: =I11*O11/10^3 -> 31.228 | S11: 0 | T11: 0 | U11: =SUM(Q11,R11,S11,T11) -> 40.5964 | W11: =IFERROR((SUM(Q11,R11,S11,T11)+(H11*K11/10^3))/H11*10^3,0) -> 10612.108 | X11: 10000
A12: =ROWS($A$6:A12) -> 7 | B12: Đại Lộc | C12: 001J3000002HLbQIAW | D12: Thương Viên (Pleiku) | E12: Gia Lai | F12: 1 | G12: {=SUMPRODUCT('2.1. Thưởng NCC - ver1'!$F$7:$Q$24*('2.1. Thưởng NCC - ver1'!$B$7:$B$24='2.2 Thưởng NCC - ver2'!$B12)*('2.1. Thưởng NCC - ver1'!$F$6:$Q$6='2.2 Thưởng NCC - ver2'!$F12)*('2.1. Thưởng NCC - ver1'!$D$7:$D$24='2.2 Thưởng NCC - ver2'!$D12))} -> 80 | H12: {=SUMPRODUCT('2.1. Thưởng NCC - ver1'!$R$7:$AC$24*('2.1. Thưởng NCC - ver1'!$B$7:$B$24='2.2 Thưởng NCC - ver2'!$B12)*('2.1. Thưởng NCC - ver1'!$R$6:$AC$6='2.2 Thưởng NCC - ver2'!$F12)*('2.1. Thưởng NCC - ver1'!$D$7:$D$24='2.2 Thưởng NCC - ver2'!$D12))} -> 136.231 | I12: {=SUMPRODUCT('2.1. Thưởng NCC - ver1'!$AD$7:$AO$24*('2.1. Thưởng NCC - ver1'!$B$7:$B$24='2.2 Thưởng NCC - ver2'!$B12)*('2.1. Thưởng NCC - ver1'!$AD$6:$AO$6='2.2 Thưởng NCC - ver2'!$F12)*('2.1. Thưởng NCC - ver1'!$D$7:$D$24='2.2 Thưởng NCC - ver2'!$D12))} -> 136.231 | J12: =IFERROR(H12/G12,0) -> 1.7028875 | K12: 10000 | L12: =K12*H12/10^3 -> 1362.31 | N12: =IF(J12<95%,0,150) -> 150 | O12: =IF(E12<>"",_xlfn.XLOOKUP($E12,'1. CS Hỗ trợ vận chuyển'!$D$8:$D$42,'1. CS Hỗ trợ vận chuyển'!$H$8:$H$42),0) -> 500 | Q12: =N12*H12/10^3 -> 20.43465 | R12: =I12*O12/10^3 -> 68.1155 | S12: 0 | T12: 0 | U12: =SUM(Q12,R12,S12,T12) -> 88.55015 | W12: =IFERROR((SUM(Q12,R12,S12,T12)+(H12*K12/10^3))/H12*10^3,0) -> 10650 | X12: 10000
A13: =ROWS($A$6:A13) -> 8 | B13: Đại Lộc | C13: 001J3000002HqzBIAS | D13: Anh Danh (Ninh Thuận) | E13: Ninh Thuận | F13: 1 | G13: {=SUMPRODUCT('2.1. Thưởng NCC - ver1'!$F$7:$Q$24*('2.1. Thưởng NCC - ver1'!$B$7:$B$24='2.2 Thưởng NCC - ver2'!$B13)*('2.1. Thưởng NCC - ver1'!$F$6:$Q$6='2.2 Thưởng NCC - ver2'!$F13)*('2.1. Thưởng NCC - ver1'!$D$7:$D$24='2.2 Thưởng NCC - ver2'!$D13))} -> 15 | H13: {=SUMPRODUCT('2.1. Thưởng NCC - ver1'!$R$7:$AC$24*('2.1. Thưởng NCC - ver1'!$B$7:$B$24='2.2 Thưởng NCC - ver2'!$B13)*('2.1. Thưởng NCC - ver1'!$R$6:$AC$6='2.2 Thưởng NCC - ver2'!$F13)*('2.1. Thưởng NCC - ver1'!$D$7:$D$24='2.2 Thưởng NCC - ver2'!$D13))} -> 12.453 | I13: {=SUMPRODUCT('2.1. Thưởng NCC - ver1'!$AD$7:$AO$24*('2.1. Thưởng NCC - ver1'!$B$7:$B$24='2.2 Thưởng NCC - ver2'!$B13)*('2.1. Thưởng NCC - ver1'!$AD$6:$AO$6='2.2 Thưởng NCC - ver2'!$F13)*('2.1. Thưởng NCC - ver1'!$D$7:$D$24='2.2 Thưởng NCC - ver2'!$D13))} -> 12.453 | J13: =IFERROR(H13/G13,0) -> 0.8302 | N13: =IF(J13<95%,0,150) -> 0 | O13: =IF(E13<>"",_xlfn.XLOOKUP($E13,'1. CS Hỗ trợ vận chuyển'!$D$8:$D$42,'1. CS Hỗ trợ vận chuyển'!$H$8:$H$42),0) -> 400 | Q13: =N13*H13/10^3 -> 0 | R13: =I13*O13/10^3 -> 4.9812 | S13: 0 | T13: 0 | U13: =SUM(Q13,R13,S13,T13) -> 4.9812
A14: =ROWS($A$6:A14) -> 9 | B14: Đại Lộc | C14: 001J3000002HLlsIAG | D14: HKD Trần Thị Phương | E14: Đà Nẵng | F14: 1 | G14: {=SUMPRODUCT('2.1. Thưởng NCC - ver1'!$F$7:$Q$24*('2.1. Thưởng NCC - ver1'!$B$7:$B$24='2.2 Thưởng NCC - ver2'!$B14)*('2.1. Thưởng NCC - ver1'!$F$6:$Q$6='2.2 Thưởng NCC - ver2'!$F14)*('2.1. Thưởng NCC - ver1'!$D$7:$D$24='2.2 Thưởng NCC - ver2'!$D14))} -> 0 | H14: {=SUMPRODUCT('2.1. Thưởng NCC - ver1'!$R$7:$AC$24*('2.1. Thưởng NCC - ver1'!$B$7:$B$24='2.2 Thưởng NCC - ver2'!$B14)*('2.1. Thưởng NCC - ver1'!$R$6:$AC$6='2.2 Thưởng NCC - ver2'!$F14)*('2.1. Thưởng NCC - ver1'!$D$7:$D$24='2.2 Thưởng NCC - ver2'!$D14))} -> 0 | I14: {=SUMPRODUCT('2.1. Thưởng NCC - ver1'!$AD$7:$AO$24*('2.1. Thưởng NCC - ver1'!$B$7:$B$24='2.2 Thưởng NCC - ver2'!$B14)*('2.1. Thưởng NCC - ver1'!$AD$6:$AO$6='2.2 Thưởng NCC - ver2'!$F14)*('2.1. Thưởng NCC - ver1'!$D$7:$D$24='2.2 Thưởng NCC - ver2'!$D14))} -> 0 | J14: =IFERROR(H14/G14,0) -> 0 | N14: =IF(J14<95%,0,150) -> 0 | O14: =IF(E14<>"",_xlfn.XLOOKUP($E14,'1. CS Hỗ trợ vận chuyển'!$D$8:$D$42,'1. CS Hỗ trợ vận chuyển'!$H$8:$H$42),0) -> 500 | Q14: =N14*H14/10^3 -> 0 | R14: =I14*O14/10^3 -> 0 | S14: 0 | T14: 0 | U14: =SUM(Q14,R14,S14,T14) -> 0
A15: =ROWS($A$6:A15) -> 10 | B15: Đại Lộc | C15: 001J3000002HLZuIAO | D15: HKD Bùi Văn Dương | E15: Bình Dương | F15: 2 | G15: {=SUMPRODUCT('2.1. Thưởng NCC - ver1'!$F$7:$Q$24*('2.1. Thưởng NCC - ver1'!$B$7:$B$24='2.2 Thưởng NCC - ver2'!$B15)*('2.1. Thưởng NCC - ver1'!$F$6:$Q$6='2.2 Thưởng NCC - ver2'!$F15)*('2.1. Thưởng NCC - ver1'!$D$7:$D$24='2.2 Thưởng NCC - ver2'!$D15))} -> 100 | H15: {=SUMPRODUCT('2.1. Thưởng NCC - ver1'!$R$7:$AC$24*('2.1. Thưởng NCC - ver1'!$B$7:$B$24='2.2 Thưởng NCC - ver2'!$B15)*('2.1. Thưởng NCC - ver1'!$R$6:$AC$6='2.2 Thưởng NCC - ver2'!$F15)*('2.1. Thưởng NCC - ver1'!$D$7:$D$24='2.2 Thưởng NCC - ver2'!$D15))} -> 279.767 | I15: {=SUMPRODUCT('2.1. Thưởng NCC - ver1'!$AD$7:$AO$24*('2.1. Thưởng NCC - ver1'!$B$7:$B$24='2.2 Thưởng NCC - ver2'!$B15)*('2.1. Thưởng NCC - ver1'!$AD$6:$AO$6='2.2 Thưởng NCC - ver2'!$F15)*('2.1. Thưởng NCC - ver1'!$D$7:$D$24='2.2 Thưởng NCC - ver2'!$D15))} -> 279.767 | J15: =IFERROR(H15/G15,0) -> 2.79767 | K15: 9698.7685 | L15: =K15*H15/10^3 -> 2713.3954 | N15: =IF(J15<95%,0,150) -> 150 | O15: =IF(E15<>"",_xlfn.XLOOKUP($E15,'1. CS Hỗ trợ vận chuyển'!$D$8:$D$42,'1. CS Hỗ trợ vận chuyển'!$H$8:$H$42),0) -> 300 | Q15: =N15*H15/10^3 -> 41.96505 | R15: =I15*O15/10^3 -> 83.9301 | S15: 0 | T15: 0 | U15: =SUM(Q15,R15,S15,T15) -> 125.89515 | W15: =IFERROR((SUM(Q15,R15,S15,T15)+(H15*K15/10^3))/H15*10^3,0) -> 10148.768 | X15: 10000
A16: =ROWS($A$6:A16) -> 11 | B16: Đại Lộc | C16: 001J3000002HqzBIAS | D16: HKD Vạn Phát | E16: Ninh Thuận | F16: 2 | G16: {=SUMPRODUCT('2.1. Thưởng NCC - ver1'!$F$7:$Q$24*('2.1. Thưởng NCC - ver1'!$B$7:$B$24='2.2 Thưởng NCC - ver2'!$B16)*('2.1. Thưởng NCC - ver1'!$F$6:$Q$6='2.2 Thưởng NCC - ver2'!$F16)*('2.1. Thưởng NCC - ver1'!$D$7:$D$24='2.2 Thưởng NCC - ver2'!$D16))} -> 30 | H16: {=SUMPRODUCT('2.1. Thưởng NCC - ver1'!$R$7:$AC$24*('2.1. Thưởng NCC - ver1'!$B$7:$B$24='2.2 Thưởng NCC - ver2'!$B16)*('2.1. Thưởng NCC - ver1'!$R$6:$AC$6='2.2 Thưởng NCC - ver2'!$F16)*('2.1. Thưởng NCC - ver1'!$D$7:$D$24='2.2 Thưởng NCC - ver2'!$D16))} -> 31.65 | I16: {=SUMPRODUCT('2.1. Thưởng NCC - ver1'!$AD$7:$AO$24*('2.1. Thưởng NCC - ver1'!$B$7:$B$24='2.2 Thưởng NCC - ver2'!$B16)*('2.1. Thưởng NCC - ver1'!$AD$6:$AO$6='2.2 Thưởng NCC - ver2'!$F16)*('2.1. Thưởng NCC - ver1'!$D$7:$D$24='2.2 Thưởng NCC - ver2'!$D16))} -> 31.65 | J16: =IFERROR(H16/G16,0) -> 1.055 | K16: 9610.6919 | L16: =K16*H16/10^3 -> 304.1784 | N16: =IF(J16<95%,0,150) -> 150 | O16: =IF(E16<>"",_xlfn.XLOOKUP($E16,'1. CS Hỗ trợ vận chuyển'!$D$8:$D$42,'1. CS Hỗ trợ vận chuyển'!$H$8:$H$42),0) -> 400 | Q16: =N16*H16/10^3 -> 4.7475 | R16: =I16*O16/10^3 -> 12.66 | S16: 0 | T16: 0 | U16: =SUM(Q16,R16,S16,T16) -> 17.4075 | W16: =IFERROR((SUM(Q16,R16,S16,T16)+(H16*K16/10^3))/H16*10^3,0) -> 10160.692 | X16: 10000
A17: =ROWS($A$6:A17) -> 12 | B17: Đại Lộc | C17: 001J3000005FztKIAS | D17: HKD Đinh Thị Thúy | E17: Phú Yên | F17: 2 | G17: {=SUMPRODUCT('2.1. Thưởng NCC - ver1'!$F$7:$Q$24*('2.1. Thưởng NCC - ver1'!$B$7:$B$24='2.2 Thưởng NCC - ver2'!$B17)*('2.1. Thưởng NCC - ver1'!$F$6:$Q$6='2.2 Thưởng NCC - ver2'!$F17)*('2.1. Thưởng NCC - ver1'!$D$7:$D$24='2.2 Thưởng NCC - ver2'!$D17))} -> 30 | H17: {=SUMPRODUCT('2.1. Thưởng NCC - ver1'!$R$7:$AC$24*('2.1. Thưởng NCC - ver1'!$B$7:$B$24='2.2 Thưởng NCC - ver2'!$B17)*('2.1. Thưởng NCC - ver1'!$R$6:$AC$6='2.2 Thưởng NCC - ver2'!$F17)*('2.1. Thưởng NCC - ver1'!$D$7:$D$24='2.2 Thưởng NCC - ver2'!$D17))} -> 32.518 | I17: {=SUMPRODUCT('2.1. Thưởng NCC - ver1'!$AD$7:$AO$24*('2.1. Thưởng NCC - ver1'!$B$7:$B$24='2.2 Thưởng NCC - ver2'!$B17)*('2.1. Thưởng NCC - ver1'!$AD$6:$AO$6='2.2 Thưởng NCC - ver2'!$F17)*('2.1. Thưởng NCC - ver1'!$D$7:$D$24='2.2 Thưởng NCC - ver2'!$D17))} -> 32.518 | J17: =IFERROR(H17/G17,0) -> 1.0839333 | K17: 9694.9013 | L17: =K17*H17/10^3 -> 315.2588 | N17: =IF(J17<95%,0,150) -> 150 | O17: =IF(E17<>"",_xlfn.XLOOKUP($E17,'1. CS Hỗ trợ vận chuyển'!$D$8:$D$42,'1. CS Hỗ trợ vận chuyển'!$H$8:$H$42),0) -> 400 | Q17: =N17*H17/10^3 -> 4.8777 | R17: =I17*O17/10^3 -> 13.0072 | S17: 0 | T17: 0 | U17: =SUM(Q17,R17,S17,T17) -> 17.8849 | W17: =IFERROR((SUM(Q17,R17,S17,T17)+(H17*K17/10^3))/H17*10^3,0) -> 10244.901 | X17: 10000
A18: =ROWS($A$6:A18) -> 13 | B18: Đại Lộc | C18: 001J300000AtDEeIAN | D18: HKD Hoàng Vân - Trần Duy Nhất | E18: Khánh Hòa | F18: 2 | G18: {=SUMPRODUCT('2.1. Thưởng NCC - ver1'!$F$7:$Q$24*('2.1. Thưởng NCC - ver1'!$B$7:$B$24='2.2 Thưởng NCC - ver2'!$B18)*('2.1. Thưởng NCC - ver1'!$F$6:$Q$6='2.2 Thưởng NCC - ver2'!$F18)*('2.1. Thưởng NCC - ver1'!$D$7:$D$24='2.2 Thưởng NCC - ver2'!$D18))} -> 50 | H18: {=SUMPRODUCT('2.1. Thưởng NCC - ver1'!$R$7:$AC$24*('2.1. Thưởng NCC - ver1'!$B$7:$B$24='2.2 Thưởng NCC - ver2'!$B18)*('2.1. Thưởng NCC - ver1'!$R$6:$AC$6='2.2 Thưởng NCC - ver2'!$F18)*('2.1. Thưởng NCC - ver1'!$D$7:$D$24='2.2 Thưởng NCC - ver2'!$D18))} -> 36.857 | I18: {=SUMPRODUCT('2.1. Thưởng NCC - ver1'!$AD$7:$AO$24*('2.1. Thưởng NCC - ver1'!$B$7:$B$24='2.2 Thưởng NCC - ver2'!$B18)*('2.1. Thưởng NCC - ver1'!$AD$6:$AO$6='2.2 Thưởng NCC - ver2'!$F18)*('2.1. Thưởng NCC - ver1'!$D$7:$D$24='2.2 Thưởng NCC - ver2'!$D18))} -> 36.857 | J18: =IFERROR(H18/G18,0) -> 0.73714 | K18: 9369.9514 | L18: =K18*H18/10^3 -> 345.3483 | N18: =IF(J18<95%,0,150) -> 0 | O18: =IF(E18<>"",_xlfn.XLOOKUP($E18,'1. CS Hỗ trợ vận chuyển'!$D$8:$D$42,'1. CS Hỗ trợ vận chuyển'!$H$8:$H$42),0) -> 400 | Q18: =N18*H18/10^3 -> 0 | R18: =I18*O18/10^3 -> 14.7428 | S18: 0 | T18: 0 | U18: =SUM(Q18,R18,S18,T18) -> 14.7428 | W18: =IFERROR((SUM(Q18,R18,S18,T18)+(H18*K18/10^3))/H18*10^3,0) -> 9769.9514 | X18: 10000
A19: =ROWS($A$6:A19) -> 14 | B19: Đại Lộc | C19: 001J3000002HLfXIAW | D19: HKD Hồ Hoàng | E19: Quảng Nam | F19: 2 | G19: {=SUMPRODUCT('2.1. Thưởng NCC - ver1'!$F$7:$Q$24*('2.1. Thưởng NCC - ver1'!$B$7:$B$24='2.2 Thưởng NCC - ver2'!$B19)*('2.1. Thưởng NCC - ver1'!$F$6:$Q$6='2.2 Thưởng NCC - ver2'!$F19)*('2.1. Thưởng NCC - ver1'!$D$7:$D$24='2.2 Thưởng NCC - ver2'!$D19))} -> 40 | H19: {=SUMPRODUCT('2.1. Thưởng NCC - ver1'!$R$7:$AC$24*('2.1. Thưởng NCC - ver1'!$B$7:$B$24='2.2 Thưởng NCC - ver2'!$B19)*('2.1. Thưởng NCC - ver1'!$R$6:$AC$6='2.2 Thưởng NCC - ver2'!$F19)*('2.1. Thưởng NCC - ver1'!$D$7:$D$24='2.2 Thưởng NCC - ver2'!$D19))} -> 0 | I19: {=SUMPRODUCT('2.1. Thưởng NCC - ver1'!$AD$7:$AO$24*('2.1. Thưởng NCC - ver1'!$B$7:$B$24='2.2 Thưởng NCC - ver2'!$B19)*('2.1. Thưởng NCC - ver1'!$AD$6:$AO$6='2.2 Thưởng NCC - ver2'!$F19)*('2.1. Thưởng NCC - ver1'!$D$7:$D$24='2.2 Thưởng NCC - ver2'!$D19))} -> 0 | J19: =IFERROR(H19/G19,0) -> 0 | K19: 0 | L19: =K19*H19/10^3 -> 0 | N19: =IF(J19<95%,0,150) -> 0 | O19: =IF(E19<>"",_xlfn.XLOOKUP($E19,'1. CS Hỗ trợ vận chuyển'!$D$8:$D$42,'1. CS Hỗ trợ vận chuyển'!$H$8:$H$42),0) -> 500 | Q19: =N19*H19/10^3 -> 0 | R19: =I19*O19/10^3 -> 0 | S19: 0 | T19: 0 | U19: =SUM(Q19,R19,S19,T19) -> 0 | W19: =IFERROR((SUM(Q19,R19,S19,T19)+(H19*K19/10^3))/H19*10^3,0) -> 0 | X19: 10000
A20: =ROWS($A$6:A20) -> 15 | B20: Đại Lộc | C20: 001J3000002HLjfIAG | D20: HKD Tâm Tường | E20: Quảng Ngãi | F20: 2 | G20: {=SUMPRODUCT('2.1. Thưởng NCC - ver1'!$F$7:$Q$24*('2.1. Thưởng NCC - ver1'!$B$7:$B$24='2.2 Thưởng NCC - ver2'!$B20)*('2.1. Thưởng NCC - ver1'!$F$6:$Q$6='2.2 Thưởng NCC - ver2'!$F20)*('2.1. Thưởng NCC - ver1'!$D$7:$D$24='2.2 Thưởng NCC - ver2'!$D20))} -> 30 | H20: {=SUMPRODUCT('2.1. Thưởng NCC - ver1'!$R$7:$AC$24*('2.1. Thưởng NCC - ver1'!$B$7:$B$24='2.2 Thưởng NCC - ver2'!$B20)*('2.1. Thưởng NCC - ver1'!$R$6:$AC$6='2.2 Thưởng NCC - ver2'!$F20)*('2.1. Thưởng NCC - ver1'!$D$7:$D$24='2.2 Thưởng NCC - ver2'!$D20))} -> 16.62 | I20: {=SUMPRODUCT('2.1. Thưởng NCC - ver1'!$AD$7:$AO$24*('2.1. Thưởng NCC - ver1'!$B$7:$B$24='2.2 Thưởng NCC - ver2'!$B20)*('2.1. Thưởng NCC - ver1'!$AD$6:$AO$6='2.2 Thưởng NCC - ver2'!$F20)*('2.1. Thưởng NCC - ver1'!$D$7:$D$24='2.2 Thưởng NCC - ver2'!$D20))} -> 16.62 | J20: =IFERROR(H20/G20,0) -> 0.554 | K20: 9800 | L20: =K20*H20/10^3 -> 162.876 | N20: =IF(J20<95%,0,150) -> 0 | O20: =IF(E20<>"",_xlfn.XLOOKUP($E20,'1. CS Hỗ trợ vận chuyển'!$D$8:$D$42,'1. CS Hỗ trợ vận chuyển'!$H$8:$H$42),0) -> 500 | Q20: =N20*H20/10^3 -> 0 | R20: =I20*O20/10^3 -> 8.31 | S20: 0 | T20: 0 | U20: =SUM(Q20,R20,S20,T20) -> 8.31 | W20: =IFERROR((SUM(Q20,R20,S20,T20)+(H20*K20/10^3))/H20*10^3,0) -> 10300 | X20: 10000
A21: =ROWS($A$6:A21) -> 16 | B21: Đại Lộc | C21: 001J3000002HLbQIAW | D21: Thương Viên (Pleiku) | E21: Gia Lai | F21: 2 | G21: {=SUMPRODUCT('2.1. Thưởng NCC - ver1'!$F$7:$Q$24*('2.1. Thưởng NCC - ver1'!$B$7:$B$24='2.2 Thưởng NCC - ver2'!$B21)*('2.1. Thưởng NCC - ver1'!$F$6:$Q$6='2.2 Thưởng NCC - ver2'!$F21)*('2.1. Thưởng NCC - ver1'!$D$7:$D$24='2.2 Thưởng NCC - ver2'!$D21))} -> 40 | H21: {=SUMPRODUCT('2.1. Thưởng NCC - ver1'!$R$7:$AC$24*('2.1. Thưởng NCC - ver1'!$B$7:$B$24='2.2 Thưởng NCC - ver2'!$B21)*('2.1. Thưởng NCC - ver1'!$R$6:$AC$6='2.2 Thưởng NCC - ver2'!$F21)*('2.1. Thưởng NCC - ver1'!$D$7:$D$24='2.2 Thưởng NCC - ver2'!$D21))} -> 47.68 | I21: {=SUMPRODUCT('2.1. Thưởng NCC - ver1'!$AD$7:$AO$24*('2.1. Thưởng NCC - ver1'!$B$7:$B$24='2.2 Thưởng NCC - ver2'!$B21)*('2.1. Thưởng NCC - ver1'!$AD$6:$AO$6='2.2 Thưởng NCC - ver2'!$F21)*('2.1. Thưởng NCC - ver1'!$D$7:$D$24='2.2 Thưởng NCC - ver2'!$D21))} -> 47.68 | J21: =IFERROR(H21/G21,0) -> 1.192 | K21: 9709.633 | L21: =K21*H21/10^3 -> 462.9553 | N21: =IF(J21<95%,0,150) -> 150 | O21: =IF(E21<>"",_xlfn.XLOOKUP($E21,'1. CS Hỗ trợ vận chuyển'!$D$8:$D$42,'1. CS Hỗ trợ vận chuyển'!$H$8:$H$42),0) -> 500 | Q21: =N21*H21/10^3 -> 7.152 | R21: =I21*O21/10^3 -> 23.84 | S21: 0 | T21: 0 | U21: =SUM(Q21,R21,S21,T21) -> 30.992 | W21: =IFERROR((SUM(Q21,R21,S21,T21)+(H21*K21/10^3))/H21*10^3,0) -> 10359.633 | X21: 10000
A22: =ROWS($A$6:A22) -> 17 | B22: Đại Lộc | C22: 001J3000002HqzBIAS | D22: Anh Danh (Ninh Thuận) | E22: Ninh Thuận | F22: 2 | G22: {=SUMPRODUCT('2.1. Thưởng NCC - ver1'!$F$7:$Q$24*('2.1. Thưởng NCC - ver1'!$B$7:$B$24='2.2 Thưởng NCC - ver2'!$B22)*('2.1. Thưởng NCC - ver1'!$F$6:$Q$6='2.2 Thưởng NCC - ver2'!$F22)*('2.1. Thưởng NCC - ver1'!$D$7:$D$24='2.2 Thưởng NCC - ver2'!$D22))} -> 0 | H22: {=SUMPRODUCT('2.1. Thưởng NCC - ver1'!$R$7:$AC$24*('2.1. Thưởng NCC - ver1'!$B$7:$B$24='2.2 Thưởng NCC - ver2'!$B22)*('2.1. Thưởng NCC - ver1'!$R$6:$AC$6='2.2 Thưởng NCC - ver2'!$F22)*('2.1. Thưởng NCC - ver1'!$D$7:$D$24='2.2 Thưởng NCC - ver2'!$D22))} -> 0 | I22: {=SUMPRODUCT('2.1. Thưởng NCC - ver1'!$AD$7:$AO$24*('2.1. Thưởng NCC - ver1'!$B$7:$B$24='2.2 Thưởng NCC - ver2'!$B22)*('2.1. Thưởng NCC - ver1'!$AD$6:$AO$6='2.2 Thưởng NCC - ver2'!$F22)*('2.1. Thưởng NCC - ver1'!$D$7:$D$24='2.2 Thưởng NCC - ver2'!$D22))} -> 0 | J22: =IFERROR(H22/G22,0) -> 0 | N22: =IF(J22<95%,0,150) -> 0 | O22: =IF(E22<>"",_xlfn.XLOOKUP($E22,'1. CS Hỗ trợ vận chuyển'!$D$8:$D$42,'1. CS Hỗ trợ vận chuyển'!$H$8:$H$42),0) -> 400 | Q22: =N22*H22/10^3 -> 0 | R22: =I22*O22/10^3 -> 0 | S22: 0 | T22: 0 | U22: =SUM(Q22,R22,S22,T22) -> 0
A23: =ROWS($A$6:A23) -> 18 | B23: Đại Lộc | C23: 001J3000002HLlsIAG | D23: HKD Trần Thị Phương | E23: Đà Nẵng | F23: 2 | G23: {=SUMPRODUCT('2.1. Thưởng NCC - ver1'!$F$7:$Q$24*('2.1. Thưởng NCC - ver1'!$B$7:$B$24='2.2 Thưởng NCC - ver2'!$B23)*('2.1. Thưởng NCC - ver1'!$F$6:$Q$6='2.2 Thưởng NCC - ver2'!$F23)*('2.1. Thưởng NCC - ver1'!$D$7:$D$24='2.2 Thưởng NCC - ver2'!$D23))} -> 0 | H23: {=SUMPRODUCT('2.1. Thưởng NCC - ver1'!$R$7:$AC$24*('2.1. Thưởng NCC - ver1'!$B$7:$B$24='2.2 Thưởng NCC - ver2'!$B23)*('2.1. Thưởng NCC - ver1'!$R$6:$AC$6='2.2 Thưởng NCC - ver2'!$F23)*('2.1. Thưởng NCC - ver1'!$D$7:$D$24='2.2 Thưởng NCC - ver2'!$D23))} -> 0 | I23: {=SUMPRODUCT('2.1. Thưởng NCC - ver1'!$AD$7:$AO$24*('2.1. Thưởng NCC - ver1'!$B$7:$B$24='2.2 Thưởng NCC - ver2'!$B23)*('2.1. Thưởng NCC - ver1'!$AD$6:$AO$6='2.2 Thưởng NCC - ver2'!$F23)*('2.1. Thưởng NCC - ver1'!$D$7:$D$24='2.2 Thưởng NCC - ver2'!$D23))} -> 0 | J23: =IFERROR(H23/G23,0) -> 0 | N23: =IF(J23<95%,0,150) -> 0 | O23: =IF(E23<>"",_xlfn.XLOOKUP($E23,'1. CS Hỗ trợ vận chuyển'!$D$8:$D$42,'1. CS Hỗ trợ vận chuyển'!$H$8:$H$42),0) -> 500 | Q23: =N23*H23/10^3 -> 0 | R23: =I23*O23/10^3 -> 0 | S23: 0 | T23: 0 | U23: =SUM(Q23,R23,S23,T23) -> 0
A24: =ROWS($A$6:A24) -> 19 | B24: Đại Lộc | C24: 001J3000002HLZuIAO | D24: HKD Bùi Văn Dương | E24: Bình Dương | F24: 3 | G24: {=SUMPRODUCT('2.1. Thưởng NCC - ver1'!$F$7:$Q$24*('2.1. Thưởng NCC - ver1'!$B$7:$B$24='2.2 Thưởng NCC - ver2'!$B24)*('2.1. Thưởng NCC - ver1'!$F$6:$Q$6='2.2 Thưởng NCC - ver2'!$F24)*('2.1. Thưởng NCC - ver1'!$D$7:$D$24='2.2 Thưởng NCC - ver2'!$D24))} -> 150 | H24: {=SUMPRODUCT('2.1. Thưởng NCC - ver1'!$R$7:$AC$24*('2.1. Thưởng NCC - ver1'!$B$7:$B$24='2.2 Thưởng NCC - ver2'!$B24)*('2.1. Thưởng NCC - ver1'!$R$6:$AC$6='2.2 Thưởng NCC - ver2'!$F24)*('2.1. Thưởng NCC - ver1'!$D$7:$D$24='2.2 Thưởng NCC - ver2'!$D24))} -> 143.573 | I24: {=SUMPRODUCT('2.1. Thưởng NCC - ver1'!$AD$7:$AO$24*('2.1. Thưởng NCC - ver1'!$B$7:$B$24='2.2 Thưởng NCC - ver2'!$B24)*('2.1. Thưởng NCC - ver1'!$AD$6:$AO$6='2.2 Thưởng NCC - ver2'!$F24)*('2.1. Thưởng NCC - ver1'!$D$7:$D$24='2.2 Thưởng NCC - ver2'!$D24))} -> 143.573 | J24: =IFERROR(H24/G24,0) -> 0.95715333 | N24: =IF(J24<95%,0,150) -> 150 | O24: =IF(E24<>"",_xlfn.XLOOKUP($E24,'1. CS Hỗ trợ vận chuyển'!$D$8:$D$42,'1. CS Hỗ trợ vận chuyển'!$H$8:$H$42),0) -> 300 | Q24: =N24*H24/10^3 -> 21.53595 | R24: =I24*O24/10^3 -> 43.0719 | S24: 0 | T24: 0 | U24: =SUM(Q24,R24,S24,T24) -> 64.60785
A25: =ROWS($A$6:A25) -> 20 | B25: Đại Lộc | C25: 001J3000002HqzBIAS | D25: HKD Vạn Phát | E25: Ninh Thuận | F25: 3 | G25: {=SUMPRODUCT('2.1. Thưởng NCC - ver1'!$F$7:$Q$24*('2.1. Thưởng NCC - ver1'!$B$7:$B$24='2.2 Thưởng NCC - ver2'!$B25)*('2.1. Thưởng NCC - ver1'!$F$6:$Q$6='2.2 Thưởng NCC - ver2'!$F25)*('2.1. Thưởng NCC - ver1'!$D$7:$D$24='2.2 Thưởng NCC - ver2'!$D25))} -> 50 | H25: {=SUMPRODUCT('2.1. Thưởng NCC - ver1'!$R$7:$AC$24*('2.1. Thưởng NCC - ver1'!$B$7:$B$24='2.2 Thưởng NCC - ver2'!$B25)*('2.1. Thưởng NCC - ver1'!$R$6:$AC$6='2.2 Thưởng NCC - ver2'!$F25)*('2.1. Thưởng NCC - ver1'!$D$7:$D$24='2.2 Thưởng NCC - ver2'!$D25))} -> 27.878 | I25: {=SUMPRODUCT('2.1. Thưởng NCC - ver1'!$AD$7:$AO$24*('2.1. Thưởng NCC - ver1'!$B$7:$B$24='2.2 Thưởng NCC - ver2'!$B25)*('2.1. Thưởng NCC - ver1'!$AD$6:$AO$6='2.2 Thưởng NCC - ver2'!$F25)*('2.1. Thưởng NCC - ver1'!$D$7:$D$24='2.2 Thưởng NCC - ver2'!$D25))} -> 27.878 | J25: =IFERROR(H25/G25,0) -> 0.55756 | N25: =IF(J25<95%,0,150) -> 0 | O25: =IF(E25<>"",_xlfn.XLOOKUP($E25,'1. CS Hỗ trợ vận chuyển'!$D$8:$D$42,'1. CS Hỗ trợ vận chuyển'!$H$8:$H$42),0) -> 400 | Q25: =N25*H25/10^3 -> 0 | R25: =I25*O25/10^3 -> 11.1512 | S25: 0 | T25: 0 | U25: =SUM(Q25,R25,S25,T25) -> 11.1512
